2025-03-31T20:40:00.729685742Z W0331 20:40:00.729601       1 feature_gate.go:227] unrecognized feature gate: RouteExternalCertificate
2025-03-31T20:40:00.729787760Z W0331 20:40:00.729778       1 feature_gate.go:227] unrecognized feature gate: VSphereStaticIPs
2025-03-31T20:40:00.729806040Z W0331 20:40:00.729799       1 feature_gate.go:227] unrecognized feature gate: ClusterAPIInstall
2025-03-31T20:40:00.729822510Z W0331 20:40:00.729816       1 feature_gate.go:227] unrecognized feature gate: ExternalCloudProvider
2025-03-31T20:40:00.729838059Z W0331 20:40:00.729831       1 feature_gate.go:227] unrecognized feature gate: ExternalCloudProviderAzure
2025-03-31T20:40:00.729853509Z W0331 20:40:00.729847       1 feature_gate.go:227] unrecognized feature gate: GatewayAPI
2025-03-31T20:40:00.729895208Z W0331 20:40:00.729862       1 feature_gate.go:227] unrecognized feature gate: MachineAPIProviderOpenStack
2025-03-31T20:40:00.729915828Z W0331 20:40:00.729908       1 feature_gate.go:227] unrecognized feature gate: MetricsServer
2025-03-31T20:40:00.729931457Z W0331 20:40:00.729925       1 feature_gate.go:227] unrecognized feature gate: PrivateHostedZoneAWS
2025-03-31T20:40:00.729946717Z W0331 20:40:00.729940       1 feature_gate.go:227] unrecognized feature gate: VSphereControlPlaneMachineSet
2025-03-31T20:40:00.729962576Z W0331 20:40:00.729956       1 feature_gate.go:227] unrecognized feature gate: ManagedBootImages
2025-03-31T20:40:00.729978386Z W0331 20:40:00.729972       1 feature_gate.go:227] unrecognized feature gate: SignatureStores
2025-03-31T20:40:00.729993616Z W0331 20:40:00.729987       1 feature_gate.go:227] unrecognized feature gate: GCPClusterHostedDNS
2025-03-31T20:40:00.730008945Z W0331 20:40:00.730002       1 feature_gate.go:227] unrecognized feature gate: InsightsConfigAPI
2025-03-31T20:40:00.730024395Z W0331 20:40:00.730018       1 feature_gate.go:227] unrecognized feature gate: ExternalCloudProviderExternal
2025-03-31T20:40:00.730039635Z W0331 20:40:00.730033       1 feature_gate.go:227] unrecognized feature gate: MixedCPUsAllocation
2025-03-31T20:40:00.730054824Z W0331 20:40:00.730048       1 feature_gate.go:227] unrecognized feature gate: CSIDriverSharedResource
2025-03-31T20:40:00.730070114Z W0331 20:40:00.730063       1 feature_gate.go:227] unrecognized feature gate: DNSNameResolver
2025-03-31T20:40:00.730086555Z W0331 20:40:00.730079       1 feature_gate.go:227] unrecognized feature gate: MachineAPIOperatorDisableMachineHealthCheckController
2025-03-31T20:40:00.730101914Z W0331 20:40:00.730095       1 feature_gate.go:227] unrecognized feature gate: MachineConfigNodes
2025-03-31T20:40:00.730117174Z W0331 20:40:00.730111       1 feature_gate.go:227] unrecognized feature gate: AdminNetworkPolicy
2025-03-31T20:40:00.730136844Z W0331 20:40:00.730130       1 feature_gate.go:227] unrecognized feature gate: AzureWorkloadIdentity
2025-03-31T20:40:00.730152593Z W0331 20:40:00.730146       1 feature_gate.go:227] unrecognized feature gate: GCPLabelsTags
2025-03-31T20:40:00.730169153Z W0331 20:40:00.730162       1 feature_gate.go:227] unrecognized feature gate: NetworkLiveMigration
2025-03-31T20:40:00.730185162Z W0331 20:40:00.730178       1 feature_gate.go:227] unrecognized feature gate: OnClusterBuild
2025-03-31T20:40:00.730200662Z W0331 20:40:00.730194       1 feature_gate.go:227] unrecognized feature gate: SigstoreImageVerification
2025-03-31T20:40:00.730215962Z W0331 20:40:00.730209       1 feature_gate.go:227] unrecognized feature gate: AlibabaPlatform
2025-03-31T20:40:00.730231191Z W0331 20:40:00.730225       1 feature_gate.go:227] unrecognized feature gate: AutomatedEtcdBackup
2025-03-31T20:40:00.730247431Z W0331 20:40:00.730241       1 feature_gate.go:227] unrecognized feature gate: InstallAlternateInfrastructureAWS
2025-03-31T20:40:00.730269001Z W0331 20:40:00.730262       1 feature_gate.go:227] unrecognized feature gate: OpenShiftPodSecurityAdmission
2025-03-31T20:40:00.730285610Z W0331 20:40:00.730279       1 feature_gate.go:227] unrecognized feature gate: BuildCSIVolumes
2025-03-31T20:40:00.730300950Z W0331 20:40:00.730294       1 feature_gate.go:227] unrecognized feature gate: ExternalCloudProviderGCP
2025-03-31T20:40:00.730373519Z I0331 20:40:00.730358       1 flags.go:64] FLAG: --allow-metric-labels="[]"
2025-03-31T20:40:00.730391649Z I0331 20:40:00.730383       1 flags.go:64] FLAG: --authentication-kubeconfig="/etc/kubernetes/static-pod-resources/configmaps/scheduler-kubeconfig/kubeconfig"
2025-03-31T20:40:00.730408108Z I0331 20:40:00.730401       1 flags.go:64] FLAG: --authentication-skip-lookup="false"
2025-03-31T20:40:00.730425178Z I0331 20:40:00.730417       1 flags.go:64] FLAG: --authentication-token-webhook-cache-ttl="10s"
2025-03-31T20:40:00.730441068Z I0331 20:40:00.730434       1 flags.go:64] FLAG: --authentication-tolerate-lookup-failure="true"
2025-03-31T20:40:00.730460907Z I0331 20:40:00.730449       1 flags.go:64] FLAG: --authorization-always-allow-paths="[/healthz,/readyz,/livez]"
2025-03-31T20:40:00.730476717Z I0331 20:40:00.730469       1 flags.go:64] FLAG: --authorization-kubeconfig="/etc/kubernetes/static-pod-resources/configmaps/scheduler-kubeconfig/kubeconfig"
2025-03-31T20:40:00.730492507Z I0331 20:40:00.730485       1 flags.go:64] FLAG: --authorization-webhook-cache-authorized-ttl="10s"
2025-03-31T20:40:00.730507466Z I0331 20:40:00.730501       1 flags.go:64] FLAG: --authorization-webhook-cache-unauthorized-ttl="10s"
2025-03-31T20:40:00.730523196Z I0331 20:40:00.730516       1 flags.go:64] FLAG: --bind-address="0.0.0.0"
2025-03-31T20:40:00.730538186Z I0331 20:40:00.730531       1 flags.go:64] FLAG: --cert-dir="/var/run/kubernetes"
2025-03-31T20:40:00.730552975Z I0331 20:40:00.730546       1 flags.go:64] FLAG: --client-ca-file=""
2025-03-31T20:40:00.730568865Z I0331 20:40:00.730562       1 flags.go:64] FLAG: --config="/etc/kubernetes/static-pod-resources/configmaps/config/config.yaml"
2025-03-31T20:40:00.730583675Z I0331 20:40:00.730577       1 flags.go:64] FLAG: --contention-profiling="true"
2025-03-31T20:40:00.730598984Z I0331 20:40:00.730592       1 flags.go:64] FLAG: --disabled-metrics="[]"
2025-03-31T20:40:00.730620894Z I0331 20:40:00.730607       1 flags.go:64] FLAG: --feature-gates="CloudDualStackNodeIPs=true,DisableKubeletCloudCredentialProviders=false,DynamicResourceAllocation=false,EventedPLEG=false,MaxUnavailableStatefulSet=false,NodeSwap=false,ValidatingAdmissionPolicy=false"
2025-03-31T20:40:00.730636693Z I0331 20:40:00.730629       1 flags.go:64] FLAG: --help="false"
2025-03-31T20:40:00.730653393Z I0331 20:40:00.730646       1 flags.go:64] FLAG: --http2-max-streams-per-connection="0"
2025-03-31T20:40:00.730669893Z I0331 20:40:00.730662       1 flags.go:64] FLAG: --kube-api-burst="100"
2025-03-31T20:40:00.730685063Z I0331 20:40:00.730678       1 flags.go:64] FLAG: --kube-api-content-type="application/vnd.kubernetes.protobuf"
2025-03-31T20:40:00.730700683Z I0331 20:40:00.730693       1 flags.go:64] FLAG: --kube-api-qps="50"
2025-03-31T20:40:00.730715903Z I0331 20:40:00.730709       1 flags.go:64] FLAG: --kubeconfig=""
2025-03-31T20:40:00.730730532Z I0331 20:40:00.730724       1 flags.go:64] FLAG: --leader-elect="true"
2025-03-31T20:40:00.730745602Z I0331 20:40:00.730739       1 flags.go:64] FLAG: --leader-elect-lease-duration="15s"
2025-03-31T20:40:00.730760372Z I0331 20:40:00.730754       1 flags.go:64] FLAG: --leader-elect-renew-deadline="10s"
2025-03-31T20:40:00.730779131Z I0331 20:40:00.730772       1 flags.go:64] FLAG: --leader-elect-resource-lock="leases"
2025-03-31T20:40:00.730794201Z I0331 20:40:00.730787       1 flags.go:64] FLAG: --leader-elect-resource-name="kube-scheduler"
2025-03-31T20:40:00.730809580Z I0331 20:40:00.730803       1 flags.go:64] FLAG: --leader-elect-resource-namespace="kube-system"
2025-03-31T20:40:00.730824420Z I0331 20:40:00.730818       1 flags.go:64] FLAG: --leader-elect-retry-period="2s"
2025-03-31T20:40:00.730839130Z I0331 20:40:00.730832       1 flags.go:64] FLAG: --log-flush-frequency="5s"
2025-03-31T20:40:00.730858489Z I0331 20:40:00.730847       1 flags.go:64] FLAG: --log-json-info-buffer-size="0"
2025-03-31T20:40:00.730884319Z I0331 20:40:00.730867       1 flags.go:64] FLAG: --log-json-split-stream="false"
2025-03-31T20:40:00.730905128Z I0331 20:40:00.730898       1 flags.go:64] FLAG: --logging-format="text"
2025-03-31T20:40:00.730920588Z I0331 20:40:00.730914       1 flags.go:64] FLAG: --master=""
2025-03-31T20:40:00.730935388Z I0331 20:40:00.730929       1 flags.go:64] FLAG: --permit-address-sharing="false"
2025-03-31T20:40:00.730950067Z I0331 20:40:00.730943       1 flags.go:64] FLAG: --permit-port-sharing="false"
2025-03-31T20:40:00.730964997Z I0331 20:40:00.730958       1 flags.go:64] FLAG: --pod-max-in-unschedulable-pods-duration="5m0s"
2025-03-31T20:40:00.730979778Z I0331 20:40:00.730973       1 flags.go:64] FLAG: --profiling="true"
2025-03-31T20:40:00.730995857Z I0331 20:40:00.730988       1 flags.go:64] FLAG: --requestheader-allowed-names="[]"
2025-03-31T20:40:00.731010767Z I0331 20:40:00.731004       1 flags.go:64] FLAG: --requestheader-client-ca-file=""
2025-03-31T20:40:00.731026227Z I0331 20:40:00.731019       1 flags.go:64] FLAG: --requestheader-extra-headers-prefix="[x-remote-extra-]"
2025-03-31T20:40:00.731041976Z I0331 20:40:00.731034       1 flags.go:64] FLAG: --requestheader-group-headers="[x-remote-group]"
2025-03-31T20:40:00.731057366Z I0331 20:40:00.731050       1 flags.go:64] FLAG: --requestheader-username-headers="[x-remote-user]"
2025-03-31T20:40:00.731073066Z I0331 20:40:00.731066       1 flags.go:64] FLAG: --secure-port="10259"
2025-03-31T20:40:00.731087735Z I0331 20:40:00.731081       1 flags.go:64] FLAG: --show-hidden-metrics-for-version=""
2025-03-31T20:40:00.731103255Z I0331 20:40:00.731096       1 flags.go:64] FLAG: --tls-cert-file="/etc/kubernetes/static-pod-resources/secrets/serving-cert/tls.crt"
2025-03-31T20:40:00.731121315Z I0331 20:40:00.731111       1 flags.go:64] FLAG: --tls-cipher-suites="[TLS_ECDHE_ECDSA_WITH_AES_128_GCM_SHA256,TLS_ECDHE_RSA_WITH_AES_128_GCM_SHA256,TLS_ECDHE_ECDSA_WITH_AES_256_GCM_SHA384,TLS_ECDHE_RSA_WITH_AES_256_GCM_SHA384,TLS_ECDHE_ECDSA_WITH_CHACHA20_POLY1305_SHA256,TLS_ECDHE_RSA_WITH_CHACHA20_POLY1305_SHA256]"
2025-03-31T20:40:00.731136504Z I0331 20:40:00.731129       1 flags.go:64] FLAG: --tls-min-version="VersionTLS12"
2025-03-31T20:40:00.731152044Z I0331 20:40:00.731145       1 flags.go:64] FLAG: --tls-private-key-file="/etc/kubernetes/static-pod-resources/secrets/serving-cert/tls.key"
2025-03-31T20:40:00.731168143Z I0331 20:40:00.731160       1 flags.go:64] FLAG: --tls-sni-cert-key="[]"
2025-03-31T20:40:00.731183383Z I0331 20:40:00.731177       1 flags.go:64] FLAG: --unsupported-kube-api-over-localhost="false"
2025-03-31T20:40:00.731199163Z I0331 20:40:00.731191       1 flags.go:64] FLAG: --v="2"
2025-03-31T20:40:00.731215292Z I0331 20:40:00.731207       1 flags.go:64] FLAG: --version="false"
2025-03-31T20:40:00.731231382Z I0331 20:40:00.731224       1 flags.go:64] FLAG: --vmodule=""
2025-03-31T20:40:00.731246212Z I0331 20:40:00.731239       1 flags.go:64] FLAG: --write-config-to=""
2025-03-31T20:40:00.736510192Z I0331 20:40:00.736449       1 dynamic_serving_content.go:113] "Loaded a new cert/key pair" name="serving-cert::/etc/kubernetes/static-pod-resources/secrets/serving-cert/tls.crt::/etc/kubernetes/static-pod-resources/secrets/serving-cert/tls.key"
2025-03-31T20:40:01.115867032Z I0331 20:40:01.115797       1 requestheader_controller.go:244] Loaded a new request header values for RequestHeaderAuthRequestController
2025-03-31T20:40:01.140242628Z I0331 20:40:01.140188       1 configfile.go:101] "Using component config" config=<
2025-03-31T20:40:01.140242628Z 	apiVersion: kubescheduler.config.k8s.io/v1
2025-03-31T20:40:01.140242628Z 	clientConnection:
2025-03-31T20:40:01.140242628Z 	  acceptContentTypes: ""
2025-03-31T20:40:01.140242628Z 	  burst: 100
2025-03-31T20:40:01.140242628Z 	  contentType: application/vnd.kubernetes.protobuf
2025-03-31T20:40:01.140242628Z 	  kubeconfig: /etc/kubernetes/static-pod-resources/configmaps/scheduler-kubeconfig/kubeconfig
2025-03-31T20:40:01.140242628Z 	  qps: 50
2025-03-31T20:40:01.140242628Z 	enableContentionProfiling: false
2025-03-31T20:40:01.140242628Z 	enableProfiling: false
2025-03-31T20:40:01.140242628Z 	kind: KubeSchedulerConfiguration
2025-03-31T20:40:01.140242628Z 	leaderElection:
2025-03-31T20:40:01.140242628Z 	  leaderElect: true
2025-03-31T20:40:01.140242628Z 	  leaseDuration: 2m17s
2025-03-31T20:40:01.140242628Z 	  renewDeadline: 1m47s
2025-03-31T20:40:01.140242628Z 	  resourceLock: leases
2025-03-31T20:40:01.140242628Z 	  resourceName: kube-scheduler
2025-03-31T20:40:01.140242628Z 	  resourceNamespace: openshift-kube-scheduler
2025-03-31T20:40:01.140242628Z 	  retryPeriod: 26s
2025-03-31T20:40:01.140242628Z 	parallelism: 16
2025-03-31T20:40:01.140242628Z 	percentageOfNodesToScore: 0
2025-03-31T20:40:01.140242628Z 	podInitialBackoffSeconds: 1
2025-03-31T20:40:01.140242628Z 	podMaxBackoffSeconds: 10
2025-03-31T20:40:01.140242628Z 	profiles:
2025-03-31T20:40:01.140242628Z 	- pluginConfig:
2025-03-31T20:40:01.140242628Z 	  - args:
2025-03-31T20:40:01.140242628Z 	      apiVersion: kubescheduler.config.k8s.io/v1
2025-03-31T20:40:01.140242628Z 	      kind: DefaultPreemptionArgs
2025-03-31T20:40:01.140242628Z 	      minCandidateNodesAbsolute: 100
2025-03-31T20:40:01.140242628Z 	      minCandidateNodesPercentage: 10
2025-03-31T20:40:01.140242628Z 	    name: DefaultPreemption
2025-03-31T20:40:01.140242628Z 	  - args:
2025-03-31T20:40:01.140242628Z 	      apiVersion: kubescheduler.config.k8s.io/v1
2025-03-31T20:40:01.140242628Z 	      hardPodAffinityWeight: 1
2025-03-31T20:40:01.140242628Z 	      ignorePreferredTermsOfExistingPods: false
2025-03-31T20:40:01.140242628Z 	      kind: InterPodAffinityArgs
2025-03-31T20:40:01.140242628Z 	    name: InterPodAffinity
2025-03-31T20:40:01.140242628Z 	  - args:
2025-03-31T20:40:01.140242628Z 	      apiVersion: kubescheduler.config.k8s.io/v1
2025-03-31T20:40:01.140242628Z 	      kind: NodeAffinityArgs
2025-03-31T20:40:01.140242628Z 	    name: NodeAffinity
2025-03-31T20:40:01.140242628Z 	  - args:
2025-03-31T20:40:01.140242628Z 	      apiVersion: kubescheduler.config.k8s.io/v1
2025-03-31T20:40:01.140242628Z 	      kind: NodeResourcesBalancedAllocationArgs
2025-03-31T20:40:01.140242628Z 	      resources:
2025-03-31T20:40:01.140242628Z 	      - name: cpu
2025-03-31T20:40:01.140242628Z 	        weight: 1
2025-03-31T20:40:01.140242628Z 	      - name: memory
2025-03-31T20:40:01.140242628Z 	        weight: 1
2025-03-31T20:40:01.140242628Z 	    name: NodeResourcesBalancedAllocation
2025-03-31T20:40:01.140242628Z 	  - args:
2025-03-31T20:40:01.140242628Z 	      apiVersion: kubescheduler.config.k8s.io/v1
2025-03-31T20:40:01.140242628Z 	      kind: NodeResourcesFitArgs
2025-03-31T20:40:01.140242628Z 	      scoringStrategy:
2025-03-31T20:40:01.140242628Z 	        resources:
2025-03-31T20:40:01.140242628Z 	        - name: cpu
2025-03-31T20:40:01.140242628Z 	          weight: 1
2025-03-31T20:40:01.140242628Z 	        - name: memory
2025-03-31T20:40:01.140242628Z 	          weight: 1
2025-03-31T20:40:01.140242628Z 	        type: LeastAllocated
2025-03-31T20:40:01.140242628Z 	    name: NodeResourcesFit
2025-03-31T20:40:01.140242628Z 	  - args:
2025-03-31T20:40:01.140242628Z 	      apiVersion: kubescheduler.config.k8s.io/v1
2025-03-31T20:40:01.140242628Z 	      defaultingType: System
2025-03-31T20:40:01.140242628Z 	      kind: PodTopologySpreadArgs
2025-03-31T20:40:01.140242628Z 	    name: PodTopologySpread
2025-03-31T20:40:01.140242628Z 	  - args:
2025-03-31T20:40:01.140242628Z 	      apiVersion: kubescheduler.config.k8s.io/v1
2025-03-31T20:40:01.140242628Z 	      bindTimeoutSeconds: 600
2025-03-31T20:40:01.140242628Z 	      kind: VolumeBindingArgs
2025-03-31T20:40:01.140242628Z 	    name: VolumeBinding
2025-03-31T20:40:01.140242628Z 	  plugins:
2025-03-31T20:40:01.140242628Z 	    bind: {}
2025-03-31T20:40:01.140242628Z 	    filter: {}
2025-03-31T20:40:01.140242628Z 	    multiPoint:
2025-03-31T20:40:01.140242628Z 	      enabled:
2025-03-31T20:40:01.140242628Z 	      - name: PrioritySort
2025-03-31T20:40:01.140242628Z 	        weight: 0
2025-03-31T20:40:01.140242628Z 	      - name: NodeUnschedulable
2025-03-31T20:40:01.140242628Z 	        weight: 0
2025-03-31T20:40:01.140242628Z 	      - name: NodeName
2025-03-31T20:40:01.140242628Z 	        weight: 0
2025-03-31T20:40:01.140242628Z 	      - name: TaintToleration
2025-03-31T20:40:01.140242628Z 	        weight: 3
2025-03-31T20:40:01.140242628Z 	      - name: NodeAffinity
2025-03-31T20:40:01.140242628Z 	        weight: 2
2025-03-31T20:40:01.140242628Z 	      - name: NodePorts
2025-03-31T20:40:01.140242628Z 	        weight: 0
2025-03-31T20:40:01.140242628Z 	      - name: NodeResourcesFit
2025-03-31T20:40:01.140242628Z 	        weight: 1
2025-03-31T20:40:01.140242628Z 	      - name: VolumeRestrictions
2025-03-31T20:40:01.140242628Z 	        weight: 0
2025-03-31T20:40:01.140242628Z 	      - name: EBSLimits
2025-03-31T20:40:01.140242628Z 	        weight: 0
2025-03-31T20:40:01.140242628Z 	      - name: GCEPDLimits
2025-03-31T20:40:01.140242628Z 	        weight: 0
2025-03-31T20:40:01.140242628Z 	      - name: NodeVolumeLimits
2025-03-31T20:40:01.140242628Z 	        weight: 0
2025-03-31T20:40:01.140242628Z 	      - name: AzureDiskLimits
2025-03-31T20:40:01.140242628Z 	        weight: 0
2025-03-31T20:40:01.140242628Z 	      - name: VolumeBinding
2025-03-31T20:40:01.140242628Z 	        weight: 0
2025-03-31T20:40:01.140242628Z 	      - name: VolumeZone
2025-03-31T20:40:01.140242628Z 	        weight: 0
2025-03-31T20:40:01.140242628Z 	      - name: PodTopologySpread
2025-03-31T20:40:01.140242628Z 	        weight: 2
2025-03-31T20:40:01.140242628Z 	      - name: InterPodAffinity
2025-03-31T20:40:01.140242628Z 	        weight: 2
2025-03-31T20:40:01.140242628Z 	      - name: DefaultPreemption
2025-03-31T20:40:01.140242628Z 	        weight: 0
2025-03-31T20:40:01.140242628Z 	      - name: NodeResourcesBalancedAllocation
2025-03-31T20:40:01.140242628Z 	        weight: 1
2025-03-31T20:40:01.140242628Z 	      - name: ImageLocality
2025-03-31T20:40:01.140242628Z 	        weight: 1
2025-03-31T20:40:01.140242628Z 	      - name: DefaultBinder
2025-03-31T20:40:01.140242628Z 	        weight: 0
2025-03-31T20:40:01.140242628Z 	      - name: SchedulingGates
2025-03-31T20:40:01.140242628Z 	        weight: 0
2025-03-31T20:40:01.140242628Z 	    permit: {}
2025-03-31T20:40:01.140242628Z 	    postBind: {}
2025-03-31T20:40:01.140242628Z 	    postFilter: {}
2025-03-31T20:40:01.140242628Z 	    preBind: {}
2025-03-31T20:40:01.140242628Z 	    preEnqueue: {}
2025-03-31T20:40:01.140242628Z 	    preFilter: {}
2025-03-31T20:40:01.140242628Z 	    preScore: {}
2025-03-31T20:40:01.140242628Z 	    queueSort: {}
2025-03-31T20:40:01.140242628Z 	    reserve: {}
2025-03-31T20:40:01.140242628Z 	    score: {}
2025-03-31T20:40:01.140242628Z 	  schedulerName: default-scheduler
2025-03-31T20:40:01.140242628Z  >
2025-03-31T20:40:01.140376875Z I0331 20:40:01.140363       1 server.go:159] "Starting Kubernetes Scheduler" version="v1.28.15+ff493be"
2025-03-31T20:40:01.140376875Z I0331 20:40:01.140369       1 server.go:161] "Golang settings" GOGC="" GOMAXPROCS="" GOTRACEBACK=""
2025-03-31T20:40:01.146443059Z I0331 20:40:01.146399       1 requestheader_controller.go:169] Starting RequestHeaderAuthRequestController
2025-03-31T20:40:01.146443059Z I0331 20:40:01.146423       1 shared_informer.go:311] Waiting for caches to sync for RequestHeaderAuthRequestController
2025-03-31T20:40:01.146477078Z I0331 20:40:01.146432       1 configmap_cafile_content.go:202] "Starting controller" name="client-ca::kube-system::extension-apiserver-authentication::client-ca-file"
2025-03-31T20:40:01.146477078Z I0331 20:40:01.146441       1 configmap_cafile_content.go:202] "Starting controller" name="client-ca::kube-system::extension-apiserver-authentication::requestheader-client-ca-file"
2025-03-31T20:40:01.146477078Z I0331 20:40:01.146449       1 shared_informer.go:311] Waiting for caches to sync for client-ca::kube-system::extension-apiserver-authentication::requestheader-client-ca-file
2025-03-31T20:40:01.146477078Z I0331 20:40:01.146449       1 shared_informer.go:311] Waiting for caches to sync for client-ca::kube-system::extension-apiserver-authentication::client-ca-file
2025-03-31T20:40:01.146734503Z I0331 20:40:01.146701       1 dynamic_serving_content.go:132] "Starting controller" name="serving-cert::/etc/kubernetes/static-pod-resources/secrets/serving-cert/tls.crt::/etc/kubernetes/static-pod-resources/secrets/serving-cert/tls.key"
2025-03-31T20:40:01.147002198Z I0331 20:40:01.146939       1 tlsconfig.go:200] "Loaded serving cert" certName="serving-cert::/etc/kubernetes/static-pod-resources/secrets/serving-cert/tls.crt::/etc/kubernetes/static-pod-resources/secrets/serving-cert/tls.key" certDetail="\"scheduler.openshift-kube-scheduler.svc\" [serving] validServingFor=[scheduler.openshift-kube-scheduler.svc,scheduler.openshift-kube-scheduler.svc.cluster.local] issuer=\"openshift-service-serving-signer@1743452529\" (2025-03-31 20:22:27 +0000 UTC to 2027-03-31 20:22:28 +0000 UTC (now=2025-03-31 20:40:01.14691007 +0000 UTC))"
2025-03-31T20:40:01.147240294Z I0331 20:40:01.147200       1 named_certificates.go:53] "Loaded SNI cert" index=0 certName="self-signed loopback" certDetail="\"apiserver-loopback-client@1743453601\" [serving] validServingFor=[apiserver-loopback-client] issuer=\"apiserver-loopback-client-ca@1743453600\" (2025-03-31 19:40:00 +0000 UTC to 2026-03-31 19:40:00 +0000 UTC (now=2025-03-31 20:40:01.147180685 +0000 UTC))"
2025-03-31T20:40:01.147240294Z I0331 20:40:01.147217       1 secure_serving.go:213] Serving securely on [::]:10259
2025-03-31T20:40:01.147270043Z I0331 20:40:01.147247       1 tlsconfig.go:240] "Starting DynamicServingCertificateController"
2025-03-31T20:40:01.155382099Z I0331 20:40:01.155328       1 node_tree.go:65] "Added node in listed group to NodeTree" node="host-10-13-0-150" zone=""
2025-03-31T20:40:01.155432517Z I0331 20:40:01.155384       1 node_tree.go:65] "Added node in listed group to NodeTree" node="host-10-13-2-160" zone=""
2025-03-31T20:40:01.155432517Z I0331 20:40:01.155413       1 node_tree.go:65] "Added node in listed group to NodeTree" node="host-10-13-2-89" zone=""
2025-03-31T20:40:01.247416995Z I0331 20:40:01.247351       1 shared_informer.go:318] Caches are synced for client-ca::kube-system::extension-apiserver-authentication::requestheader-client-ca-file
2025-03-31T20:40:01.247416995Z I0331 20:40:01.247394       1 shared_informer.go:318] Caches are synced for RequestHeaderAuthRequestController
2025-03-31T20:40:01.247618181Z I0331 20:40:01.247569       1 tlsconfig.go:178] "Loaded client CA" index=0 certName="client-ca::kube-system::extension-apiserver-authentication::client-ca-file,client-ca::kube-system::extension-apiserver-authentication::requestheader-client-ca-file" certDetail="\"aggregator-signer\" [] issuer=\"<self>\" (2025-03-31 12:55:14 +0000 UTC to 2025-04-01 12:55:14 +0000 UTC (now=2025-03-31 20:40:01.247548052 +0000 UTC))"
2025-03-31T20:40:01.247640761Z I0331 20:40:01.247627       1 shared_informer.go:318] Caches are synced for client-ca::kube-system::extension-apiserver-authentication::client-ca-file
2025-03-31T20:40:01.247691210Z I0331 20:40:01.247664       1 leaderelection.go:250] attempting to acquire leader lease openshift-kube-scheduler/kube-scheduler...
2025-03-31T20:40:01.248026883Z I0331 20:40:01.247966       1 tlsconfig.go:200] "Loaded serving cert" certName="serving-cert::/etc/kubernetes/static-pod-resources/secrets/serving-cert/tls.crt::/etc/kubernetes/static-pod-resources/secrets/serving-cert/tls.key" certDetail="\"scheduler.openshift-kube-scheduler.svc\" [serving] validServingFor=[scheduler.openshift-kube-scheduler.svc,scheduler.openshift-kube-scheduler.svc.cluster.local] issuer=\"openshift-service-serving-signer@1743452529\" (2025-03-31 20:22:27 +0000 UTC to 2027-03-31 20:22:28 +0000 UTC (now=2025-03-31 20:40:01.247952755 +0000 UTC))"
2025-03-31T20:40:01.248324617Z I0331 20:40:01.248293       1 named_certificates.go:53] "Loaded SNI cert" index=0 certName="self-signed loopback" certDetail="\"apiserver-loopback-client@1743453601\" [serving] validServingFor=[apiserver-loopback-client] issuer=\"apiserver-loopback-client-ca@1743453600\" (2025-03-31 19:40:00 +0000 UTC to 2026-03-31 19:40:00 +0000 UTC (now=2025-03-31 20:40:01.248269969 +0000 UTC))"
2025-03-31T20:40:01.248452385Z I0331 20:40:01.248422       1 tlsconfig.go:178] "Loaded client CA" index=0 certName="client-ca::kube-system::extension-apiserver-authentication::client-ca-file,client-ca::kube-system::extension-apiserver-authentication::requestheader-client-ca-file" certDetail="\"admin-kubeconfig-signer\" [] issuer=\"<self>\" (2025-03-31 12:55:13 +0000 UTC to 2035-03-29 12:55:13 +0000 UTC (now=2025-03-31 20:40:01.248408146 +0000 UTC))"
2025-03-31T20:40:01.248452385Z I0331 20:40:01.248442       1 tlsconfig.go:178] "Loaded client CA" index=1 certName="client-ca::kube-system::extension-apiserver-authentication::client-ca-file,client-ca::kube-system::extension-apiserver-authentication::requestheader-client-ca-file" certDetail="\"kubelet-signer\" [] issuer=\"<self>\" (2025-03-31 12:55:15 +0000 UTC to 2025-04-01 12:55:15 +0000 UTC (now=2025-03-31 20:40:01.248435365 +0000 UTC))"
2025-03-31T20:40:01.248485864Z I0331 20:40:01.248460       1 tlsconfig.go:178] "Loaded client CA" index=2 certName="client-ca::kube-system::extension-apiserver-authentication::client-ca-file,client-ca::kube-system::extension-apiserver-authentication::requestheader-client-ca-file" certDetail="\"kube-control-plane-signer\" [] issuer=\"<self>\" (2025-03-31 12:55:15 +0000 UTC to 2026-03-31 12:55:15 +0000 UTC (now=2025-03-31 20:40:01.248447785 +0000 UTC))"
2025-03-31T20:40:01.248485864Z I0331 20:40:01.248480       1 tlsconfig.go:178] "Loaded client CA" index=3 certName="client-ca::kube-system::extension-apiserver-authentication::client-ca-file,client-ca::kube-system::extension-apiserver-authentication::requestheader-client-ca-file" certDetail="\"kube-apiserver-to-kubelet-signer\" [] issuer=\"<self>\" (2025-03-31 12:55:15 +0000 UTC to 2026-03-31 12:55:15 +0000 UTC (now=2025-03-31 20:40:01.248467904 +0000 UTC))"
2025-03-31T20:40:01.248518164Z I0331 20:40:01.248499       1 tlsconfig.go:178] "Loaded client CA" index=4 certName="client-ca::kube-system::extension-apiserver-authentication::client-ca-file,client-ca::kube-system::extension-apiserver-authentication::requestheader-client-ca-file" certDetail="\"kubelet-bootstrap-kubeconfig-signer\" [] issuer=\"<self>\" (2025-03-31 12:55:13 +0000 UTC to 2035-03-29 12:55:13 +0000 UTC (now=2025-03-31 20:40:01.248486904 +0000 UTC))"
2025-03-31T20:40:01.248533144Z I0331 20:40:01.248517       1 tlsconfig.go:178] "Loaded client CA" index=5 certName="client-ca::kube-system::extension-apiserver-authentication::client-ca-file,client-ca::kube-system::extension-apiserver-authentication::requestheader-client-ca-file" certDetail="\"kube-csr-signer_@1743452525\" [] issuer=\"kubelet-signer\" (2025-03-31 20:22:04 +0000 UTC to 2025-04-01 12:55:15 +0000 UTC (now=2025-03-31 20:40:01.248505704 +0000 UTC))"
2025-03-31T20:40:01.248547593Z I0331 20:40:01.248539       1 tlsconfig.go:178] "Loaded client CA" index=6 certName="client-ca::kube-system::extension-apiserver-authentication::client-ca-file,client-ca::kube-system::extension-apiserver-authentication::requestheader-client-ca-file" certDetail="\"openshift-kube-apiserver-operator_node-system-admin-signer@1743452539\" [] issuer=\"<self>\" (2025-03-31 20:22:18 +0000 UTC to 2026-03-31 20:22:19 +0000 UTC (now=2025-03-31 20:40:01.248524444 +0000 UTC))"
2025-03-31T20:40:01.248565383Z I0331 20:40:01.248555       1 tlsconfig.go:178] "Loaded client CA" index=7 certName="client-ca::kube-system::extension-apiserver-authentication::client-ca-file,client-ca::kube-system::extension-apiserver-authentication::requestheader-client-ca-file" certDetail="\"aggregator-signer\" [] issuer=\"<self>\" (2025-03-31 12:55:14 +0000 UTC to 2025-04-01 12:55:14 +0000 UTC (now=2025-03-31 20:40:01.248546524 +0000 UTC))"
2025-03-31T20:40:01.248929746Z I0331 20:40:01.248898       1 tlsconfig.go:200] "Loaded serving cert" certName="serving-cert::/etc/kubernetes/static-pod-resources/secrets/serving-cert/tls.crt::/etc/kubernetes/static-pod-resources/secrets/serving-cert/tls.key" certDetail="\"scheduler.openshift-kube-scheduler.svc\" [serving] validServingFor=[scheduler.openshift-kube-scheduler.svc,scheduler.openshift-kube-scheduler.svc.cluster.local] issuer=\"openshift-service-serving-signer@1743452529\" (2025-03-31 20:22:27 +0000 UTC to 2027-03-31 20:22:28 +0000 UTC (now=2025-03-31 20:40:01.248888507 +0000 UTC))"
2025-03-31T20:40:01.249197331Z I0331 20:40:01.249164       1 named_certificates.go:53] "Loaded SNI cert" index=0 certName="self-signed loopback" certDetail="\"apiserver-loopback-client@1743453601\" [serving] validServingFor=[apiserver-loopback-client] issuer=\"apiserver-loopback-client-ca@1743453600\" (2025-03-31 19:40:00 +0000 UTC to 2026-03-31 19:40:00 +0000 UTC (now=2025-03-31 20:40:01.249145732 +0000 UTC))"
2025-03-31T20:40:01.258421755Z I0331 20:40:01.258369       1 leaderelection.go:260] successfully acquired lease openshift-kube-scheduler/kube-scheduler
2025-03-31T20:40:34.209618679Z I0331 20:40:34.209572       1 schedule_one.go:286] "Successfully bound pod to node" pod="openshift-multus/cni-sysctl-allowlist-ds-s575d" node="host-10-13-0-150" evaluatedNodes=1 feasibleNodes=1
2025-03-31T20:40:34.216059085Z I0331 20:40:34.216035       1 schedule_one.go:286] "Successfully bound pod to node" pod="openshift-multus/cni-sysctl-allowlist-ds-dsk26" node="host-10-13-2-160" evaluatedNodes=1 feasibleNodes=1
2025-03-31T20:40:34.226191343Z I0331 20:40:34.226164       1 schedule_one.go:286] "Successfully bound pod to node" pod="openshift-multus/cni-sysctl-allowlist-ds-n8jwf" node="host-10-13-2-89" evaluatedNodes=1 feasibleNodes=1
2025-03-31T20:44:02.780966815Z I0331 20:44:02.780939       1 schedule_one.go:286] "Successfully bound pod to node" pod="openshift-marketplace/community-operators-f8njj" node="host-10-13-2-160" evaluatedNodes=3 feasibleNodes=3
2025-03-31T20:44:25.878324680Z I0331 20:44:25.877244       1 schedule_one.go:286] "Successfully bound pod to node" pod="openshift-marketplace/redhat-operators-4zn6n" node="host-10-13-2-160" evaluatedNodes=3 feasibleNodes=3
2025-03-31T20:44:52.846486896Z I0331 20:44:52.846357       1 schedule_one.go:286] "Successfully bound pod to node" pod="openshift-marketplace/redhat-marketplace-czkjz" node="host-10-13-2-160" evaluatedNodes=3 feasibleNodes=3
2025-03-31T20:45:00.218342809Z I0331 20:45:00.218271       1 schedule_one.go:286] "Successfully bound pod to node" pod="openshift-operator-lifecycle-manager/collect-profiles-29057565-vp9jn" node="host-10-13-0-150" evaluatedNodes=3 feasibleNodes=3
2025-03-31T20:47:36.442801745Z I0331 20:47:36.442743       1 schedule_one.go:286] "Successfully bound pod to node" pod="openshift-marketplace/certified-operators-v7q4d" node="host-10-13-2-160" evaluatedNodes=3 feasibleNodes=3
2025-03-31T20:54:29.540864218Z I0331 20:54:29.540821       1 schedule_one.go:286] "Successfully bound pod to node" pod="openshift-marketplace/community-operators-zt4cn" node="host-10-13-2-160" evaluatedNodes=3 feasibleNodes=3
2025-03-31T20:54:32.140408973Z I0331 20:54:32.140365       1 schedule_one.go:286] "Successfully bound pod to node" pod="openshift-marketplace/redhat-operators-zwggb" node="host-10-13-2-89" evaluatedNodes=3 feasibleNodes=3
2025-03-31T20:58:38.094660742Z I0331 20:58:38.094609       1 schedule_one.go:286] "Successfully bound pod to node" pod="openshift-marketplace/redhat-marketplace-z7vjm" node="host-10-13-2-160" evaluatedNodes=3 feasibleNodes=3
2025-03-31T20:58:39.466964993Z I0331 20:58:39.466913       1 schedule_one.go:286] "Successfully bound pod to node" pod="openshift-marketplace/certified-operators-88tj4" node="host-10-13-2-89" evaluatedNodes=3 feasibleNodes=3
2025-03-31T21:00:00.165006627Z I0331 21:00:00.164951       1 schedule_one.go:286] "Successfully bound pod to node" pod="openshift-operator-lifecycle-manager/collect-profiles-29057580-j44hb" node="host-10-13-0-150" evaluatedNodes=3 feasibleNodes=3
2025-03-31T21:04:56.396015331Z I0331 21:04:56.395939       1 schedule_one.go:286] "Successfully bound pod to node" pod="openshift-marketplace/redhat-operators-4c46l" node="host-10-13-2-160" evaluatedNodes=3 feasibleNodes=3
2025-03-31T21:04:57.959626965Z I0331 21:04:57.959541       1 schedule_one.go:286] "Successfully bound pod to node" pod="openshift-marketplace/community-operators-626bk" node="host-10-13-2-89" evaluatedNodes=3 feasibleNodes=3
2025-03-31T21:09:07.803554926Z I0331 21:09:07.803500       1 schedule_one.go:286] "Successfully bound pod to node" pod="openshift-marketplace/certified-operators-585th" node="host-10-13-2-160" evaluatedNodes=3 feasibleNodes=3
2025-03-31T21:09:11.946424637Z I0331 21:09:11.946369       1 schedule_one.go:286] "Successfully bound pod to node" pod="openshift-marketplace/redhat-marketplace-m56k7" node="host-10-13-2-89" evaluatedNodes=3 feasibleNodes=3
2025-03-31T21:15:00.160868766Z I0331 21:15:00.160780       1 schedule_one.go:286] "Successfully bound pod to node" pod="openshift-operator-lifecycle-manager/collect-profiles-29057595-j5ntw" node="host-10-13-0-150" evaluatedNodes=3 feasibleNodes=3
2025-03-31T21:15:28.970349781Z I0331 21:15:28.970263       1 schedule_one.go:286] "Successfully bound pod to node" pod="openshift-marketplace/community-operators-jkv74" node="host-10-13-2-160" evaluatedNodes=3 feasibleNodes=3
2025-03-31T21:15:31.549089374Z I0331 21:15:31.549018       1 schedule_one.go:286] "Successfully bound pod to node" pod="openshift-marketplace/redhat-operators-wbqlq" node="host-10-13-2-89" evaluatedNodes=3 feasibleNodes=3
2025-03-31T21:20:16.250696462Z I0331 21:20:16.250549       1 schedule_one.go:286] "Successfully bound pod to node" pod="openshift-marketplace/certified-operators-vfrc6" node="host-10-13-2-160" evaluatedNodes=3 feasibleNodes=3
2025-03-31T21:20:37.118019421Z I0331 21:20:37.117398       1 schedule_one.go:286] "Successfully bound pod to node" pod="openshift-marketplace/redhat-marketplace-ltmql" node="host-10-13-2-160" evaluatedNodes=3 feasibleNodes=3
2025-03-31T21:25:32.033220684Z I0331 21:25:32.033078       1 schedule_one.go:286] "Successfully bound pod to node" pod="openshift-marketplace/redhat-operators-nw79g" node="host-10-13-2-160" evaluatedNodes=3 feasibleNodes=3
2025-03-31T21:26:12.425797934Z I0331 21:26:12.425727       1 schedule_one.go:286] "Successfully bound pod to node" pod="openshift-marketplace/community-operators-9dp9b" node="host-10-13-2-160" evaluatedNodes=3 feasibleNodes=3
2025-03-31T21:30:00.165985449Z I0331 21:30:00.163029       1 schedule_one.go:286] "Successfully bound pod to node" pod="openshift-operator-lifecycle-manager/collect-profiles-29057610-2h7q9" node="host-10-13-0-150" evaluatedNodes=3 feasibleNodes=3
2025-03-31T21:31:42.460083734Z I0331 21:31:42.460024       1 schedule_one.go:286] "Successfully bound pod to node" pod="openshift-marketplace/redhat-marketplace-tjrdv" node="host-10-13-2-160" evaluatedNodes=3 feasibleNodes=3
2025-03-31T21:34:20.779319695Z I0331 21:34:20.778641       1 schedule_one.go:286] "Successfully bound pod to node" pod="openshift-marketplace/certified-operators-dhnvj" node="host-10-13-2-160" evaluatedNodes=3 feasibleNodes=3
2025-03-31T21:35:58.213750849Z I0331 21:35:58.213598       1 schedule_one.go:286] "Successfully bound pod to node" pod="openshift-marketplace/redhat-operators-268wm" node="host-10-13-2-160" evaluatedNodes=3 feasibleNodes=3
2025-03-31T21:36:30.649436201Z I0331 21:36:30.649133       1 schedule_one.go:286] "Successfully bound pod to node" pod="openshift-marketplace/community-operators-7mqdz" node="host-10-13-2-160" evaluatedNodes=3 feasibleNodes=3
2025-03-31T21:41:51.629527298Z I0331 21:41:51.626269       1 schedule_one.go:286] "Successfully bound pod to node" pod="openshift-marketplace/redhat-marketplace-zdrf7" node="host-10-13-2-89" evaluatedNodes=3 feasibleNodes=3
2025-03-31T21:44:35.392024886Z I0331 21:44:35.391989       1 schedule_one.go:286] "Successfully bound pod to node" pod="openshift-marketplace/certified-operators-k9f6f" node="host-10-13-2-89" evaluatedNodes=3 feasibleNodes=3
2025-03-31T21:45:00.248656206Z I0331 21:45:00.248397       1 schedule_one.go:286] "Successfully bound pod to node" pod="openshift-operator-lifecycle-manager/collect-profiles-29057625-dzt6x" node="host-10-13-0-150" evaluatedNodes=3 feasibleNodes=3
2025-03-31T21:46:59.129349755Z I0331 21:46:59.129267       1 schedule_one.go:286] "Successfully bound pod to node" pod="openshift-marketplace/redhat-operators-cfvs4" node="host-10-13-2-89" evaluatedNodes=3 feasibleNodes=3
2025-03-31T21:48:02.921976185Z I0331 21:48:02.921939       1 schedule_one.go:286] "Successfully bound pod to node" pod="openshift-marketplace/community-operators-ff6zd" node="host-10-13-2-89" evaluatedNodes=3 feasibleNodes=3
2025-03-31T21:52:09.302952088Z I0331 21:52:09.301445       1 schedule_one.go:286] "Successfully bound pod to node" pod="openshift-marketplace/redhat-marketplace-msmkt" node="host-10-13-2-89" evaluatedNodes=3 feasibleNodes=3
2025-03-31T21:55:34.440935480Z I0331 21:55:34.440290       1 schedule_one.go:286] "Successfully bound pod to node" pod="openshift-marketplace/certified-operators-pndhl" node="host-10-13-2-89" evaluatedNodes=3 feasibleNodes=3
2025-03-31T21:57:46.566946175Z I0331 21:57:46.566863       1 schedule_one.go:286] "Successfully bound pod to node" pod="openshift-marketplace/redhat-operators-nlx4w" node="host-10-13-2-89" evaluatedNodes=3 feasibleNodes=3
2025-03-31T21:59:22.731191677Z I0331 21:59:22.731012       1 schedule_one.go:286] "Successfully bound pod to node" pod="openshift-marketplace/community-operators-gbdl2" node="host-10-13-2-89" evaluatedNodes=3 feasibleNodes=3
2025-03-31T22:00:00.161866510Z I0331 22:00:00.161810       1 schedule_one.go:286] "Successfully bound pod to node" pod="openshift-operator-lifecycle-manager/collect-profiles-29057640-kdppf" node="host-10-13-0-150" evaluatedNodes=3 feasibleNodes=3
2025-03-31T22:02:55.411636224Z I0331 22:02:55.411548       1 schedule_one.go:286] "Successfully bound pod to node" pod="openshift-marketplace/redhat-marketplace-l5nmp" node="host-10-13-2-89" evaluatedNodes=3 feasibleNodes=3
2025-03-31T22:06:33.047208616Z I0331 22:06:33.047159       1 schedule_one.go:286] "Successfully bound pod to node" pod="openshift-marketplace/certified-operators-pbkfb" node="host-10-13-2-89" evaluatedNodes=3 feasibleNodes=3
2025-03-31T22:07:56.808552028Z I0331 22:07:56.808465       1 schedule_one.go:286] "Successfully bound pod to node" pod="openshift-marketplace/redhat-operators-c7bdf" node="host-10-13-2-89" evaluatedNodes=3 feasibleNodes=3
2025-03-31T22:10:02.889968280Z I0331 22:10:02.889792       1 schedule_one.go:286] "Successfully bound pod to node" pod="openshift-marketplace/community-operators-jg2ch" node="host-10-13-2-89" evaluatedNodes=3 feasibleNodes=3
2025-03-31T22:12:59.055452284Z I0331 22:12:59.055345       1 schedule_one.go:286] "Successfully bound pod to node" pod="openshift-marketplace/redhat-marketplace-cfmzv" node="host-10-13-2-89" evaluatedNodes=3 feasibleNodes=3
2025-03-31T22:15:00.160242788Z I0331 22:15:00.159973       1 schedule_one.go:286] "Successfully bound pod to node" pod="openshift-operator-lifecycle-manager/collect-profiles-29057655-5fwtm" node="host-10-13-0-150" evaluatedNodes=3 feasibleNodes=3
2025-03-31T22:16:40.410825409Z I0331 22:16:40.410789       1 schedule_one.go:286] "Successfully bound pod to node" pod="openshift-marketplace/certified-operators-zkcm2" node="host-10-13-2-89" evaluatedNodes=3 feasibleNodes=3
2025-03-31T22:18:49.266318459Z I0331 22:18:49.266241       1 schedule_one.go:286] "Successfully bound pod to node" pod="openshift-marketplace/redhat-operators-vvbzs" node="host-10-13-2-89" evaluatedNodes=3 feasibleNodes=3
2025-03-31T22:20:35.719420664Z I0331 22:20:35.719295       1 schedule_one.go:286] "Successfully bound pod to node" pod="openshift-marketplace/community-operators-hdr58" node="host-10-13-2-89" evaluatedNodes=3 feasibleNodes=3
2025-03-31T22:24:15.442297018Z I0331 22:24:15.442230       1 schedule_one.go:286] "Successfully bound pod to node" pod="openshift-marketplace/redhat-marketplace-q8ppf" node="host-10-13-2-89" evaluatedNodes=3 feasibleNodes=3
2025-03-31T22:26:45.419766911Z I0331 22:26:45.419383       1 schedule_one.go:286] "Successfully bound pod to node" pod="openshift-marketplace/certified-operators-ggkh2" node="host-10-13-2-89" evaluatedNodes=3 feasibleNodes=3
2025-03-31T22:29:24.580929456Z I0331 22:29:24.580828       1 schedule_one.go:286] "Successfully bound pod to node" pod="openshift-marketplace/redhat-operators-gpldw" node="host-10-13-2-89" evaluatedNodes=3 feasibleNodes=3
2025-03-31T22:30:00.156329193Z I0331 22:30:00.156194       1 schedule_one.go:286] "Successfully bound pod to node" pod="openshift-operator-lifecycle-manager/collect-profiles-29057670-57nk8" node="host-10-13-0-150" evaluatedNodes=3 feasibleNodes=3
2025-03-31T22:34:39.241444692Z I0331 22:34:39.241366       1 schedule_one.go:286] "Successfully bound pod to node" pod="openshift-marketplace/community-operators-65g72" node="host-10-13-2-89" evaluatedNodes=3 feasibleNodes=3
2025-03-31T22:34:39.435832509Z I0331 22:34:39.435418       1 schedule_one.go:286] "Successfully bound pod to node" pod="openshift-marketplace/redhat-marketplace-tp92d" node="host-10-13-2-89" evaluatedNodes=3 feasibleNodes=3
2025-03-31T22:36:57.645439276Z I0331 22:36:57.645073       1 schedule_one.go:286] "Successfully bound pod to node" pod="openshift-marketplace/certified-operators-sx67v" node="host-10-13-2-89" evaluatedNodes=3 feasibleNodes=3
2025-03-31T22:39:40.189021131Z I0331 22:39:40.188949       1 schedule_one.go:286] "Successfully bound pod to node" pod="openshift-marketplace/redhat-operators-2htf7" node="host-10-13-2-89" evaluatedNodes=3 feasibleNodes=3
2025-03-31T22:45:00.223491337Z I0331 22:45:00.223410       1 schedule_one.go:286] "Successfully bound pod to node" pod="openshift-operator-lifecycle-manager/collect-profiles-29057685-vbnpk" node="host-10-13-0-150" evaluatedNodes=3 feasibleNodes=3
2025-03-31T22:45:12.201181876Z I0331 22:45:12.201103       1 schedule_one.go:286] "Successfully bound pod to node" pod="openshift-marketplace/community-operators-g65nx" node="host-10-13-2-89" evaluatedNodes=3 feasibleNodes=3
2025-03-31T22:45:23.941083946Z I0331 22:45:23.941012       1 schedule_one.go:286] "Successfully bound pod to node" pod="openshift-marketplace/redhat-marketplace-qwr8h" node="host-10-13-2-89" evaluatedNodes=3 feasibleNodes=3
2025-03-31T22:47:40.068986154Z I0331 22:47:40.068762       1 schedule_one.go:286] "Successfully bound pod to node" pod="openshift-marketplace/certified-operators-x4smf" node="host-10-13-2-89" evaluatedNodes=3 feasibleNodes=3
2025-03-31T22:54:31.956782927Z I0331 22:54:31.956294       1 schedule_one.go:286] "Successfully bound pod to node" pod="openshift-marketplace/redhat-operators-8lkmt" node="host-10-13-2-89" evaluatedNodes=3 feasibleNodes=3
2025-03-31T22:56:05.388297230Z I0331 22:56:05.388254       1 schedule_one.go:286] "Successfully bound pod to node" pod="openshift-marketplace/redhat-marketplace-sh5gz" node="host-10-13-2-89" evaluatedNodes=3 feasibleNodes=3
2025-03-31T23:00:00.160015129Z I0331 23:00:00.156038       1 schedule_one.go:286] "Successfully bound pod to node" pod="openshift-operator-lifecycle-manager/collect-profiles-29057700-6s9jg" node="host-10-13-0-150" evaluatedNodes=3 feasibleNodes=3
2025-03-31T23:00:34.714026022Z I0331 23:00:34.713986       1 schedule_one.go:286] "Successfully bound pod to node" pod="openshift-marketplace/certified-operators-mxnj9" node="host-10-13-2-89" evaluatedNodes=3 feasibleNodes=3
2025-03-31T23:00:34.721169792Z I0331 23:00:34.721090       1 schedule_one.go:286] "Successfully bound pod to node" pod="openshift-marketplace/community-operators-gdqmk" node="host-10-13-2-89" evaluatedNodes=3 feasibleNodes=3
2025-03-31T23:05:30.180236934Z I0331 23:05:30.180076       1 schedule_one.go:286] "Successfully bound pod to node" pod="openshift-marketplace/redhat-operators-mpkqw" node="host-10-13-2-89" evaluatedNodes=3 feasibleNodes=3
2025-03-31T23:06:44.742246338Z I0331 23:06:44.742203       1 schedule_one.go:286] "Successfully bound pod to node" pod="openshift-marketplace/redhat-marketplace-v675j" node="host-10-13-2-89" evaluatedNodes=3 feasibleNodes=3
2025-03-31T23:12:02.162702841Z I0331 23:12:02.162168       1 schedule_one.go:286] "Successfully bound pod to node" pod="openshift-marketplace/community-operators-6sbj4" node="host-10-13-2-89" evaluatedNodes=3 feasibleNodes=3
2025-03-31T23:12:04.759696945Z I0331 23:12:04.757772       1 schedule_one.go:286] "Successfully bound pod to node" pod="openshift-marketplace/certified-operators-rvmrj" node="host-10-13-2-89" evaluatedNodes=3 feasibleNodes=3
2025-03-31T23:15:00.160108189Z I0331 23:15:00.158003       1 schedule_one.go:286] "Successfully bound pod to node" pod="openshift-operator-lifecycle-manager/collect-profiles-29057715-6ndk4" node="host-10-13-0-150" evaluatedNodes=3 feasibleNodes=3
2025-03-31T23:16:50.916162201Z I0331 23:16:50.916039       1 schedule_one.go:286] "Successfully bound pod to node" pod="openshift-marketplace/redhat-marketplace-7bl7w" node="host-10-13-2-89" evaluatedNodes=3 feasibleNodes=3
2025-03-31T23:21:26.510365872Z I0331 23:21:26.510087       1 schedule_one.go:286] "Successfully bound pod to node" pod="openshift-marketplace/redhat-operators-qw827" node="host-10-13-2-89" evaluatedNodes=3 feasibleNodes=3
2025-03-31T23:22:11.624374227Z I0331 23:22:11.624290       1 schedule_one.go:286] "Successfully bound pod to node" pod="openshift-marketplace/certified-operators-n98zz" node="host-10-13-2-89" evaluatedNodes=3 feasibleNodes=3
2025-03-31T23:24:29.556254957Z I0331 23:24:29.556000       1 schedule_one.go:286] "Successfully bound pod to node" pod="openshift-marketplace/community-operators-7nwbp" node="host-10-13-2-89" evaluatedNodes=3 feasibleNodes=3
2025-03-31T23:27:53.310598233Z I0331 23:27:53.310478       1 schedule_one.go:286] "Successfully bound pod to node" pod="openshift-marketplace/redhat-marketplace-lwnzc" node="host-10-13-2-89" evaluatedNodes=3 feasibleNodes=3
2025-03-31T23:30:00.151566740Z I0331 23:30:00.151451       1 schedule_one.go:286] "Successfully bound pod to node" pod="openshift-operator-lifecycle-manager/collect-profiles-29057730-s9vcq" node="host-10-13-0-150" evaluatedNodes=3 feasibleNodes=3
2025-03-31T23:34:31.361966586Z I0331 23:34:31.360937       1 schedule_one.go:286] "Successfully bound pod to node" pod="openshift-marketplace/certified-operators-rxpn2" node="host-10-13-2-89" evaluatedNodes=3 feasibleNodes=3
2025-03-31T23:34:47.698060587Z I0331 23:34:47.696099       1 schedule_one.go:286] "Successfully bound pod to node" pod="openshift-marketplace/community-operators-hzss7" node="host-10-13-2-89" evaluatedNodes=3 feasibleNodes=3
2025-03-31T23:36:51.192315878Z I0331 23:36:51.191517       1 schedule_one.go:286] "Successfully bound pod to node" pod="openshift-marketplace/redhat-operators-877pw" node="host-10-13-2-89" evaluatedNodes=3 feasibleNodes=3
2025-03-31T23:39:12.803856492Z I0331 23:39:12.803545       1 schedule_one.go:286] "Successfully bound pod to node" pod="openshift-marketplace/redhat-marketplace-dgd28" node="host-10-13-2-89" evaluatedNodes=3 feasibleNodes=3
2025-03-31T23:44:36.507455527Z I0331 23:44:36.507030       1 schedule_one.go:286] "Successfully bound pod to node" pod="openshift-marketplace/certified-operators-bjkpx" node="host-10-13-2-89" evaluatedNodes=3 feasibleNodes=3
2025-03-31T23:45:00.248344893Z I0331 23:45:00.245269       1 schedule_one.go:286] "Successfully bound pod to node" pod="openshift-operator-lifecycle-manager/collect-profiles-29057745-2lhpc" node="host-10-13-0-150" evaluatedNodes=3 feasibleNodes=3
2025-03-31T23:48:55.909640800Z I0331 23:48:55.909441       1 schedule_one.go:286] "Successfully bound pod to node" pod="openshift-marketplace/community-operators-5bfs2" node="host-10-13-2-89" evaluatedNodes=3 feasibleNodes=3
2025-03-31T23:48:57.277061249Z I0331 23:48:57.276681       1 schedule_one.go:286] "Successfully bound pod to node" pod="openshift-marketplace/redhat-operators-b4jqz" node="host-10-13-2-89" evaluatedNodes=3 feasibleNodes=3
2025-03-31T23:49:39.523156423Z I0331 23:49:39.523080       1 schedule_one.go:286] "Successfully bound pod to node" pod="openshift-marketplace/redhat-marketplace-xxl6w" node="host-10-13-2-89" evaluatedNodes=3 feasibleNodes=3
2025-03-31T23:57:09.231844079Z I0331 23:57:09.230401       1 schedule_one.go:286] "Successfully bound pod to node" pod="openshift-marketplace/certified-operators-dwjzg" node="host-10-13-2-89" evaluatedNodes=3 feasibleNodes=3
2025-03-31T23:59:04.396564106Z I0331 23:59:04.396441       1 schedule_one.go:286] "Successfully bound pod to node" pod="openshift-marketplace/redhat-operators-wb52c" node="host-10-13-2-89" evaluatedNodes=3 feasibleNodes=3
2025-04-01T00:00:00.152162851Z I0401 00:00:00.152091       1 schedule_one.go:286] "Successfully bound pod to node" pod="openshift-operator-lifecycle-manager/collect-profiles-29057760-c8g7z" node="host-10-13-0-150" evaluatedNodes=3 feasibleNodes=3
2025-04-01T00:00:00.168655849Z I0401 00:00:00.168538       1 schedule_one.go:286] "Successfully bound pod to node" pod="openshift-image-registry/image-pruner-29057760-x6f7s" node="host-10-13-2-89" evaluatedNodes=3 feasibleNodes=3
2025-04-01T00:00:57.250008781Z I0401 00:00:57.249942       1 schedule_one.go:286] "Successfully bound pod to node" pod="openshift-marketplace/redhat-marketplace-jjmhb" node="host-10-13-2-89" evaluatedNodes=3 feasibleNodes=3
2025-04-01T00:01:01.187232651Z I0401 00:01:01.187170       1 schedule_one.go:286] "Successfully bound pod to node" pod="openshift-marketplace/community-operators-t67pl" node="host-10-13-2-89" evaluatedNodes=3 feasibleNodes=3
2025-04-01T00:07:21.363769896Z I0401 00:07:21.363673       1 schedule_one.go:286] "Successfully bound pod to node" pod="openshift-marketplace/certified-operators-vq82h" node="host-10-13-2-89" evaluatedNodes=3 feasibleNodes=3
2025-04-01T00:09:32.356042124Z I0401 00:09:32.355957       1 schedule_one.go:286] "Successfully bound pod to node" pod="openshift-marketplace/redhat-operators-zhm97" node="host-10-13-2-89" evaluatedNodes=3 feasibleNodes=3
2025-04-01T00:11:10.684533522Z I0401 00:11:10.684480       1 schedule_one.go:286] "Successfully bound pod to node" pod="openshift-marketplace/community-operators-lcmk9" node="host-10-13-2-89" evaluatedNodes=3 feasibleNodes=3
2025-04-01T00:12:18.801711479Z I0401 00:12:18.801087       1 schedule_one.go:286] "Successfully bound pod to node" pod="openshift-marketplace/redhat-marketplace-5hzcb" node="host-10-13-2-89" evaluatedNodes=3 feasibleNodes=3
2025-04-01T00:15:00.160200666Z I0401 00:15:00.160153       1 schedule_one.go:286] "Successfully bound pod to node" pod="openshift-operator-lifecycle-manager/collect-profiles-29057775-2vnvl" node="host-10-13-0-150" evaluatedNodes=3 feasibleNodes=3
2025-04-01T00:18:15.452269539Z I0401 00:18:15.452240       1 schedule_one.go:286] "Successfully bound pod to node" pod="openshift-marketplace/certified-operators-xq7jw" node="host-10-13-2-89" evaluatedNodes=3 feasibleNodes=3
2025-04-01T00:24:29.553005000Z I0401 00:24:29.552953       1 schedule_one.go:286] "Successfully bound pod to node" pod="openshift-marketplace/community-operators-vwjpk" node="host-10-13-2-89" evaluatedNodes=3 feasibleNodes=3
2025-04-01T00:24:30.955494626Z I0401 00:24:30.955444       1 schedule_one.go:286] "Successfully bound pod to node" pod="openshift-marketplace/redhat-marketplace-nftks" node="host-10-13-2-89" evaluatedNodes=3 feasibleNodes=3
2025-04-01T00:24:32.359058042Z I0401 00:24:32.358991       1 schedule_one.go:286] "Successfully bound pod to node" pod="openshift-marketplace/redhat-operators-v4tl5" node="host-10-13-2-160" evaluatedNodes=3 feasibleNodes=3
2025-04-01T00:30:00.159653818Z I0401 00:30:00.157140       1 schedule_one.go:286] "Successfully bound pod to node" pod="openshift-operator-lifecycle-manager/collect-profiles-29057790-65gnc" node="host-10-13-0-150" evaluatedNodes=3 feasibleNodes=3
2025-04-01T00:31:51.344703329Z I0401 00:31:51.344636       1 schedule_one.go:286] "Successfully bound pod to node" pod="openshift-marketplace/certified-operators-lmwzx" node="host-10-13-2-89" evaluatedNodes=3 feasibleNodes=3
2025-04-01T00:34:32.137078656Z I0401 00:34:32.135455       1 schedule_one.go:286] "Successfully bound pod to node" pod="openshift-marketplace/redhat-operators-p8kgv" node="host-10-13-2-89" evaluatedNodes=3 feasibleNodes=3
2025-04-01T00:34:35.952505154Z I0401 00:34:35.952441       1 schedule_one.go:286] "Successfully bound pod to node" pod="openshift-marketplace/redhat-marketplace-bpj7x" node="host-10-13-2-89" evaluatedNodes=3 feasibleNodes=3
2025-04-01T00:37:17.086259301Z I0401 00:37:17.086206       1 schedule_one.go:286] "Successfully bound pod to node" pod="openshift-marketplace/community-operators-h9xfd" node="host-10-13-2-89" evaluatedNodes=3 feasibleNodes=3
2025-04-01T00:44:41.571708148Z I0401 00:44:41.571631       1 schedule_one.go:286] "Successfully bound pod to node" pod="openshift-marketplace/redhat-operators-jvr8x" node="host-10-13-2-89" evaluatedNodes=3 feasibleNodes=3
2025-04-01T00:44:52.742408153Z I0401 00:44:52.742341       1 schedule_one.go:286] "Successfully bound pod to node" pod="openshift-marketplace/certified-operators-jv2f8" node="host-10-13-2-160" evaluatedNodes=3 feasibleNodes=3
2025-04-01T00:44:52.750591164Z I0401 00:44:52.750550       1 schedule_one.go:286] "Successfully bound pod to node" pod="openshift-marketplace/redhat-marketplace-ts9sc" node="host-10-13-2-89" evaluatedNodes=3 feasibleNodes=3
2025-04-01T00:45:00.183108723Z I0401 00:45:00.183020       1 schedule_one.go:286] "Successfully bound pod to node" pod="openshift-operator-lifecycle-manager/collect-profiles-29057805-kszlw" node="host-10-13-0-150" evaluatedNodes=3 feasibleNodes=3
2025-04-01T00:48:26.026395226Z I0401 00:48:26.026322       1 schedule_one.go:286] "Successfully bound pod to node" pod="openshift-marketplace/community-operators-26skm" node="host-10-13-2-89" evaluatedNodes=3 feasibleNodes=3
2025-04-01T00:55:18.337366987Z I0401 00:55:18.337284       1 schedule_one.go:286] "Successfully bound pod to node" pod="openshift-marketplace/redhat-marketplace-w6zc6" node="host-10-13-2-89" evaluatedNodes=3 feasibleNodes=3
2025-04-01T00:57:54.178623910Z I0401 00:57:54.178553       1 schedule_one.go:286] "Successfully bound pod to node" pod="openshift-marketplace/certified-operators-sp2tm" node="host-10-13-2-89" evaluatedNodes=3 feasibleNodes=3
2025-04-01T00:57:55.526967214Z I0401 00:57:55.526913       1 schedule_one.go:286] "Successfully bound pod to node" pod="openshift-marketplace/redhat-operators-tj7fr" node="host-10-13-2-89" evaluatedNodes=3 feasibleNodes=3
2025-04-01T00:58:27.444364943Z I0401 00:58:27.444112       1 schedule_one.go:286] "Successfully bound pod to node" pod="openshift-marketplace/community-operators-g5fvr" node="host-10-13-2-89" evaluatedNodes=3 feasibleNodes=3
2025-04-01T01:00:00.160993692Z I0401 01:00:00.160941       1 schedule_one.go:286] "Successfully bound pod to node" pod="openshift-operator-lifecycle-manager/collect-profiles-29057820-2zzzm" node="host-10-13-0-150" evaluatedNodes=3 feasibleNodes=3
2025-04-01T01:06:14.903399755Z I0401 01:06:14.903321       1 schedule_one.go:286] "Successfully bound pod to node" pod="openshift-marketplace/redhat-marketplace-6k2fz" node="host-10-13-2-89" evaluatedNodes=3 feasibleNodes=3
2025-04-01T01:08:32.827580504Z I0401 01:08:32.827180       1 schedule_one.go:286] "Successfully bound pod to node" pod="openshift-marketplace/redhat-operators-m6mvf" node="host-10-13-2-89" evaluatedNodes=3 feasibleNodes=3
2025-04-01T01:08:33.006166630Z I0401 01:08:33.006103       1 schedule_one.go:286] "Successfully bound pod to node" pod="openshift-marketplace/certified-operators-8vs8l" node="host-10-13-2-89" evaluatedNodes=3 feasibleNodes=3
2025-04-01T01:08:34.405385699Z I0401 01:08:34.404337       1 schedule_one.go:286] "Successfully bound pod to node" pod="openshift-marketplace/community-operators-xv75w" node="host-10-13-2-89" evaluatedNodes=3 feasibleNodes=3
2025-04-01T01:15:00.157569204Z I0401 01:15:00.157473       1 schedule_one.go:286] "Successfully bound pod to node" pod="openshift-operator-lifecycle-manager/collect-profiles-29057835-kxqj7" node="host-10-13-0-150" evaluatedNodes=3 feasibleNodes=3
2025-04-01T01:16:26.190934578Z I0401 01:16:26.190838       1 schedule_one.go:286] "Successfully bound pod to node" pod="openshift-marketplace/redhat-marketplace-7snvc" node="host-10-13-2-89" evaluatedNodes=3 feasibleNodes=3
2025-04-01T01:18:34.882527633Z I0401 01:18:34.882369       1 schedule_one.go:286] "Successfully bound pod to node" pod="openshift-marketplace/certified-operators-nnjtz" node="host-10-13-2-89" evaluatedNodes=3 feasibleNodes=3
2025-04-01T01:19:01.971294613Z I0401 01:19:01.971129       1 schedule_one.go:286] "Successfully bound pod to node" pod="openshift-marketplace/community-operators-675m4" node="host-10-13-2-89" evaluatedNodes=3 feasibleNodes=3
2025-04-01T01:19:59.215014576Z I0401 01:19:59.214944       1 schedule_one.go:286] "Successfully bound pod to node" pod="openshift-marketplace/redhat-operators-tvf7m" node="host-10-13-2-89" evaluatedNodes=3 feasibleNodes=3
2025-04-01T01:27:13.753163780Z I0401 01:27:13.752994       1 schedule_one.go:286] "Successfully bound pod to node" pod="openshift-marketplace/redhat-marketplace-6tx6n" node="host-10-13-2-89" evaluatedNodes=3 feasibleNodes=3
2025-04-01T01:30:00.158519910Z I0401 01:30:00.158396       1 schedule_one.go:286] "Successfully bound pod to node" pod="openshift-operator-lifecycle-manager/collect-profiles-29057850-4xvxq" node="host-10-13-0-150" evaluatedNodes=3 feasibleNodes=3
2025-04-01T01:31:09.312119224Z I0401 01:31:09.310840       1 schedule_one.go:286] "Successfully bound pod to node" pod="openshift-marketplace/redhat-operators-99fxr" node="host-10-13-2-89" evaluatedNodes=3 feasibleNodes=3
2025-04-01T01:33:33.747888321Z I0401 01:33:33.747491       1 schedule_one.go:286] "Successfully bound pod to node" pod="openshift-marketplace/certified-operators-d566m" node="host-10-13-2-89" evaluatedNodes=3 feasibleNodes=3
2025-04-01T01:34:34.731109714Z I0401 01:34:34.730792       1 schedule_one.go:286] "Successfully bound pod to node" pod="openshift-marketplace/community-operators-2rg5x" node="host-10-13-2-89" evaluatedNodes=3 feasibleNodes=3
2025-04-01T01:37:44.159607718Z I0401 01:37:44.159529       1 schedule_one.go:286] "Successfully bound pod to node" pod="openshift-marketplace/redhat-marketplace-mlnrv" node="host-10-13-2-89" evaluatedNodes=3 feasibleNodes=3
2025-04-01T01:44:15.531471732Z I0401 01:44:15.530318       1 schedule_one.go:286] "Successfully bound pod to node" pod="openshift-marketplace/redhat-operators-jw8sp" node="host-10-13-2-89" evaluatedNodes=3 feasibleNodes=3
2025-04-01T01:44:15.717342947Z I0401 01:44:15.717287       1 schedule_one.go:286] "Successfully bound pod to node" pod="openshift-marketplace/certified-operators-zj5wn" node="host-10-13-2-89" evaluatedNodes=3 feasibleNodes=3
2025-04-01T01:45:00.234193161Z I0401 01:45:00.233752       1 schedule_one.go:286] "Successfully bound pod to node" pod="openshift-operator-lifecycle-manager/collect-profiles-29057865-96s7p" node="host-10-13-0-150" evaluatedNodes=3 feasibleNodes=3
2025-04-01T01:45:10.002386976Z I0401 01:45:10.001749       1 schedule_one.go:286] "Successfully bound pod to node" pod="openshift-marketplace/community-operators-j6r5h" node="host-10-13-2-89" evaluatedNodes=3 feasibleNodes=3
2025-04-01T01:48:10.488501329Z I0401 01:48:10.488306       1 schedule_one.go:286] "Successfully bound pod to node" pod="openshift-marketplace/redhat-marketplace-fzrf5" node="host-10-13-2-89" evaluatedNodes=3 feasibleNodes=3
2025-04-01T01:54:28.391253478Z I0401 01:54:28.391202       1 schedule_one.go:286] "Successfully bound pod to node" pod="openshift-marketplace/certified-operators-xnjrv" node="host-10-13-2-89" evaluatedNodes=3 feasibleNodes=3
2025-04-01T01:54:32.757112266Z I0401 01:54:32.757073       1 schedule_one.go:286] "Successfully bound pod to node" pod="openshift-marketplace/redhat-operators-kbrdl" node="host-10-13-2-89" evaluatedNodes=3 feasibleNodes=3
2025-04-01T01:56:20.942350805Z I0401 01:56:20.940691       1 schedule_one.go:286] "Successfully bound pod to node" pod="openshift-marketplace/community-operators-4np5t" node="host-10-13-2-89" evaluatedNodes=3 feasibleNodes=3
2025-04-01T01:58:17.581275686Z I0401 01:58:17.581190       1 schedule_one.go:286] "Successfully bound pod to node" pod="openshift-marketplace/redhat-marketplace-z84wq" node="host-10-13-2-89" evaluatedNodes=3 feasibleNodes=3
2025-04-01T02:00:00.155963349Z I0401 02:00:00.155866       1 schedule_one.go:286] "Successfully bound pod to node" pod="openshift-operator-lifecycle-manager/collect-profiles-29057880-qkv9x" node="host-10-13-0-150" evaluatedNodes=3 feasibleNodes=3
2025-04-01T02:04:45.449668482Z I0401 02:04:45.449603       1 schedule_one.go:286] "Successfully bound pod to node" pod="openshift-marketplace/redhat-operators-dh584" node="host-10-13-2-89" evaluatedNodes=3 feasibleNodes=3
2025-04-01T02:05:04.722504375Z I0401 02:05:04.722258       1 schedule_one.go:286] "Successfully bound pod to node" pod="openshift-marketplace/certified-operators-hhbqf" node="host-10-13-2-89" evaluatedNodes=3 feasibleNodes=3
2025-04-01T02:06:34.428627864Z I0401 02:06:34.428101       1 schedule_one.go:286] "Successfully bound pod to node" pod="openshift-marketplace/community-operators-wrhwr" node="host-10-13-2-89" evaluatedNodes=3 feasibleNodes=3
2025-04-01T02:09:04.187392932Z I0401 02:09:04.187316       1 schedule_one.go:286] "Successfully bound pod to node" pod="openshift-marketplace/redhat-marketplace-2lkfb" node="host-10-13-2-89" evaluatedNodes=3 feasibleNodes=3
2025-04-01T02:15:00.158653270Z I0401 02:15:00.151717       1 schedule_one.go:286] "Successfully bound pod to node" pod="openshift-operator-lifecycle-manager/collect-profiles-29057895-mq9fn" node="host-10-13-0-150" evaluatedNodes=3 feasibleNodes=3
2025-04-01T02:16:02.248100694Z I0401 02:16:02.248067       1 schedule_one.go:286] "Successfully bound pod to node" pod="openshift-marketplace/redhat-operators-7tkpc" node="host-10-13-2-89" evaluatedNodes=3 feasibleNodes=3
2025-04-01T02:16:04.039252173Z I0401 02:16:04.039193       1 schedule_one.go:286] "Successfully bound pod to node" pod="openshift-marketplace/certified-operators-vmfs5" node="host-10-13-2-89" evaluatedNodes=3 feasibleNodes=3
2025-04-01T02:19:57.052159075Z I0401 02:19:57.052106       1 schedule_one.go:286] "Successfully bound pod to node" pod="openshift-marketplace/redhat-marketplace-kg8ts" node="host-10-13-2-89" evaluatedNodes=3 feasibleNodes=3
2025-04-01T02:19:58.421707642Z I0401 02:19:58.420185       1 schedule_one.go:286] "Successfully bound pod to node" pod="openshift-marketplace/community-operators-qvm54" node="host-10-13-2-89" evaluatedNodes=3 feasibleNodes=3
2025-04-01T02:26:04.763769470Z I0401 02:26:04.762587       1 schedule_one.go:286] "Successfully bound pod to node" pod="openshift-marketplace/certified-operators-5xpns" node="host-10-13-2-89" evaluatedNodes=3 feasibleNodes=3
2025-04-01T02:26:06.139392933Z I0401 02:26:06.138784       1 schedule_one.go:286] "Successfully bound pod to node" pod="openshift-marketplace/redhat-operators-8ldbc" node="host-10-13-2-89" evaluatedNodes=3 feasibleNodes=3
2025-04-01T02:30:00.170542314Z I0401 02:30:00.168190       1 schedule_one.go:286] "Successfully bound pod to node" pod="openshift-operator-lifecycle-manager/collect-profiles-29057910-hdcmf" node="host-10-13-0-150" evaluatedNodes=3 feasibleNodes=3
2025-04-01T02:30:54.676160252Z I0401 02:30:54.676099       1 schedule_one.go:286] "Successfully bound pod to node" pod="openshift-marketplace/redhat-marketplace-k26jq" node="host-10-13-2-89" evaluatedNodes=3 feasibleNodes=3
2025-04-01T02:34:07.747958165Z I0401 02:34:07.747012       1 schedule_one.go:286] "Successfully bound pod to node" pod="openshift-marketplace/community-operators-7qhst" node="host-10-13-2-89" evaluatedNodes=3 feasibleNodes=3
2025-04-01T02:36:29.327422745Z I0401 02:36:29.327144       1 schedule_one.go:286] "Successfully bound pod to node" pod="openshift-marketplace/redhat-operators-hm2gr" node="host-10-13-2-89" evaluatedNodes=3 feasibleNodes=3
2025-04-01T02:37:48.682568849Z I0401 02:37:48.682250       1 schedule_one.go:286] "Successfully bound pod to node" pod="openshift-marketplace/certified-operators-sp8t7" node="host-10-13-2-89" evaluatedNodes=3 feasibleNodes=3
2025-04-01T02:41:41.829563443Z I0401 02:41:41.829502       1 schedule_one.go:286] "Successfully bound pod to node" pod="openshift-marketplace/redhat-marketplace-l4dnn" node="host-10-13-2-89" evaluatedNodes=3 feasibleNodes=3
2025-04-01T02:45:00.226723974Z I0401 02:45:00.226694       1 schedule_one.go:286] "Successfully bound pod to node" pod="openshift-operator-lifecycle-manager/collect-profiles-29057925-v77mk" node="host-10-13-0-150" evaluatedNodes=3 feasibleNodes=3
2025-04-01T02:45:13.589431071Z I0401 02:45:13.589393       1 schedule_one.go:286] "Successfully bound pod to node" pod="openshift-marketplace/community-operators-jqrhn" node="host-10-13-2-89" evaluatedNodes=3 feasibleNodes=3
2025-04-01T02:46:52.745122838Z I0401 02:46:52.744967       1 schedule_one.go:286] "Successfully bound pod to node" pod="openshift-marketplace/redhat-operators-9d46z" node="host-10-13-2-89" evaluatedNodes=3 feasibleNodes=3
2025-04-01T02:48:35.886510821Z I0401 02:48:35.886450       1 schedule_one.go:286] "Successfully bound pod to node" pod="openshift-marketplace/certified-operators-bqv6f" node="host-10-13-2-89" evaluatedNodes=3 feasibleNodes=3
2025-04-01T02:52:42.012560696Z I0401 02:52:42.011715       1 schedule_one.go:286] "Successfully bound pod to node" pod="openshift-marketplace/redhat-marketplace-gcdf6" node="host-10-13-2-89" evaluatedNodes=3 feasibleNodes=3
2025-04-01T02:55:39.145309662Z I0401 02:55:39.144855       1 schedule_one.go:286] "Successfully bound pod to node" pod="openshift-marketplace/community-operators-t29rh" node="host-10-13-2-89" evaluatedNodes=3 feasibleNodes=3
2025-04-01T02:57:00.123941059Z I0401 02:57:00.123333       1 schedule_one.go:286] "Successfully bound pod to node" pod="openshift-marketplace/redhat-operators-zqwzw" node="host-10-13-2-89" evaluatedNodes=3 feasibleNodes=3
2025-04-01T02:59:24.661006212Z I0401 02:59:24.660916       1 schedule_one.go:286] "Successfully bound pod to node" pod="openshift-marketplace/certified-operators-ppnst" node="host-10-13-2-89" evaluatedNodes=3 feasibleNodes=3
2025-04-01T03:00:00.160266499Z I0401 03:00:00.160191       1 schedule_one.go:286] "Successfully bound pod to node" pod="openshift-operator-lifecycle-manager/collect-profiles-29057940-b2wb5" node="host-10-13-0-150" evaluatedNodes=3 feasibleNodes=3
2025-04-01T03:08:08.250012515Z I0401 03:08:08.249955       1 schedule_one.go:286] "Successfully bound pod to node" pod="openshift-marketplace/community-operators-54fmd" node="host-10-13-2-89" evaluatedNodes=3 feasibleNodes=3
2025-04-01T03:08:08.428823277Z I0401 03:08:08.428529       1 schedule_one.go:286] "Successfully bound pod to node" pod="openshift-marketplace/redhat-marketplace-kwczm" node="host-10-13-2-89" evaluatedNodes=3 feasibleNodes=3
2025-04-01T03:08:09.824729736Z I0401 03:08:09.824628       1 schedule_one.go:286] "Successfully bound pod to node" pod="openshift-marketplace/redhat-operators-jkc9n" node="host-10-13-2-160" evaluatedNodes=3 feasibleNodes=3
2025-04-01T03:09:42.850002458Z I0401 03:09:42.849943       1 schedule_one.go:286] "Successfully bound pod to node" pod="openshift-marketplace/certified-operators-fss66" node="host-10-13-2-160" evaluatedNodes=3 feasibleNodes=3
2025-04-01T03:15:00.169047661Z I0401 03:15:00.165614       1 schedule_one.go:286] "Successfully bound pod to node" pod="openshift-operator-lifecycle-manager/collect-profiles-29057955-k5wgm" node="host-10-13-0-150" evaluatedNodes=3 feasibleNodes=3
2025-04-01T03:18:14.137642191Z I0401 03:18:14.137610       1 schedule_one.go:286] "Successfully bound pod to node" pod="openshift-marketplace/community-operators-2ld86" node="host-10-13-2-160" evaluatedNodes=3 feasibleNodes=3
2025-04-01T03:19:03.654438076Z I0401 03:19:03.654398       1 schedule_one.go:286] "Successfully bound pod to node" pod="openshift-marketplace/redhat-marketplace-769xt" node="host-10-13-2-160" evaluatedNodes=3 feasibleNodes=3
2025-04-01T03:19:27.257846670Z I0401 03:19:27.257816       1 schedule_one.go:286] "Successfully bound pod to node" pod="openshift-marketplace/redhat-operators-9rcwf" node="host-10-13-2-160" evaluatedNodes=3 feasibleNodes=3
2025-04-01T03:20:48.062231627Z I0401 03:20:48.062062       1 schedule_one.go:286] "Successfully bound pod to node" pod="openshift-marketplace/certified-operators-kvdww" node="host-10-13-2-89" evaluatedNodes=3 feasibleNodes=3
2025-04-01T03:29:30.943145606Z I0401 03:29:30.943006       1 schedule_one.go:286] "Successfully bound pod to node" pod="openshift-marketplace/redhat-operators-zgk98" node="host-10-13-2-89" evaluatedNodes=3 feasibleNodes=3
2025-04-01T03:29:43.107727898Z I0401 03:29:43.107377       1 schedule_one.go:286] "Successfully bound pod to node" pod="openshift-marketplace/community-operators-4n25q" node="host-10-13-2-89" evaluatedNodes=3 feasibleNodes=3
2025-04-01T03:30:00.140195234Z I0401 03:30:00.140102       1 schedule_one.go:286] "Successfully bound pod to node" pod="openshift-operator-lifecycle-manager/collect-profiles-29057970-b6s4k" node="host-10-13-0-150" evaluatedNodes=3 feasibleNodes=3
2025-04-01T03:30:28.820306483Z I0401 03:30:28.820241       1 schedule_one.go:286] "Successfully bound pod to node" pod="openshift-marketplace/redhat-marketplace-7vgcd" node="host-10-13-2-89" evaluatedNodes=3 feasibleNodes=3
2025-04-01T03:31:21.264369711Z I0401 03:31:21.264149       1 schedule_one.go:286] "Successfully bound pod to node" pod="openshift-marketplace/certified-operators-w5kkm" node="host-10-13-2-89" evaluatedNodes=3 feasibleNodes=3
2025-04-01T03:40:14.768291111Z I0401 03:40:14.768230       1 schedule_one.go:286] "Successfully bound pod to node" pod="openshift-marketplace/redhat-operators-q978q" node="host-10-13-2-89" evaluatedNodes=3 feasibleNodes=3
2025-04-01T03:40:34.225527891Z I0401 03:40:34.225327       1 schedule_one.go:286] "Successfully bound pod to node" pod="openshift-marketplace/community-operators-h765h" node="host-10-13-2-89" evaluatedNodes=3 feasibleNodes=3
2025-04-01T03:42:43.180097273Z I0401 03:42:43.179323       1 schedule_one.go:286] "Successfully bound pod to node" pod="openshift-marketplace/certified-operators-6r7g8" node="host-10-13-2-89" evaluatedNodes=3 feasibleNodes=3
2025-04-01T03:45:00.249291028Z I0401 03:45:00.249213       1 schedule_one.go:286] "Successfully bound pod to node" pod="openshift-operator-lifecycle-manager/collect-profiles-29057985-qk25x" node="host-10-13-0-150" evaluatedNodes=3 feasibleNodes=3
2025-04-01T03:47:13.053557978Z I0401 03:47:13.053230       1 schedule_one.go:286] "Successfully bound pod to node" pod="openshift-marketplace/redhat-marketplace-v2tdp" node="host-10-13-2-89" evaluatedNodes=3 feasibleNodes=3
2025-04-01T03:50:41.861173149Z I0401 03:50:41.861122       1 schedule_one.go:286] "Successfully bound pod to node" pod="openshift-marketplace/community-operators-8vs8d" node="host-10-13-2-89" evaluatedNodes=3 feasibleNodes=3
2025-04-01T03:50:43.229848930Z I0401 03:50:43.229815       1 schedule_one.go:286] "Successfully bound pod to node" pod="openshift-marketplace/redhat-operators-gktpn" node="host-10-13-2-89" evaluatedNodes=3 feasibleNodes=3
2025-04-01T03:54:04.728379646Z I0401 03:54:04.728232       1 schedule_one.go:286] "Successfully bound pod to node" pod="openshift-marketplace/certified-operators-vm5pj" node="host-10-13-2-89" evaluatedNodes=3 feasibleNodes=3
2025-04-01T03:58:32.735688079Z I0401 03:58:32.735644       1 schedule_one.go:286] "Successfully bound pod to node" pod="openshift-marketplace/redhat-marketplace-v4nzs" node="host-10-13-2-89" evaluatedNodes=3 feasibleNodes=3
2025-04-01T04:00:00.157855489Z I0401 04:00:00.157128       1 schedule_one.go:286] "Successfully bound pod to node" pod="openshift-operator-lifecycle-manager/collect-profiles-29058000-msc58" node="host-10-13-0-150" evaluatedNodes=3 feasibleNodes=3
2025-04-01T04:01:29.323348979Z I0401 04:01:29.323287       1 schedule_one.go:286] "Successfully bound pod to node" pod="openshift-marketplace/redhat-operators-48crj" node="host-10-13-2-89" evaluatedNodes=3 feasibleNodes=3
2025-04-01T04:02:47.145895306Z I0401 04:02:47.144480       1 schedule_one.go:286] "Successfully bound pod to node" pod="openshift-marketplace/community-operators-c4t7q" node="host-10-13-2-89" evaluatedNodes=3 feasibleNodes=3
2025-04-01T04:07:03.361732339Z I0401 04:07:03.361452       1 schedule_one.go:286] "Successfully bound pod to node" pod="openshift-marketplace/certified-operators-c9hfn" node="host-10-13-2-89" evaluatedNodes=3 feasibleNodes=3
2025-04-01T04:09:05.487535673Z I0401 04:09:05.486768       1 schedule_one.go:286] "Successfully bound pod to node" pod="openshift-marketplace/redhat-marketplace-g7v88" node="host-10-13-2-89" evaluatedNodes=3 feasibleNodes=3
2025-04-01T04:13:15.280505067Z I0401 04:13:15.280426       1 schedule_one.go:286] "Successfully bound pod to node" pod="openshift-marketplace/redhat-operators-lqk6j" node="host-10-13-2-89" evaluatedNodes=3 feasibleNodes=3
2025-04-01T04:13:15.464239152Z I0401 04:13:15.464174       1 schedule_one.go:286] "Successfully bound pod to node" pod="openshift-marketplace/community-operators-m6kxk" node="host-10-13-2-89" evaluatedNodes=3 feasibleNodes=3
2025-04-01T04:15:00.153061873Z I0401 04:15:00.152970       1 schedule_one.go:286] "Successfully bound pod to node" pod="openshift-operator-lifecycle-manager/collect-profiles-29058015-6knf6" node="host-10-13-0-150" evaluatedNodes=3 feasibleNodes=3
2025-04-01T04:17:58.552175690Z I0401 04:17:58.552128       1 schedule_one.go:286] "Successfully bound pod to node" pod="openshift-marketplace/certified-operators-nwfsx" node="host-10-13-2-89" evaluatedNodes=3 feasibleNodes=3
2025-04-01T04:19:26.081112465Z I0401 04:19:26.081041       1 schedule_one.go:286] "Successfully bound pod to node" pod="openshift-marketplace/redhat-marketplace-wtxfp" node="host-10-13-2-89" evaluatedNodes=3 feasibleNodes=3
2025-04-01T04:23:58.982344759Z I0401 04:23:58.982083       1 schedule_one.go:286] "Successfully bound pod to node" pod="openshift-marketplace/community-operators-6545p" node="host-10-13-2-89" evaluatedNodes=3 feasibleNodes=3
2025-04-01T04:24:11.349389501Z I0401 04:24:11.348610       1 schedule_one.go:286] "Successfully bound pod to node" pod="openshift-marketplace/redhat-operators-dj74v" node="host-10-13-2-89" evaluatedNodes=3 feasibleNodes=3
2025-04-01T04:29:02.533275721Z I0401 04:29:02.533214       1 schedule_one.go:286] "Successfully bound pod to node" pod="openshift-marketplace/certified-operators-dmdp2" node="host-10-13-2-89" evaluatedNodes=3 feasibleNodes=3
2025-04-01T04:30:00.157751673Z I0401 04:30:00.157681       1 schedule_one.go:286] "Successfully bound pod to node" pod="openshift-operator-lifecycle-manager/collect-profiles-29058030-tqlgl" node="host-10-13-0-150" evaluatedNodes=3 feasibleNodes=3
2025-04-01T04:30:29.116604918Z I0401 04:30:29.114890       1 schedule_one.go:286] "Successfully bound pod to node" pod="openshift-marketplace/redhat-marketplace-vq6gg" node="host-10-13-2-89" evaluatedNodes=3 feasibleNodes=3
2025-04-01T04:35:10.860049891Z I0401 04:35:10.858860       1 schedule_one.go:286] "Successfully bound pod to node" pod="openshift-marketplace/redhat-operators-7s5p6" node="host-10-13-2-89" evaluatedNodes=3 feasibleNodes=3
2025-04-01T04:39:03.042691873Z I0401 04:39:03.042623       1 schedule_one.go:286] "Successfully bound pod to node" pod="openshift-marketplace/certified-operators-wtt6p" node="host-10-13-2-89" evaluatedNodes=3 feasibleNodes=3
2025-04-01T04:39:03.053595548Z I0401 04:39:03.053554       1 schedule_one.go:286] "Successfully bound pod to node" pod="openshift-marketplace/community-operators-2lh4d" node="host-10-13-2-89" evaluatedNodes=3 feasibleNodes=3
2025-04-01T04:41:49.720038895Z I0401 04:41:49.719955       1 schedule_one.go:286] "Successfully bound pod to node" pod="openshift-marketplace/redhat-marketplace-2h67p" node="host-10-13-2-89" evaluatedNodes=3 feasibleNodes=3
2025-04-01T04:45:00.228134593Z I0401 04:45:00.227021       1 schedule_one.go:286] "Successfully bound pod to node" pod="openshift-operator-lifecycle-manager/collect-profiles-29058045-xqgt9" node="host-10-13-0-150" evaluatedNodes=3 feasibleNodes=3
2025-04-01T04:50:04.230105538Z I0401 04:50:04.230054       1 schedule_one.go:286] "Successfully bound pod to node" pod="openshift-marketplace/certified-operators-br56h" node="host-10-13-2-89" evaluatedNodes=3 feasibleNodes=3
2025-04-01T04:51:08.349459793Z I0401 04:51:08.348857       1 schedule_one.go:286] "Successfully bound pod to node" pod="openshift-marketplace/community-operators-bbs2j" node="host-10-13-2-89" evaluatedNodes=3 feasibleNodes=3
2025-04-01T04:51:08.517596222Z I0401 04:51:08.517322       1 schedule_one.go:286] "Successfully bound pod to node" pod="openshift-marketplace/redhat-operators-96fkm" node="host-10-13-2-89" evaluatedNodes=3 feasibleNodes=3
2025-04-01T04:51:49.723791561Z I0401 04:51:49.723699       1 schedule_one.go:286] "Successfully bound pod to node" pod="openshift-marketplace/redhat-marketplace-gflw6" node="host-10-13-2-89" evaluatedNodes=3 feasibleNodes=3
2025-04-01T05:00:00.175909562Z I0401 05:00:00.169035       1 schedule_one.go:286] "Successfully bound pod to node" pod="openshift-operator-lifecycle-manager/collect-profiles-29058060-rsspp" node="host-10-13-0-150" evaluatedNodes=3 feasibleNodes=3
2025-04-01T05:00:37.102522875Z I0401 05:00:37.101712       1 schedule_one.go:286] "Successfully bound pod to node" pod="openshift-marketplace/certified-operators-2jb4q" node="host-10-13-2-89" evaluatedNodes=3 feasibleNodes=3
2025-04-01T05:03:13.637620277Z I0401 05:03:13.637351       1 schedule_one.go:286] "Successfully bound pod to node" pod="openshift-marketplace/redhat-operators-2shlz" node="host-10-13-2-89" evaluatedNodes=3 feasibleNodes=3
2025-04-01T05:03:13.807663626Z I0401 05:03:13.807381       1 schedule_one.go:286] "Successfully bound pod to node" pod="openshift-marketplace/community-operators-fn8fr" node="host-10-13-2-89" evaluatedNodes=3 feasibleNodes=3
2025-04-01T05:03:15.210263604Z I0401 05:03:15.209817       1 schedule_one.go:286] "Successfully bound pod to node" pod="openshift-marketplace/redhat-marketplace-bq9l8" node="host-10-13-2-160" evaluatedNodes=3 feasibleNodes=3
2025-04-01T05:11:17.181259183Z I0401 05:11:17.181181       1 schedule_one.go:286] "Successfully bound pod to node" pod="openshift-marketplace/certified-operators-b6gmb" node="host-10-13-2-89" evaluatedNodes=3 feasibleNodes=3
2025-04-01T05:13:26.035522617Z I0401 05:13:26.035116       1 schedule_one.go:286] "Successfully bound pod to node" pod="openshift-marketplace/redhat-marketplace-hxzfs" node="host-10-13-2-89" evaluatedNodes=3 feasibleNodes=3
2025-04-01T05:13:31.611310460Z I0401 05:13:31.609917       1 schedule_one.go:286] "Successfully bound pod to node" pod="openshift-marketplace/community-operators-j5n4s" node="host-10-13-2-89" evaluatedNodes=3 feasibleNodes=3
2025-04-01T05:14:01.224820383Z I0401 05:14:01.224668       1 schedule_one.go:286] "Successfully bound pod to node" pod="openshift-marketplace/redhat-operators-sprkx" node="host-10-13-2-89" evaluatedNodes=3 feasibleNodes=3
2025-04-01T05:15:00.161298466Z I0401 05:15:00.160894       1 schedule_one.go:286] "Successfully bound pod to node" pod="openshift-operator-lifecycle-manager/collect-profiles-29058075-77hbg" node="host-10-13-0-150" evaluatedNodes=3 feasibleNodes=3
2025-04-01T05:24:26.013311575Z I0401 05:24:26.013040       1 schedule_one.go:286] "Successfully bound pod to node" pod="openshift-marketplace/community-operators-x6mbn" node="host-10-13-2-89" evaluatedNodes=3 feasibleNodes=3
2025-04-01T05:24:28.589035406Z I0401 05:24:28.586983       1 schedule_one.go:286] "Successfully bound pod to node" pod="openshift-marketplace/certified-operators-h2zg9" node="host-10-13-2-89" evaluatedNodes=3 feasibleNodes=3
2025-04-01T05:24:31.587712955Z I0401 05:24:31.586004       1 schedule_one.go:286] "Successfully bound pod to node" pod="openshift-marketplace/redhat-marketplace-49mqd" node="host-10-13-2-160" evaluatedNodes=3 feasibleNodes=3
2025-04-01T05:24:33.180799150Z I0401 05:24:33.180517       1 schedule_one.go:286] "Successfully bound pod to node" pod="openshift-marketplace/redhat-operators-qvc7j" node="host-10-13-2-89" evaluatedNodes=3 feasibleNodes=3
2025-04-01T05:30:00.164157446Z I0401 05:30:00.163960       1 schedule_one.go:286] "Successfully bound pod to node" pod="openshift-operator-lifecycle-manager/collect-profiles-29058090-5ghcj" node="host-10-13-0-150" evaluatedNodes=3 feasibleNodes=3
2025-04-01T05:35:19.563077007Z I0401 05:35:19.562696       1 schedule_one.go:286] "Successfully bound pod to node" pod="openshift-marketplace/community-operators-pqvt9" node="host-10-13-2-89" evaluatedNodes=3 feasibleNodes=3
2025-04-01T05:35:50.315759952Z I0401 05:35:50.315324       1 schedule_one.go:286] "Successfully bound pod to node" pod="openshift-marketplace/redhat-operators-8xklf" node="host-10-13-2-89" evaluatedNodes=3 feasibleNodes=3
2025-04-01T05:36:18.630380496Z I0401 05:36:18.629764       1 schedule_one.go:286] "Successfully bound pod to node" pod="openshift-marketplace/redhat-marketplace-tjt72" node="host-10-13-2-89" evaluatedNodes=3 feasibleNodes=3
2025-04-01T05:36:18.636573305Z I0401 05:36:18.636347       1 schedule_one.go:286] "Successfully bound pod to node" pod="openshift-marketplace/certified-operators-8x9c7" node="host-10-13-2-89" evaluatedNodes=3 feasibleNodes=3
2025-04-01T05:45:00.216922034Z I0401 05:45:00.216763       1 schedule_one.go:286] "Successfully bound pod to node" pod="openshift-operator-lifecycle-manager/collect-profiles-29058105-946x2" node="host-10-13-0-150" evaluatedNodes=3 feasibleNodes=3
2025-04-01T05:45:22.545180239Z I0401 05:45:22.545108       1 schedule_one.go:286] "Successfully bound pod to node" pod="openshift-marketplace/community-operators-k42fz" node="host-10-13-2-89" evaluatedNodes=3 feasibleNodes=3
2025-04-01T05:46:09.588177892Z I0401 05:46:09.588097       1 schedule_one.go:286] "Successfully bound pod to node" pod="openshift-marketplace/redhat-operators-2bzkb" node="host-10-13-2-89" evaluatedNodes=3 feasibleNodes=3
2025-04-01T05:46:30.681276417Z I0401 05:46:30.679443       1 schedule_one.go:286] "Successfully bound pod to node" pod="openshift-marketplace/redhat-marketplace-792j9" node="host-10-13-2-89" evaluatedNodes=3 feasibleNodes=3
2025-04-01T05:47:03.375095910Z I0401 05:47:03.375067       1 schedule_one.go:286] "Successfully bound pod to node" pod="openshift-marketplace/certified-operators-k5lnz" node="host-10-13-2-89" evaluatedNodes=3 feasibleNodes=3
2025-04-01T05:55:53.416163764Z I0401 05:55:53.415388       1 schedule_one.go:286] "Successfully bound pod to node" pod="openshift-marketplace/community-operators-nwl6b" node="host-10-13-2-89" evaluatedNodes=3 feasibleNodes=3
2025-04-01T05:56:48.437983437Z I0401 05:56:48.437933       1 schedule_one.go:286] "Successfully bound pod to node" pod="openshift-marketplace/redhat-operators-wn7b2" node="host-10-13-2-89" evaluatedNodes=3 feasibleNodes=3
2025-04-01T05:57:26.558506036Z I0401 05:57:26.558443       1 schedule_one.go:286] "Successfully bound pod to node" pod="openshift-marketplace/certified-operators-wd8dd" node="host-10-13-2-89" evaluatedNodes=3 feasibleNodes=3
2025-04-01T05:57:26.737020189Z I0401 05:57:26.736850       1 schedule_one.go:286] "Successfully bound pod to node" pod="openshift-marketplace/redhat-marketplace-662g6" node="host-10-13-2-89" evaluatedNodes=3 feasibleNodes=3
2025-04-01T06:00:00.154717980Z I0401 06:00:00.154557       1 schedule_one.go:286] "Successfully bound pod to node" pod="openshift-operator-lifecycle-manager/collect-profiles-29058120-ngxw5" node="host-10-13-0-150" evaluatedNodes=3 feasibleNodes=3
2025-04-01T06:07:51.162746305Z I0401 06:07:51.162675       1 schedule_one.go:286] "Successfully bound pod to node" pod="openshift-marketplace/redhat-operators-vn4wj" node="host-10-13-2-89" evaluatedNodes=3 feasibleNodes=3
2025-04-01T06:07:58.008689173Z I0401 06:07:58.008629       1 schedule_one.go:286] "Successfully bound pod to node" pod="openshift-marketplace/certified-operators-5g5g7" node="host-10-13-2-89" evaluatedNodes=3 feasibleNodes=3
2025-04-01T06:08:12.290195193Z I0401 06:08:12.289713       1 schedule_one.go:286] "Successfully bound pod to node" pod="openshift-marketplace/redhat-marketplace-2jcg4" node="host-10-13-2-89" evaluatedNodes=3 feasibleNodes=3
2025-04-01T06:10:27.969987211Z I0401 06:10:27.967776       1 schedule_one.go:286] "Successfully bound pod to node" pod="openshift-marketplace/community-operators-wh7v8" node="host-10-13-2-89" evaluatedNodes=3 feasibleNodes=3
2025-04-01T06:15:00.159190495Z I0401 06:15:00.156295       1 schedule_one.go:286] "Successfully bound pod to node" pod="openshift-operator-lifecycle-manager/collect-profiles-29058135-886lq" node="host-10-13-0-150" evaluatedNodes=3 feasibleNodes=3
2025-04-01T06:18:25.363375632Z I0401 06:18:25.363339       1 schedule_one.go:286] "Successfully bound pod to node" pod="openshift-marketplace/redhat-marketplace-dxczx" node="host-10-13-2-89" evaluatedNodes=3 feasibleNodes=3
2025-04-01T06:18:55.955516044Z I0401 06:18:55.955427       1 schedule_one.go:286] "Successfully bound pod to node" pod="openshift-marketplace/certified-operators-xfgw9" node="host-10-13-2-89" evaluatedNodes=3 feasibleNodes=3
2025-04-01T06:21:09.177052545Z I0401 06:21:09.176586       1 schedule_one.go:286] "Successfully bound pod to node" pod="openshift-marketplace/community-operators-kgkbp" node="host-10-13-2-89" evaluatedNodes=3 feasibleNodes=3
2025-04-01T06:23:29.387224294Z I0401 06:23:29.387177       1 schedule_one.go:286] "Successfully bound pod to node" pod="openshift-marketplace/redhat-operators-xw64f" node="host-10-13-2-89" evaluatedNodes=3 feasibleNodes=3
2025-04-01T06:29:19.478241596Z I0401 06:29:19.478179       1 schedule_one.go:286] "Successfully bound pod to node" pod="openshift-marketplace/redhat-marketplace-66d8r" node="host-10-13-2-89" evaluatedNodes=3 feasibleNodes=3
2025-04-01T06:29:51.783137258Z I0401 06:29:51.783095       1 schedule_one.go:286] "Successfully bound pod to node" pod="openshift-marketplace/certified-operators-qd5cx" node="host-10-13-2-89" evaluatedNodes=3 feasibleNodes=3
2025-04-01T06:30:00.183213376Z I0401 06:30:00.183184       1 schedule_one.go:286] "Successfully bound pod to node" pod="openshift-operator-lifecycle-manager/collect-profiles-29058150-w7wnk" node="host-10-13-0-150" evaluatedNodes=3 feasibleNodes=3
2025-04-01T06:32:34.070698884Z I0401 06:32:34.068970       1 schedule_one.go:286] "Successfully bound pod to node" pod="openshift-marketplace/community-operators-wrzvh" node="host-10-13-2-89" evaluatedNodes=3 feasibleNodes=3
2025-04-01T06:34:28.212100063Z I0401 06:34:28.212038       1 schedule_one.go:286] "Successfully bound pod to node" pod="openshift-marketplace/redhat-operators-cppv7" node="host-10-13-2-89" evaluatedNodes=3 feasibleNodes=3
2025-04-01T06:39:29.943964437Z I0401 06:39:29.943904       1 schedule_one.go:286] "Successfully bound pod to node" pod="openshift-marketplace/redhat-marketplace-rbgwr" node="host-10-13-2-89" evaluatedNodes=3 feasibleNodes=3
2025-04-01T06:39:56.584118643Z I0401 06:39:56.584067       1 schedule_one.go:286] "Successfully bound pod to node" pod="openshift-marketplace/certified-operators-xp788" node="host-10-13-2-89" evaluatedNodes=3 feasibleNodes=3
2025-04-01T06:45:00.202085259Z I0401 06:45:00.201317       1 schedule_one.go:286] "Successfully bound pod to node" pod="openshift-operator-lifecycle-manager/collect-profiles-29058165-qx7vx" node="host-10-13-0-150" evaluatedNodes=3 feasibleNodes=3
2025-04-01T06:45:49.610101899Z I0401 06:45:49.609996       1 schedule_one.go:286] "Successfully bound pod to node" pod="openshift-marketplace/redhat-operators-p46vh" node="host-10-13-2-89" evaluatedNodes=3 feasibleNodes=3
2025-04-01T06:47:42.843205312Z I0401 06:47:42.843141       1 schedule_one.go:286] "Successfully bound pod to node" pod="openshift-marketplace/community-operators-ssb9k" node="host-10-13-2-89" evaluatedNodes=3 feasibleNodes=3
2025-04-01T06:49:32.585800510Z I0401 06:49:32.585762       1 schedule_one.go:286] "Successfully bound pod to node" pod="openshift-marketplace/redhat-marketplace-jkpzs" node="host-10-13-2-89" evaluatedNodes=3 feasibleNodes=3
2025-04-01T06:50:24.436491738Z I0401 06:50:24.435790       1 schedule_one.go:286] "Successfully bound pod to node" pod="openshift-marketplace/certified-operators-6ms96" node="host-10-13-2-89" evaluatedNodes=3 feasibleNodes=3
2025-04-01T06:56:11.324228326Z I0401 06:56:11.323441       1 schedule_one.go:286] "Successfully bound pod to node" pod="openshift-marketplace/redhat-operators-jc562" node="host-10-13-2-89" evaluatedNodes=3 feasibleNodes=3
2025-04-01T07:00:00.164250277Z I0401 07:00:00.164198       1 schedule_one.go:286] "Successfully bound pod to node" pod="openshift-operator-lifecycle-manager/collect-profiles-29058180-7t7g8" node="host-10-13-0-150" evaluatedNodes=3 feasibleNodes=3
2025-04-01T07:02:33.613980004Z I0401 07:02:33.613921       1 schedule_one.go:286] "Successfully bound pod to node" pod="openshift-marketplace/community-operators-g6522" node="host-10-13-2-89" evaluatedNodes=3 feasibleNodes=3
2025-04-01T07:02:33.616842579Z I0401 07:02:33.616804       1 schedule_one.go:286] "Successfully bound pod to node" pod="openshift-marketplace/redhat-marketplace-gq5pf" node="host-10-13-2-89" evaluatedNodes=3 feasibleNodes=3
2025-04-01T07:02:34.576036472Z I0401 07:02:34.575997       1 schedule_one.go:286] "Successfully bound pod to node" pod="openshift-marketplace/certified-operators-p6sln" node="host-10-13-2-160" evaluatedNodes=3 feasibleNodes=3
2025-04-01T07:07:24.279610846Z I0401 07:07:24.279505       1 schedule_one.go:286] "Successfully bound pod to node" pod="openshift-marketplace/redhat-operators-b6wkk" node="host-10-13-2-89" evaluatedNodes=3 feasibleNodes=3
2025-04-01T07:12:44.658028780Z I0401 07:12:44.656766       1 schedule_one.go:286] "Successfully bound pod to node" pod="openshift-marketplace/community-operators-xtml6" node="host-10-13-2-89" evaluatedNodes=3 feasibleNodes=3
2025-04-01T07:13:09.968213980Z I0401 07:13:09.967319       1 schedule_one.go:286] "Successfully bound pod to node" pod="openshift-marketplace/redhat-marketplace-94vs2" node="host-10-13-2-89" evaluatedNodes=3 feasibleNodes=3
2025-04-01T07:13:54.645134585Z I0401 07:13:54.644863       1 schedule_one.go:286] "Successfully bound pod to node" pod="openshift-marketplace/certified-operators-lc7pr" node="host-10-13-2-89" evaluatedNodes=3 feasibleNodes=3
2025-04-01T07:15:00.142215814Z I0401 07:15:00.142154       1 schedule_one.go:286] "Successfully bound pod to node" pod="openshift-operator-lifecycle-manager/collect-profiles-29058195-vjfbv" node="host-10-13-0-150" evaluatedNodes=3 feasibleNodes=3
2025-04-01T07:17:43.059201767Z I0401 07:17:43.059108       1 schedule_one.go:286] "Successfully bound pod to node" pod="openshift-marketplace/redhat-operators-f6t2n" node="host-10-13-2-89" evaluatedNodes=3 feasibleNodes=3
2025-04-01T07:23:25.530026006Z I0401 07:23:25.529994       1 schedule_one.go:286] "Successfully bound pod to node" pod="openshift-marketplace/redhat-marketplace-rfrkx" node="host-10-13-2-89" evaluatedNodes=3 feasibleNodes=3
2025-04-01T07:23:25.724131798Z I0401 07:23:25.723682       1 schedule_one.go:286] "Successfully bound pod to node" pod="openshift-marketplace/community-operators-rlnhf" node="host-10-13-2-89" evaluatedNodes=3 feasibleNodes=3
2025-04-01T07:24:18.436290786Z I0401 07:24:18.436107       1 schedule_one.go:286] "Successfully bound pod to node" pod="openshift-marketplace/certified-operators-n8gwx" node="host-10-13-2-89" evaluatedNodes=3 feasibleNodes=3
2025-04-01T07:28:17.795485174Z I0401 07:28:17.794979       1 schedule_one.go:286] "Successfully bound pod to node" pod="openshift-marketplace/redhat-operators-qtd2t" node="host-10-13-2-89" evaluatedNodes=3 feasibleNodes=3
2025-04-01T07:30:00.144139097Z I0401 07:30:00.144062       1 schedule_one.go:286] "Successfully bound pod to node" pod="openshift-operator-lifecycle-manager/collect-profiles-29058210-hqjfl" node="host-10-13-0-150" evaluatedNodes=3 feasibleNodes=3
2025-04-01T07:34:10.008523432Z I0401 07:34:10.008448       1 schedule_one.go:286] "Successfully bound pod to node" pod="openshift-marketplace/redhat-marketplace-smb9g" node="host-10-13-2-89" evaluatedNodes=3 feasibleNodes=3
2025-04-01T07:34:18.654479945Z I0401 07:34:18.654442       1 schedule_one.go:286] "Successfully bound pod to node" pod="openshift-marketplace/community-operators-c8fh2" node="host-10-13-2-89" evaluatedNodes=3 feasibleNodes=3
2025-04-01T07:35:45.382820893Z I0401 07:35:45.382597       1 schedule_one.go:286] "Successfully bound pod to node" pod="openshift-marketplace/certified-operators-lr9rr" node="host-10-13-2-89" evaluatedNodes=3 feasibleNodes=3
2025-04-01T07:39:17.767183223Z I0401 07:39:17.766696       1 schedule_one.go:286] "Successfully bound pod to node" pod="openshift-marketplace/redhat-operators-59nzt" node="host-10-13-2-89" evaluatedNodes=3 feasibleNodes=3
2025-04-01T07:44:20.802725811Z I0401 07:44:20.801412       1 schedule_one.go:286] "Successfully bound pod to node" pod="openshift-marketplace/community-operators-vq6tv" node="host-10-13-2-89" evaluatedNodes=3 feasibleNodes=3
2025-04-01T07:45:00.223759757Z I0401 07:45:00.221223       1 schedule_one.go:286] "Successfully bound pod to node" pod="openshift-operator-lifecycle-manager/collect-profiles-29058225-n8kjf" node="host-10-13-0-150" evaluatedNodes=3 feasibleNodes=3
2025-04-01T07:45:58.923720288Z I0401 07:45:58.923624       1 schedule_one.go:286] "Successfully bound pod to node" pod="openshift-marketplace/certified-operators-k8cv6" node="host-10-13-2-89" evaluatedNodes=3 feasibleNodes=3
2025-04-01T07:50:21.292443916Z I0401 07:50:21.292353       1 schedule_one.go:286] "Successfully bound pod to node" pod="openshift-marketplace/redhat-operators-kjkxd" node="host-10-13-2-89" evaluatedNodes=3 feasibleNodes=3
2025-04-01T07:52:27.790981645Z I0401 07:52:27.790928       1 schedule_one.go:286] "Successfully bound pod to node" pod="openshift-marketplace/redhat-marketplace-b6vcf" node="host-10-13-2-89" evaluatedNodes=3 feasibleNodes=3
2025-04-01T07:54:28.981768386Z I0401 07:54:28.981059       1 schedule_one.go:286] "Successfully bound pod to node" pod="openshift-marketplace/community-operators-pnmb5" node="host-10-13-2-89" evaluatedNodes=3 feasibleNodes=3
2025-04-01T07:59:07.056575492Z I0401 07:59:07.056227       1 schedule_one.go:286] "Successfully bound pod to node" pod="openshift-marketplace/certified-operators-2fdxn" node="host-10-13-2-89" evaluatedNodes=3 feasibleNodes=3
2025-04-01T08:00:00.163799099Z I0401 08:00:00.162547       1 schedule_one.go:286] "Successfully bound pod to node" pod="openshift-operator-lifecycle-manager/collect-profiles-29058240-gn26k" node="host-10-13-0-150" evaluatedNodes=3 feasibleNodes=3
2025-04-01T08:01:16.441493628Z I0401 08:01:16.441432       1 schedule_one.go:286] "Successfully bound pod to node" pod="openshift-marketplace/redhat-operators-49dnf" node="host-10-13-2-89" evaluatedNodes=3 feasibleNodes=3
2025-04-01T08:03:31.188242215Z I0401 08:03:31.188143       1 schedule_one.go:286] "Successfully bound pod to node" pod="openshift-marketplace/redhat-marketplace-p6nh4" node="host-10-13-2-89" evaluatedNodes=3 feasibleNodes=3
2025-04-01T08:04:33.090386551Z I0401 08:04:33.090306       1 schedule_one.go:286] "Successfully bound pod to node" pod="openshift-marketplace/community-operators-z62z4" node="host-10-13-2-89" evaluatedNodes=3 feasibleNodes=3
2025-04-01T08:07:35.205965622Z I0401 08:07:35.205393       1 tlsconfig.go:178] "Loaded client CA" index=0 certName="client-ca::kube-system::extension-apiserver-authentication::client-ca-file,client-ca::kube-system::extension-apiserver-authentication::requestheader-client-ca-file" certDetail="\"admin-kubeconfig-signer\" [] issuer=\"<self>\" (2025-03-31 12:55:13 +0000 UTC to 2035-03-29 12:55:13 +0000 UTC (now=2025-04-01 08:07:35.205367194 +0000 UTC))"
2025-04-01T08:07:35.205965622Z I0401 08:07:35.205420       1 tlsconfig.go:178] "Loaded client CA" index=1 certName="client-ca::kube-system::extension-apiserver-authentication::client-ca-file,client-ca::kube-system::extension-apiserver-authentication::requestheader-client-ca-file" certDetail="\"kubelet-signer\" [] issuer=\"<self>\" (2025-03-31 12:55:15 +0000 UTC to 2025-04-01 12:55:15 +0000 UTC (now=2025-04-01 08:07:35.205409963 +0000 UTC))"
2025-04-01T08:07:35.205965622Z I0401 08:07:35.205432       1 tlsconfig.go:178] "Loaded client CA" index=2 certName="client-ca::kube-system::extension-apiserver-authentication::client-ca-file,client-ca::kube-system::extension-apiserver-authentication::requestheader-client-ca-file" certDetail="\"kube-control-plane-signer\" [] issuer=\"<self>\" (2025-03-31 12:55:15 +0000 UTC to 2026-03-31 12:55:15 +0000 UTC (now=2025-04-01 08:07:35.205425522 +0000 UTC))"
2025-04-01T08:07:35.205965622Z I0401 08:07:35.205444       1 tlsconfig.go:178] "Loaded client CA" index=3 certName="client-ca::kube-system::extension-apiserver-authentication::client-ca-file,client-ca::kube-system::extension-apiserver-authentication::requestheader-client-ca-file" certDetail="\"kube-apiserver-to-kubelet-signer\" [] issuer=\"<self>\" (2025-03-31 12:55:15 +0000 UTC to 2026-03-31 12:55:15 +0000 UTC (now=2025-04-01 08:07:35.205437882 +0000 UTC))"
2025-04-01T08:07:35.205965622Z I0401 08:07:35.205456       1 tlsconfig.go:178] "Loaded client CA" index=4 certName="client-ca::kube-system::extension-apiserver-authentication::client-ca-file,client-ca::kube-system::extension-apiserver-authentication::requestheader-client-ca-file" certDetail="\"kubelet-bootstrap-kubeconfig-signer\" [] issuer=\"<self>\" (2025-03-31 12:55:13 +0000 UTC to 2035-03-29 12:55:13 +0000 UTC (now=2025-04-01 08:07:35.205450282 +0000 UTC))"
2025-04-01T08:07:35.205965622Z I0401 08:07:35.205468       1 tlsconfig.go:178] "Loaded client CA" index=5 certName="client-ca::kube-system::extension-apiserver-authentication::client-ca-file,client-ca::kube-system::extension-apiserver-authentication::requestheader-client-ca-file" certDetail="\"kube-csr-signer_@1743452525\" [] issuer=\"kubelet-signer\" (2025-03-31 20:22:04 +0000 UTC to 2025-04-01 12:55:15 +0000 UTC (now=2025-04-01 08:07:35.205461431 +0000 UTC))"
2025-04-01T08:07:35.205965622Z I0401 08:07:35.205480       1 tlsconfig.go:178] "Loaded client CA" index=6 certName="client-ca::kube-system::extension-apiserver-authentication::client-ca-file,client-ca::kube-system::extension-apiserver-authentication::requestheader-client-ca-file" certDetail="\"openshift-kube-apiserver-operator_node-system-admin-signer@1743452539\" [] issuer=\"<self>\" (2025-03-31 20:22:18 +0000 UTC to 2026-03-31 20:22:19 +0000 UTC (now=2025-04-01 08:07:35.205472821 +0000 UTC))"
2025-04-01T08:07:35.205965622Z I0401 08:07:35.205493       1 tlsconfig.go:178] "Loaded client CA" index=7 certName="client-ca::kube-system::extension-apiserver-authentication::client-ca-file,client-ca::kube-system::extension-apiserver-authentication::requestheader-client-ca-file" certDetail="\"aggregator-signer\" [] issuer=\"<self>\" (2025-03-31 12:55:14 +0000 UTC to 2025-04-01 12:55:14 +0000 UTC (now=2025-04-01 08:07:35.205486761 +0000 UTC))"
2025-04-01T08:07:35.205965622Z I0401 08:07:35.205505       1 tlsconfig.go:178] "Loaded client CA" index=8 certName="client-ca::kube-system::extension-apiserver-authentication::client-ca-file,client-ca::kube-system::extension-apiserver-authentication::requestheader-client-ca-file" certDetail="\"openshift-kube-apiserver-operator_aggregator-client-signer@1743494854\" [] issuer=\"<self>\" (2025-04-01 08:07:34 +0000 UTC to 2025-05-01 08:07:35 +0000 UTC (now=2025-04-01 08:07:35.205497601 +0000 UTC))"
2025-04-01T08:07:35.205965622Z I0401 08:07:35.205782       1 tlsconfig.go:200] "Loaded serving cert" certName="serving-cert::/etc/kubernetes/static-pod-resources/secrets/serving-cert/tls.crt::/etc/kubernetes/static-pod-resources/secrets/serving-cert/tls.key" certDetail="\"scheduler.openshift-kube-scheduler.svc\" [serving] validServingFor=[scheduler.openshift-kube-scheduler.svc,scheduler.openshift-kube-scheduler.svc.cluster.local] issuer=\"openshift-service-serving-signer@1743452529\" (2025-03-31 20:22:27 +0000 UTC to 2027-03-31 20:22:28 +0000 UTC (now=2025-04-01 08:07:35.205771915 +0000 UTC))"
2025-04-01T08:07:35.206133558Z I0401 08:07:35.206099       1 named_certificates.go:53] "Loaded SNI cert" index=0 certName="self-signed loopback" certDetail="\"apiserver-loopback-client@1743453601\" [serving] validServingFor=[apiserver-loopback-client] issuer=\"apiserver-loopback-client-ca@1743453600\" (2025-03-31 19:40:00 +0000 UTC to 2026-03-31 19:40:00 +0000 UTC (now=2025-04-01 08:07:35.20606517 +0000 UTC))"
2025-04-01T08:07:40.727400705Z I0401 08:07:40.727367       1 schedule_one.go:286] "Successfully bound pod to node" pod="openshift-monitoring/prometheus-adapter-bf97fd779-bmplv" node="host-10-13-2-89" evaluatedNodes=3 feasibleNodes=1
2025-04-01T08:07:40.762910885Z I0401 08:07:40.762674       1 schedule_one.go:988] "Unable to schedule pod; no fit; waiting" pod="openshift-monitoring/prometheus-adapter-bf97fd779-hfwts" err="0/3 nodes are available: 3 node(s) didn't match pod anti-affinity rules. preemption: 0/3 nodes are available: 3 node(s) didn't match pod anti-affinity rules.."
2025-04-01T08:07:42.468229547Z I0401 08:07:42.468199       1 schedule_one.go:286] "Successfully bound pod to node" pod="openshift-monitoring/prometheus-adapter-bf97fd779-hfwts" node="host-10-13-0-150" evaluatedNodes=3 feasibleNodes=1
2025-04-01T08:07:49.547996901Z I0401 08:07:49.542779       1 tlsconfig.go:178] "Loaded client CA" index=0 certName="client-ca::kube-system::extension-apiserver-authentication::client-ca-file,client-ca::kube-system::extension-apiserver-authentication::requestheader-client-ca-file" certDetail="\"admin-kubeconfig-signer\" [] issuer=\"<self>\" (2025-03-31 12:55:13 +0000 UTC to 2035-03-29 12:55:13 +0000 UTC (now=2025-04-01 08:07:49.542755204 +0000 UTC))"
2025-04-01T08:07:49.547996901Z I0401 08:07:49.542801       1 tlsconfig.go:178] "Loaded client CA" index=1 certName="client-ca::kube-system::extension-apiserver-authentication::client-ca-file,client-ca::kube-system::extension-apiserver-authentication::requestheader-client-ca-file" certDetail="\"kubelet-signer\" [] issuer=\"<self>\" (2025-03-31 12:55:15 +0000 UTC to 2025-04-01 12:55:15 +0000 UTC (now=2025-04-01 08:07:49.542792693 +0000 UTC))"
2025-04-01T08:07:49.547996901Z I0401 08:07:49.542812       1 tlsconfig.go:178] "Loaded client CA" index=2 certName="client-ca::kube-system::extension-apiserver-authentication::client-ca-file,client-ca::kube-system::extension-apiserver-authentication::requestheader-client-ca-file" certDetail="\"kube-control-plane-signer\" [] issuer=\"<self>\" (2025-03-31 12:55:15 +0000 UTC to 2026-03-31 12:55:15 +0000 UTC (now=2025-04-01 08:07:49.542806272 +0000 UTC))"
2025-04-01T08:07:49.547996901Z I0401 08:07:49.542825       1 tlsconfig.go:178] "Loaded client CA" index=3 certName="client-ca::kube-system::extension-apiserver-authentication::client-ca-file,client-ca::kube-system::extension-apiserver-authentication::requestheader-client-ca-file" certDetail="\"kube-apiserver-to-kubelet-signer\" [] issuer=\"<self>\" (2025-03-31 12:55:15 +0000 UTC to 2026-03-31 12:55:15 +0000 UTC (now=2025-04-01 08:07:49.542817312 +0000 UTC))"
2025-04-01T08:07:49.547996901Z I0401 08:07:49.542835       1 tlsconfig.go:178] "Loaded client CA" index=4 certName="client-ca::kube-system::extension-apiserver-authentication::client-ca-file,client-ca::kube-system::extension-apiserver-authentication::requestheader-client-ca-file" certDetail="\"kubelet-bootstrap-kubeconfig-signer\" [] issuer=\"<self>\" (2025-03-31 12:55:13 +0000 UTC to 2035-03-29 12:55:13 +0000 UTC (now=2025-04-01 08:07:49.542829192 +0000 UTC))"
2025-04-01T08:07:49.547996901Z I0401 08:07:49.542845       1 tlsconfig.go:178] "Loaded client CA" index=5 certName="client-ca::kube-system::extension-apiserver-authentication::client-ca-file,client-ca::kube-system::extension-apiserver-authentication::requestheader-client-ca-file" certDetail="\"kube-csr-signer_@1743452525\" [] issuer=\"kubelet-signer\" (2025-03-31 20:22:04 +0000 UTC to 2025-04-01 12:55:15 +0000 UTC (now=2025-04-01 08:07:49.542839292 +0000 UTC))"
2025-04-01T08:07:49.547996901Z I0401 08:07:49.542857       1 tlsconfig.go:178] "Loaded client CA" index=6 certName="client-ca::kube-system::extension-apiserver-authentication::client-ca-file,client-ca::kube-system::extension-apiserver-authentication::requestheader-client-ca-file" certDetail="\"openshift-kube-apiserver-operator_node-system-admin-signer@1743452539\" [] issuer=\"<self>\" (2025-03-31 20:22:18 +0000 UTC to 2026-03-31 20:22:19 +0000 UTC (now=2025-04-01 08:07:49.542850611 +0000 UTC))"
2025-04-01T08:07:49.547996901Z I0401 08:07:49.542880       1 tlsconfig.go:178] "Loaded client CA" index=7 certName="client-ca::kube-system::extension-apiserver-authentication::client-ca-file,client-ca::kube-system::extension-apiserver-authentication::requestheader-client-ca-file" certDetail="\"openshift-kube-controller-manager-operator_csr-signer-signer@1743494861\" [] issuer=\"<self>\" (2025-04-01 08:07:40 +0000 UTC to 2025-05-31 08:07:41 +0000 UTC (now=2025-04-01 08:07:49.542862461 +0000 UTC))"
2025-04-01T08:07:49.547996901Z I0401 08:07:49.542894       1 tlsconfig.go:178] "Loaded client CA" index=8 certName="client-ca::kube-system::extension-apiserver-authentication::client-ca-file,client-ca::kube-system::extension-apiserver-authentication::requestheader-client-ca-file" certDetail="\"aggregator-signer\" [] issuer=\"<self>\" (2025-03-31 12:55:14 +0000 UTC to 2025-04-01 12:55:14 +0000 UTC (now=2025-04-01 08:07:49.542885911 +0000 UTC))"
2025-04-01T08:07:49.547996901Z I0401 08:07:49.542909       1 tlsconfig.go:178] "Loaded client CA" index=9 certName="client-ca::kube-system::extension-apiserver-authentication::client-ca-file,client-ca::kube-system::extension-apiserver-authentication::requestheader-client-ca-file" certDetail="\"openshift-kube-apiserver-operator_aggregator-client-signer@1743494854\" [] issuer=\"<self>\" (2025-04-01 08:07:34 +0000 UTC to 2025-05-01 08:07:35 +0000 UTC (now=2025-04-01 08:07:49.54290136 +0000 UTC))"
2025-04-01T08:07:49.547996901Z I0401 08:07:49.543164       1 tlsconfig.go:200] "Loaded serving cert" certName="serving-cert::/etc/kubernetes/static-pod-resources/secrets/serving-cert/tls.crt::/etc/kubernetes/static-pod-resources/secrets/serving-cert/tls.key" certDetail="\"scheduler.openshift-kube-scheduler.svc\" [serving] validServingFor=[scheduler.openshift-kube-scheduler.svc,scheduler.openshift-kube-scheduler.svc.cluster.local] issuer=\"openshift-service-serving-signer@1743452529\" (2025-03-31 20:22:27 +0000 UTC to 2027-03-31 20:22:28 +0000 UTC (now=2025-04-01 08:07:49.543153145 +0000 UTC))"
2025-04-01T08:07:49.547996901Z I0401 08:07:49.543387       1 named_certificates.go:53] "Loaded SNI cert" index=0 certName="self-signed loopback" certDetail="\"apiserver-loopback-client@1743453601\" [serving] validServingFor=[apiserver-loopback-client] issuer=\"apiserver-loopback-client-ca@1743453600\" (2025-03-31 19:40:00 +0000 UTC to 2026-03-31 19:40:00 +0000 UTC (now=2025-04-01 08:07:49.543379071 +0000 UTC))"
2025-04-01T08:08:00.147659385Z I0401 08:08:00.146107       1 schedule_one.go:286] "Successfully bound pod to node" pod="openshift-monitoring/prometheus-adapter-5497c8b8db-9kntz" node="host-10-13-2-160" evaluatedNodes=3 feasibleNodes=1
2025-04-01T08:08:00.195777269Z I0401 08:08:00.192770       1 schedule_one.go:988] "Unable to schedule pod; no fit; waiting" pod="openshift-monitoring/prometheus-adapter-5497c8b8db-4gj85" err="0/3 nodes are available: 3 node(s) didn't match pod anti-affinity rules. preemption: 0/3 nodes are available: 3 node(s) didn't match pod anti-affinity rules.."
2025-04-01T08:08:01.481096128Z I0401 08:08:01.481055       1 schedule_one.go:286] "Successfully bound pod to node" pod="openshift-monitoring/prometheus-adapter-5497c8b8db-4gj85" node="host-10-13-0-150" evaluatedNodes=3 feasibleNodes=1
2025-04-01T08:09:34.297091646Z I0401 08:09:34.295809       1 schedule_one.go:286] "Successfully bound pod to node" pod="openshift-marketplace/certified-operators-f62zg" node="host-10-13-2-89" evaluatedNodes=3 feasibleNodes=3
2025-04-01T08:10:26.023651704Z I0401 08:10:26.021366       1 schedule_one.go:988] "Unable to schedule pod; no fit; waiting" pod="openshift-controller-manager/controller-manager-56648cc6db-xs4c2" err="0/3 nodes are available: 3 node(s) didn't match pod anti-affinity rules. preemption: 0/3 nodes are available: 3 node(s) didn't match pod anti-affinity rules.."
2025-04-01T08:10:26.039724051Z I0401 08:10:26.039689       1 schedule_one.go:988] "Unable to schedule pod; no fit; waiting" pod="openshift-route-controller-manager/route-controller-manager-86877db94c-g47ld" err="0/3 nodes are available: 3 node(s) didn't match pod anti-affinity rules. preemption: 0/3 nodes are available: 3 node(s) didn't match pod anti-affinity rules.."
2025-04-01T08:10:26.303146819Z I0401 08:10:26.301310       1 schedule_one.go:988] "Unable to schedule pod; no fit; waiting" pod="openshift-route-controller-manager/route-controller-manager-79f4955b65-bwh9d" err="0/3 nodes are available: 3 node(s) didn't match pod anti-affinity rules. preemption: 0/3 nodes are available: 3 node(s) didn't match pod anti-affinity rules.."
2025-04-01T08:10:26.327106404Z I0401 08:10:26.327045       1 schedule_one.go:988] "Unable to schedule pod; no fit; waiting" pod="openshift-controller-manager/controller-manager-58b7b7d877-ll7bv" err="0/3 nodes are available: 3 node(s) didn't match pod anti-affinity rules. preemption: 0/3 nodes are available: 3 node(s) didn't match pod anti-affinity rules.."
2025-04-01T08:10:27.565219759Z I0401 08:10:27.565141       1 schedule_one.go:286] "Successfully bound pod to node" pod="openshift-controller-manager/controller-manager-58b7b7d877-ll7bv" node="host-10-13-2-89" evaluatedNodes=3 feasibleNodes=1
2025-04-01T08:10:27.566865438Z I0401 08:10:27.566828       1 schedule_one.go:286] "Successfully bound pod to node" pod="openshift-route-controller-manager/route-controller-manager-79f4955b65-bwh9d" node="host-10-13-2-89" evaluatedNodes=3 feasibleNodes=1
2025-04-01T08:10:29.325070082Z I0401 08:10:29.324347       1 schedule_one.go:988] "Unable to schedule pod; no fit; waiting" pod="openshift-route-controller-manager/route-controller-manager-79f4955b65-7vg9n" err="0/3 nodes are available: 3 node(s) didn't match pod anti-affinity rules. preemption: 0/3 nodes are available: 3 node(s) didn't match pod anti-affinity rules.."
2025-04-01T08:10:30.332946266Z I0401 08:10:30.332623       1 schedule_one.go:988] "Unable to schedule pod; no fit; waiting" pod="openshift-controller-manager/controller-manager-58b7b7d877-vxrhx" err="0/3 nodes are available: 3 node(s) didn't match pod anti-affinity rules. preemption: 0/3 nodes are available: 3 node(s) didn't match pod anti-affinity rules.."
2025-04-01T08:10:30.564700469Z I0401 08:10:30.564453       1 schedule_one.go:286] "Successfully bound pod to node" pod="openshift-route-controller-manager/route-controller-manager-79f4955b65-7vg9n" node="host-10-13-2-160" evaluatedNodes=3 feasibleNodes=1
2025-04-01T08:10:31.565660767Z I0401 08:10:31.565594       1 schedule_one.go:286] "Successfully bound pod to node" pod="openshift-controller-manager/controller-manager-58b7b7d877-vxrhx" node="host-10-13-2-160" evaluatedNodes=3 feasibleNodes=1
2025-04-01T08:10:32.843187087Z I0401 08:10:32.843156       1 schedule_one.go:988] "Unable to schedule pod; no fit; waiting" pod="openshift-route-controller-manager/route-controller-manager-79f4955b65-nfsjl" err="0/3 nodes are available: 3 node(s) didn't match pod anti-affinity rules. preemption: 0/3 nodes are available: 3 node(s) didn't match pod anti-affinity rules.."
2025-04-01T08:10:32.876954280Z I0401 08:10:32.876915       1 schedule_one.go:988] "Unable to schedule pod; no fit; waiting" pod="openshift-controller-manager/controller-manager-58b7b7d877-lqh6b" err="0/3 nodes are available: 3 node(s) didn't match pod anti-affinity rules. preemption: 0/3 nodes are available: 3 node(s) didn't match pod anti-affinity rules.."
2025-04-01T08:10:34.566793934Z I0401 08:10:34.566648       1 schedule_one.go:286] "Successfully bound pod to node" pod="openshift-route-controller-manager/route-controller-manager-79f4955b65-nfsjl" node="host-10-13-0-150" evaluatedNodes=3 feasibleNodes=1
2025-04-01T08:10:34.573935886Z I0401 08:10:34.571676       1 schedule_one.go:286] "Successfully bound pod to node" pod="openshift-controller-manager/controller-manager-58b7b7d877-lqh6b" node="host-10-13-0-150" evaluatedNodes=3 feasibleNodes=1
2025-04-01T08:11:35.279214342Z I0401 08:11:35.278276       1 schedule_one.go:286] "Successfully bound pod to node" pod="openshift-marketplace/redhat-operators-l7ht4" node="host-10-13-2-89" evaluatedNodes=3 feasibleNodes=3
2025-04-01T08:13:35.007897961Z I0401 08:13:35.007829       1 schedule_one.go:286] "Successfully bound pod to node" pod="openshift-marketplace/redhat-marketplace-nb7vv" node="host-10-13-2-89" evaluatedNodes=3 feasibleNodes=3
2025-04-01T08:15:00.139578309Z I0401 08:15:00.139095       1 schedule_one.go:286] "Successfully bound pod to node" pod="openshift-operator-lifecycle-manager/collect-profiles-29058255-t4f84" node="host-10-13-0-150" evaluatedNodes=3 feasibleNodes=3
2025-04-01T08:15:02.407363325Z I0401 08:15:02.407310       1 schedule_one.go:286] "Successfully bound pod to node" pod="openshift-marketplace/community-operators-xx99j" node="host-10-13-2-89" evaluatedNodes=3 feasibleNodes=3
2025-04-01T08:20:42.064591520Z I0401 08:20:42.064499       1 schedule_one.go:286] "Successfully bound pod to node" pod="openshift-marketplace/certified-operators-p2q5b" node="host-10-13-2-89" evaluatedNodes=3 feasibleNodes=3
2025-04-01T08:22:22.584780101Z I0401 08:22:22.584108       1 schedule_one.go:286] "Successfully bound pod to node" pod="openshift-marketplace/redhat-operators-fcmrl" node="host-10-13-2-89" evaluatedNodes=3 feasibleNodes=3
2025-04-01T08:24:30.387794794Z I0401 08:24:30.387393       1 schedule_one.go:286] "Successfully bound pod to node" pod="openshift-marketplace/redhat-marketplace-gjlrx" node="host-10-13-2-89" evaluatedNodes=3 feasibleNodes=3
2025-04-01T08:27:24.313247106Z I0401 08:27:24.307407       1 node_tree.go:65] "Added node in listed group to NodeTree" node="host-10-13-3-78" zone=""
2025-04-01T08:27:24.405343585Z I0401 08:27:24.405275       1 schedule_one.go:286] "Successfully bound pod to node" pod="openshift-dns/node-resolver-4dsrr" node="host-10-13-3-78" evaluatedNodes=1 feasibleNodes=1
2025-04-01T08:27:24.407120341Z I0401 08:27:24.407096       1 schedule_one.go:286] "Successfully bound pod to node" pod="openshift-machine-config-operator/machine-config-daemon-nvqvs" node="host-10-13-3-78" evaluatedNodes=1 feasibleNodes=1
2025-04-01T08:27:24.438895612Z I0401 08:27:24.438744       1 schedule_one.go:286] "Successfully bound pod to node" pod="openshift-multus/multus-additional-cni-plugins-jptk9" node="host-10-13-3-78" evaluatedNodes=1 feasibleNodes=1
2025-04-01T08:27:24.442213639Z I0401 08:27:24.442186       1 schedule_one.go:286] "Successfully bound pod to node" pod="openshift-network-diagnostics/network-check-target-shjhk" node="host-10-13-3-78" evaluatedNodes=1 feasibleNodes=1
2025-04-01T08:27:24.458148569Z I0401 08:27:24.457178       1 schedule_one.go:286] "Successfully bound pod to node" pod="openshift-cluster-node-tuning-operator/tuned-q7kz5" node="host-10-13-3-78" evaluatedNodes=1 feasibleNodes=1
2025-04-01T08:27:24.482081622Z I0401 08:27:24.482052       1 schedule_one.go:286] "Successfully bound pod to node" pod="openshift-image-registry/node-ca-sn2tw" node="host-10-13-3-78" evaluatedNodes=1 feasibleNodes=1
2025-04-01T08:27:24.501478926Z I0401 08:27:24.500077       1 schedule_one.go:286] "Successfully bound pod to node" pod="openshift-multus/multus-px4hp" node="host-10-13-3-78" evaluatedNodes=1 feasibleNodes=1
2025-04-01T08:27:24.516942435Z I0401 08:27:24.515682       1 schedule_one.go:286] "Successfully bound pod to node" pod="openshift-multus/network-metrics-daemon-hbcjf" node="host-10-13-3-78" evaluatedNodes=1 feasibleNodes=1
2025-04-01T08:27:24.544178405Z I0401 08:27:24.542794       1 schedule_one.go:286] "Successfully bound pod to node" pod="openshift-monitoring/node-exporter-gqb67" node="host-10-13-3-78" evaluatedNodes=1 feasibleNodes=1
2025-04-01T08:27:24.563806734Z I0401 08:27:24.563738       1 schedule_one.go:286] "Successfully bound pod to node" pod="openshift-ovn-kubernetes/ovnkube-node-czhrl" node="host-10-13-3-78" evaluatedNodes=1 feasibleNodes=1
2025-04-01T08:28:43.862360646Z I0401 08:28:43.862279       1 schedule_one.go:286] "Successfully bound pod to node" pod="openshift-marketplace/community-operators-rvklh" node="host-10-13-2-89" evaluatedNodes=4 feasibleNodes=3
2025-04-01T08:28:51.609013867Z I0401 08:28:51.608971       1 schedule_one.go:286] "Successfully bound pod to node" pod="openshift-dns/dns-default-sknnq" node="host-10-13-3-78" evaluatedNodes=1 feasibleNodes=1
2025-04-01T08:28:51.623994475Z I0401 08:28:51.623741       1 schedule_one.go:286] "Successfully bound pod to node" pod="openshift-ingress-canary/ingress-canary-758jl" node="host-10-13-3-78" evaluatedNodes=1 feasibleNodes=1
2025-04-01T08:30:00.142985963Z I0401 08:30:00.142167       1 schedule_one.go:286] "Successfully bound pod to node" pod="openshift-operator-lifecycle-manager/collect-profiles-29058270-dxksp" node="host-10-13-0-150" evaluatedNodes=4 feasibleNodes=4
2025-04-01T08:32:46.032614978Z I0401 08:32:46.032562       1 schedule_one.go:286] "Successfully bound pod to node" pod="openshift-marketplace/redhat-operators-lxkp9" node="host-10-13-2-89" evaluatedNodes=4 feasibleNodes=3
2025-04-01T08:32:57.673648318Z I0401 08:32:57.671495       1 node_tree.go:65] "Added node in listed group to NodeTree" node="host-10-13-3-120" zone=""
2025-04-01T08:32:57.719689763Z I0401 08:32:57.719516       1 schedule_one.go:286] "Successfully bound pod to node" pod="openshift-multus/network-metrics-daemon-stgrn" node="host-10-13-3-120" evaluatedNodes=1 feasibleNodes=1
2025-04-01T08:32:57.734947366Z I0401 08:32:57.734551       1 schedule_one.go:286] "Successfully bound pod to node" pod="openshift-ovn-kubernetes/ovnkube-node-twdpb" node="host-10-13-3-120" evaluatedNodes=1 feasibleNodes=1
2025-04-01T08:32:57.754190382Z I0401 08:32:57.752048       1 schedule_one.go:286] "Successfully bound pod to node" pod="openshift-dns/node-resolver-ztcbr" node="host-10-13-3-120" evaluatedNodes=1 feasibleNodes=1
2025-04-01T08:32:57.779683166Z I0401 08:32:57.779648       1 schedule_one.go:286] "Successfully bound pod to node" pod="openshift-machine-config-operator/machine-config-daemon-mkwcm" node="host-10-13-3-120" evaluatedNodes=1 feasibleNodes=1
2025-04-01T08:32:57.787467185Z I0401 08:32:57.787384       1 schedule_one.go:286] "Successfully bound pod to node" pod="openshift-multus/multus-additional-cni-plugins-lrgth" node="host-10-13-3-120" evaluatedNodes=1 feasibleNodes=1
2025-04-01T08:32:57.815454061Z I0401 08:32:57.813278       1 schedule_one.go:286] "Successfully bound pod to node" pod="openshift-multus/multus-twdcw" node="host-10-13-3-120" evaluatedNodes=1 feasibleNodes=1
2025-04-01T08:32:57.823669801Z I0401 08:32:57.823291       1 schedule_one.go:286] "Successfully bound pod to node" pod="openshift-network-diagnostics/network-check-target-t7fm9" node="host-10-13-3-120" evaluatedNodes=1 feasibleNodes=1
2025-04-01T08:32:57.842231100Z I0401 08:32:57.842195       1 schedule_one.go:286] "Successfully bound pod to node" pod="openshift-cluster-node-tuning-operator/tuned-8mldx" node="host-10-13-3-120" evaluatedNodes=1 feasibleNodes=1
2025-04-01T08:32:57.852036380Z I0401 08:32:57.852009       1 schedule_one.go:286] "Successfully bound pod to node" pod="openshift-image-registry/node-ca-s4zjl" node="host-10-13-3-120" evaluatedNodes=1 feasibleNodes=1
2025-04-01T08:32:57.870580249Z I0401 08:32:57.870513       1 schedule_one.go:286] "Successfully bound pod to node" pod="openshift-monitoring/node-exporter-jsv7x" node="host-10-13-3-120" evaluatedNodes=1 feasibleNodes=1
2025-04-01T08:33:00.044534091Z I0401 08:33:00.044164       1 node_tree.go:65] "Added node in listed group to NodeTree" node="host-10-13-2-1" zone=""
2025-04-01T08:33:00.078160697Z I0401 08:33:00.077302       1 schedule_one.go:286] "Successfully bound pod to node" pod="openshift-image-registry/node-ca-pdq6p" node="host-10-13-2-1" evaluatedNodes=1 feasibleNodes=1
2025-04-01T08:33:00.087123303Z I0401 08:33:00.084555       1 schedule_one.go:286] "Successfully bound pod to node" pod="openshift-cluster-node-tuning-operator/tuned-gsmzj" node="host-10-13-2-1" evaluatedNodes=1 feasibleNodes=1
2025-04-01T08:33:00.097652508Z I0401 08:33:00.096390       1 schedule_one.go:286] "Successfully bound pod to node" pod="openshift-monitoring/node-exporter-9hw28" node="host-10-13-2-1" evaluatedNodes=1 feasibleNodes=1
2025-04-01T08:33:00.116918943Z I0401 08:33:00.116892       1 schedule_one.go:286] "Successfully bound pod to node" pod="openshift-multus/multus-s8z98" node="host-10-13-2-1" evaluatedNodes=1 feasibleNodes=1
2025-04-01T08:33:00.131755365Z I0401 08:33:00.131096       1 schedule_one.go:286] "Successfully bound pod to node" pod="openshift-multus/network-metrics-daemon-2hq4z" node="host-10-13-2-1" evaluatedNodes=1 feasibleNodes=1
2025-04-01T08:33:00.150841683Z I0401 08:33:00.150803       1 schedule_one.go:286] "Successfully bound pod to node" pod="openshift-dns/node-resolver-l9trs" node="host-10-13-2-1" evaluatedNodes=1 feasibleNodes=1
2025-04-01T08:33:00.158419606Z I0401 08:33:00.158395       1 schedule_one.go:286] "Successfully bound pod to node" pod="openshift-ovn-kubernetes/ovnkube-node-crpn4" node="host-10-13-2-1" evaluatedNodes=1 feasibleNodes=1
2025-04-01T08:33:00.184092467Z I0401 08:33:00.184065       1 schedule_one.go:286] "Successfully bound pod to node" pod="openshift-machine-config-operator/machine-config-daemon-9hwff" node="host-10-13-2-1" evaluatedNodes=1 feasibleNodes=1
2025-04-01T08:33:00.191100050Z I0401 08:33:00.191073       1 schedule_one.go:286] "Successfully bound pod to node" pod="openshift-multus/multus-additional-cni-plugins-4lxcb" node="host-10-13-2-1" evaluatedNodes=1 feasibleNodes=1
2025-04-01T08:33:00.207023661Z I0401 08:33:00.206542       1 schedule_one.go:286] "Successfully bound pod to node" pod="openshift-network-diagnostics/network-check-target-9xqfh" node="host-10-13-2-1" evaluatedNodes=1 feasibleNodes=1
2025-04-01T08:33:43.469787415Z I0401 08:33:43.469738       1 schedule_one.go:286] "Successfully bound pod to node" pod="openshift-marketplace/certified-operators-8smxx" node="host-10-13-2-89" evaluatedNodes=6 feasibleNodes=3
2025-04-01T08:34:49.740976800Z I0401 08:34:49.740728       1 schedule_one.go:286] "Successfully bound pod to node" pod="openshift-marketplace/redhat-marketplace-6thg8" node="host-10-13-2-89" evaluatedNodes=6 feasibleNodes=3
2025-04-01T08:34:53.047608769Z I0401 08:34:53.044958       1 schedule_one.go:286] "Successfully bound pod to node" pod="openshift-ingress-canary/ingress-canary-4xsvh" node="host-10-13-2-1" evaluatedNodes=1 feasibleNodes=1
2025-04-01T08:34:53.047608769Z I0401 08:34:53.047332       1 schedule_one.go:286] "Successfully bound pod to node" pod="openshift-dns/dns-default-mc6g5" node="host-10-13-2-1" evaluatedNodes=1 feasibleNodes=1
2025-04-01T08:34:59.840232298Z I0401 08:34:59.840190       1 schedule_one.go:286] "Successfully bound pod to node" pod="openshift-dns/dns-default-tq6d7" node="host-10-13-3-120" evaluatedNodes=1 feasibleNodes=1
2025-04-01T08:34:59.846585764Z I0401 08:34:59.846444       1 schedule_one.go:286] "Successfully bound pod to node" pod="openshift-ingress-canary/ingress-canary-4blmj" node="host-10-13-3-120" evaluatedNodes=1 feasibleNodes=1
2025-04-01T08:39:53.224531641Z I0401 08:39:53.224496       1 schedule_one.go:286] "Successfully bound pod to node" pod="openshift-marketplace/community-operators-6k2qt" node="host-10-13-2-89" evaluatedNodes=6 feasibleNodes=3
2025-04-01T08:45:00.188066819Z I0401 08:45:00.187983       1 schedule_one.go:286] "Successfully bound pod to node" pod="openshift-operator-lifecycle-manager/collect-profiles-29058285-mdmmr" node="host-10-13-2-1" evaluatedNodes=6 feasibleNodes=3
2025-04-01T08:45:41.826140066Z I0401 08:45:41.824859       1 schedule_one.go:286] "Successfully bound pod to node" pod="openshift-marketplace/redhat-marketplace-pjxzk" node="host-10-13-2-89" evaluatedNodes=6 feasibleNodes=3
2025-04-01T08:46:45.459952302Z I0401 08:46:45.459887       1 schedule_one.go:286] "Successfully bound pod to node" pod="openshift-marketplace/redhat-operators-6twpn" node="host-10-13-2-89" evaluatedNodes=6 feasibleNodes=3
2025-04-01T08:46:45.662217266Z I0401 08:46:45.660584       1 schedule_one.go:286] "Successfully bound pod to node" pod="openshift-marketplace/certified-operators-kjl6j" node="host-10-13-2-89" evaluatedNodes=6 feasibleNodes=3
2025-04-01T08:52:40.796115264Z I0401 08:52:40.794705       1 schedule_one.go:286] "Successfully bound pod to node" pod="openshift-marketplace/community-operators-f8gxc" node="host-10-13-2-89" evaluatedNodes=6 feasibleNodes=3
2025-04-01T08:55:44.734438044Z I0401 08:55:44.734370       1 schedule_one.go:286] "Successfully bound pod to node" pod="openshift-marketplace/redhat-marketplace-lhm4k" node="host-10-13-2-89" evaluatedNodes=6 feasibleNodes=3
2025-04-01T08:57:56.051345103Z I0401 08:57:56.051109       1 schedule_one.go:286] "Successfully bound pod to node" pod="openshift-marketplace/certified-operators-vdtbf" node="host-10-13-2-89" evaluatedNodes=6 feasibleNodes=3
2025-04-01T08:59:47.077595214Z I0401 08:59:47.077545       1 schedule_one.go:286] "Successfully bound pod to node" pod="openshift-marketplace/redhat-operators-dbml8" node="host-10-13-2-89" evaluatedNodes=6 feasibleNodes=3
2025-04-01T09:00:00.141412708Z I0401 09:00:00.141349       1 schedule_one.go:286] "Successfully bound pod to node" pod="openshift-operator-lifecycle-manager/collect-profiles-29058300-nfcqz" node="host-10-13-2-1" evaluatedNodes=6 feasibleNodes=3
2025-04-01T09:03:47.830942063Z I0401 09:03:47.828146       1 schedule_one.go:286] "Successfully bound pod to node" pod="openshift-marketplace/community-operators-5rpdc" node="host-10-13-2-89" evaluatedNodes=6 feasibleNodes=3
2025-04-01T09:06:01.462600412Z I0401 09:06:01.462122       1 schedule_one.go:286] "Successfully bound pod to node" pod="openshift-marketplace/redhat-marketplace-n9tb9" node="host-10-13-2-89" evaluatedNodes=6 feasibleNodes=3
2025-04-01T09:08:39.288362338Z I0401 09:08:39.288191       1 schedule_one.go:286] "Successfully bound pod to node" pod="openshift-marketplace/certified-operators-stsp6" node="host-10-13-2-89" evaluatedNodes=6 feasibleNodes=3
2025-04-01T09:10:31.270722251Z I0401 09:10:31.269834       1 schedule_one.go:286] "Successfully bound pod to node" pod="openshift-marketplace/redhat-operators-4bl48" node="host-10-13-2-89" evaluatedNodes=6 feasibleNodes=3
2025-04-01T09:15:00.180490201Z I0401 09:15:00.177012       1 schedule_one.go:286] "Successfully bound pod to node" pod="openshift-operator-lifecycle-manager/collect-profiles-29058315-hs9vf" node="host-10-13-2-1" evaluatedNodes=6 feasibleNodes=3
2025-04-01T09:16:50.786918781Z I0401 09:16:50.786235       1 schedule_one.go:286] "Successfully bound pod to node" pod="openshift-marketplace/redhat-marketplace-wk5z4" node="host-10-13-2-89" evaluatedNodes=6 feasibleNodes=3
2025-04-01T09:17:05.636740326Z I0401 09:17:05.634263       1 schedule_one.go:286] "Successfully bound pod to node" pod="openshift-marketplace/community-operators-7mhv7" node="host-10-13-2-89" evaluatedNodes=6 feasibleNodes=3
2025-04-01T09:20:51.809693903Z I0401 09:20:51.805737       1 schedule_one.go:286] "Successfully bound pod to node" pod="openshift-marketplace/redhat-operators-bnr66" node="host-10-13-2-89" evaluatedNodes=6 feasibleNodes=3
2025-04-01T09:24:28.414773903Z I0401 09:24:28.413378       1 schedule_one.go:286] "Successfully bound pod to node" pod="openshift-marketplace/certified-operators-rn9nm" node="host-10-13-2-89" evaluatedNodes=6 feasibleNodes=3
2025-04-01T09:27:26.590133413Z I0401 09:27:26.590023       1 schedule_one.go:286] "Successfully bound pod to node" pod="openshift-marketplace/redhat-marketplace-zvp7l" node="host-10-13-2-89" evaluatedNodes=6 feasibleNodes=3
2025-04-01T09:28:22.908149129Z I0401 09:28:22.907548       1 schedule_one.go:286] "Successfully bound pod to node" pod="openshift-marketplace/community-operators-pjwlb" node="host-10-13-2-89" evaluatedNodes=6 feasibleNodes=3
2025-04-01T09:30:00.168817179Z I0401 09:30:00.168759       1 schedule_one.go:286] "Successfully bound pod to node" pod="openshift-operator-lifecycle-manager/collect-profiles-29058330-w6p6s" node="host-10-13-2-1" evaluatedNodes=6 feasibleNodes=3
2025-04-01T09:31:30.692257091Z I0401 09:31:30.692084       1 schedule_one.go:286] "Successfully bound pod to node" pod="openshift-marketplace/redhat-operators-22656" node="host-10-13-2-89" evaluatedNodes=6 feasibleNodes=3
2025-04-01T09:35:07.044149991Z I0401 09:35:07.043255       1 schedule_one.go:286] "Successfully bound pod to node" pod="openshift-marketplace/certified-operators-xspsf" node="host-10-13-2-89" evaluatedNodes=6 feasibleNodes=3
2025-04-01T09:36:42.352716933Z I0401 09:36:42.352098       1 tlsconfig.go:178] "Loaded client CA" index=0 certName="client-ca::kube-system::extension-apiserver-authentication::client-ca-file,client-ca::kube-system::extension-apiserver-authentication::requestheader-client-ca-file" certDetail="\"admin-kubeconfig-signer\" [] issuer=\"<self>\" (2025-03-31 12:55:13 +0000 UTC to 2035-03-29 12:55:13 +0000 UTC (now=2025-04-01 09:36:42.352071015 +0000 UTC))"
2025-04-01T09:36:42.352716933Z I0401 09:36:42.352122       1 tlsconfig.go:178] "Loaded client CA" index=1 certName="client-ca::kube-system::extension-apiserver-authentication::client-ca-file,client-ca::kube-system::extension-apiserver-authentication::requestheader-client-ca-file" certDetail="\"kubelet-signer\" [] issuer=\"<self>\" (2025-03-31 12:55:15 +0000 UTC to 2025-04-01 12:55:15 +0000 UTC (now=2025-04-01 09:36:42.352112664 +0000 UTC))"
2025-04-01T09:36:42.352716933Z I0401 09:36:42.352157       1 tlsconfig.go:178] "Loaded client CA" index=2 certName="client-ca::kube-system::extension-apiserver-authentication::client-ca-file,client-ca::kube-system::extension-apiserver-authentication::requestheader-client-ca-file" certDetail="\"kube-control-plane-signer\" [] issuer=\"<self>\" (2025-03-31 12:55:15 +0000 UTC to 2026-03-31 12:55:15 +0000 UTC (now=2025-04-01 09:36:42.352127284 +0000 UTC))"
2025-04-01T09:36:42.352716933Z I0401 09:36:42.352169       1 tlsconfig.go:178] "Loaded client CA" index=3 certName="client-ca::kube-system::extension-apiserver-authentication::client-ca-file,client-ca::kube-system::extension-apiserver-authentication::requestheader-client-ca-file" certDetail="\"kube-apiserver-to-kubelet-signer\" [] issuer=\"<self>\" (2025-03-31 12:55:15 +0000 UTC to 2026-03-31 12:55:15 +0000 UTC (now=2025-04-01 09:36:42.352161633 +0000 UTC))"
2025-04-01T09:36:42.352716933Z I0401 09:36:42.352180       1 tlsconfig.go:178] "Loaded client CA" index=4 certName="client-ca::kube-system::extension-apiserver-authentication::client-ca-file,client-ca::kube-system::extension-apiserver-authentication::requestheader-client-ca-file" certDetail="\"kubelet-bootstrap-kubeconfig-signer\" [] issuer=\"<self>\" (2025-03-31 12:55:13 +0000 UTC to 2035-03-29 12:55:13 +0000 UTC (now=2025-04-01 09:36:42.352173883 +0000 UTC))"
2025-04-01T09:36:42.352716933Z I0401 09:36:42.352190       1 tlsconfig.go:178] "Loaded client CA" index=5 certName="client-ca::kube-system::extension-apiserver-authentication::client-ca-file,client-ca::kube-system::extension-apiserver-authentication::requestheader-client-ca-file" certDetail="\"kube-csr-signer_@1743452525\" [] issuer=\"kubelet-signer\" (2025-03-31 20:22:04 +0000 UTC to 2025-04-01 12:55:15 +0000 UTC (now=2025-04-01 09:36:42.352184443 +0000 UTC))"
2025-04-01T09:36:42.352716933Z I0401 09:36:42.352202       1 tlsconfig.go:178] "Loaded client CA" index=6 certName="client-ca::kube-system::extension-apiserver-authentication::client-ca-file,client-ca::kube-system::extension-apiserver-authentication::requestheader-client-ca-file" certDetail="\"openshift-kube-apiserver-operator_node-system-admin-signer@1743452539\" [] issuer=\"<self>\" (2025-03-31 20:22:18 +0000 UTC to 2026-03-31 20:22:19 +0000 UTC (now=2025-04-01 09:36:42.352195003 +0000 UTC))"
2025-04-01T09:36:42.352716933Z I0401 09:36:42.352215       1 tlsconfig.go:178] "Loaded client CA" index=7 certName="client-ca::kube-system::extension-apiserver-authentication::client-ca-file,client-ca::kube-system::extension-apiserver-authentication::requestheader-client-ca-file" certDetail="\"openshift-kube-controller-manager-operator_csr-signer-signer@1743494861\" [] issuer=\"<self>\" (2025-04-01 08:07:40 +0000 UTC to 2025-05-31 08:07:41 +0000 UTC (now=2025-04-01 09:36:42.352208282 +0000 UTC))"
2025-04-01T09:36:42.352716933Z I0401 09:36:42.352227       1 tlsconfig.go:178] "Loaded client CA" index=8 certName="client-ca::kube-system::extension-apiserver-authentication::client-ca-file,client-ca::kube-system::extension-apiserver-authentication::requestheader-client-ca-file" certDetail="\"kube-csr-signer_@1743500201\" [] issuer=\"openshift-kube-controller-manager-operator_csr-signer-signer@1743494861\" (2025-04-01 09:36:40 +0000 UTC to 2025-05-01 09:36:41 +0000 UTC (now=2025-04-01 09:36:42.352219512 +0000 UTC))"
2025-04-01T09:36:42.352716933Z I0401 09:36:42.352251       1 tlsconfig.go:178] "Loaded client CA" index=9 certName="client-ca::kube-system::extension-apiserver-authentication::client-ca-file,client-ca::kube-system::extension-apiserver-authentication::requestheader-client-ca-file" certDetail="\"aggregator-signer\" [] issuer=\"<self>\" (2025-03-31 12:55:14 +0000 UTC to 2025-04-01 12:55:14 +0000 UTC (now=2025-04-01 09:36:42.352232223 +0000 UTC))"
2025-04-01T09:36:42.352716933Z I0401 09:36:42.352266       1 tlsconfig.go:178] "Loaded client CA" index=10 certName="client-ca::kube-system::extension-apiserver-authentication::client-ca-file,client-ca::kube-system::extension-apiserver-authentication::requestheader-client-ca-file" certDetail="\"openshift-kube-apiserver-operator_aggregator-client-signer@1743494854\" [] issuer=\"<self>\" (2025-04-01 08:07:34 +0000 UTC to 2025-05-01 08:07:35 +0000 UTC (now=2025-04-01 09:36:42.352257772 +0000 UTC))"
2025-04-01T09:36:42.352716933Z I0401 09:36:42.352523       1 tlsconfig.go:200] "Loaded serving cert" certName="serving-cert::/etc/kubernetes/static-pod-resources/secrets/serving-cert/tls.crt::/etc/kubernetes/static-pod-resources/secrets/serving-cert/tls.key" certDetail="\"scheduler.openshift-kube-scheduler.svc\" [serving] validServingFor=[scheduler.openshift-kube-scheduler.svc,scheduler.openshift-kube-scheduler.svc.cluster.local] issuer=\"openshift-service-serving-signer@1743452529\" (2025-03-31 20:22:27 +0000 UTC to 2027-03-31 20:22:28 +0000 UTC (now=2025-04-01 09:36:42.352514076 +0000 UTC))"
2025-04-01T09:36:42.352766022Z I0401 09:36:42.352747       1 named_certificates.go:53] "Loaded SNI cert" index=0 certName="self-signed loopback" certDetail="\"apiserver-loopback-client@1743453601\" [serving] validServingFor=[apiserver-loopback-client] issuer=\"apiserver-loopback-client-ca@1743453600\" (2025-03-31 19:40:00 +0000 UTC to 2026-03-31 19:40:00 +0000 UTC (now=2025-04-01 09:36:42.352738842 +0000 UTC))"
2025-04-01T09:36:47.178098796Z I0401 09:36:47.178060       1 schedule_one.go:286] "Successfully bound pod to node" pod="openshift-monitoring/prometheus-adapter-55bb5b7fb-8qj8j" node="host-10-13-3-78" evaluatedNodes=6 feasibleNodes=3
2025-04-01T09:36:47.226742890Z I0401 09:36:47.226700       1 schedule_one.go:286] "Successfully bound pod to node" pod="openshift-monitoring/prometheus-adapter-55bb5b7fb-mbfjh" node="host-10-13-2-1" evaluatedNodes=6 feasibleNodes=2
2025-04-01T09:37:48.418247646Z I0401 09:37:48.418120       1 schedule_one.go:286] "Successfully bound pod to node" pod="openshift-marketplace/redhat-marketplace-ftz5k" node="host-10-13-2-89" evaluatedNodes=6 feasibleNodes=3
2025-04-01T09:38:50.519066965Z I0401 09:38:50.518804       1 schedule_one.go:286] "Successfully bound pod to node" pod="openshift-marketplace/community-operators-mrhb5" node="host-10-13-2-89" evaluatedNodes=6 feasibleNodes=3
2025-04-01T09:39:07.426474618Z I0401 09:39:07.426380       1 schedule_one.go:988] "Unable to schedule pod; no fit; waiting" pod="openshift-controller-manager/controller-manager-895846ddf-65tlt" err="0/6 nodes are available: 3 node(s) didn't match Pod's node affinity/selector, 3 node(s) didn't match pod anti-affinity rules. preemption: 0/6 nodes are available: 3 Preemption is not helpful for scheduling, 3 node(s) didn't match pod anti-affinity rules.."
2025-04-01T09:39:07.459130550Z I0401 09:39:07.457706       1 schedule_one.go:988] "Unable to schedule pod; no fit; waiting" pod="openshift-route-controller-manager/route-controller-manager-6f5895fb69-dhf4l" err="0/6 nodes are available: 3 node(s) didn't match Pod's node affinity/selector, 3 node(s) didn't match pod anti-affinity rules. preemption: 0/6 nodes are available: 3 Preemption is not helpful for scheduling, 3 node(s) didn't match pod anti-affinity rules.."
2025-04-01T09:39:07.554501514Z I0401 09:39:07.554334       1 schedule_one.go:988] "Unable to schedule pod; no fit; waiting" pod="openshift-controller-manager/controller-manager-74d786c997-sfmnx" err="0/6 nodes are available: 3 node(s) didn't match Pod's node affinity/selector, 3 node(s) didn't match pod anti-affinity rules. preemption: 0/6 nodes are available: 3 Preemption is not helpful for scheduling, 3 node(s) didn't match pod anti-affinity rules.."
2025-04-01T09:39:07.581644721Z I0401 09:39:07.580658       1 schedule_one.go:988] "Unable to schedule pod; no fit; waiting" pod="openshift-route-controller-manager/route-controller-manager-6987788844-5mzhv" err="0/6 nodes are available: 3 node(s) didn't match Pod's node affinity/selector, 3 node(s) didn't match pod anti-affinity rules. preemption: 0/6 nodes are available: 3 Preemption is not helpful for scheduling, 3 node(s) didn't match pod anti-affinity rules.."
2025-04-01T09:39:08.866473526Z I0401 09:39:08.866174       1 schedule_one.go:286] "Successfully bound pod to node" pod="openshift-controller-manager/controller-manager-74d786c997-sfmnx" node="host-10-13-2-89" evaluatedNodes=6 feasibleNodes=1
2025-04-01T09:39:08.866568294Z I0401 09:39:08.866536       1 schedule_one.go:286] "Successfully bound pod to node" pod="openshift-route-controller-manager/route-controller-manager-6987788844-5mzhv" node="host-10-13-2-89" evaluatedNodes=6 feasibleNodes=1
2025-04-01T09:39:10.316637768Z I0401 09:39:10.316603       1 schedule_one.go:988] "Unable to schedule pod; no fit; waiting" pod="openshift-controller-manager/controller-manager-74d786c997-867xq" err="0/6 nodes are available: 3 node(s) didn't match Pod's node affinity/selector, 3 node(s) didn't match pod anti-affinity rules. preemption: 0/6 nodes are available: 3 Preemption is not helpful for scheduling, 3 node(s) didn't match pod anti-affinity rules.."
2025-04-01T09:39:10.462596658Z I0401 09:39:10.452251       1 schedule_one.go:988] "Unable to schedule pod; no fit; waiting" pod="openshift-route-controller-manager/route-controller-manager-6987788844-sth7g" err="0/6 nodes are available: 3 node(s) didn't match Pod's node affinity/selector, 3 node(s) didn't match pod anti-affinity rules. preemption: 0/6 nodes are available: 3 Preemption is not helpful for scheduling, 3 node(s) didn't match pod anti-affinity rules.."
2025-04-01T09:39:11.867580509Z I0401 09:39:11.866707       1 schedule_one.go:286] "Successfully bound pod to node" pod="openshift-controller-manager/controller-manager-74d786c997-867xq" node="host-10-13-0-150" evaluatedNodes=6 feasibleNodes=1
2025-04-01T09:39:11.867580509Z I0401 09:39:11.866742       1 schedule_one.go:286] "Successfully bound pod to node" pod="openshift-route-controller-manager/route-controller-manager-6987788844-sth7g" node="host-10-13-0-150" evaluatedNodes=6 feasibleNodes=1
2025-04-01T09:39:13.643099677Z I0401 09:39:13.643059       1 schedule_one.go:988] "Unable to schedule pod; no fit; waiting" pod="openshift-controller-manager/controller-manager-74d786c997-4k7lz" err="0/6 nodes are available: 3 node(s) didn't match Pod's node affinity/selector, 3 node(s) didn't match pod anti-affinity rules. preemption: 0/6 nodes are available: 3 Preemption is not helpful for scheduling, 3 node(s) didn't match pod anti-affinity rules.."
2025-04-01T09:39:13.699882045Z I0401 09:39:13.699833       1 schedule_one.go:988] "Unable to schedule pod; no fit; waiting" pod="openshift-route-controller-manager/route-controller-manager-6987788844-2rw2m" err="0/6 nodes are available: 3 node(s) didn't match Pod's node affinity/selector, 3 node(s) didn't match pod anti-affinity rules. preemption: 0/6 nodes are available: 3 Preemption is not helpful for scheduling, 3 node(s) didn't match pod anti-affinity rules.."
2025-04-01T09:39:14.866814069Z I0401 09:39:14.866757       1 schedule_one.go:286] "Successfully bound pod to node" pod="openshift-route-controller-manager/route-controller-manager-6987788844-2rw2m" node="host-10-13-2-160" evaluatedNodes=6 feasibleNodes=1
2025-04-01T09:39:14.870829782Z I0401 09:39:14.870793       1 schedule_one.go:286] "Successfully bound pod to node" pod="openshift-controller-manager/controller-manager-74d786c997-4k7lz" node="host-10-13-2-160" evaluatedNodes=6 feasibleNodes=1
2025-04-01T09:42:53.033214020Z I0401 09:42:53.033149       1 schedule_one.go:286] "Successfully bound pod to node" pod="openshift-marketplace/redhat-operators-9rfhw" node="host-10-13-2-89" evaluatedNodes=6 feasibleNodes=3
2025-04-01T09:45:00.236836072Z I0401 09:45:00.236742       1 schedule_one.go:286] "Successfully bound pod to node" pod="openshift-operator-lifecycle-manager/collect-profiles-29058345-6kcfc" node="host-10-13-2-1" evaluatedNodes=6 feasibleNodes=3
2025-04-01T09:45:07.096306865Z I0401 09:45:07.096269       1 schedule_one.go:286] "Successfully bound pod to node" pod="openshift-marketplace/certified-operators-bsk7j" node="host-10-13-2-89" evaluatedNodes=6 feasibleNodes=3
2025-04-01T09:49:26.054568799Z I0401 09:49:26.054157       1 schedule_one.go:286] "Successfully bound pod to node" pod="openshift-marketplace/community-operators-vrnqw" node="host-10-13-2-89" evaluatedNodes=6 feasibleNodes=3
2025-04-01T09:51:52.711023714Z I0401 09:51:52.710954       1 schedule_one.go:286] "Successfully bound pod to node" pod="openshift-marketplace/redhat-marketplace-wd68m" node="host-10-13-2-89" evaluatedNodes=6 feasibleNodes=3
2025-04-01T09:54:31.997136096Z I0401 09:54:31.997067       1 schedule_one.go:286] "Successfully bound pod to node" pod="openshift-marketplace/redhat-operators-m5n6q" node="host-10-13-2-89" evaluatedNodes=6 feasibleNodes=3
2025-04-01T09:57:12.389819161Z I0401 09:57:12.388930       1 schedule_one.go:286] "Successfully bound pod to node" pod="openshift-marketplace/certified-operators-vt64v" node="host-10-13-2-89" evaluatedNodes=6 feasibleNodes=3
2025-04-01T10:00:00.156325118Z I0401 10:00:00.156247       1 schedule_one.go:286] "Successfully bound pod to node" pod="openshift-operator-lifecycle-manager/collect-profiles-29058360-vj679" node="host-10-13-2-1" evaluatedNodes=6 feasibleNodes=3
2025-04-01T10:02:26.515332749Z I0401 10:02:26.515267       1 schedule_one.go:286] "Successfully bound pod to node" pod="openshift-marketplace/redhat-marketplace-6jgv9" node="host-10-13-2-89" evaluatedNodes=6 feasibleNodes=3
2025-04-01T10:04:04.434359177Z I0401 10:04:04.434295       1 schedule_one.go:286] "Successfully bound pod to node" pod="openshift-marketplace/community-operators-9jxx8" node="host-10-13-2-89" evaluatedNodes=6 feasibleNodes=3
2025-04-01T10:04:53.336195442Z I0401 10:04:53.336015       1 schedule_one.go:286] "Successfully bound pod to node" pod="openshift-marketplace/redhat-operators-jl6ks" node="host-10-13-2-89" evaluatedNodes=6 feasibleNodes=3
2025-04-01T10:09:17.703580690Z I0401 10:09:17.701863       1 schedule_one.go:286] "Successfully bound pod to node" pod="openshift-marketplace/certified-operators-7r4hl" node="host-10-13-2-89" evaluatedNodes=6 feasibleNodes=3
2025-04-01T10:13:07.929334731Z I0401 10:13:07.924053       1 schedule_one.go:286] "Successfully bound pod to node" pod="openshift-marketplace/redhat-marketplace-xdd92" node="host-10-13-2-89" evaluatedNodes=6 feasibleNodes=3
2025-04-01T10:14:55.377863084Z I0401 10:14:55.377803       1 schedule_one.go:286] "Successfully bound pod to node" pod="openshift-marketplace/redhat-operators-dngp7" node="host-10-13-2-89" evaluatedNodes=6 feasibleNodes=3
2025-04-01T10:15:00.152752979Z I0401 10:15:00.150763       1 schedule_one.go:286] "Successfully bound pod to node" pod="openshift-operator-lifecycle-manager/collect-profiles-29058375-jxbxr" node="host-10-13-2-1" evaluatedNodes=6 feasibleNodes=3
2025-04-01T10:17:54.755144200Z I0401 10:17:54.755091       1 schedule_one.go:286] "Successfully bound pod to node" pod="openshift-marketplace/community-operators-l4lqq" node="host-10-13-2-89" evaluatedNodes=6 feasibleNodes=3
2025-04-01T10:19:54.933861076Z I0401 10:19:54.933634       1 schedule_one.go:286] "Successfully bound pod to node" pod="openshift-marketplace/certified-operators-qjmxs" node="host-10-13-2-89" evaluatedNodes=6 feasibleNodes=3
2025-04-01T10:24:30.995619865Z I0401 10:24:30.992204       1 schedule_one.go:286] "Successfully bound pod to node" pod="openshift-marketplace/redhat-marketplace-pkztg" node="host-10-13-2-89" evaluatedNodes=6 feasibleNodes=3
2025-04-01T10:25:30.699618128Z I0401 10:25:30.699566       1 schedule_one.go:286] "Successfully bound pod to node" pod="openshift-marketplace/redhat-operators-5nw9s" node="host-10-13-2-89" evaluatedNodes=6 feasibleNodes=3
2025-04-01T10:30:00.145884139Z I0401 10:30:00.145840       1 schedule_one.go:286] "Successfully bound pod to node" pod="openshift-operator-lifecycle-manager/collect-profiles-29058390-2rswb" node="host-10-13-2-1" evaluatedNodes=6 feasibleNodes=3
2025-04-01T10:30:56.158808603Z I0401 10:30:56.158706       1 schedule_one.go:286] "Successfully bound pod to node" pod="openshift-marketplace/certified-operators-svxwp" node="host-10-13-2-89" evaluatedNodes=6 feasibleNodes=3
2025-04-01T10:30:56.526234892Z I0401 10:30:56.526183       1 schedule_one.go:286] "Successfully bound pod to node" pod="openshift-marketplace/community-operators-m2j7v" node="host-10-13-2-89" evaluatedNodes=6 feasibleNodes=3
2025-04-01T10:39:46.560798475Z I0401 10:39:46.560050       1 schedule_one.go:286] "Successfully bound pod to node" pod="openshift-marketplace/redhat-operators-vtnf7" node="host-10-13-2-89" evaluatedNodes=6 feasibleNodes=3
2025-04-01T10:39:46.718463073Z I0401 10:39:46.718280       1 schedule_one.go:286] "Successfully bound pod to node" pod="openshift-marketplace/redhat-marketplace-cbj99" node="host-10-13-2-89" evaluatedNodes=6 feasibleNodes=3
2025-04-01T10:41:12.473663984Z I0401 10:41:12.473619       1 schedule_one.go:286] "Successfully bound pod to node" pod="openshift-marketplace/certified-operators-hgqxp" node="host-10-13-2-89" evaluatedNodes=6 feasibleNodes=3
2025-04-01T10:43:58.152585355Z I0401 10:43:58.148346       1 schedule_one.go:286] "Successfully bound pod to node" pod="openshift-marketplace/community-operators-77ztt" node="host-10-13-2-89" evaluatedNodes=6 feasibleNodes=3
2025-04-01T10:45:00.186390181Z I0401 10:45:00.186352       1 schedule_one.go:286] "Successfully bound pod to node" pod="openshift-operator-lifecycle-manager/collect-profiles-29058405-cwdbq" node="host-10-13-2-1" evaluatedNodes=6 feasibleNodes=3
2025-04-01T10:50:44.673093634Z I0401 10:50:44.670928       1 schedule_one.go:286] "Successfully bound pod to node" pod="openshift-marketplace/redhat-marketplace-ptgjl" node="host-10-13-2-89" evaluatedNodes=6 feasibleNodes=3
2025-04-01T10:54:28.411489443Z I0401 10:54:28.411367       1 schedule_one.go:286] "Successfully bound pod to node" pod="openshift-marketplace/certified-operators-c65t6" node="host-10-13-2-89" evaluatedNodes=6 feasibleNodes=3
2025-04-01T10:54:30.389782641Z I0401 10:54:30.389595       1 schedule_one.go:286] "Successfully bound pod to node" pod="openshift-marketplace/community-operators-l8vwg" node="host-10-13-2-89" evaluatedNodes=6 feasibleNodes=3
2025-04-01T10:54:31.995463864Z I0401 10:54:31.995395       1 schedule_one.go:286] "Successfully bound pod to node" pod="openshift-marketplace/redhat-operators-5pn2m" node="host-10-13-2-160" evaluatedNodes=6 feasibleNodes=3
2025-04-01T11:00:00.150787580Z I0401 11:00:00.150742       1 schedule_one.go:286] "Successfully bound pod to node" pod="openshift-operator-lifecycle-manager/collect-profiles-29058420-46nqr" node="host-10-13-2-1" evaluatedNodes=6 feasibleNodes=3
2025-04-01T11:04:39.409390000Z I0401 11:04:39.409279       1 schedule_one.go:286] "Successfully bound pod to node" pod="openshift-marketplace/redhat-operators-8hp62" node="host-10-13-2-89" evaluatedNodes=6 feasibleNodes=3
2025-04-01T11:04:58.694533142Z I0401 11:04:58.694444       1 schedule_one.go:286] "Successfully bound pod to node" pod="openshift-marketplace/certified-operators-8csvb" node="host-10-13-2-89" evaluatedNodes=6 feasibleNodes=3
2025-04-01T11:09:44.164290057Z I0401 11:09:44.163661       1 schedule_one.go:286] "Successfully bound pod to node" pod="openshift-marketplace/community-operators-cb4vb" node="host-10-13-2-160" evaluatedNodes=6 feasibleNodes=3
2025-04-01T11:09:44.352206951Z I0401 11:09:44.352177       1 schedule_one.go:286] "Successfully bound pod to node" pod="openshift-marketplace/redhat-marketplace-zgkcl" node="host-10-13-2-89" evaluatedNodes=6 feasibleNodes=3
2025-04-01T11:15:00.161246447Z I0401 11:15:00.161148       1 schedule_one.go:286] "Successfully bound pod to node" pod="openshift-operator-lifecycle-manager/collect-profiles-29058435-vbn5w" node="host-10-13-2-1" evaluatedNodes=6 feasibleNodes=3
2025-04-01T11:15:05.691634076Z I0401 11:15:05.691581       1 schedule_one.go:286] "Successfully bound pod to node" pod="openshift-marketplace/certified-operators-2kh7w" node="host-10-13-2-160" evaluatedNodes=6 feasibleNodes=3
2025-04-01T11:15:29.424918123Z I0401 11:15:29.423977       1 schedule_one.go:286] "Successfully bound pod to node" pod="openshift-marketplace/redhat-operators-dpptx" node="host-10-13-2-89" evaluatedNodes=6 feasibleNodes=3
2025-04-01T11:21:12.284632542Z I0401 11:21:12.284537       1 schedule_one.go:286] "Successfully bound pod to node" pod="openshift-marketplace/redhat-marketplace-86fkq" node="host-10-13-2-160" evaluatedNodes=6 feasibleNodes=3
2025-04-01T11:21:31.698417307Z I0401 11:21:31.697767       1 schedule_one.go:286] "Successfully bound pod to node" pod="openshift-marketplace/community-operators-g2kpf" node="host-10-13-2-160" evaluatedNodes=6 feasibleNodes=3
2025-04-01T11:25:54.275524564Z I0401 11:25:54.273272       1 schedule_one.go:286] "Successfully bound pod to node" pod="openshift-marketplace/redhat-operators-nntvm" node="host-10-13-2-89" evaluatedNodes=6 feasibleNodes=3
2025-04-01T11:30:00.158613054Z I0401 11:30:00.158538       1 schedule_one.go:286] "Successfully bound pod to node" pod="openshift-operator-lifecycle-manager/collect-profiles-29058450-np2v6" node="host-10-13-2-1" evaluatedNodes=6 feasibleNodes=3
2025-04-01T11:33:19.705966305Z I0401 11:33:19.705317       1 schedule_one.go:286] "Successfully bound pod to node" pod="openshift-marketplace/certified-operators-pj2gv" node="host-10-13-2-89" evaluatedNodes=6 feasibleNodes=3
2025-04-01T11:33:19.720342327Z I0401 11:33:19.720273       1 schedule_one.go:286] "Successfully bound pod to node" pod="openshift-marketplace/redhat-marketplace-xbtx7" node="host-10-13-2-89" evaluatedNodes=6 feasibleNodes=3
2025-04-01T11:33:20.502691503Z I0401 11:33:20.502640       1 schedule_one.go:286] "Successfully bound pod to node" pod="openshift-marketplace/community-operators-gr7h9" node="host-10-13-2-160" evaluatedNodes=6 feasibleNodes=3
2025-04-01T11:36:03.206932078Z I0401 11:36:03.205405       1 schedule_one.go:286] "Successfully bound pod to node" pod="openshift-marketplace/redhat-operators-qmq2t" node="host-10-13-2-89" evaluatedNodes=6 feasibleNodes=3
2025-04-01T11:44:38.119002650Z I0401 11:44:38.118757       1 schedule_one.go:286] "Successfully bound pod to node" pod="openshift-marketplace/community-operators-mx7fc" node="host-10-13-2-89" evaluatedNodes=6 feasibleNodes=3
2025-04-01T11:45:00.220013922Z I0401 11:45:00.219695       1 schedule_one.go:286] "Successfully bound pod to node" pod="openshift-operator-lifecycle-manager/collect-profiles-29058465-tzwgn" node="host-10-13-2-1" evaluatedNodes=6 feasibleNodes=3
2025-04-01T11:46:00.073047171Z I0401 11:46:00.073012       1 schedule_one.go:286] "Successfully bound pod to node" pod="openshift-marketplace/certified-operators-2b8zk" node="host-10-13-2-89" evaluatedNodes=6 feasibleNodes=3
2025-04-01T11:46:00.246452270Z I0401 11:46:00.246419       1 schedule_one.go:286] "Successfully bound pod to node" pod="openshift-marketplace/redhat-marketplace-fkbll" node="host-10-13-2-89" evaluatedNodes=6 feasibleNodes=3
2025-04-01T11:46:37.800976713Z I0401 11:46:37.800846       1 schedule_one.go:286] "Successfully bound pod to node" pod="openshift-marketplace/redhat-operators-wxr2d" node="host-10-13-2-89" evaluatedNodes=6 feasibleNodes=3
2025-04-01T11:56:28.520367209Z I0401 11:56:28.520266       1 schedule_one.go:286] "Successfully bound pod to node" pod="openshift-marketplace/certified-operators-n49rv" node="host-10-13-2-89" evaluatedNodes=6 feasibleNodes=3
2025-04-01T11:57:40.271234396Z I0401 11:57:40.271177       1 schedule_one.go:286] "Successfully bound pod to node" pod="openshift-marketplace/redhat-operators-wmfqs" node="host-10-13-2-89" evaluatedNodes=6 feasibleNodes=3
2025-04-01T11:58:05.374810086Z I0401 11:58:05.374776       1 schedule_one.go:286] "Successfully bound pod to node" pod="openshift-marketplace/community-operators-5q2fg" node="host-10-13-2-89" evaluatedNodes=6 feasibleNodes=3
2025-04-01T11:58:05.741530682Z I0401 11:58:05.741291       1 schedule_one.go:286] "Successfully bound pod to node" pod="openshift-marketplace/redhat-marketplace-f2j5m" node="host-10-13-2-89" evaluatedNodes=6 feasibleNodes=3
2025-04-01T12:00:00.161122479Z I0401 12:00:00.160386       1 schedule_one.go:286] "Successfully bound pod to node" pod="openshift-operator-lifecycle-manager/collect-profiles-29058480-cdx47" node="host-10-13-2-1" evaluatedNodes=6 feasibleNodes=3
2025-04-01T12:06:36.503611717Z I0401 12:06:36.503577       1 schedule_one.go:286] "Successfully bound pod to node" pod="openshift-marketplace/certified-operators-lgt62" node="host-10-13-2-160" evaluatedNodes=6 feasibleNodes=3
2025-04-01T12:08:39.306948653Z I0401 12:08:39.306802       1 schedule_one.go:286] "Successfully bound pod to node" pod="openshift-marketplace/redhat-marketplace-bqrf4" node="host-10-13-2-160" evaluatedNodes=6 feasibleNodes=3
2025-04-01T12:08:53.873642806Z I0401 12:08:53.873316       1 schedule_one.go:286] "Successfully bound pod to node" pod="openshift-marketplace/redhat-operators-52qct" node="host-10-13-2-160" evaluatedNodes=6 feasibleNodes=3
2025-04-01T12:09:02.377459298Z I0401 12:09:02.377258       1 schedule_one.go:286] "Successfully bound pod to node" pod="openshift-marketplace/community-operators-2pb6k" node="host-10-13-2-89" evaluatedNodes=6 feasibleNodes=3
2025-04-01T12:13:05.847050367Z I0401 12:13:05.847014       1 schedule_one.go:988] "Unable to schedule pod; no fit; waiting" pod="default/nginx" err="0/6 nodes are available: pod has unbound immediate PersistentVolumeClaims. preemption: 0/6 nodes are available: 6 Preemption is not helpful for scheduling.."
2025-04-01T12:15:00.158425956Z I0401 12:15:00.158355       1 schedule_one.go:286] "Successfully bound pod to node" pod="openshift-operator-lifecycle-manager/collect-profiles-29058495-shnx9" node="host-10-13-2-1" evaluatedNodes=6 feasibleNodes=3
2025-04-01T12:17:29.079655893Z I0401 12:17:29.079445       1 schedule_one.go:286] "Successfully bound pod to node" pod="openshift-marketplace/certified-operators-b5xlq" node="host-10-13-2-160" evaluatedNodes=6 feasibleNodes=3
2025-04-01T12:18:32.392029213Z I0401 12:18:32.391933       1 schedule_one.go:988] "Unable to schedule pod; no fit; waiting" pod="default/nginx" err="0/6 nodes are available: pod has unbound immediate PersistentVolumeClaims. preemption: 0/6 nodes are available: 6 Preemption is not helpful for scheduling.."
2025-04-01T12:18:42.381696984Z I0401 12:18:42.381661       1 schedule_one.go:286] "Successfully bound pod to node" pod="openshift-marketplace/redhat-marketplace-94f5g" node="host-10-13-2-160" evaluatedNodes=6 feasibleNodes=3
2025-04-01T12:19:07.252753425Z I0401 12:19:07.251047       1 schedule_one.go:286] "Successfully bound pod to node" pod="openshift-marketplace/community-operators-vxkqw" node="host-10-13-2-160" evaluatedNodes=6 feasibleNodes=3
2025-04-01T12:23:32.396519815Z I0401 12:23:32.396469       1 schedule_one.go:988] "Unable to schedule pod; no fit; waiting" pod="default/nginx" err="0/6 nodes are available: pod has unbound immediate PersistentVolumeClaims. preemption: 0/6 nodes are available: 6 Preemption is not helpful for scheduling.."
2025-04-01T12:24:32.003786356Z I0401 12:24:32.002832       1 schedule_one.go:286] "Successfully bound pod to node" pod="openshift-marketplace/redhat-operators-tn4tz" node="host-10-13-2-160" evaluatedNodes=6 feasibleNodes=3
2025-04-01T12:28:08.833579836Z I0401 12:28:08.833454       1 schedule_one.go:286] "Successfully bound pod to node" pod="openshift-marketplace/certified-operators-bkv5g" node="host-10-13-2-160" evaluatedNodes=6 feasibleNodes=3
2025-04-01T12:28:32.401794132Z I0401 12:28:32.401491       1 schedule_one.go:988] "Unable to schedule pod; no fit; waiting" pod="default/nginx" err="0/6 nodes are available: pod has unbound immediate PersistentVolumeClaims. preemption: 0/6 nodes are available: 6 Preemption is not helpful for scheduling.."
2025-04-01T12:29:12.639474253Z I0401 12:29:12.639372       1 schedule_one.go:286] "Successfully bound pod to node" pod="openshift-marketplace/community-operators-lwwml" node="host-10-13-2-160" evaluatedNodes=6 feasibleNodes=3
2025-04-01T12:29:44.996212593Z I0401 12:29:44.996115       1 schedule_one.go:286] "Successfully bound pod to node" pod="openshift-marketplace/redhat-marketplace-vm8nt" node="host-10-13-2-160" evaluatedNodes=6 feasibleNodes=3
2025-04-01T12:30:00.145566428Z I0401 12:30:00.145512       1 schedule_one.go:286] "Successfully bound pod to node" pod="openshift-operator-lifecycle-manager/collect-profiles-29058510-cs76v" node="host-10-13-2-1" evaluatedNodes=6 feasibleNodes=3
2025-04-01T12:33:32.412182069Z I0401 12:33:32.412109       1 schedule_one.go:988] "Unable to schedule pod; no fit; waiting" pod="default/nginx" err="0/6 nodes are available: pod has unbound immediate PersistentVolumeClaims. preemption: 0/6 nodes are available: 6 Preemption is not helpful for scheduling.."
2025-04-01T12:35:30.173916911Z I0401 12:35:30.173840       1 schedule_one.go:286] "Successfully bound pod to node" pod="openshift-marketplace/redhat-operators-fnzxb" node="host-10-13-2-160" evaluatedNodes=6 feasibleNodes=3
2025-04-01T12:38:32.417144073Z I0401 12:38:32.417087       1 schedule_one.go:988] "Unable to schedule pod; no fit; waiting" pod="default/nginx" err="0/6 nodes are available: pod has unbound immediate PersistentVolumeClaims. preemption: 0/6 nodes are available: 6 Preemption is not helpful for scheduling.."
2025-04-01T12:38:50.179055913Z I0401 12:38:50.178958       1 schedule_one.go:286] "Successfully bound pod to node" pod="kube-system/csi-cinder-controllerplugin-5847b67f7b-8l8p4" node="host-10-13-3-120" evaluatedNodes=6 feasibleNodes=3
2025-04-01T12:38:50.447752647Z I0401 12:38:50.447706       1 schedule_one.go:286] "Successfully bound pod to node" pod="kube-system/csi-cinder-nodeplugin-7q5nb" node="host-10-13-3-120" evaluatedNodes=1 feasibleNodes=1
2025-04-01T12:38:50.462052582Z I0401 12:38:50.461782       1 schedule_one.go:286] "Successfully bound pod to node" pod="kube-system/csi-cinder-nodeplugin-mqd7k" node="host-10-13-0-150" evaluatedNodes=1 feasibleNodes=1
2025-04-01T12:38:50.463772399Z I0401 12:38:50.463738       1 schedule_one.go:988] "Unable to schedule pod; no fit; waiting" pod="default/nginx" err="0/6 nodes are available: pod has unbound immediate PersistentVolumeClaims. preemption: 0/6 nodes are available: 6 Preemption is not helpful for scheduling.."
2025-04-01T12:38:50.466849910Z I0401 12:38:50.466799       1 schedule_one.go:286] "Successfully bound pod to node" pod="kube-system/csi-cinder-nodeplugin-smlq4" node="host-10-13-2-1" evaluatedNodes=1 feasibleNodes=1
2025-04-01T12:38:50.481131476Z I0401 12:38:50.481095       1 schedule_one.go:286] "Successfully bound pod to node" pod="kube-system/csi-cinder-nodeplugin-gpgc9" node="host-10-13-3-78" evaluatedNodes=1 feasibleNodes=1
2025-04-01T12:38:50.491536575Z I0401 12:38:50.491360       1 schedule_one.go:286] "Successfully bound pod to node" pod="kube-system/csi-cinder-nodeplugin-fb8br" node="host-10-13-2-160" evaluatedNodes=1 feasibleNodes=1
2025-04-01T12:38:50.491935358Z I0401 12:38:50.491764       1 schedule_one.go:286] "Successfully bound pod to node" pod="kube-system/csi-cinder-nodeplugin-s9v8s" node="host-10-13-2-89" evaluatedNodes=1 feasibleNodes=1
2025-04-01T12:39:00.952380638Z I0401 12:39:00.952326       1 schedule_one.go:988] "Unable to schedule pod; no fit; waiting" pod="default/nginx" err="0/6 nodes are available: pod has unbound immediate PersistentVolumeClaims. preemption: 0/6 nodes are available: 6 Preemption is not helpful for scheduling.."
2025-04-01T12:39:11.522652552Z I0401 12:39:11.522574       1 schedule_one.go:988] "Unable to schedule pod; no fit; waiting" pod="default/nginx" err="0/6 nodes are available: pod has unbound immediate PersistentVolumeClaims. preemption: 0/6 nodes are available: 6 Preemption is not helpful for scheduling.."
2025-04-01T12:39:21.529808895Z I0401 12:39:21.529741       1 schedule_one.go:988] "Unable to schedule pod; no fit; waiting" pod="default/nginx" err="0/6 nodes are available: pod has unbound immediate PersistentVolumeClaims. preemption: 0/6 nodes are available: 6 Preemption is not helpful for scheduling.."
2025-04-01T12:39:38.934201736Z I0401 12:39:38.934135       1 schedule_one.go:286] "Successfully bound pod to node" pod="openshift-marketplace/community-operators-2lg2c" node="host-10-13-2-160" evaluatedNodes=6 feasibleNodes=3
2025-04-01T12:40:43.354665274Z I0401 12:40:43.354609       1 schedule_one.go:286] "Successfully bound pod to node" pod="openshift-marketplace/redhat-marketplace-z8brn" node="host-10-13-2-89" evaluatedNodes=6 feasibleNodes=3
2025-04-01T12:41:10.420283091Z I0401 12:41:10.419706       1 schedule_one.go:286] "Successfully bound pod to node" pod="openshift-marketplace/certified-operators-szftf" node="host-10-13-2-89" evaluatedNodes=6 feasibleNodes=3
2025-04-01T12:44:32.424711166Z I0401 12:44:32.424662       1 schedule_one.go:988] "Unable to schedule pod; no fit; waiting" pod="default/nginx" err="0/6 nodes are available: pod has unbound immediate PersistentVolumeClaims. preemption: 0/6 nodes are available: 6 Preemption is not helpful for scheduling.."
2025-04-01T12:45:00.236573028Z I0401 12:45:00.236259       1 schedule_one.go:286] "Successfully bound pod to node" pod="openshift-operator-lifecycle-manager/collect-profiles-29058525-t59w6" node="host-10-13-2-1" evaluatedNodes=6 feasibleNodes=3
2025-04-01T12:46:35.530587285Z I0401 12:46:35.530549       1 schedule_one.go:286] "Successfully bound pod to node" pod="openshift-marketplace/redhat-operators-c8km9" node="host-10-13-2-89" evaluatedNodes=6 feasibleNodes=3
2025-04-01T12:49:32.430596909Z I0401 12:49:32.430532       1 schedule_one.go:988] "Unable to schedule pod; no fit; waiting" pod="default/nginx" err="0/6 nodes are available: pod has unbound immediate PersistentVolumeClaims. preemption: 0/6 nodes are available: 6 Preemption is not helpful for scheduling.."
2025-04-01T12:49:45.116598543Z I0401 12:49:45.115501       1 schedule_one.go:286] "Successfully bound pod to node" pod="openshift-marketplace/community-operators-75sqd" node="host-10-13-2-89" evaluatedNodes=6 feasibleNodes=3
2025-04-01T12:51:43.429065640Z I0401 12:51:43.428049       1 schedule_one.go:286] "Successfully bound pod to node" pod="openshift-marketplace/redhat-marketplace-tdwnr" node="host-10-13-2-89" evaluatedNodes=6 feasibleNodes=3
2025-04-01T12:54:11.662006640Z I0401 12:54:11.661951       1 schedule_one.go:286] "Successfully bound pod to node" pod="openshift-marketplace/certified-operators-jbx8t" node="host-10-13-2-89" evaluatedNodes=6 feasibleNodes=3
2025-04-01T12:54:32.439116604Z I0401 12:54:32.438072       1 schedule_one.go:988] "Unable to schedule pod; no fit; waiting" pod="default/nginx" err="0/6 nodes are available: pod has unbound immediate PersistentVolumeClaims. preemption: 0/6 nodes are available: 6 Preemption is not helpful for scheduling.."
2025-04-01T12:58:08.924962139Z I0401 12:58:08.923381       1 schedule_one.go:988] "Unable to schedule pod; no fit; waiting" pod="openshift-controller-manager/controller-manager-5fcfbfc7f5-vf6md" err="0/6 nodes are available: 3 node(s) didn't match Pod's node affinity/selector, 3 node(s) didn't match pod anti-affinity rules. preemption: 0/6 nodes are available: 3 Preemption is not helpful for scheduling, 3 node(s) didn't match pod anti-affinity rules.."
2025-04-01T12:58:08.951995736Z I0401 12:58:08.951966       1 schedule_one.go:988] "Unable to schedule pod; no fit; waiting" pod="openshift-route-controller-manager/route-controller-manager-7586cd99c-8gqsr" err="0/6 nodes are available: 3 node(s) didn't match Pod's node affinity/selector, 3 node(s) didn't match pod anti-affinity rules. preemption: 0/6 nodes are available: 3 Preemption is not helpful for scheduling, 3 node(s) didn't match pod anti-affinity rules.."
2025-04-01T12:58:09.033693587Z I0401 12:58:09.033549       1 schedule_one.go:988] "Unable to schedule pod; no fit; waiting" pod="openshift-route-controller-manager/route-controller-manager-5b9ddfc46b-t68tg" err="0/6 nodes are available: 3 node(s) didn't match Pod's node affinity/selector, 3 node(s) didn't match pod anti-affinity rules. preemption: 0/6 nodes are available: 3 Preemption is not helpful for scheduling, 3 node(s) didn't match pod anti-affinity rules.."
2025-04-01T12:58:09.137854313Z I0401 12:58:09.137800       1 schedule_one.go:988] "Unable to schedule pod; no fit; waiting" pod="openshift-controller-manager/controller-manager-58677c5d57-4wll7" err="0/6 nodes are available: 3 node(s) didn't match Pod's node affinity/selector, 3 node(s) didn't match pod anti-affinity rules. preemption: 0/6 nodes are available: 3 Preemption is not helpful for scheduling, 3 node(s) didn't match pod anti-affinity rules.."
2025-04-01T12:58:10.206320295Z I0401 12:58:10.206268       1 schedule_one.go:286] "Successfully bound pod to node" pod="openshift-route-controller-manager/route-controller-manager-5b9ddfc46b-t68tg" node="host-10-13-0-150" evaluatedNodes=6 feasibleNodes=1
2025-04-01T12:58:10.206425233Z I0401 12:58:10.206402       1 schedule_one.go:286] "Successfully bound pod to node" pod="openshift-controller-manager/controller-manager-58677c5d57-4wll7" node="host-10-13-2-89" evaluatedNodes=6 feasibleNodes=1
2025-04-01T12:58:11.467454396Z I0401 12:58:11.467419       1 schedule_one.go:988] "Unable to schedule pod; no fit; waiting" pod="openshift-controller-manager/controller-manager-58677c5d57-qztg5" err="0/6 nodes are available: 3 node(s) didn't match Pod's node affinity/selector, 3 node(s) didn't match pod anti-affinity rules. preemption: 0/6 nodes are available: 3 Preemption is not helpful for scheduling, 3 node(s) didn't match pod anti-affinity rules.."
2025-04-01T12:58:12.974316066Z I0401 12:58:12.974284       1 schedule_one.go:988] "Unable to schedule pod; no fit; waiting" pod="openshift-route-controller-manager/route-controller-manager-5b9ddfc46b-kgqdt" err="0/6 nodes are available: 3 node(s) didn't match Pod's node affinity/selector, 3 node(s) didn't match pod anti-affinity rules. preemption: 0/6 nodes are available: 3 Preemption is not helpful for scheduling, 3 node(s) didn't match pod anti-affinity rules.."
2025-04-01T12:58:13.207307959Z I0401 12:58:13.206848       1 schedule_one.go:286] "Successfully bound pod to node" pod="openshift-controller-manager/controller-manager-58677c5d57-qztg5" node="host-10-13-0-150" evaluatedNodes=6 feasibleNodes=1
2025-04-01T12:58:14.207485437Z I0401 12:58:14.207395       1 schedule_one.go:286] "Successfully bound pod to node" pod="openshift-route-controller-manager/route-controller-manager-5b9ddfc46b-kgqdt" node="host-10-13-2-89" evaluatedNodes=6 feasibleNodes=1
2025-04-01T12:58:14.998082068Z I0401 12:58:14.998028       1 schedule_one.go:988] "Unable to schedule pod; no fit; waiting" pod="openshift-controller-manager/controller-manager-58677c5d57-w2th6" err="0/6 nodes are available: 3 node(s) didn't match Pod's node affinity/selector, 3 node(s) didn't match pod anti-affinity rules. preemption: 0/6 nodes are available: 3 Preemption is not helpful for scheduling, 3 node(s) didn't match pod anti-affinity rules.."
2025-04-01T12:58:16.212243498Z I0401 12:58:16.212053       1 schedule_one.go:286] "Successfully bound pod to node" pod="openshift-controller-manager/controller-manager-58677c5d57-w2th6" node="host-10-13-2-160" evaluatedNodes=6 feasibleNodes=1
2025-04-01T12:58:16.487494849Z I0401 12:58:16.487442       1 schedule_one.go:988] "Unable to schedule pod; no fit; waiting" pod="openshift-route-controller-manager/route-controller-manager-5b9ddfc46b-7bnpt" err="0/6 nodes are available: 3 node(s) didn't match Pod's node affinity/selector, 3 node(s) didn't match pod anti-affinity rules. preemption: 0/6 nodes are available: 3 Preemption is not helpful for scheduling, 3 node(s) didn't match pod anti-affinity rules.."
2025-04-01T12:58:18.282071036Z I0401 12:58:18.282037       1 schedule_one.go:286] "Successfully bound pod to node" pod="openshift-route-controller-manager/route-controller-manager-5b9ddfc46b-7bnpt" node="host-10-13-2-160" evaluatedNodes=6 feasibleNodes=1
2025-04-01T12:59:32.442776178Z I0401 12:59:32.442703       1 schedule_one.go:988] "Unable to schedule pod; no fit; waiting" pod="default/nginx" err="0/6 nodes are available: pod has unbound immediate PersistentVolumeClaims. preemption: 0/6 nodes are available: 6 Preemption is not helpful for scheduling.."
2025-04-01T13:00:00.156645874Z I0401 13:00:00.156591       1 schedule_one.go:286] "Successfully bound pod to node" pod="openshift-operator-lifecycle-manager/collect-profiles-29058540-rb9r2" node="host-10-13-2-1" evaluatedNodes=6 feasibleNodes=3
2025-04-01T13:00:20.766164547Z I0401 13:00:20.766132       1 tlsconfig.go:178] "Loaded client CA" index=0 certName="client-ca::kube-system::extension-apiserver-authentication::client-ca-file,client-ca::kube-system::extension-apiserver-authentication::requestheader-client-ca-file" certDetail="\"admin-kubeconfig-signer\" [] issuer=\"<self>\" (2025-03-31 12:55:13 +0000 UTC to 2035-03-29 12:55:13 +0000 UTC (now=2025-04-01 13:00:20.766106427 +0000 UTC))"
2025-04-01T13:00:20.766212456Z I0401 13:00:20.766204       1 tlsconfig.go:178] "Loaded client CA" index=1 certName="client-ca::kube-system::extension-apiserver-authentication::client-ca-file,client-ca::kube-system::extension-apiserver-authentication::requestheader-client-ca-file" certDetail="\"kube-control-plane-signer\" [] issuer=\"<self>\" (2025-03-31 12:55:15 +0000 UTC to 2026-03-31 12:55:15 +0000 UTC (now=2025-04-01 13:00:20.766194676 +0000 UTC))"
2025-04-01T13:00:20.766240135Z I0401 13:00:20.766233       1 tlsconfig.go:178] "Loaded client CA" index=2 certName="client-ca::kube-system::extension-apiserver-authentication::client-ca-file,client-ca::kube-system::extension-apiserver-authentication::requestheader-client-ca-file" certDetail="\"kube-apiserver-to-kubelet-signer\" [] issuer=\"<self>\" (2025-03-31 12:55:15 +0000 UTC to 2026-03-31 12:55:15 +0000 UTC (now=2025-04-01 13:00:20.766225756 +0000 UTC))"
2025-04-01T13:00:20.766269385Z I0401 13:00:20.766262       1 tlsconfig.go:178] "Loaded client CA" index=3 certName="client-ca::kube-system::extension-apiserver-authentication::client-ca-file,client-ca::kube-system::extension-apiserver-authentication::requestheader-client-ca-file" certDetail="\"kubelet-bootstrap-kubeconfig-signer\" [] issuer=\"<self>\" (2025-03-31 12:55:13 +0000 UTC to 2035-03-29 12:55:13 +0000 UTC (now=2025-04-01 13:00:20.766254705 +0000 UTC))"
2025-04-01T13:00:20.766294424Z I0401 13:00:20.766287       1 tlsconfig.go:178] "Loaded client CA" index=4 certName="client-ca::kube-system::extension-apiserver-authentication::client-ca-file,client-ca::kube-system::extension-apiserver-authentication::requestheader-client-ca-file" certDetail="\"openshift-kube-apiserver-operator_node-system-admin-signer@1743452539\" [] issuer=\"<self>\" (2025-03-31 20:22:18 +0000 UTC to 2026-03-31 20:22:19 +0000 UTC (now=2025-04-01 13:00:20.766279894 +0000 UTC))"
2025-04-01T13:00:20.766319533Z I0401 13:00:20.766312       1 tlsconfig.go:178] "Loaded client CA" index=5 certName="client-ca::kube-system::extension-apiserver-authentication::client-ca-file,client-ca::kube-system::extension-apiserver-authentication::requestheader-client-ca-file" certDetail="\"openshift-kube-controller-manager-operator_csr-signer-signer@1743494861\" [] issuer=\"<self>\" (2025-04-01 08:07:40 +0000 UTC to 2025-05-31 08:07:41 +0000 UTC (now=2025-04-01 13:00:20.766305194 +0000 UTC))"
2025-04-01T13:00:20.766344883Z I0401 13:00:20.766338       1 tlsconfig.go:178] "Loaded client CA" index=6 certName="client-ca::kube-system::extension-apiserver-authentication::client-ca-file,client-ca::kube-system::extension-apiserver-authentication::requestheader-client-ca-file" certDetail="\"kube-csr-signer_@1743500201\" [] issuer=\"openshift-kube-controller-manager-operator_csr-signer-signer@1743494861\" (2025-04-01 09:36:40 +0000 UTC to 2025-05-01 09:36:41 +0000 UTC (now=2025-04-01 13:00:20.766330153 +0000 UTC))"
2025-04-01T13:00:20.766372552Z I0401 13:00:20.766365       1 tlsconfig.go:178] "Loaded client CA" index=7 certName="client-ca::kube-system::extension-apiserver-authentication::client-ca-file,client-ca::kube-system::extension-apiserver-authentication::requestheader-client-ca-file" certDetail="\"aggregator-signer\" [] issuer=\"<self>\" (2025-03-31 12:55:14 +0000 UTC to 2025-04-01 12:55:14 +0000 UTC (now=2025-04-01 13:00:20.766355683 +0000 UTC))"
2025-04-01T13:00:20.766398832Z I0401 13:00:20.766392       1 tlsconfig.go:178] "Loaded client CA" index=8 certName="client-ca::kube-system::extension-apiserver-authentication::client-ca-file,client-ca::kube-system::extension-apiserver-authentication::requestheader-client-ca-file" certDetail="\"openshift-kube-apiserver-operator_aggregator-client-signer@1743494854\" [] issuer=\"<self>\" (2025-04-01 08:07:34 +0000 UTC to 2025-05-01 08:07:35 +0000 UTC (now=2025-04-01 13:00:20.766384532 +0000 UTC))"
2025-04-01T13:00:20.766711116Z I0401 13:00:20.766700       1 tlsconfig.go:200] "Loaded serving cert" certName="serving-cert::/etc/kubernetes/static-pod-resources/secrets/serving-cert/tls.crt::/etc/kubernetes/static-pod-resources/secrets/serving-cert/tls.key" certDetail="\"scheduler.openshift-kube-scheduler.svc\" [serving] validServingFor=[scheduler.openshift-kube-scheduler.svc,scheduler.openshift-kube-scheduler.svc.cluster.local] issuer=\"openshift-service-serving-signer@1743452529\" (2025-03-31 20:22:27 +0000 UTC to 2027-03-31 20:22:28 +0000 UTC (now=2025-04-01 13:00:20.766689376 +0000 UTC))"
2025-04-01T13:00:20.767010790Z I0401 13:00:20.766999       1 named_certificates.go:53] "Loaded SNI cert" index=0 certName="self-signed loopback" certDetail="\"apiserver-loopback-client@1743453601\" [serving] validServingFor=[apiserver-loopback-client] issuer=\"apiserver-loopback-client-ca@1743453600\" (2025-03-31 19:40:00 +0000 UTC to 2026-03-31 19:40:00 +0000 UTC (now=2025-04-01 13:00:20.766987941 +0000 UTC))"
2025-04-01T13:00:20.778041644Z I0401 13:00:20.768206       1 tlsconfig.go:178] "Loaded client CA" index=0 certName="client-ca::kube-system::extension-apiserver-authentication::client-ca-file,client-ca::kube-system::extension-apiserver-authentication::requestheader-client-ca-file" certDetail="\"admin-kubeconfig-signer\" [] issuer=\"<self>\" (2025-03-31 12:55:13 +0000 UTC to 2035-03-29 12:55:13 +0000 UTC (now=2025-04-01 13:00:20.768163979 +0000 UTC))"
2025-04-01T13:00:20.778041644Z I0401 13:00:20.773829       1 tlsconfig.go:178] "Loaded client CA" index=1 certName="client-ca::kube-system::extension-apiserver-authentication::client-ca-file,client-ca::kube-system::extension-apiserver-authentication::requestheader-client-ca-file" certDetail="\"kube-control-plane-signer\" [] issuer=\"<self>\" (2025-03-31 12:55:15 +0000 UTC to 2026-03-31 12:55:15 +0000 UTC (now=2025-04-01 13:00:20.768236138 +0000 UTC))"
2025-04-01T13:00:20.778041644Z I0401 13:00:20.773915       1 tlsconfig.go:178] "Loaded client CA" index=2 certName="client-ca::kube-system::extension-apiserver-authentication::client-ca-file,client-ca::kube-system::extension-apiserver-authentication::requestheader-client-ca-file" certDetail="\"kube-apiserver-to-kubelet-signer\" [] issuer=\"<self>\" (2025-03-31 12:55:15 +0000 UTC to 2026-03-31 12:55:15 +0000 UTC (now=2025-04-01 13:00:20.773870732 +0000 UTC))"
2025-04-01T13:00:20.778041644Z I0401 13:00:20.773946       1 tlsconfig.go:178] "Loaded client CA" index=3 certName="client-ca::kube-system::extension-apiserver-authentication::client-ca-file,client-ca::kube-system::extension-apiserver-authentication::requestheader-client-ca-file" certDetail="\"kubelet-bootstrap-kubeconfig-signer\" [] issuer=\"<self>\" (2025-03-31 12:55:13 +0000 UTC to 2035-03-29 12:55:13 +0000 UTC (now=2025-04-01 13:00:20.773928401 +0000 UTC))"
2025-04-01T13:00:20.778041644Z I0401 13:00:20.773986       1 tlsconfig.go:178] "Loaded client CA" index=4 certName="client-ca::kube-system::extension-apiserver-authentication::client-ca-file,client-ca::kube-system::extension-apiserver-authentication::requestheader-client-ca-file" certDetail="\"openshift-kube-apiserver-operator_node-system-admin-signer@1743452539\" [] issuer=\"<self>\" (2025-03-31 20:22:18 +0000 UTC to 2026-03-31 20:22:19 +0000 UTC (now=2025-04-01 13:00:20.773956471 +0000 UTC))"
2025-04-01T13:00:20.778041644Z I0401 13:00:20.774017       1 tlsconfig.go:178] "Loaded client CA" index=5 certName="client-ca::kube-system::extension-apiserver-authentication::client-ca-file,client-ca::kube-system::extension-apiserver-authentication::requestheader-client-ca-file" certDetail="\"openshift-kube-controller-manager-operator_csr-signer-signer@1743494861\" [] issuer=\"<self>\" (2025-04-01 08:07:40 +0000 UTC to 2025-05-31 08:07:41 +0000 UTC (now=2025-04-01 13:00:20.77399846 +0000 UTC))"
2025-04-01T13:00:20.778041644Z I0401 13:00:20.774049       1 tlsconfig.go:178] "Loaded client CA" index=6 certName="client-ca::kube-system::extension-apiserver-authentication::client-ca-file,client-ca::kube-system::extension-apiserver-authentication::requestheader-client-ca-file" certDetail="\"kube-csr-signer_@1743500201\" [] issuer=\"openshift-kube-controller-manager-operator_csr-signer-signer@1743494861\" (2025-04-01 09:36:40 +0000 UTC to 2025-05-01 09:36:41 +0000 UTC (now=2025-04-01 13:00:20.77402874 +0000 UTC))"
2025-04-01T13:00:20.778041644Z I0401 13:00:20.774077       1 tlsconfig.go:178] "Loaded client CA" index=7 certName="client-ca::kube-system::extension-apiserver-authentication::client-ca-file,client-ca::kube-system::extension-apiserver-authentication::requestheader-client-ca-file" certDetail="\"openshift-kube-apiserver-operator_aggregator-client-signer@1743494854\" [] issuer=\"<self>\" (2025-04-01 08:07:34 +0000 UTC to 2025-05-01 08:07:35 +0000 UTC (now=2025-04-01 13:00:20.774060659 +0000 UTC))"
2025-04-01T13:00:20.778041644Z I0401 13:00:20.776397       1 tlsconfig.go:200] "Loaded serving cert" certName="serving-cert::/etc/kubernetes/static-pod-resources/secrets/serving-cert/tls.crt::/etc/kubernetes/static-pod-resources/secrets/serving-cert/tls.key" certDetail="\"scheduler.openshift-kube-scheduler.svc\" [serving] validServingFor=[scheduler.openshift-kube-scheduler.svc,scheduler.openshift-kube-scheduler.svc.cluster.local] issuer=\"openshift-service-serving-signer@1743452529\" (2025-03-31 20:22:27 +0000 UTC to 2027-03-31 20:22:28 +0000 UTC (now=2025-04-01 13:00:20.776370386 +0000 UTC))"
2025-04-01T13:00:20.783139459Z I0401 13:00:20.779961       1 named_certificates.go:53] "Loaded SNI cert" index=0 certName="self-signed loopback" certDetail="\"apiserver-loopback-client@1743453601\" [serving] validServingFor=[apiserver-loopback-client] issuer=\"apiserver-loopback-client-ca@1743453600\" (2025-03-31 19:40:00 +0000 UTC to 2026-03-31 19:40:00 +0000 UTC (now=2025-04-01 13:00:20.779934459 +0000 UTC))"
2025-04-01T13:00:26.239980619Z I0401 13:00:26.239944       1 schedule_one.go:286] "Successfully bound pod to node" pod="openshift-monitoring/prometheus-adapter-74878b69dd-7pqxq" node="host-10-13-3-120" evaluatedNodes=6 feasibleNodes=1
2025-04-01T13:00:26.304723958Z I0401 13:00:26.302392       1 schedule_one.go:988] "Unable to schedule pod; no fit; waiting" pod="openshift-monitoring/prometheus-adapter-74878b69dd-qz4fm" err="0/6 nodes are available: 3 node(s) didn't match pod anti-affinity rules, 3 node(s) had untolerated taint {node-role.kubernetes.io/master: }. preemption: 0/6 nodes are available: 3 Preemption is not helpful for scheduling, 3 node(s) didn't match pod anti-affinity rules.."
2025-04-01T13:00:28.291477363Z I0401 13:00:28.291440       1 schedule_one.go:286] "Successfully bound pod to node" pod="openshift-monitoring/prometheus-adapter-74878b69dd-qz4fm" node="host-10-13-3-78" evaluatedNodes=6 feasibleNodes=1
2025-04-01T13:01:11.573659818Z I0401 13:01:11.573625       1 schedule_one.go:286] "Successfully bound pod to node" pod="openshift-marketplace/community-operators-drfg6" node="host-10-13-2-89" evaluatedNodes=6 feasibleNodes=3
2025-04-01T13:01:12.968842855Z I0401 13:01:12.968750       1 schedule_one.go:286] "Successfully bound pod to node" pod="openshift-marketplace/redhat-operators-4l4hs" node="host-10-13-2-160" evaluatedNodes=6 feasibleNodes=3
2025-04-01T13:02:34.976742643Z I0401 13:02:34.976678       1 schedule_one.go:286] "Successfully bound pod to node" pod="openshift-marketplace/redhat-marketplace-cfdz7" node="host-10-13-2-89" evaluatedNodes=6 feasibleNodes=3
2025-04-01T13:04:32.447829071Z I0401 13:04:32.447772       1 schedule_one.go:988] "Unable to schedule pod; no fit; waiting" pod="default/nginx" err="0/6 nodes are available: pod has unbound immediate PersistentVolumeClaims. preemption: 0/6 nodes are available: 6 Preemption is not helpful for scheduling.."
2025-04-01T13:07:13.056329186Z I0401 13:07:13.055407       1 schedule_one.go:286] "Successfully bound pod to node" pod="openshift-marketplace/certified-operators-h5dvw" node="host-10-13-2-89" evaluatedNodes=6 feasibleNodes=3
2025-04-01T13:09:32.453333837Z I0401 13:09:32.453223       1 schedule_one.go:988] "Unable to schedule pod; no fit; waiting" pod="default/nginx" err="0/6 nodes are available: pod has unbound immediate PersistentVolumeClaims. preemption: 0/6 nodes are available: 6 Preemption is not helpful for scheduling.."
2025-04-01T13:12:15.640828553Z I0401 13:12:15.639419       1 schedule_one.go:286] "Successfully bound pod to node" pod="openshift-marketplace/community-operators-tbtvw" node="host-10-13-2-89" evaluatedNodes=6 feasibleNodes=3
2025-04-01T13:12:50.961010368Z I0401 13:12:50.960714       1 schedule_one.go:286] "Successfully bound pod to node" pod="openshift-marketplace/redhat-operators-mfh28" node="host-10-13-2-160" evaluatedNodes=6 feasibleNodes=3
2025-04-01T13:13:16.881820893Z I0401 13:13:16.881745       1 schedule_one.go:286] "Successfully bound pod to node" pod="openshift-marketplace/redhat-marketplace-48r5v" node="host-10-13-2-160" evaluatedNodes=6 feasibleNodes=3
2025-04-01T13:14:32.461140978Z I0401 13:14:32.461055       1 schedule_one.go:988] "Unable to schedule pod; no fit; waiting" pod="default/nginx" err="0/6 nodes are available: pod has unbound immediate PersistentVolumeClaims. preemption: 0/6 nodes are available: 6 Preemption is not helpful for scheduling.."
2025-04-01T13:15:00.204257011Z I0401 13:15:00.203832       1 schedule_one.go:286] "Successfully bound pod to node" pod="openshift-operator-lifecycle-manager/collect-profiles-29058555-cmm5c" node="host-10-13-2-1" evaluatedNodes=6 feasibleNodes=3
2025-04-01T13:18:01.581079168Z I0401 13:18:01.581041       1 schedule_one.go:286] "Successfully bound pod to node" pod="openshift-marketplace/certified-operators-tg6sg" node="host-10-13-2-160" evaluatedNodes=6 feasibleNodes=3
2025-04-01T13:19:32.468664015Z I0401 13:19:32.468603       1 schedule_one.go:988] "Unable to schedule pod; no fit; waiting" pod="default/nginx" err="0/6 nodes are available: pod has unbound immediate PersistentVolumeClaims. preemption: 0/6 nodes are available: 6 Preemption is not helpful for scheduling.."
2025-04-01T13:24:29.599234656Z I0401 13:24:29.599187       1 schedule_one.go:286] "Successfully bound pod to node" pod="openshift-marketplace/community-operators-6kbpc" node="host-10-13-2-160" evaluatedNodes=6 feasibleNodes=3
2025-04-01T13:24:31.001428680Z I0401 13:24:31.000136       1 schedule_one.go:286] "Successfully bound pod to node" pod="openshift-marketplace/redhat-marketplace-8gzd9" node="host-10-13-2-89" evaluatedNodes=6 feasibleNodes=3
2025-04-01T13:24:32.407962025Z I0401 13:24:32.407917       1 schedule_one.go:286] "Successfully bound pod to node" pod="openshift-marketplace/redhat-operators-f727l" node="host-10-13-2-160" evaluatedNodes=6 feasibleNodes=3
2025-04-01T13:24:32.474597294Z I0401 13:24:32.474556       1 schedule_one.go:988] "Unable to schedule pod; no fit; waiting" pod="default/nginx" err="0/6 nodes are available: pod has unbound immediate PersistentVolumeClaims. preemption: 0/6 nodes are available: 6 Preemption is not helpful for scheduling.."
2025-04-01T13:29:32.478911139Z I0401 13:29:32.478850       1 schedule_one.go:988] "Unable to schedule pod; no fit; waiting" pod="default/nginx" err="0/6 nodes are available: pod has unbound immediate PersistentVolumeClaims. preemption: 0/6 nodes are available: 6 Preemption is not helpful for scheduling.."
2025-04-01T13:30:00.164753865Z I0401 13:30:00.164358       1 schedule_one.go:286] "Successfully bound pod to node" pod="openshift-operator-lifecycle-manager/collect-profiles-29058570-vxpj5" node="host-10-13-2-1" evaluatedNodes=6 feasibleNodes=3
2025-04-01T13:33:15.880005770Z I0401 13:33:15.878756       1 schedule_one.go:286] "Successfully bound pod to node" pod="openshift-marketplace/certified-operators-jczvz" node="host-10-13-2-160" evaluatedNodes=6 feasibleNodes=3
2025-04-01T13:34:32.485355956Z I0401 13:34:32.484934       1 schedule_one.go:988] "Unable to schedule pod; no fit; waiting" pod="default/nginx" err="0/6 nodes are available: pod has unbound immediate PersistentVolumeClaims. preemption: 0/6 nodes are available: 6 Preemption is not helpful for scheduling.."
2025-04-01T13:35:35.195450787Z I0401 13:35:35.195412       1 schedule_one.go:286] "Successfully bound pod to node" pod="openshift-marketplace/redhat-marketplace-x99jn" node="host-10-13-2-160" evaluatedNodes=6 feasibleNodes=3
2025-04-01T13:36:29.339166629Z I0401 13:36:29.339109       1 schedule_one.go:286] "Successfully bound pod to node" pod="openshift-marketplace/community-operators-ptg68" node="host-10-13-2-160" evaluatedNodes=6 feasibleNodes=3
2025-04-01T13:37:28.058934755Z I0401 13:37:28.058892       1 schedule_one.go:286] "Successfully bound pod to node" pod="openshift-marketplace/redhat-operators-hmrs9" node="host-10-13-2-160" evaluatedNodes=6 feasibleNodes=3
2025-04-01T13:39:32.491017762Z I0401 13:39:32.490977       1 schedule_one.go:988] "Unable to schedule pod; no fit; waiting" pod="default/nginx" err="0/6 nodes are available: pod has unbound immediate PersistentVolumeClaims. preemption: 0/6 nodes are available: 6 Preemption is not helpful for scheduling.."
2025-04-01T13:43:26.022019558Z I0401 13:43:26.021889       1 schedule_one.go:286] "Successfully bound pod to node" pod="openshift-marketplace/certified-operators-xfcpz" node="host-10-13-2-160" evaluatedNodes=6 feasibleNodes=3
2025-04-01T13:44:32.496377676Z I0401 13:44:32.496303       1 schedule_one.go:988] "Unable to schedule pod; no fit; waiting" pod="default/nginx" err="0/6 nodes are available: pod has unbound immediate PersistentVolumeClaims. preemption: 0/6 nodes are available: 6 Preemption is not helpful for scheduling.."
2025-04-01T13:45:00.224143045Z I0401 13:45:00.224093       1 schedule_one.go:286] "Successfully bound pod to node" pod="openshift-operator-lifecycle-manager/collect-profiles-29058585-xv8ng" node="host-10-13-2-1" evaluatedNodes=6 feasibleNodes=3
2025-04-01T13:46:17.302465012Z I0401 13:46:17.302272       1 schedule_one.go:286] "Successfully bound pod to node" pod="openshift-marketplace/redhat-marketplace-lvl62" node="host-10-13-2-160" evaluatedNodes=6 feasibleNodes=3
2025-04-01T13:48:31.751866722Z I0401 13:48:31.751034       1 schedule_one.go:286] "Successfully bound pod to node" pod="openshift-marketplace/redhat-operators-zc6t4" node="host-10-13-2-160" evaluatedNodes=6 feasibleNodes=3
2025-04-01T13:49:32.501616724Z I0401 13:49:32.501559       1 schedule_one.go:988] "Unable to schedule pod; no fit; waiting" pod="default/nginx" err="0/6 nodes are available: pod has unbound immediate PersistentVolumeClaims. preemption: 0/6 nodes are available: 6 Preemption is not helpful for scheduling.."
2025-04-01T13:49:32.766231691Z I0401 13:49:32.766205       1 schedule_one.go:286] "Successfully bound pod to node" pod="openshift-marketplace/community-operators-4hq72" node="host-10-13-2-160" evaluatedNodes=6 feasibleNodes=3
2025-04-01T13:54:28.426971398Z I0401 13:54:28.426660       1 schedule_one.go:286] "Successfully bound pod to node" pod="openshift-marketplace/certified-operators-qd2s7" node="host-10-13-2-160" evaluatedNodes=6 feasibleNodes=3
2025-04-01T13:54:32.506925890Z I0401 13:54:32.506854       1 schedule_one.go:988] "Unable to schedule pod; no fit; waiting" pod="default/nginx" err="0/6 nodes are available: pod has unbound immediate PersistentVolumeClaims. preemption: 0/6 nodes are available: 6 Preemption is not helpful for scheduling.."
2025-04-01T13:56:38.151392726Z I0401 13:56:38.150739       1 schedule_one.go:286] "Successfully bound pod to node" pod="openshift-marketplace/redhat-marketplace-hbmvp" node="host-10-13-2-160" evaluatedNodes=6 feasibleNodes=3
2025-04-01T13:59:18.702474366Z I0401 13:59:18.702179       1 schedule_one.go:286] "Successfully bound pod to node" pod="openshift-marketplace/redhat-operators-g8vjx" node="host-10-13-2-160" evaluatedNodes=6 feasibleNodes=3
2025-04-01T13:59:32.513541770Z I0401 13:59:32.513498       1 schedule_one.go:988] "Unable to schedule pod; no fit; waiting" pod="default/nginx" err="0/6 nodes are available: pod has unbound immediate PersistentVolumeClaims. preemption: 0/6 nodes are available: 6 Preemption is not helpful for scheduling.."
2025-04-01T14:00:00.149650312Z I0401 14:00:00.149582       1 schedule_one.go:286] "Successfully bound pod to node" pod="openshift-operator-lifecycle-manager/collect-profiles-29058600-dr4xm" node="host-10-13-2-1" evaluatedNodes=6 feasibleNodes=3
2025-04-01T14:01:38.073108487Z I0401 14:01:38.072821       1 schedule_one.go:286] "Successfully bound pod to node" pod="openshift-marketplace/community-operators-7rnzt" node="host-10-13-2-160" evaluatedNodes=6 feasibleNodes=3
2025-04-01T14:04:32.518799727Z I0401 14:04:32.518622       1 schedule_one.go:988] "Unable to schedule pod; no fit; waiting" pod="default/nginx" err="0/6 nodes are available: pod has unbound immediate PersistentVolumeClaims. preemption: 0/6 nodes are available: 6 Preemption is not helpful for scheduling.."
2025-04-01T14:04:53.147199275Z I0401 14:04:53.147144       1 schedule_one.go:286] "Successfully bound pod to node" pod="openshift-marketplace/certified-operators-t2n8f" node="host-10-13-2-160" evaluatedNodes=6 feasibleNodes=3
2025-04-01T14:09:19.210585185Z I0401 14:09:19.210529       1 schedule_one.go:286] "Successfully bound pod to node" pod="openshift-marketplace/redhat-operators-p5kjk" node="host-10-13-2-160" evaluatedNodes=6 feasibleNodes=3
2025-04-01T14:09:32.524897534Z I0401 14:09:32.524707       1 schedule_one.go:988] "Unable to schedule pod; no fit; waiting" pod="default/nginx" err="0/6 nodes are available: pod has unbound immediate PersistentVolumeClaims. preemption: 0/6 nodes are available: 6 Preemption is not helpful for scheduling.."
2025-04-01T14:12:20.102244243Z I0401 14:12:20.102202       1 schedule_one.go:286] "Successfully bound pod to node" pod="openshift-marketplace/community-operators-gmtvb" node="host-10-13-2-160" evaluatedNodes=6 feasibleNodes=3
2025-04-01T14:12:20.280155772Z I0401 14:12:20.280121       1 schedule_one.go:286] "Successfully bound pod to node" pod="openshift-marketplace/redhat-marketplace-b96vl" node="host-10-13-2-160" evaluatedNodes=6 feasibleNodes=3
2025-04-01T14:14:32.530336711Z I0401 14:14:32.530274       1 schedule_one.go:988] "Unable to schedule pod; no fit; waiting" pod="default/nginx" err="0/6 nodes are available: pod has unbound immediate PersistentVolumeClaims. preemption: 0/6 nodes are available: 6 Preemption is not helpful for scheduling.."
2025-04-01T14:15:00.154770573Z I0401 14:15:00.154713       1 schedule_one.go:286] "Successfully bound pod to node" pod="openshift-operator-lifecycle-manager/collect-profiles-29058615-m8n96" node="host-10-13-2-1" evaluatedNodes=6 feasibleNodes=3
2025-04-01T14:15:43.448472852Z I0401 14:15:43.448440       1 schedule_one.go:286] "Successfully bound pod to node" pod="openshift-marketplace/certified-operators-gscjw" node="host-10-13-2-160" evaluatedNodes=6 feasibleNodes=3
2025-04-01T14:19:32.537555718Z I0401 14:19:32.537340       1 schedule_one.go:988] "Unable to schedule pod; no fit; waiting" pod="default/nginx" err="0/6 nodes are available: pod has unbound immediate PersistentVolumeClaims. preemption: 0/6 nodes are available: 6 Preemption is not helpful for scheduling.."
2025-04-01T14:20:33.596590566Z I0401 14:20:33.596541       1 schedule_one.go:286] "Successfully bound pod to node" pod="openshift-marketplace/redhat-operators-w45cl" node="host-10-13-2-160" evaluatedNodes=6 feasibleNodes=3
2025-04-01T14:22:32.687178890Z I0401 14:22:32.687123       1 schedule_one.go:286] "Successfully bound pod to node" pod="openshift-marketplace/redhat-marketplace-qrkpj" node="host-10-13-2-160" evaluatedNodes=6 feasibleNodes=3
2025-04-01T14:23:07.445900740Z I0401 14:23:07.445839       1 schedule_one.go:286] "Successfully bound pod to node" pod="openshift-marketplace/community-operators-bz8qq" node="host-10-13-2-160" evaluatedNodes=6 feasibleNodes=3
2025-04-01T14:24:32.544673056Z I0401 14:24:32.544460       1 schedule_one.go:988] "Unable to schedule pod; no fit; waiting" pod="default/nginx" err="0/6 nodes are available: pod has unbound immediate PersistentVolumeClaims. preemption: 0/6 nodes are available: 6 Preemption is not helpful for scheduling.."
2025-04-01T14:25:48.664995321Z I0401 14:25:48.664430       1 schedule_one.go:286] "Successfully bound pod to node" pod="openshift-marketplace/certified-operators-vn4cx" node="host-10-13-2-160" evaluatedNodes=6 feasibleNodes=3
2025-04-01T14:29:32.549134457Z I0401 14:29:32.549058       1 schedule_one.go:988] "Unable to schedule pod; no fit; waiting" pod="default/nginx" err="0/6 nodes are available: pod has unbound immediate PersistentVolumeClaims. preemption: 0/6 nodes are available: 6 Preemption is not helpful for scheduling.."
2025-04-01T14:30:00.155088485Z I0401 14:30:00.154484       1 schedule_one.go:286] "Successfully bound pod to node" pod="openshift-operator-lifecycle-manager/collect-profiles-29058630-bbrpc" node="host-10-13-2-1" evaluatedNodes=6 feasibleNodes=3
2025-04-01T14:31:50.234344624Z I0401 14:31:50.233555       1 schedule_one.go:286] "Successfully bound pod to node" pod="openshift-marketplace/redhat-operators-xrs52" node="host-10-13-2-160" evaluatedNodes=6 feasibleNodes=3
2025-04-01T14:33:38.936304563Z I0401 14:33:38.934643       1 schedule_one.go:286] "Successfully bound pod to node" pod="openshift-marketplace/redhat-marketplace-5zcw2" node="host-10-13-2-160" evaluatedNodes=6 feasibleNodes=3
2025-04-01T14:34:06.745852326Z I0401 14:34:06.745743       1 schedule_one.go:286] "Successfully bound pod to node" pod="openshift-marketplace/community-operators-hkxqd" node="host-10-13-2-160" evaluatedNodes=6 feasibleNodes=3
2025-04-01T14:34:32.554985411Z I0401 14:34:32.554932       1 schedule_one.go:988] "Unable to schedule pod; no fit; waiting" pod="default/nginx" err="0/6 nodes are available: pod has unbound immediate PersistentVolumeClaims. preemption: 0/6 nodes are available: 6 Preemption is not helpful for scheduling.."
2025-04-01T14:36:24.172583852Z I0401 14:36:24.172509       1 schedule_one.go:286] "Successfully bound pod to node" pod="openshift-marketplace/certified-operators-989rh" node="host-10-13-2-160" evaluatedNodes=6 feasibleNodes=3
2025-04-01T14:39:32.560602606Z I0401 14:39:32.560562       1 schedule_one.go:988] "Unable to schedule pod; no fit; waiting" pod="default/nginx" err="0/6 nodes are available: pod has unbound immediate PersistentVolumeClaims. preemption: 0/6 nodes are available: 6 Preemption is not helpful for scheduling.."
2025-04-01T14:42:21.806868999Z I0401 14:42:21.804561       1 schedule_one.go:286] "Successfully bound pod to node" pod="openshift-marketplace/redhat-operators-wmgj4" node="host-10-13-2-89" evaluatedNodes=6 feasibleNodes=3
2025-04-01T14:44:32.566689802Z I0401 14:44:32.565534       1 schedule_one.go:988] "Unable to schedule pod; no fit; waiting" pod="default/nginx" err="0/6 nodes are available: pod has unbound immediate PersistentVolumeClaims. preemption: 0/6 nodes are available: 6 Preemption is not helpful for scheduling.."
2025-04-01T14:44:34.439835479Z I0401 14:44:34.438687       1 schedule_one.go:286] "Successfully bound pod to node" pod="kube-system/csi-cinder-controllerplugin-5847b67f7b-snqxx" node="host-10-13-3-78" evaluatedNodes=6 feasibleNodes=3
2025-04-01T14:45:00.216786012Z I0401 14:45:00.216730       1 schedule_one.go:286] "Successfully bound pod to node" pod="openshift-operator-lifecycle-manager/collect-profiles-29058645-d87nr" node="host-10-13-2-1" evaluatedNodes=6 feasibleNodes=3
2025-04-01T14:45:00.274435028Z I0401 14:45:00.272470       1 schedule_one.go:286] "Successfully bound pod to node" pod="openshift-marketplace/redhat-marketplace-76b9b" node="host-10-13-2-89" evaluatedNodes=6 feasibleNodes=3
2025-04-01T14:47:19.831391580Z I0401 14:47:19.831325       1 schedule_one.go:286] "Successfully bound pod to node" pod="openshift-marketplace/certified-operators-nvdr9" node="host-10-13-2-89" evaluatedNodes=6 feasibleNodes=3
2025-04-01T14:48:24.406114045Z I0401 14:48:24.405387       1 schedule_one.go:286] "Successfully bound pod to node" pod="kube-system/csi-cinder-controllerplugin-5847b67f7b-fdzk8" node="host-10-13-3-120" evaluatedNodes=6 feasibleNodes=3
2025-04-01T14:48:30.139610089Z I0401 14:48:30.139510       1 schedule_one.go:988] "Unable to schedule pod; no fit; waiting" pod="default/nginx" err="0/6 nodes are available: pod has unbound immediate PersistentVolumeClaims. preemption: 0/6 nodes are available: 6 Preemption is not helpful for scheduling.."
2025-04-01T14:48:40.269716410Z I0401 14:48:40.269484       1 schedule_one.go:286] "Successfully bound pod to node" pod="default/nginx" node="host-10-13-2-1" evaluatedNodes=6 feasibleNodes=3
2025-04-01T14:49:41.264238067Z I0401 14:49:41.263804       1 schedule_one.go:286] "Successfully bound pod to node" pod="openshift-marketplace/community-operators-69xzp" node="host-10-13-2-89" evaluatedNodes=6 feasibleNodes=3
2025-04-01T14:54:32.009418224Z I0401 14:54:32.009356       1 schedule_one.go:286] "Successfully bound pod to node" pod="openshift-marketplace/redhat-operators-r7bzq" node="host-10-13-2-89" evaluatedNodes=6 feasibleNodes=3
2025-04-01T14:56:07.969486634Z I0401 14:56:07.968354       1 schedule_one.go:286] "Successfully bound pod to node" pod="openshift-marketplace/redhat-marketplace-lfr22" node="host-10-13-2-89" evaluatedNodes=6 feasibleNodes=3
2025-04-01T15:00:00.140001327Z I0401 15:00:00.139786       1 schedule_one.go:286] "Successfully bound pod to node" pod="openshift-operator-lifecycle-manager/collect-profiles-29058660-z2jl6" node="host-10-13-2-1" evaluatedNodes=6 feasibleNodes=3
2025-04-01T15:02:04.553560284Z I0401 15:02:04.553399       1 schedule_one.go:286] "Successfully bound pod to node" pod="openshift-marketplace/community-operators-6pt8s" node="host-10-13-2-89" evaluatedNodes=6 feasibleNodes=3
2025-04-01T15:02:04.559382467Z I0401 15:02:04.559340       1 schedule_one.go:286] "Successfully bound pod to node" pod="openshift-marketplace/certified-operators-bl8wt" node="host-10-13-2-160" evaluatedNodes=6 feasibleNodes=3
2025-04-01T15:06:07.243660944Z I0401 15:06:07.240685       1 schedule_one.go:286] "Successfully bound pod to node" pod="openshift-marketplace/redhat-marketplace-282lv" node="host-10-13-2-89" evaluatedNodes=6 feasibleNodes=3
2025-04-01T15:07:32.911767817Z I0401 15:07:32.911719       1 schedule_one.go:286] "Successfully bound pod to node" pod="openshift-marketplace/redhat-operators-dzbdf" node="host-10-13-2-89" evaluatedNodes=6 feasibleNodes=3
2025-04-01T15:12:25.467169922Z I0401 15:12:25.466204       1 schedule_one.go:286] "Successfully bound pod to node" pod="openshift-marketplace/community-operators-d75x5" node="host-10-13-2-89" evaluatedNodes=6 feasibleNodes=3
2025-04-01T15:13:19.401578912Z I0401 15:13:19.401305       1 schedule_one.go:286] "Successfully bound pod to node" pod="openshift-marketplace/certified-operators-mnztk" node="host-10-13-2-89" evaluatedNodes=6 feasibleNodes=3
2025-04-01T15:15:00.166569933Z I0401 15:15:00.166488       1 schedule_one.go:286] "Successfully bound pod to node" pod="openshift-operator-lifecycle-manager/collect-profiles-29058675-ggwrj" node="host-10-13-2-1" evaluatedNodes=6 feasibleNodes=3
2025-04-01T15:16:28.945221080Z I0401 15:16:28.945145       1 schedule_one.go:286] "Successfully bound pod to node" pod="openshift-marketplace/redhat-marketplace-d5m74" node="host-10-13-2-89" evaluatedNodes=6 feasibleNodes=3
2025-04-01T15:17:41.690096584Z I0401 15:17:41.690035       1 schedule_one.go:286] "Successfully bound pod to node" pod="openshift-marketplace/redhat-operators-m6h44" node="host-10-13-2-89" evaluatedNodes=6 feasibleNodes=3
2025-04-01T15:18:08.448372344Z I0401 15:18:08.448328       1 schedule_one.go:286] "Successfully bound pod to node" pod="default/openstack-manila-csi-controllerplugin-0" node="host-10-13-3-78" evaluatedNodes=6 feasibleNodes=3
2025-04-01T15:18:08.871395868Z I0401 15:18:08.871366       1 schedule_one.go:286] "Successfully bound pod to node" pod="default/openstack-manila-csi-nodeplugin-br2fv" node="host-10-13-3-78" evaluatedNodes=1 feasibleNodes=1
2025-04-01T15:18:08.883475075Z I0401 15:18:08.883445       1 schedule_one.go:286] "Successfully bound pod to node" pod="default/openstack-manila-csi-nodeplugin-x7qxz" node="host-10-13-2-1" evaluatedNodes=1 feasibleNodes=1
2025-04-01T15:18:08.883675702Z I0401 15:18:08.883660       1 schedule_one.go:286] "Successfully bound pod to node" pod="default/openstack-manila-csi-nodeplugin-rkfvr" node="host-10-13-3-120" evaluatedNodes=1 feasibleNodes=1
2025-04-01T15:20:32.843942579Z I0401 15:20:32.842073       1 schedule_one.go:286] "Successfully bound pod to node" pod="default/openstack-manila-csi-controllerplugin-0" node="host-10-13-3-78" evaluatedNodes=6 feasibleNodes=3
2025-04-01T15:20:33.182937687Z I0401 15:20:33.180884       1 schedule_one.go:286] "Successfully bound pod to node" pod="default/openstack-manila-csi-nodeplugin-4t6gk" node="host-10-13-3-78" evaluatedNodes=1 feasibleNodes=1
2025-04-01T15:20:33.194124992Z I0401 15:20:33.194084       1 schedule_one.go:286] "Successfully bound pod to node" pod="default/openstack-manila-csi-nodeplugin-rbpnc" node="host-10-13-3-120" evaluatedNodes=1 feasibleNodes=1
2025-04-01T15:20:33.194299119Z I0401 15:20:33.194285       1 schedule_one.go:286] "Successfully bound pod to node" pod="default/openstack-manila-csi-nodeplugin-9dkp7" node="host-10-13-2-1" evaluatedNodes=1 feasibleNodes=1
2025-04-01T15:21:52.278350029Z I0401 15:21:52.278302       1 schedule_one.go:286] "Successfully bound pod to node" pod="default/openstack-manila-csi-controllerplugin-0" node="host-10-13-3-78" evaluatedNodes=6 feasibleNodes=3
2025-04-01T15:21:52.646301850Z I0401 15:21:52.646255       1 schedule_one.go:286] "Successfully bound pod to node" pod="default/openstack-manila-csi-nodeplugin-rx7fp" node="host-10-13-3-78" evaluatedNodes=1 feasibleNodes=1
2025-04-01T15:21:52.657065054Z I0401 15:21:52.655123       1 schedule_one.go:286] "Successfully bound pod to node" pod="default/openstack-manila-csi-nodeplugin-4lpk5" node="host-10-13-3-120" evaluatedNodes=1 feasibleNodes=1
2025-04-01T15:21:52.659721703Z I0401 15:21:52.659479       1 schedule_one.go:286] "Successfully bound pod to node" pod="default/openstack-manila-csi-nodeplugin-hkq7j" node="host-10-13-2-1" evaluatedNodes=1 feasibleNodes=1
2025-04-01T15:23:22.310992287Z I0401 15:23:22.310939       1 schedule_one.go:286] "Successfully bound pod to node" pod="openshift-marketplace/community-operators-d2bp6" node="host-10-13-2-89" evaluatedNodes=6 feasibleNodes=3
2025-04-01T15:24:28.442158208Z I0401 15:24:28.441966       1 schedule_one.go:286] "Successfully bound pod to node" pod="openshift-marketplace/certified-operators-sdpzn" node="host-10-13-2-89" evaluatedNodes=6 feasibleNodes=3
2025-04-01T15:26:37.036123908Z I0401 15:26:37.036064       1 schedule_one.go:286] "Successfully bound pod to node" pod="openshift-marketplace/redhat-marketplace-x82nz" node="host-10-13-2-89" evaluatedNodes=6 feasibleNodes=3
2025-04-01T15:30:00.150256488Z I0401 15:30:00.149513       1 schedule_one.go:286] "Successfully bound pod to node" pod="openshift-operator-lifecycle-manager/collect-profiles-29058690-p2mx7" node="host-10-13-2-1" evaluatedNodes=6 feasibleNodes=3
2025-04-01T15:30:28.564963480Z I0401 15:30:28.564369       1 schedule_one.go:286] "Successfully bound pod to node" pod="openshift-marketplace/redhat-operators-dkqhk" node="host-10-13-2-89" evaluatedNodes=6 feasibleNodes=3
2025-04-01T15:34:51.155667442Z I0401 15:34:51.155626       1 schedule_one.go:286] "Successfully bound pod to node" pod="openshift-marketplace/certified-operators-knj7c" node="host-10-13-2-89" evaluatedNodes=6 feasibleNodes=3
2025-04-01T15:38:20.458757892Z I0401 15:38:20.458695       1 schedule_one.go:286] "Successfully bound pod to node" pod="openshift-marketplace/community-operators-kbfbt" node="host-10-13-2-89" evaluatedNodes=6 feasibleNodes=3
2025-04-01T15:38:20.628867442Z I0401 15:38:20.628823       1 schedule_one.go:286] "Successfully bound pod to node" pod="openshift-marketplace/redhat-marketplace-lrjtn" node="host-10-13-2-89" evaluatedNodes=6 feasibleNodes=3
2025-04-01T15:40:47.379752424Z I0401 15:40:47.379048       1 schedule_one.go:286] "Successfully bound pod to node" pod="openshift-marketplace/redhat-operators-kp279" node="host-10-13-2-89" evaluatedNodes=6 feasibleNodes=3
2025-04-01T15:44:51.924396412Z I0401 15:44:51.924038       1 schedule_one.go:286] "Successfully bound pod to node" pod="openshift-marketplace/certified-operators-52mpm" node="host-10-13-2-89" evaluatedNodes=6 feasibleNodes=3
2025-04-01T15:45:00.240391805Z I0401 15:45:00.240359       1 schedule_one.go:286] "Successfully bound pod to node" pod="openshift-operator-lifecycle-manager/collect-profiles-29058705-ms9lw" node="host-10-13-2-1" evaluatedNodes=6 feasibleNodes=3
2025-04-01T15:50:25.750691205Z I0401 15:50:25.750630       1 schedule_one.go:286] "Successfully bound pod to node" pod="openshift-marketplace/community-operators-4glvb" node="host-10-13-2-89" evaluatedNodes=6 feasibleNodes=3
2025-04-01T15:50:25.931564102Z I0401 15:50:25.931482       1 schedule_one.go:286] "Successfully bound pod to node" pod="openshift-marketplace/redhat-marketplace-kwgs7" node="host-10-13-2-160" evaluatedNodes=6 feasibleNodes=3
2025-04-01T15:52:01.760082089Z I0401 15:52:01.758580       1 schedule_one.go:286] "Successfully bound pod to node" pod="openshift-marketplace/redhat-operators-tcbcp" node="host-10-13-2-89" evaluatedNodes=6 feasibleNodes=3
2025-04-01T15:56:32.159014349Z I0401 15:56:32.156543       1 schedule_one.go:286] "Successfully bound pod to node" pod="openshift-marketplace/certified-operators-bptrv" node="host-10-13-2-89" evaluatedNodes=6 feasibleNodes=3
2025-04-01T16:00:00.151011747Z I0401 16:00:00.150956       1 schedule_one.go:286] "Successfully bound pod to node" pod="openshift-operator-lifecycle-manager/collect-profiles-29058720-n464v" node="host-10-13-2-1" evaluatedNodes=6 feasibleNodes=3
2025-04-01T16:01:04.470397227Z I0401 16:01:04.460343       1 schedule_one.go:286] "Successfully bound pod to node" pod="openshift-marketplace/redhat-marketplace-tm4p7" node="host-10-13-2-89" evaluatedNodes=6 feasibleNodes=3
2025-04-01T16:01:08.265271327Z I0401 16:01:08.264719       1 schedule_one.go:286] "Successfully bound pod to node" pod="openshift-marketplace/community-operators-4jgkj" node="host-10-13-2-89" evaluatedNodes=6 feasibleNodes=3
2025-04-01T16:02:32.035218407Z I0401 16:02:32.035134       1 schedule_one.go:286] "Successfully bound pod to node" pod="openshift-marketplace/redhat-operators-pgnjt" node="host-10-13-2-89" evaluatedNodes=6 feasibleNodes=3
2025-04-01T16:07:32.258957063Z I0401 16:07:32.257652       1 schedule_one.go:286] "Successfully bound pod to node" pod="openshift-marketplace/certified-operators-rfnb6" node="host-10-13-2-89" evaluatedNodes=6 feasibleNodes=3
2025-04-01T16:11:47.209995926Z I0401 16:11:47.209823       1 schedule_one.go:286] "Successfully bound pod to node" pod="openshift-marketplace/redhat-marketplace-n5r2n" node="host-10-13-2-89" evaluatedNodes=6 feasibleNodes=3
2025-04-01T16:11:55.103215300Z I0401 16:11:55.102168       1 schedule_one.go:286] "Successfully bound pod to node" pod="openshift-marketplace/community-operators-kcn5c" node="host-10-13-2-160" evaluatedNodes=6 feasibleNodes=3
2025-04-01T16:13:14.484777193Z I0401 16:13:14.484695       1 schedule_one.go:286] "Successfully bound pod to node" pod="openshift-marketplace/redhat-operators-rdmlt" node="host-10-13-2-89" evaluatedNodes=6 feasibleNodes=3
2025-04-01T16:15:00.146528220Z I0401 16:15:00.146435       1 schedule_one.go:286] "Successfully bound pod to node" pod="openshift-operator-lifecycle-manager/collect-profiles-29058735-22l9j" node="host-10-13-2-1" evaluatedNodes=6 feasibleNodes=3
2025-04-01T16:17:46.773097988Z I0401 16:17:46.768923       1 schedule_one.go:286] "Successfully bound pod to node" pod="openshift-marketplace/certified-operators-6ld7l" node="host-10-13-2-89" evaluatedNodes=6 feasibleNodes=3
2025-04-01T16:22:19.895051882Z I0401 16:22:19.894998       1 schedule_one.go:286] "Successfully bound pod to node" pod="openshift-marketplace/redhat-marketplace-7gprn" node="host-10-13-2-89" evaluatedNodes=6 feasibleNodes=3
2025-04-01T16:22:30.599166271Z I0401 16:22:30.597083       1 schedule_one.go:286] "Successfully bound pod to node" pod="openshift-marketplace/community-operators-xzv5m" node="host-10-13-2-160" evaluatedNodes=6 feasibleNodes=3
2025-04-01T16:24:01.930588359Z I0401 16:24:01.930117       1 schedule_one.go:286] "Successfully bound pod to node" pod="openshift-marketplace/redhat-operators-hbqc9" node="host-10-13-2-89" evaluatedNodes=6 feasibleNodes=3
2025-04-01T16:30:00.170037531Z I0401 16:30:00.169988       1 schedule_one.go:286] "Successfully bound pod to node" pod="openshift-operator-lifecycle-manager/collect-profiles-29058750-8m99g" node="host-10-13-2-1" evaluatedNodes=6 feasibleNodes=3
2025-04-01T16:32:54.125556278Z I0401 16:32:54.122107       1 schedule_one.go:286] "Successfully bound pod to node" pod="openshift-marketplace/redhat-marketplace-5nstr" node="host-10-13-2-89" evaluatedNodes=6 feasibleNodes=3
2025-04-01T16:33:20.655192250Z I0401 16:33:20.655117       1 schedule_one.go:286] "Successfully bound pod to node" pod="openshift-marketplace/community-operators-574z2" node="host-10-13-2-89" evaluatedNodes=6 feasibleNodes=3
2025-04-01T16:33:29.752820747Z I0401 16:33:29.752781       1 schedule_one.go:286] "Successfully bound pod to node" pod="openshift-marketplace/certified-operators-bwl8x" node="host-10-13-2-89" evaluatedNodes=6 feasibleNodes=3
2025-04-01T16:34:20.916797105Z I0401 16:34:20.916760       1 schedule_one.go:286] "Successfully bound pod to node" pod="openshift-marketplace/redhat-operators-sv68m" node="host-10-13-2-89" evaluatedNodes=6 feasibleNodes=3
2025-04-01T16:40:21.880463705Z I0401 16:40:21.880223       1 schedule_one.go:286] "Successfully bound pod to node" pod="default/openstack-manila-csi-controllerplugin-0" node="host-10-13-3-78" evaluatedNodes=6 feasibleNodes=3
2025-04-01T16:40:22.242928396Z I0401 16:40:22.242085       1 schedule_one.go:286] "Successfully bound pod to node" pod="default/openstack-manila-csi-nodeplugin-pc95s" node="host-10-13-3-78" evaluatedNodes=1 feasibleNodes=1
2025-04-01T16:40:22.255216237Z I0401 16:40:22.255153       1 schedule_one.go:286] "Successfully bound pod to node" pod="default/openstack-manila-csi-nodeplugin-xf2bb" node="host-10-13-3-120" evaluatedNodes=1 feasibleNodes=1
2025-04-01T16:40:22.262507850Z I0401 16:40:22.261888       1 schedule_one.go:286] "Successfully bound pod to node" pod="default/openstack-manila-csi-nodeplugin-855ph" node="host-10-13-2-1" evaluatedNodes=1 feasibleNodes=1
2025-04-01T16:43:48.981589471Z I0401 16:43:48.981269       1 schedule_one.go:286] "Successfully bound pod to node" pod="openshift-marketplace/redhat-marketplace-sf7vq" node="host-10-13-2-89" evaluatedNodes=6 feasibleNodes=3
2025-04-01T16:43:55.588850117Z I0401 16:43:55.588812       1 schedule_one.go:286] "Successfully bound pod to node" pod="openshift-marketplace/community-operators-84v75" node="host-10-13-2-160" evaluatedNodes=6 feasibleNodes=3
2025-04-01T16:44:08.618905620Z I0401 16:44:08.618080       1 schedule_one.go:286] "Successfully bound pod to node" pod="default/openstack-manila-csi-controllerplugin-0" node="host-10-13-3-78" evaluatedNodes=6 feasibleNodes=3
2025-04-01T16:44:09.025400157Z I0401 16:44:09.025307       1 schedule_one.go:286] "Successfully bound pod to node" pod="default/openstack-manila-csi-nodeplugin-6tt68" node="host-10-13-3-78" evaluatedNodes=1 feasibleNodes=1
2025-04-01T16:44:09.041005386Z I0401 16:44:09.039915       1 schedule_one.go:286] "Successfully bound pod to node" pod="default/openstack-manila-csi-nodeplugin-6bl7h" node="host-10-13-2-1" evaluatedNodes=1 feasibleNodes=1
2025-04-01T16:44:09.041005386Z I0401 16:44:09.039994       1 schedule_one.go:286] "Successfully bound pod to node" pod="default/openstack-manila-csi-nodeplugin-vhs27" node="host-10-13-3-120" evaluatedNodes=1 feasibleNodes=1
2025-04-01T16:44:35.180048099Z I0401 16:44:35.179239       1 schedule_one.go:286] "Successfully bound pod to node" pod="openshift-marketplace/certified-operators-b6wh8" node="host-10-13-2-89" evaluatedNodes=6 feasibleNodes=3
2025-04-01T16:45:00.211058174Z I0401 16:45:00.211019       1 schedule_one.go:286] "Successfully bound pod to node" pod="openshift-operator-lifecycle-manager/collect-profiles-29058765-v462n" node="host-10-13-2-1" evaluatedNodes=6 feasibleNodes=3
2025-04-01T16:48:37.016790500Z I0401 16:48:37.016180       1 schedule_one.go:286] "Successfully bound pod to node" pod="openshift-marketplace/redhat-operators-jzgqk" node="host-10-13-2-89" evaluatedNodes=6 feasibleNodes=3
2025-04-01T16:54:29.611440434Z I0401 16:54:29.611240       1 schedule_one.go:286] "Successfully bound pod to node" pod="openshift-marketplace/community-operators-npm42" node="host-10-13-2-89" evaluatedNodes=6 feasibleNodes=3
2025-04-01T16:54:31.016022492Z I0401 16:54:31.015918       1 schedule_one.go:286] "Successfully bound pod to node" pod="openshift-marketplace/redhat-marketplace-qrpqc" node="host-10-13-2-89" evaluatedNodes=6 feasibleNodes=3
2025-04-01T16:54:38.657377799Z I0401 16:54:38.656344       1 schedule_one.go:286] "Successfully bound pod to node" pod="openshift-marketplace/certified-operators-mrfcn" node="host-10-13-2-160" evaluatedNodes=6 feasibleNodes=3
2025-04-01T16:59:20.964866648Z I0401 16:59:20.964825       1 schedule_one.go:286] "Successfully bound pod to node" pod="default/openstack-manila-csi-controllerplugin-0" node="host-10-13-3-78" evaluatedNodes=6 feasibleNodes=3
2025-04-01T16:59:21.346079755Z I0401 16:59:21.346042       1 schedule_one.go:286] "Successfully bound pod to node" pod="default/openstack-manila-csi-nodeplugin-6624r" node="host-10-13-3-78" evaluatedNodes=1 feasibleNodes=1
2025-04-01T16:59:21.356114206Z I0401 16:59:21.355248       1 schedule_one.go:286] "Successfully bound pod to node" pod="default/openstack-manila-csi-nodeplugin-fnlqr" node="host-10-13-3-120" evaluatedNodes=1 feasibleNodes=1
2025-04-01T16:59:21.359931034Z I0401 16:59:21.359909       1 schedule_one.go:286] "Successfully bound pod to node" pod="default/openstack-manila-csi-nodeplugin-vt2qh" node="host-10-13-2-1" evaluatedNodes=1 feasibleNodes=1
2025-04-01T17:00:00.160675719Z I0401 17:00:00.160610       1 schedule_one.go:286] "Successfully bound pod to node" pod="openshift-operator-lifecycle-manager/collect-profiles-29058780-jmhjz" node="host-10-13-2-1" evaluatedNodes=6 feasibleNodes=3
2025-04-01T17:01:38.426094609Z I0401 17:01:38.426039       1 schedule_one.go:286] "Successfully bound pod to node" pod="openshift-marketplace/redhat-operators-rvkkp" node="host-10-13-2-89" evaluatedNodes=6 feasibleNodes=3
2025-04-01T17:01:52.282118680Z I0401 17:01:52.282081       1 schedule_one.go:286] "Successfully bound pod to node" pod="default/openstack-manila-csi-controllerplugin-0" node="host-10-13-3-78" evaluatedNodes=6 feasibleNodes=3
2025-04-01T17:01:52.632900312Z I0401 17:01:52.632856       1 schedule_one.go:286] "Successfully bound pod to node" pod="default/openstack-manila-csi-nodeplugin-v2xwn" node="host-10-13-3-78" evaluatedNodes=1 feasibleNodes=1
2025-04-01T17:01:52.643804406Z I0401 17:01:52.643743       1 schedule_one.go:286] "Successfully bound pod to node" pod="default/openstack-manila-csi-nodeplugin-mc65v" node="host-10-13-2-1" evaluatedNodes=1 feasibleNodes=1
2025-04-01T17:01:52.655405137Z I0401 17:01:52.655241       1 schedule_one.go:286] "Successfully bound pod to node" pod="default/openstack-manila-csi-nodeplugin-t7qlx" node="host-10-13-3-120" evaluatedNodes=1 feasibleNodes=1
2025-04-01T17:05:29.088845218Z I0401 17:05:29.088521       1 schedule_one.go:286] "Successfully bound pod to node" pod="openshift-marketplace/certified-operators-k8jpq" node="host-10-13-2-89" evaluatedNodes=6 feasibleNodes=3
2025-04-01T17:05:37.596854734Z I0401 17:05:37.596006       1 schedule_one.go:286] "Successfully bound pod to node" pod="openshift-marketplace/redhat-marketplace-5swwg" node="host-10-13-2-89" evaluatedNodes=6 feasibleNodes=3
2025-04-01T17:12:01.014923048Z I0401 17:12:01.014428       1 schedule_one.go:286] "Successfully bound pod to node" pod="openshift-marketplace/redhat-operators-kkcw5" node="host-10-13-2-89" evaluatedNodes=6 feasibleNodes=3
2025-04-01T17:12:29.694052316Z I0401 17:12:29.693525       1 schedule_one.go:286] "Successfully bound pod to node" pod="openshift-marketplace/community-operators-xnxh4" node="host-10-13-2-89" evaluatedNodes=6 feasibleNodes=3
2025-04-01T17:15:00.160919766Z I0401 17:15:00.160766       1 schedule_one.go:286] "Successfully bound pod to node" pod="openshift-operator-lifecycle-manager/collect-profiles-29058795-7mn87" node="host-10-13-2-1" evaluatedNodes=6 feasibleNodes=3
2025-04-01T17:15:39.796541801Z I0401 17:15:39.796486       1 schedule_one.go:286] "Successfully bound pod to node" pod="openshift-marketplace/redhat-marketplace-x557d" node="host-10-13-2-89" evaluatedNodes=6 feasibleNodes=3
2025-04-01T17:16:06.142677797Z I0401 17:16:06.142383       1 schedule_one.go:286] "Successfully bound pod to node" pod="openshift-marketplace/certified-operators-qjvqf" node="host-10-13-2-89" evaluatedNodes=6 feasibleNodes=3
2025-04-01T17:22:11.597739480Z I0401 17:22:11.597578       1 schedule_one.go:286] "Successfully bound pod to node" pod="openshift-marketplace/redhat-operators-z5k9l" node="host-10-13-2-89" evaluatedNodes=6 feasibleNodes=3
2025-04-01T17:24:29.609132520Z I0401 17:24:29.609087       1 schedule_one.go:286] "Successfully bound pod to node" pod="openshift-marketplace/community-operators-j7crc" node="host-10-13-2-89" evaluatedNodes=6 feasibleNodes=3
2025-04-01T17:25:42.552731868Z I0401 17:25:42.552568       1 schedule_one.go:286] "Successfully bound pod to node" pod="openshift-marketplace/redhat-marketplace-gjk2g" node="host-10-13-2-89" evaluatedNodes=6 feasibleNodes=3
2025-04-01T17:27:08.714481794Z I0401 17:27:08.714444       1 schedule_one.go:286] "Successfully bound pod to node" pod="openshift-marketplace/certified-operators-qdthp" node="host-10-13-2-89" evaluatedNodes=6 feasibleNodes=3
2025-04-01T17:30:00.154638996Z I0401 17:30:00.154562       1 schedule_one.go:286] "Successfully bound pod to node" pod="openshift-operator-lifecycle-manager/collect-profiles-29058810-955tq" node="host-10-13-2-1" evaluatedNodes=6 feasibleNodes=3
2025-04-01T17:32:43.966484320Z I0401 17:32:43.966367       1 schedule_one.go:286] "Successfully bound pod to node" pod="openshift-marketplace/redhat-operators-rlrzv" node="host-10-13-2-89" evaluatedNodes=6 feasibleNodes=3
2025-04-01T17:35:31.479636473Z I0401 17:35:31.479574       1 schedule_one.go:286] "Successfully bound pod to node" pod="openshift-marketplace/community-operators-jtsfj" node="host-10-13-2-89" evaluatedNodes=6 feasibleNodes=3
2025-04-01T17:36:56.092060310Z I0401 17:36:56.091011       1 schedule_one.go:286] "Successfully bound pod to node" pod="openshift-marketplace/redhat-marketplace-4xpxt" node="host-10-13-2-89" evaluatedNodes=6 feasibleNodes=3
2025-04-01T17:39:13.436466224Z I0401 17:39:13.436344       1 schedule_one.go:286] "Successfully bound pod to node" pod="openshift-marketplace/certified-operators-jppr4" node="host-10-13-2-89" evaluatedNodes=6 feasibleNodes=3
2025-04-01T17:43:29.240157031Z I0401 17:43:29.239769       1 schedule_one.go:286] "Successfully bound pod to node" pod="openshift-marketplace/redhat-operators-22jnd" node="host-10-13-2-89" evaluatedNodes=6 feasibleNodes=3
2025-04-01T17:45:00.233403864Z I0401 17:45:00.233352       1 schedule_one.go:286] "Successfully bound pod to node" pod="openshift-operator-lifecycle-manager/collect-profiles-29058825-tssqm" node="host-10-13-2-1" evaluatedNodes=6 feasibleNodes=3
2025-04-01T17:46:19.183046054Z I0401 17:46:19.182753       1 schedule_one.go:286] "Successfully bound pod to node" pod="openshift-marketplace/community-operators-f527b" node="host-10-13-2-89" evaluatedNodes=6 feasibleNodes=3
2025-04-01T17:47:57.306410957Z I0401 17:47:57.306351       1 schedule_one.go:286] "Successfully bound pod to node" pod="openshift-marketplace/redhat-marketplace-8fbnj" node="host-10-13-2-89" evaluatedNodes=6 feasibleNodes=3
2025-04-01T17:50:07.885949710Z I0401 17:50:07.883173       1 schedule_one.go:286] "Successfully bound pod to node" pod="openshift-marketplace/certified-operators-h9g4g" node="host-10-13-2-89" evaluatedNodes=6 feasibleNodes=3
2025-04-01T17:53:44.830956295Z I0401 17:53:44.830163       1 schedule_one.go:286] "Successfully bound pod to node" pod="openshift-marketplace/redhat-operators-5nb72" node="host-10-13-2-89" evaluatedNodes=6 feasibleNodes=3
2025-04-01T17:56:29.835117047Z I0401 17:56:29.833797       1 schedule_one.go:286] "Successfully bound pod to node" pod="openshift-marketplace/community-operators-ggz9w" node="host-10-13-2-89" evaluatedNodes=6 feasibleNodes=3
2025-04-01T18:00:00.158599536Z I0401 18:00:00.158514       1 schedule_one.go:286] "Successfully bound pod to node" pod="openshift-operator-lifecycle-manager/collect-profiles-29058840-b44tl" node="host-10-13-2-1" evaluatedNodes=6 feasibleNodes=3
2025-04-01T18:03:24.009499955Z I0401 18:03:24.009424       1 schedule_one.go:286] "Successfully bound pod to node" pod="openshift-marketplace/certified-operators-7ht5p" node="host-10-13-2-89" evaluatedNodes=6 feasibleNodes=3
2025-04-01T18:03:25.398206080Z I0401 18:03:25.398156       1 schedule_one.go:286] "Successfully bound pod to node" pod="openshift-marketplace/redhat-marketplace-f6znh" node="host-10-13-2-160" evaluatedNodes=6 feasibleNodes=3
2025-04-01T18:06:03.447654182Z I0401 18:06:03.447587       1 schedule_one.go:286] "Successfully bound pod to node" pod="openshift-marketplace/redhat-operators-9hds7" node="host-10-13-2-89" evaluatedNodes=6 feasibleNodes=3
2025-04-01T18:06:46.247929019Z I0401 18:06:46.245811       1 schedule_one.go:286] "Successfully bound pod to node" pod="openshift-marketplace/community-operators-tvzgw" node="host-10-13-2-89" evaluatedNodes=6 feasibleNodes=3
2025-04-01T18:14:16.455181779Z I0401 18:14:16.454413       1 schedule_one.go:286] "Successfully bound pod to node" pod="openshift-marketplace/certified-operators-54twq" node="host-10-13-2-89" evaluatedNodes=6 feasibleNodes=3
2025-04-01T18:15:00.137366944Z I0401 18:15:00.137310       1 schedule_one.go:286] "Successfully bound pod to node" pod="openshift-operator-lifecycle-manager/collect-profiles-29058855-drd85" node="host-10-13-2-1" evaluatedNodes=6 feasibleNodes=3
2025-04-01T18:15:29.326931555Z I0401 18:15:29.325011       1 schedule_one.go:286] "Successfully bound pod to node" pod="openshift-marketplace/redhat-marketplace-bcvsn" node="host-10-13-2-89" evaluatedNodes=6 feasibleNodes=3
2025-04-01T18:16:04.946089603Z I0401 18:16:04.944701       1 schedule_one.go:286] "Successfully bound pod to node" pod="openshift-marketplace/redhat-operators-wzrdg" node="host-10-13-2-89" evaluatedNodes=6 feasibleNodes=3
2025-04-01T18:17:05.021092257Z I0401 18:17:05.020796       1 schedule_one.go:286] "Successfully bound pod to node" pod="openshift-marketplace/community-operators-jp4kx" node="host-10-13-2-89" evaluatedNodes=6 feasibleNodes=3
2025-04-01T18:24:28.446617167Z I0401 18:24:28.443161       1 schedule_one.go:286] "Successfully bound pod to node" pod="openshift-marketplace/certified-operators-wbbng" node="host-10-13-2-89" evaluatedNodes=6 feasibleNodes=3
2025-04-01T18:26:23.152412360Z I0401 18:26:23.152325       1 schedule_one.go:286] "Successfully bound pod to node" pod="openshift-marketplace/redhat-operators-pg4kb" node="host-10-13-2-89" evaluatedNodes=6 feasibleNodes=3
2025-04-01T18:27:34.607213109Z I0401 18:27:34.607139       1 schedule_one.go:286] "Successfully bound pod to node" pod="openshift-marketplace/community-operators-4b6vl" node="host-10-13-2-89" evaluatedNodes=6 feasibleNodes=3
2025-04-01T18:27:34.790585204Z I0401 18:27:34.789314       1 schedule_one.go:286] "Successfully bound pod to node" pod="openshift-marketplace/redhat-marketplace-c25mb" node="host-10-13-2-89" evaluatedNodes=6 feasibleNodes=3
2025-04-01T18:30:00.153102087Z I0401 18:30:00.153035       1 schedule_one.go:286] "Successfully bound pod to node" pod="openshift-operator-lifecycle-manager/collect-profiles-29058870-knnj8" node="host-10-13-2-1" evaluatedNodes=6 feasibleNodes=3
2025-04-01T18:35:28.937811371Z I0401 18:35:28.937770       1 schedule_one.go:286] "Successfully bound pod to node" pod="openshift-marketplace/certified-operators-9nmzz" node="host-10-13-2-89" evaluatedNodes=6 feasibleNodes=3
2025-04-01T18:38:36.299131587Z I0401 18:38:36.298782       1 schedule_one.go:286] "Successfully bound pod to node" pod="openshift-marketplace/community-operators-ddsbd" node="host-10-13-2-89" evaluatedNodes=6 feasibleNodes=3
2025-04-01T18:39:40.510149134Z I0401 18:39:40.509895       1 schedule_one.go:286] "Successfully bound pod to node" pod="openshift-marketplace/redhat-marketplace-24l4c" node="host-10-13-2-89" evaluatedNodes=6 feasibleNodes=3
2025-04-01T18:39:40.690226343Z I0401 18:39:40.690190       1 schedule_one.go:286] "Successfully bound pod to node" pod="openshift-marketplace/redhat-operators-f7t6n" node="host-10-13-2-89" evaluatedNodes=6 feasibleNodes=3
2025-04-01T18:45:00.201896395Z I0401 18:45:00.200396       1 schedule_one.go:286] "Successfully bound pod to node" pod="openshift-operator-lifecycle-manager/collect-profiles-29058885-bslc2" node="host-10-13-2-1" evaluatedNodes=6 feasibleNodes=3
2025-04-01T18:45:49.680589923Z I0401 18:45:49.680543       1 schedule_one.go:286] "Successfully bound pod to node" pod="openshift-marketplace/certified-operators-5p5gk" node="host-10-13-2-89" evaluatedNodes=6 feasibleNodes=3
2025-04-01T18:49:28.954389461Z I0401 18:49:28.953141       1 schedule_one.go:286] "Successfully bound pod to node" pod="openshift-marketplace/community-operators-hsck5" node="host-10-13-2-89" evaluatedNodes=6 feasibleNodes=3
2025-04-01T18:49:59.537229023Z I0401 18:49:59.536820       1 schedule_one.go:286] "Successfully bound pod to node" pod="openshift-marketplace/redhat-marketplace-5kzxc" node="host-10-13-2-89" evaluatedNodes=6 feasibleNodes=3
2025-04-01T18:51:45.207006973Z I0401 18:51:45.204540       1 schedule_one.go:286] "Successfully bound pod to node" pod="openshift-marketplace/redhat-operators-bqbxp" node="host-10-13-2-89" evaluatedNodes=6 feasibleNodes=3
2025-04-01T18:58:51.096610286Z I0401 18:58:51.096268       1 schedule_one.go:286] "Successfully bound pod to node" pod="openshift-marketplace/certified-operators-2jrzr" node="host-10-13-2-89" evaluatedNodes=6 feasibleNodes=3
2025-04-01T18:59:36.605011959Z I0401 18:59:36.604981       1 schedule_one.go:286] "Successfully bound pod to node" pod="openshift-marketplace/community-operators-c7wmn" node="host-10-13-2-89" evaluatedNodes=6 feasibleNodes=3
2025-04-01T19:00:00.161196037Z I0401 19:00:00.160656       1 schedule_one.go:286] "Successfully bound pod to node" pod="openshift-operator-lifecycle-manager/collect-profiles-29058900-49gls" node="host-10-13-2-1" evaluatedNodes=6 feasibleNodes=3
2025-04-01T19:01:24.073129451Z I0401 19:01:24.071589       1 schedule_one.go:286] "Successfully bound pod to node" pod="openshift-marketplace/redhat-marketplace-s7qz6" node="host-10-13-2-89" evaluatedNodes=6 feasibleNodes=3
2025-04-01T19:03:51.291692848Z I0401 19:03:51.290106       1 schedule_one.go:286] "Successfully bound pod to node" pod="openshift-marketplace/redhat-operators-gnlk7" node="host-10-13-2-160" evaluatedNodes=6 feasibleNodes=3
2025-04-01T19:09:43.046980100Z I0401 19:09:43.044232       1 schedule_one.go:286] "Successfully bound pod to node" pod="openshift-marketplace/certified-operators-rg7rn" node="host-10-13-2-160" evaluatedNodes=6 feasibleNodes=3
2025-04-01T19:10:28.416921225Z I0401 19:10:28.416831       1 schedule_one.go:286] "Successfully bound pod to node" pod="openshift-marketplace/community-operators-mlxmd" node="host-10-13-2-160" evaluatedNodes=6 feasibleNodes=3
2025-04-01T19:11:52.687970920Z I0401 19:11:52.686224       1 schedule_one.go:286] "Successfully bound pod to node" pod="openshift-marketplace/redhat-marketplace-vm2nl" node="host-10-13-2-160" evaluatedNodes=6 feasibleNodes=3
2025-04-01T19:14:39.748384727Z I0401 19:14:39.747774       1 schedule_one.go:286] "Successfully bound pod to node" pod="openshift-marketplace/redhat-operators-mlpb9" node="host-10-13-2-160" evaluatedNodes=6 feasibleNodes=3
2025-04-01T19:15:00.164961629Z I0401 19:15:00.163252       1 schedule_one.go:286] "Successfully bound pod to node" pod="openshift-operator-lifecycle-manager/collect-profiles-29058915-p7b4m" node="host-10-13-2-1" evaluatedNodes=6 feasibleNodes=3
2025-04-01T19:20:54.526355262Z I0401 19:20:54.526230       1 schedule_one.go:286] "Successfully bound pod to node" pod="openshift-marketplace/certified-operators-hphtt" node="host-10-13-2-160" evaluatedNodes=6 feasibleNodes=3
2025-04-01T19:20:57.554032697Z I0401 19:20:57.551093       1 schedule_one.go:286] "Successfully bound pod to node" pod="openshift-marketplace/community-operators-7b8nz" node="host-10-13-2-89" evaluatedNodes=6 feasibleNodes=3
2025-04-01T19:23:09.669556355Z I0401 19:23:09.668527       1 schedule_one.go:286] "Successfully bound pod to node" pod="openshift-marketplace/redhat-marketplace-9kcfb" node="host-10-13-2-160" evaluatedNodes=6 feasibleNodes=3
2025-04-01T19:24:54.495101293Z I0401 19:24:54.494966       1 schedule_one.go:286] "Successfully bound pod to node" pod="openshift-marketplace/redhat-operators-cp7wx" node="host-10-13-2-160" evaluatedNodes=6 feasibleNodes=3
2025-04-01T19:30:00.153155493Z I0401 19:30:00.152992       1 schedule_one.go:286] "Successfully bound pod to node" pod="openshift-operator-lifecycle-manager/collect-profiles-29058930-5rvzz" node="host-10-13-2-1" evaluatedNodes=6 feasibleNodes=3
2025-04-01T19:31:33.296640787Z I0401 19:31:33.296247       1 schedule_one.go:286] "Successfully bound pod to node" pod="openshift-marketplace/community-operators-r6flj" node="host-10-13-2-160" evaluatedNodes=6 feasibleNodes=3
2025-04-01T19:34:43.079390307Z I0401 19:34:43.079263       1 schedule_one.go:286] "Successfully bound pod to node" pod="openshift-marketplace/certified-operators-j99kh" node="host-10-13-2-160" evaluatedNodes=6 feasibleNodes=3
2025-04-01T19:35:18.131896066Z I0401 19:35:18.131789       1 schedule_one.go:286] "Successfully bound pod to node" pod="openshift-marketplace/redhat-marketplace-9kp4z" node="host-10-13-2-160" evaluatedNodes=6 feasibleNodes=3
2025-04-01T19:35:19.516388301Z I0401 19:35:19.516356       1 schedule_one.go:286] "Successfully bound pod to node" pod="openshift-marketplace/redhat-operators-pl2xp" node="host-10-13-2-89" evaluatedNodes=6 feasibleNodes=3
2025-04-01T19:42:05.832327634Z I0401 19:42:05.832294       1 schedule_one.go:286] "Successfully bound pod to node" pod="openshift-marketplace/community-operators-n8j92" node="host-10-13-2-160" evaluatedNodes=6 feasibleNodes=3
2025-04-01T19:45:00.218337517Z I0401 19:45:00.217561       1 schedule_one.go:286] "Successfully bound pod to node" pod="openshift-operator-lifecycle-manager/collect-profiles-29058945-wh6zp" node="host-10-13-2-1" evaluatedNodes=6 feasibleNodes=3
2025-04-01T19:45:25.025463123Z I0401 19:45:25.024910       1 schedule_one.go:286] "Successfully bound pod to node" pod="openshift-marketplace/certified-operators-vbttz" node="host-10-13-2-160" evaluatedNodes=6 feasibleNodes=3
2025-04-01T19:46:13.423566986Z I0401 19:46:13.423529       1 schedule_one.go:286] "Successfully bound pod to node" pod="openshift-marketplace/redhat-operators-nwv4g" node="host-10-13-2-160" evaluatedNodes=6 feasibleNodes=3
2025-04-01T19:50:57.310127571Z I0401 19:50:57.310075       1 schedule_one.go:286] "Successfully bound pod to node" pod="openshift-marketplace/redhat-marketplace-wpg92" node="host-10-13-2-160" evaluatedNodes=6 feasibleNodes=3
2025-04-01T19:52:11.706225641Z I0401 19:52:11.706118       1 schedule_one.go:286] "Successfully bound pod to node" pod="openshift-marketplace/community-operators-kq5wb" node="host-10-13-2-160" evaluatedNodes=6 feasibleNodes=3
2025-04-01T19:55:53.444628334Z I0401 19:55:53.444566       1 schedule_one.go:286] "Successfully bound pod to node" pod="openshift-marketplace/certified-operators-8lrbj" node="host-10-13-2-160" evaluatedNodes=6 feasibleNodes=3
2025-04-01T20:00:00.153065501Z I0401 20:00:00.152861       1 schedule_one.go:286] "Successfully bound pod to node" pod="openshift-operator-lifecycle-manager/collect-profiles-29058960-s2g5k" node="host-10-13-2-1" evaluatedNodes=6 feasibleNodes=3
2025-04-01T20:02:47.417619226Z I0401 20:02:47.417347       1 schedule_one.go:286] "Successfully bound pod to node" pod="openshift-marketplace/community-operators-48hvg" node="host-10-13-2-160" evaluatedNodes=6 feasibleNodes=3
2025-04-01T20:03:40.462202980Z I0401 20:03:40.461554       1 schedule_one.go:286] "Successfully bound pod to node" pod="openshift-marketplace/redhat-marketplace-7mkp9" node="host-10-13-2-160" evaluatedNodes=6 feasibleNodes=3
2025-04-01T20:03:58.133779103Z I0401 20:03:58.133284       1 schedule_one.go:286] "Successfully bound pod to node" pod="openshift-marketplace/redhat-operators-d8rpd" node="host-10-13-2-160" evaluatedNodes=6 feasibleNodes=3
2025-04-01T20:11:00.829947206Z I0401 20:11:00.829442       1 schedule_one.go:286] "Successfully bound pod to node" pod="openshift-marketplace/certified-operators-h4848" node="host-10-13-2-160" evaluatedNodes=6 feasibleNodes=3
2025-04-01T20:14:01.915035989Z I0401 20:14:01.914607       1 schedule_one.go:286] "Successfully bound pod to node" pod="openshift-marketplace/redhat-operators-bcd78" node="host-10-13-2-160" evaluatedNodes=6 feasibleNodes=3
2025-04-01T20:14:42.852960990Z I0401 20:14:42.850596       1 schedule_one.go:286] "Successfully bound pod to node" pod="openshift-marketplace/redhat-marketplace-5hpcx" node="host-10-13-2-160" evaluatedNodes=6 feasibleNodes=3
2025-04-01T20:15:00.162089513Z I0401 20:15:00.161935       1 schedule_one.go:286] "Successfully bound pod to node" pod="openshift-operator-lifecycle-manager/collect-profiles-29058975-94pd8" node="host-10-13-2-1" evaluatedNodes=6 feasibleNodes=3
2025-04-01T20:16:22.875558899Z I0401 20:16:22.875493       1 schedule_one.go:286] "Successfully bound pod to node" pod="openshift-marketplace/community-operators-bpgjt" node="host-10-13-2-160" evaluatedNodes=6 feasibleNodes=3
2025-04-01T20:21:25.655693863Z I0401 20:21:25.655463       1 schedule_one.go:286] "Successfully bound pod to node" pod="openshift-marketplace/certified-operators-htwqk" node="host-10-13-2-160" evaluatedNodes=6 feasibleNodes=3
2025-04-01T20:24:32.037090356Z I0401 20:24:32.037016       1 schedule_one.go:286] "Successfully bound pod to node" pod="openshift-marketplace/redhat-operators-hxhrv" node="host-10-13-2-160" evaluatedNodes=6 feasibleNodes=3
2025-04-01T20:24:45.843109217Z I0401 20:24:45.842974       1 schedule_one.go:286] "Successfully bound pod to node" pod="openshift-marketplace/redhat-marketplace-9h99n" node="host-10-13-2-160" evaluatedNodes=6 feasibleNodes=3
2025-04-01T20:28:28.362152378Z I0401 20:28:28.362071       1 schedule_one.go:286] "Successfully bound pod to node" pod="openshift-marketplace/community-operators-7mvfc" node="host-10-13-2-160" evaluatedNodes=6 feasibleNodes=3
2025-04-01T20:30:00.162569349Z I0401 20:30:00.160720       1 schedule_one.go:286] "Successfully bound pod to node" pod="openshift-operator-lifecycle-manager/collect-profiles-29058990-fc9wj" node="host-10-13-2-1" evaluatedNodes=6 feasibleNodes=3
2025-04-01T20:34:15.922622001Z I0401 20:34:15.922533       1 schedule_one.go:286] "Successfully bound pod to node" pod="openshift-marketplace/certified-operators-cfnh6" node="host-10-13-2-160" evaluatedNodes=6 feasibleNodes=3
2025-04-01T20:34:50.952099362Z I0401 20:34:50.952069       1 schedule_one.go:286] "Successfully bound pod to node" pod="openshift-marketplace/redhat-operators-jw2qb" node="host-10-13-2-160" evaluatedNodes=6 feasibleNodes=3
2025-04-01T20:35:01.382648154Z I0401 20:35:01.382584       1 schedule_one.go:286] "Successfully bound pod to node" pod="openshift-marketplace/redhat-marketplace-dc5zx" node="host-10-13-2-89" evaluatedNodes=6 feasibleNodes=3
2025-04-01T20:40:32.869165929Z I0401 20:40:32.868668       1 schedule_one.go:286] "Successfully bound pod to node" pod="openshift-marketplace/community-operators-w96w7" node="host-10-13-2-160" evaluatedNodes=6 feasibleNodes=3
2025-04-01T20:45:00.178217292Z I0401 20:45:00.178064       1 schedule_one.go:286] "Successfully bound pod to node" pod="openshift-operator-lifecycle-manager/collect-profiles-29059005-jrgl5" node="host-10-13-2-1" evaluatedNodes=6 feasibleNodes=3
2025-04-01T20:45:11.392478303Z I0401 20:45:11.390934       1 schedule_one.go:286] "Successfully bound pod to node" pod="openshift-marketplace/redhat-marketplace-57bd7" node="host-10-13-2-160" evaluatedNodes=6 feasibleNodes=3
2025-04-01T20:45:28.720345124Z I0401 20:45:28.720285       1 schedule_one.go:286] "Successfully bound pod to node" pod="openshift-marketplace/redhat-operators-vkw2l" node="host-10-13-2-160" evaluatedNodes=6 feasibleNodes=3
2025-04-01T20:45:33.229336908Z I0401 20:45:33.229268       1 schedule_one.go:286] "Successfully bound pod to node" pod="openshift-marketplace/certified-operators-xtsxx" node="host-10-13-2-89" evaluatedNodes=6 feasibleNodes=3
2025-04-01T20:51:29.941235287Z I0401 20:51:29.941185       1 schedule_one.go:286] "Successfully bound pod to node" pod="openshift-marketplace/community-operators-xnnc7" node="host-10-13-2-160" evaluatedNodes=6 feasibleNodes=3
2025-04-01T20:56:03.768047535Z I0401 20:56:03.767459       1 schedule_one.go:286] "Successfully bound pod to node" pod="openshift-marketplace/certified-operators-kgmpw" node="host-10-13-2-160" evaluatedNodes=6 feasibleNodes=3
2025-04-01T20:56:03.949867285Z I0401 20:56:03.949731       1 schedule_one.go:286] "Successfully bound pod to node" pod="openshift-marketplace/redhat-marketplace-j4vz6" node="host-10-13-2-160" evaluatedNodes=6 feasibleNodes=3
2025-04-01T20:56:05.343230462Z I0401 20:56:05.342980       1 schedule_one.go:286] "Successfully bound pod to node" pod="openshift-marketplace/redhat-operators-ljlns" node="host-10-13-2-89" evaluatedNodes=6 feasibleNodes=3
2025-04-01T21:00:00.153277525Z I0401 21:00:00.153021       1 schedule_one.go:286] "Successfully bound pod to node" pod="openshift-operator-lifecycle-manager/collect-profiles-29059020-dvgsr" node="host-10-13-2-1" evaluatedNodes=6 feasibleNodes=3
2025-04-01T21:04:03.665800754Z I0401 21:04:03.665742       1 schedule_one.go:286] "Successfully bound pod to node" pod="openshift-marketplace/community-operators-rhrbv" node="host-10-13-2-160" evaluatedNodes=6 feasibleNodes=3
2025-04-01T21:06:15.222912105Z I0401 21:06:15.222342       1 schedule_one.go:286] "Successfully bound pod to node" pod="openshift-marketplace/redhat-operators-6w62b" node="host-10-13-2-160" evaluatedNodes=6 feasibleNodes=3
2025-04-01T21:06:44.938103796Z I0401 21:06:44.937352       1 schedule_one.go:286] "Successfully bound pod to node" pod="openshift-marketplace/certified-operators-thtrf" node="host-10-13-2-160" evaluatedNodes=6 feasibleNodes=3
2025-04-01T21:06:46.933794767Z I0401 21:06:46.933653       1 schedule_one.go:286] "Successfully bound pod to node" pod="openshift-marketplace/redhat-marketplace-tchqv" node="host-10-13-2-160" evaluatedNodes=6 feasibleNodes=3
2025-04-01T21:15:00.161271584Z I0401 21:15:00.160937       1 schedule_one.go:286] "Successfully bound pod to node" pod="openshift-operator-lifecycle-manager/collect-profiles-29059035-9rpmr" node="host-10-13-2-1" evaluatedNodes=6 feasibleNodes=3
2025-04-01T21:16:48.775058842Z I0401 21:16:48.774621       1 schedule_one.go:286] "Successfully bound pod to node" pod="openshift-marketplace/certified-operators-lnv9z" node="host-10-13-2-160" evaluatedNodes=6 feasibleNodes=3
2025-04-01T21:16:48.788828943Z I0401 21:16:48.786422       1 schedule_one.go:286] "Successfully bound pod to node" pod="openshift-marketplace/community-operators-rkrv5" node="host-10-13-2-160" evaluatedNodes=6 feasibleNodes=3
2025-04-01T21:16:49.754614670Z I0401 21:16:49.754036       1 schedule_one.go:286] "Successfully bound pod to node" pod="openshift-marketplace/redhat-marketplace-5hbjg" node="host-10-13-2-160" evaluatedNodes=6 feasibleNodes=3
2025-04-01T21:16:49.948913323Z I0401 21:16:49.948814       1 schedule_one.go:286] "Successfully bound pod to node" pod="openshift-marketplace/redhat-operators-hcdrr" node="host-10-13-2-160" evaluatedNodes=6 feasibleNodes=3
2025-04-01T21:28:01.803988186Z I0401 21:28:01.803366       1 schedule_one.go:286] "Successfully bound pod to node" pod="openshift-marketplace/redhat-marketplace-69sd5" node="host-10-13-2-160" evaluatedNodes=6 feasibleNodes=3
2025-04-01T21:28:05.152421180Z I0401 21:28:05.152272       1 schedule_one.go:286] "Successfully bound pod to node" pod="openshift-marketplace/redhat-operators-nhvqs" node="host-10-13-2-160" evaluatedNodes=6 feasibleNodes=3
2025-04-01T21:28:16.787069682Z I0401 21:28:16.785596       1 schedule_one.go:286] "Successfully bound pod to node" pod="openshift-marketplace/community-operators-ksbl8" node="host-10-13-2-160" evaluatedNodes=6 feasibleNodes=3
2025-04-01T21:28:54.069396172Z I0401 21:28:54.069108       1 schedule_one.go:286] "Successfully bound pod to node" pod="openshift-marketplace/certified-operators-f8wwp" node="host-10-13-2-160" evaluatedNodes=6 feasibleNodes=3
2025-04-01T21:30:00.157340154Z I0401 21:30:00.157283       1 schedule_one.go:286] "Successfully bound pod to node" pod="openshift-operator-lifecycle-manager/collect-profiles-29059050-7w77c" node="host-10-13-2-1" evaluatedNodes=6 feasibleNodes=3
2025-04-01T21:38:33.505321506Z I0401 21:38:33.504972       1 schedule_one.go:286] "Successfully bound pod to node" pod="openshift-marketplace/community-operators-pdtnk" node="host-10-13-2-160" evaluatedNodes=6 feasibleNodes=3
2025-04-01T21:40:15.504636521Z I0401 21:40:15.504571       1 schedule_one.go:286] "Successfully bound pod to node" pod="openshift-marketplace/redhat-marketplace-4594d" node="host-10-13-2-160" evaluatedNodes=6 feasibleNodes=3
2025-04-01T21:40:15.686931565Z I0401 21:40:15.686173       1 schedule_one.go:286] "Successfully bound pod to node" pod="openshift-marketplace/redhat-operators-vcm6h" node="host-10-13-2-160" evaluatedNodes=6 feasibleNodes=3
2025-04-01T21:40:17.092278566Z I0401 21:40:17.092135       1 schedule_one.go:286] "Successfully bound pod to node" pod="openshift-marketplace/certified-operators-g25f6" node="host-10-13-2-160" evaluatedNodes=6 feasibleNodes=3
2025-04-01T21:45:00.228950393Z I0401 21:45:00.228913       1 schedule_one.go:286] "Successfully bound pod to node" pod="openshift-operator-lifecycle-manager/collect-profiles-29059065-rszv8" node="host-10-13-2-1" evaluatedNodes=6 feasibleNodes=3
2025-04-01T21:48:41.954412618Z I0401 21:48:41.954350       1 schedule_one.go:286] "Successfully bound pod to node" pod="openshift-marketplace/community-operators-z4cmg" node="host-10-13-2-160" evaluatedNodes=6 feasibleNodes=3
2025-04-01T21:50:24.981295140Z I0401 21:50:24.981223       1 schedule_one.go:286] "Successfully bound pod to node" pod="openshift-marketplace/redhat-operators-mdw9r" node="host-10-13-2-160" evaluatedNodes=6 feasibleNodes=3
2025-04-01T21:50:27.643386401Z I0401 21:50:27.642292       1 schedule_one.go:286] "Successfully bound pod to node" pod="openshift-marketplace/redhat-marketplace-tnkgt" node="host-10-13-2-160" evaluatedNodes=6 feasibleNodes=3
2025-04-01T21:53:04.668999974Z I0401 21:53:04.668944       1 schedule_one.go:286] "Successfully bound pod to node" pod="openshift-marketplace/certified-operators-djlnd" node="host-10-13-2-160" evaluatedNodes=6 feasibleNodes=3
2025-04-01T22:00:00.149423650Z I0401 22:00:00.148969       1 schedule_one.go:286] "Successfully bound pod to node" pod="openshift-operator-lifecycle-manager/collect-profiles-29059080-fpcl2" node="host-10-13-2-1" evaluatedNodes=6 feasibleNodes=3
2025-04-01T22:01:10.816852954Z I0401 22:01:10.816768       1 schedule_one.go:286] "Successfully bound pod to node" pod="openshift-marketplace/community-operators-ck65w" node="host-10-13-2-160" evaluatedNodes=6 feasibleNodes=3
2025-04-01T22:01:10.821032084Z I0401 22:01:10.820259       1 schedule_one.go:286] "Successfully bound pod to node" pod="openshift-marketplace/redhat-marketplace-4kwxp" node="host-10-13-2-160" evaluatedNodes=6 feasibleNodes=3
2025-04-01T22:01:11.789641752Z I0401 22:01:11.789148       1 schedule_one.go:286] "Successfully bound pod to node" pod="openshift-marketplace/redhat-operators-kfhdw" node="host-10-13-2-160" evaluatedNodes=6 feasibleNodes=3
2025-04-01T22:03:49.445711509Z I0401 22:03:49.445409       1 schedule_one.go:286] "Successfully bound pod to node" pod="openshift-marketplace/certified-operators-k6n7v" node="host-10-13-2-160" evaluatedNodes=6 feasibleNodes=3
2025-04-01T22:11:49.645950234Z I0401 22:11:49.644321       1 schedule_one.go:286] "Successfully bound pod to node" pod="openshift-marketplace/community-operators-6fbhp" node="host-10-13-2-160" evaluatedNodes=6 feasibleNodes=3
2025-04-01T22:11:56.499794361Z I0401 22:11:56.497191       1 schedule_one.go:286] "Successfully bound pod to node" pod="openshift-marketplace/redhat-operators-zpqhx" node="host-10-13-2-160" evaluatedNodes=6 feasibleNodes=3
2025-04-01T22:12:27.618617859Z I0401 22:12:27.618520       1 schedule_one.go:286] "Successfully bound pod to node" pod="openshift-marketplace/redhat-marketplace-5574v" node="host-10-13-2-160" evaluatedNodes=6 feasibleNodes=3
2025-04-01T22:13:54.026470351Z I0401 22:13:54.022607       1 schedule_one.go:286] "Successfully bound pod to node" pod="openshift-marketplace/certified-operators-88zsw" node="host-10-13-2-160" evaluatedNodes=6 feasibleNodes=3
2025-04-01T22:15:00.161164635Z I0401 22:15:00.160581       1 schedule_one.go:286] "Successfully bound pod to node" pod="openshift-operator-lifecycle-manager/collect-profiles-29059095-m7hn5" node="host-10-13-2-1" evaluatedNodes=6 feasibleNodes=3
2025-04-01T22:22:53.180503015Z I0401 22:22:53.180444       1 schedule_one.go:286] "Successfully bound pod to node" pod="openshift-marketplace/redhat-operators-4rsjx" node="host-10-13-2-160" evaluatedNodes=6 feasibleNodes=3
2025-04-01T22:23:47.931712808Z I0401 22:23:47.931658       1 schedule_one.go:286] "Successfully bound pod to node" pod="openshift-marketplace/redhat-marketplace-2jmff" node="host-10-13-2-160" evaluatedNodes=6 feasibleNodes=3
2025-04-01T22:24:28.463053204Z I0401 22:24:28.461282       1 schedule_one.go:286] "Successfully bound pod to node" pod="openshift-marketplace/certified-operators-t5qr8" node="host-10-13-2-160" evaluatedNodes=6 feasibleNodes=3
2025-04-01T22:24:30.436618604Z I0401 22:24:30.436583       1 schedule_one.go:286] "Successfully bound pod to node" pod="openshift-marketplace/community-operators-bg4tg" node="host-10-13-2-160" evaluatedNodes=6 feasibleNodes=3
2025-04-01T22:30:00.142697496Z I0401 22:30:00.140620       1 schedule_one.go:286] "Successfully bound pod to node" pod="openshift-operator-lifecycle-manager/collect-profiles-29059110-gtzb4" node="host-10-13-2-1" evaluatedNodes=6 feasibleNodes=3
2025-04-01T22:33:13.416498925Z I0401 22:33:13.416132       1 schedule_one.go:286] "Successfully bound pod to node" pod="openshift-marketplace/redhat-operators-bmv9k" node="host-10-13-2-160" evaluatedNodes=6 feasibleNodes=3
2025-04-01T22:33:49.247778956Z I0401 22:33:49.246670       1 schedule_one.go:286] "Successfully bound pod to node" pod="openshift-marketplace/redhat-marketplace-6nq8d" node="host-10-13-2-160" evaluatedNodes=6 feasibleNodes=3
2025-04-01T22:35:26.485504993Z I0401 22:35:26.485040       1 schedule_one.go:286] "Successfully bound pod to node" pod="openshift-marketplace/certified-operators-j99st" node="host-10-13-2-160" evaluatedNodes=6 feasibleNodes=3
2025-04-01T22:35:56.446419518Z I0401 22:35:56.446388       1 schedule_one.go:286] "Successfully bound pod to node" pod="openshift-marketplace/community-operators-lpqr7" node="host-10-13-2-160" evaluatedNodes=6 feasibleNodes=3
2025-04-01T22:43:29.867066339Z I0401 22:43:29.867031       1 schedule_one.go:286] "Successfully bound pod to node" pod="openshift-marketplace/redhat-operators-ljcrv" node="host-10-13-2-160" evaluatedNodes=6 feasibleNodes=3
2025-04-01T22:44:40.050585990Z I0401 22:44:40.049704       1 schedule_one.go:286] "Successfully bound pod to node" pod="openshift-marketplace/redhat-marketplace-g525v" node="host-10-13-2-160" evaluatedNodes=6 feasibleNodes=3
2025-04-01T22:45:00.208305005Z I0401 22:45:00.208245       1 schedule_one.go:286] "Successfully bound pod to node" pod="openshift-operator-lifecycle-manager/collect-profiles-29059125-4fgwd" node="host-10-13-2-1" evaluatedNodes=6 feasibleNodes=3
2025-04-01T22:45:47.494652903Z I0401 22:45:47.494355       1 schedule_one.go:286] "Successfully bound pod to node" pod="openshift-marketplace/certified-operators-c78wg" node="host-10-13-2-160" evaluatedNodes=6 feasibleNodes=3
2025-04-01T22:46:32.423078683Z I0401 22:46:32.422671       1 schedule_one.go:286] "Successfully bound pod to node" pod="openshift-marketplace/community-operators-mfkzj" node="host-10-13-2-160" evaluatedNodes=6 feasibleNodes=3
2025-04-01T22:53:31.145645351Z I0401 22:53:31.144844       1 schedule_one.go:286] "Successfully bound pod to node" pod="openshift-marketplace/redhat-operators-n5kwv" node="host-10-13-2-160" evaluatedNodes=6 feasibleNodes=3
2025-04-01T22:54:49.193675895Z I0401 22:54:49.193648       1 schedule_one.go:286] "Successfully bound pod to node" pod="openshift-marketplace/redhat-marketplace-r48s9" node="host-10-13-2-160" evaluatedNodes=6 feasibleNodes=3
2025-04-01T23:00:00.163603943Z I0401 23:00:00.163502       1 schedule_one.go:286] "Successfully bound pod to node" pod="openshift-operator-lifecycle-manager/collect-profiles-29059140-74q7v" node="host-10-13-2-1" evaluatedNodes=6 feasibleNodes=3
2025-04-01T23:04:53.903460086Z I0401 23:04:53.902804       1 schedule_one.go:286] "Successfully bound pod to node" pod="openshift-marketplace/certified-operators-9md97" node="host-10-13-2-160" evaluatedNodes=6 feasibleNodes=3
2025-04-01T23:04:57.312858062Z I0401 23:04:57.312806       1 schedule_one.go:286] "Successfully bound pod to node" pod="openshift-marketplace/community-operators-bvxpn" node="host-10-13-2-160" evaluatedNodes=6 feasibleNodes=3
2025-04-01T23:05:36.439003413Z I0401 23:05:36.438971       1 schedule_one.go:286] "Successfully bound pod to node" pod="openshift-marketplace/redhat-marketplace-5c8lb" node="host-10-13-2-89" evaluatedNodes=6 feasibleNodes=3
2025-04-01T23:05:37.825801205Z I0401 23:05:37.824422       1 schedule_one.go:286] "Successfully bound pod to node" pod="openshift-marketplace/redhat-operators-s8p4f" node="host-10-13-2-89" evaluatedNodes=6 feasibleNodes=3
2025-04-01T23:15:00.159317632Z I0401 23:15:00.159259       1 schedule_one.go:286] "Successfully bound pod to node" pod="openshift-operator-lifecycle-manager/collect-profiles-29059155-2wnlv" node="host-10-13-2-1" evaluatedNodes=6 feasibleNodes=3
2025-04-01T23:15:00.194154865Z I0401 23:15:00.192051       1 schedule_one.go:286] "Successfully bound pod to node" pod="openshift-marketplace/community-operators-rgxsf" node="host-10-13-2-89" evaluatedNodes=6 feasibleNodes=3
2025-04-01T23:15:17.974907640Z I0401 23:15:17.974801       1 schedule_one.go:286] "Successfully bound pod to node" pod="openshift-marketplace/certified-operators-4zsjr" node="host-10-13-2-160" evaluatedNodes=6 feasibleNodes=3
2025-04-01T23:15:39.716073444Z I0401 23:15:39.715290       1 schedule_one.go:286] "Successfully bound pod to node" pod="openshift-marketplace/redhat-marketplace-phqxp" node="host-10-13-2-89" evaluatedNodes=6 feasibleNodes=3
2025-04-01T23:17:12.619420851Z I0401 23:17:12.619066       1 schedule_one.go:286] "Successfully bound pod to node" pod="openshift-marketplace/redhat-operators-xzrzs" node="host-10-13-2-89" evaluatedNodes=6 feasibleNodes=3
2025-04-01T23:27:21.838731025Z I0401 23:27:21.838658       1 schedule_one.go:286] "Successfully bound pod to node" pod="openshift-marketplace/redhat-marketplace-ps84v" node="host-10-13-2-89" evaluatedNodes=6 feasibleNodes=3
2025-04-01T23:27:21.838775434Z I0401 23:27:21.838727       1 schedule_one.go:286] "Successfully bound pod to node" pod="openshift-marketplace/certified-operators-j9rb4" node="host-10-13-2-89" evaluatedNodes=6 feasibleNodes=3
2025-04-01T23:27:22.807784455Z I0401 23:27:22.807574       1 schedule_one.go:286] "Successfully bound pod to node" pod="openshift-marketplace/community-operators-m8xb5" node="host-10-13-2-160" evaluatedNodes=6 feasibleNodes=3
2025-04-01T23:27:23.011636570Z I0401 23:27:23.010585       1 schedule_one.go:286] "Successfully bound pod to node" pod="openshift-marketplace/redhat-operators-6nvv8" node="host-10-13-2-89" evaluatedNodes=6 feasibleNodes=3
2025-04-01T23:30:00.166141443Z I0401 23:30:00.166074       1 schedule_one.go:286] "Successfully bound pod to node" pod="openshift-operator-lifecycle-manager/collect-profiles-29059170-zhhbl" node="host-10-13-2-1" evaluatedNodes=6 feasibleNodes=3
2025-04-01T23:38:04.632470278Z I0401 23:38:04.631462       1 schedule_one.go:286] "Successfully bound pod to node" pod="openshift-marketplace/redhat-operators-tsm7w" node="host-10-13-2-89" evaluatedNodes=6 feasibleNodes=3
2025-04-01T23:38:17.143894899Z I0401 23:38:17.143782       1 schedule_one.go:286] "Successfully bound pod to node" pod="openshift-marketplace/community-operators-f5tbz" node="host-10-13-2-89" evaluatedNodes=6 feasibleNodes=3
2025-04-01T23:38:39.116532214Z I0401 23:38:39.114215       1 schedule_one.go:286] "Successfully bound pod to node" pod="openshift-marketplace/redhat-marketplace-jm57w" node="host-10-13-2-160" evaluatedNodes=6 feasibleNodes=3
2025-04-01T23:41:52.327427977Z I0401 23:41:52.327366       1 schedule_one.go:286] "Successfully bound pod to node" pod="openshift-marketplace/certified-operators-bvvcj" node="host-10-13-2-160" evaluatedNodes=6 feasibleNodes=3
2025-04-01T23:45:00.226455718Z I0401 23:45:00.226384       1 schedule_one.go:286] "Successfully bound pod to node" pod="openshift-operator-lifecycle-manager/collect-profiles-29059185-b647v" node="host-10-13-2-1" evaluatedNodes=6 feasibleNodes=3
2025-04-01T23:49:57.010086962Z I0401 23:49:57.010016       1 schedule_one.go:286] "Successfully bound pod to node" pod="openshift-marketplace/redhat-marketplace-5jkpj" node="host-10-13-2-160" evaluatedNodes=6 feasibleNodes=3
2025-04-01T23:52:10.641473911Z I0401 23:52:10.641066       1 schedule_one.go:286] "Successfully bound pod to node" pod="openshift-marketplace/certified-operators-7nrdm" node="host-10-13-2-160" evaluatedNodes=6 feasibleNodes=3
2025-04-01T23:53:57.626370576Z I0401 23:53:57.626233       1 schedule_one.go:286] "Successfully bound pod to node" pod="openshift-marketplace/community-operators-sz445" node="host-10-13-2-160" evaluatedNodes=6 feasibleNodes=3
2025-04-01T23:53:59.018325424Z I0401 23:53:59.017567       1 schedule_one.go:286] "Successfully bound pod to node" pod="openshift-marketplace/redhat-operators-q9hm9" node="host-10-13-2-160" evaluatedNodes=6 feasibleNodes=3
2025-04-02T00:00:00.162055683Z I0402 00:00:00.162002       1 schedule_one.go:286] "Successfully bound pod to node" pod="openshift-operator-lifecycle-manager/collect-profiles-29059200-p472m" node="host-10-13-2-1" evaluatedNodes=6 feasibleNodes=3
2025-04-02T00:00:00.165334082Z I0402 00:00:00.163427       1 schedule_one.go:286] "Successfully bound pod to node" pod="openshift-image-registry/image-pruner-29059200-ttgl8" node="host-10-13-2-1" evaluatedNodes=6 feasibleNodes=3
2025-04-02T00:02:23.162111387Z I0402 00:02:23.160550       1 schedule_one.go:286] "Successfully bound pod to node" pod="openshift-marketplace/certified-operators-g7989" node="host-10-13-2-160" evaluatedNodes=6 feasibleNodes=3
2025-04-02T00:03:04.520973528Z I0402 00:03:04.519969       1 schedule_one.go:286] "Successfully bound pod to node" pod="openshift-marketplace/redhat-marketplace-p6h9q" node="host-10-13-2-160" evaluatedNodes=6 feasibleNodes=3
2025-04-02T00:04:20.734934153Z I0402 00:04:20.733060       1 schedule_one.go:286] "Successfully bound pod to node" pod="openshift-marketplace/community-operators-kwclk" node="host-10-13-2-160" evaluatedNodes=6 feasibleNodes=3
2025-04-02T00:06:03.915078299Z I0402 00:06:03.915012       1 schedule_one.go:286] "Successfully bound pod to node" pod="openshift-marketplace/redhat-operators-b2tpx" node="host-10-13-2-89" evaluatedNodes=6 feasibleNodes=3
2025-04-02T00:14:46.731076604Z I0402 00:14:46.729101       1 schedule_one.go:286] "Successfully bound pod to node" pod="openshift-marketplace/community-operators-hxv4l" node="host-10-13-2-89" evaluatedNodes=6 feasibleNodes=3
2025-04-02T00:15:00.153105469Z I0402 00:15:00.152107       1 schedule_one.go:286] "Successfully bound pod to node" pod="openshift-operator-lifecycle-manager/collect-profiles-29059215-jrl44" node="host-10-13-2-1" evaluatedNodes=6 feasibleNodes=3
2025-04-02T00:17:20.492568938Z I0402 00:17:20.492272       1 schedule_one.go:286] "Successfully bound pod to node" pod="openshift-marketplace/redhat-operators-8ck62" node="host-10-13-2-89" evaluatedNodes=6 feasibleNodes=3
2025-04-02T00:18:08.222311687Z I0402 00:18:08.222255       1 schedule_one.go:286] "Successfully bound pod to node" pod="openshift-marketplace/certified-operators-4xbnj" node="host-10-13-2-160" evaluatedNodes=6 feasibleNodes=3
2025-04-02T00:18:08.417285490Z I0402 00:18:08.417230       1 schedule_one.go:286] "Successfully bound pod to node" pod="openshift-marketplace/redhat-marketplace-n8bgs" node="host-10-13-2-89" evaluatedNodes=6 feasibleNodes=3
2025-04-02T00:26:28.139908636Z I0402 00:26:28.139725       1 schedule_one.go:286] "Successfully bound pod to node" pod="openshift-marketplace/community-operators-xcmcq" node="host-10-13-2-160" evaluatedNodes=6 feasibleNodes=3
2025-04-02T00:27:27.384154236Z I0402 00:27:27.383932       1 schedule_one.go:286] "Successfully bound pod to node" pod="openshift-marketplace/redhat-operators-klrz9" node="host-10-13-2-160" evaluatedNodes=6 feasibleNodes=3
2025-04-02T00:28:17.657718399Z I0402 00:28:17.657051       1 schedule_one.go:286] "Successfully bound pod to node" pod="openshift-marketplace/certified-operators-557rm" node="host-10-13-2-160" evaluatedNodes=6 feasibleNodes=3
2025-04-02T00:28:33.086551728Z I0402 00:28:33.086448       1 schedule_one.go:286] "Successfully bound pod to node" pod="openshift-marketplace/redhat-marketplace-9gxmf" node="host-10-13-2-160" evaluatedNodes=6 feasibleNodes=3
2025-04-02T00:30:00.158223869Z I0402 00:30:00.157954       1 schedule_one.go:286] "Successfully bound pod to node" pod="openshift-operator-lifecycle-manager/collect-profiles-29059230-sft2x" node="host-10-13-2-1" evaluatedNodes=6 feasibleNodes=3
2025-04-02T00:37:27.758906945Z I0402 00:37:27.755930       1 schedule_one.go:286] "Successfully bound pod to node" pod="openshift-marketplace/community-operators-j5kxq" node="host-10-13-2-160" evaluatedNodes=6 feasibleNodes=3
2025-04-02T00:37:29.104627438Z I0402 00:37:29.104557       1 schedule_one.go:286] "Successfully bound pod to node" pod="openshift-marketplace/redhat-operators-4ws57" node="host-10-13-2-89" evaluatedNodes=6 feasibleNodes=3
2025-04-02T00:38:46.043169384Z I0402 00:38:46.042812       1 schedule_one.go:286] "Successfully bound pod to node" pod="openshift-marketplace/certified-operators-lqnk6" node="host-10-13-2-160" evaluatedNodes=6 feasibleNodes=3
2025-04-02T00:38:47.427342843Z I0402 00:38:47.427291       1 schedule_one.go:286] "Successfully bound pod to node" pod="openshift-marketplace/redhat-marketplace-jlkjf" node="host-10-13-2-89" evaluatedNodes=6 feasibleNodes=3
2025-04-02T00:45:00.205550295Z I0402 00:45:00.205431       1 schedule_one.go:286] "Successfully bound pod to node" pod="openshift-operator-lifecycle-manager/collect-profiles-29059245-pz5s2" node="host-10-13-2-1" evaluatedNodes=6 feasibleNodes=3
2025-04-02T00:47:37.762125958Z I0402 00:47:37.761782       1 schedule_one.go:286] "Successfully bound pod to node" pod="openshift-marketplace/community-operators-qzx77" node="host-10-13-2-160" evaluatedNodes=6 feasibleNodes=3
2025-04-02T00:48:14.405611292Z I0402 00:48:14.405577       1 schedule_one.go:286] "Successfully bound pod to node" pod="openshift-marketplace/redhat-operators-74xln" node="host-10-13-2-160" evaluatedNodes=6 feasibleNodes=3
2025-04-02T00:50:29.135640693Z I0402 00:50:29.135599       1 schedule_one.go:286] "Successfully bound pod to node" pod="openshift-marketplace/certified-operators-78znp" node="host-10-13-2-160" evaluatedNodes=6 feasibleNodes=3
2025-04-02T00:50:29.316682420Z I0402 00:50:29.315017       1 schedule_one.go:286] "Successfully bound pod to node" pod="openshift-marketplace/redhat-marketplace-xc2hx" node="host-10-13-2-89" evaluatedNodes=6 feasibleNodes=3
2025-04-02T00:59:36.995558732Z I0402 00:59:36.995505       1 schedule_one.go:286] "Successfully bound pod to node" pod="openshift-marketplace/redhat-operators-bjwms" node="host-10-13-2-160" evaluatedNodes=6 feasibleNodes=3
2025-04-02T01:00:00.139989334Z I0402 01:00:00.138836       1 schedule_one.go:286] "Successfully bound pod to node" pod="openshift-operator-lifecycle-manager/collect-profiles-29059260-9z45j" node="host-10-13-2-1" evaluatedNodes=6 feasibleNodes=3
2025-04-02T01:01:25.651445149Z I0402 01:01:25.651387       1 schedule_one.go:286] "Successfully bound pod to node" pod="openshift-marketplace/certified-operators-6fksj" node="host-10-13-2-160" evaluatedNodes=6 feasibleNodes=3
2025-04-02T01:03:30.539089826Z I0402 01:03:30.537663       1 schedule_one.go:286] "Successfully bound pod to node" pod="openshift-marketplace/redhat-marketplace-n9j7h" node="host-10-13-2-89" evaluatedNodes=6 feasibleNodes=3
2025-04-02T01:03:30.543260978Z I0402 01:03:30.543196       1 schedule_one.go:286] "Successfully bound pod to node" pod="openshift-marketplace/community-operators-46htc" node="host-10-13-2-160" evaluatedNodes=6 feasibleNodes=3
2025-04-02T01:09:42.073417196Z I0402 01:09:42.071223       1 schedule_one.go:286] "Successfully bound pod to node" pod="openshift-marketplace/redhat-operators-45c2w" node="host-10-13-2-160" evaluatedNodes=6 feasibleNodes=3
2025-04-02T01:12:37.777543167Z I0402 01:12:37.777438       1 schedule_one.go:286] "Successfully bound pod to node" pod="openshift-marketplace/certified-operators-v5wht" node="host-10-13-2-160" evaluatedNodes=6 feasibleNodes=3
2025-04-02T01:14:02.143388337Z I0402 01:14:02.143013       1 schedule_one.go:286] "Successfully bound pod to node" pod="openshift-marketplace/community-operators-tzj82" node="host-10-13-2-160" evaluatedNodes=6 feasibleNodes=3
2025-04-02T01:14:28.740550329Z I0402 01:14:28.734729       1 schedule_one.go:286] "Successfully bound pod to node" pod="openshift-marketplace/redhat-marketplace-rmcnx" node="host-10-13-2-160" evaluatedNodes=6 feasibleNodes=3
2025-04-02T01:15:00.170898601Z I0402 01:15:00.168114       1 schedule_one.go:286] "Successfully bound pod to node" pod="openshift-operator-lifecycle-manager/collect-profiles-29059275-gzfbx" node="host-10-13-2-1" evaluatedNodes=6 feasibleNodes=3
2025-04-02T01:20:01.255481704Z I0402 01:20:01.254343       1 schedule_one.go:286] "Successfully bound pod to node" pod="openshift-marketplace/redhat-operators-ctghf" node="host-10-13-2-160" evaluatedNodes=6 feasibleNodes=3
2025-04-02T01:23:19.339567732Z I0402 01:23:19.339067       1 schedule_one.go:286] "Successfully bound pod to node" pod="openshift-marketplace/certified-operators-9fpjz" node="host-10-13-2-160" evaluatedNodes=6 feasibleNodes=3
2025-04-02T01:24:29.026945869Z I0402 01:24:29.026724       1 schedule_one.go:286] "Successfully bound pod to node" pod="openshift-marketplace/community-operators-frfrg" node="host-10-13-2-160" evaluatedNodes=6 feasibleNodes=3
2025-04-02T01:24:31.046214108Z I0402 01:24:31.046114       1 schedule_one.go:286] "Successfully bound pod to node" pod="openshift-marketplace/redhat-marketplace-w75b8" node="host-10-13-2-89" evaluatedNodes=6 feasibleNodes=3
2025-04-02T01:30:00.165838695Z I0402 01:30:00.165747       1 schedule_one.go:286] "Successfully bound pod to node" pod="openshift-operator-lifecycle-manager/collect-profiles-29059290-gj4s9" node="host-10-13-2-1" evaluatedNodes=6 feasibleNodes=3
2025-04-02T01:30:40.592067858Z I0402 01:30:40.592024       1 schedule_one.go:286] "Successfully bound pod to node" pod="openshift-marketplace/redhat-operators-xrd9q" node="host-10-13-2-160" evaluatedNodes=6 feasibleNodes=3
2025-04-02T01:34:51.152921980Z I0402 01:34:51.151720       1 schedule_one.go:286] "Successfully bound pod to node" pod="openshift-marketplace/community-operators-rrjzp" node="host-10-13-2-160" evaluatedNodes=6 feasibleNodes=3
2025-04-02T01:35:57.921076122Z I0402 01:35:57.916533       1 schedule_one.go:286] "Successfully bound pod to node" pod="openshift-marketplace/redhat-marketplace-bhz48" node="host-10-13-2-160" evaluatedNodes=6 feasibleNodes=3
2025-04-02T01:42:34.770976074Z I0402 01:42:34.770792       1 schedule_one.go:286] "Successfully bound pod to node" pod="openshift-marketplace/certified-operators-nwq6w" node="host-10-13-2-160" evaluatedNodes=6 feasibleNodes=3
2025-04-02T01:42:36.143072322Z I0402 01:42:36.142760       1 schedule_one.go:286] "Successfully bound pod to node" pod="openshift-marketplace/redhat-operators-7f4v4" node="host-10-13-2-89" evaluatedNodes=6 feasibleNodes=3
2025-04-02T01:45:00.238197562Z I0402 01:45:00.237982       1 schedule_one.go:286] "Successfully bound pod to node" pod="openshift-operator-lifecycle-manager/collect-profiles-29059305-xf6d8" node="host-10-13-2-1" evaluatedNodes=6 feasibleNodes=3
2025-04-02T01:47:10.017662738Z I0402 01:47:10.016493       1 schedule_one.go:286] "Successfully bound pod to node" pod="openshift-marketplace/redhat-marketplace-b8pfg" node="host-10-13-2-160" evaluatedNodes=6 feasibleNodes=3
2025-04-02T01:50:10.851267217Z I0402 01:50:10.846955       1 schedule_one.go:286] "Successfully bound pod to node" pod="openshift-marketplace/community-operators-xfkx5" node="host-10-13-2-160" evaluatedNodes=6 feasibleNodes=3
2025-04-02T01:53:17.598257381Z I0402 01:53:17.596463       1 schedule_one.go:286] "Successfully bound pod to node" pod="openshift-marketplace/redhat-operators-84rh2" node="host-10-13-2-160" evaluatedNodes=6 feasibleNodes=3
2025-04-02T01:53:53.478530418Z I0402 01:53:53.478174       1 schedule_one.go:286] "Successfully bound pod to node" pod="openshift-marketplace/certified-operators-krvlg" node="host-10-13-2-160" evaluatedNodes=6 feasibleNodes=3
2025-04-02T02:00:00.150046574Z I0402 02:00:00.149360       1 schedule_one.go:286] "Successfully bound pod to node" pod="openshift-operator-lifecycle-manager/collect-profiles-29059320-5mxlv" node="host-10-13-2-1" evaluatedNodes=6 feasibleNodes=3
2025-04-02T02:01:27.789274813Z I0402 02:01:27.789237       1 schedule_one.go:286] "Successfully bound pod to node" pod="openshift-marketplace/community-operators-sj96c" node="host-10-13-2-160" evaluatedNodes=6 feasibleNodes=3
2025-04-02T02:03:31.867266465Z I0402 02:03:31.866403       1 schedule_one.go:286] "Successfully bound pod to node" pod="openshift-marketplace/redhat-operators-t82k5" node="host-10-13-2-160" evaluatedNodes=6 feasibleNodes=3
2025-04-02T02:03:44.920597158Z I0402 02:03:44.918569       1 schedule_one.go:286] "Successfully bound pod to node" pod="openshift-marketplace/redhat-marketplace-hvx7t" node="host-10-13-2-89" evaluatedNodes=6 feasibleNodes=3
2025-04-02T02:04:00.094723566Z I0402 02:04:00.094515       1 schedule_one.go:286] "Successfully bound pod to node" pod="openshift-marketplace/certified-operators-ghrzp" node="host-10-13-2-160" evaluatedNodes=6 feasibleNodes=3
2025-04-02T02:12:00.363833890Z I0402 02:12:00.363776       1 schedule_one.go:286] "Successfully bound pod to node" pod="openshift-marketplace/community-operators-cn8s2" node="host-10-13-2-160" evaluatedNodes=6 feasibleNodes=3
2025-04-02T02:14:53.712710039Z I0402 02:14:53.712664       1 schedule_one.go:286] "Successfully bound pod to node" pod="openshift-marketplace/redhat-marketplace-b2zvq" node="host-10-13-2-160" evaluatedNodes=6 feasibleNodes=3
2025-04-02T02:15:00.161939189Z I0402 02:15:00.161130       1 schedule_one.go:286] "Successfully bound pod to node" pod="openshift-operator-lifecycle-manager/collect-profiles-29059335-sjbps" node="host-10-13-2-1" evaluatedNodes=6 feasibleNodes=3
2025-04-02T02:19:01.188356565Z I0402 02:19:01.186711       1 schedule_one.go:286] "Successfully bound pod to node" pod="openshift-marketplace/certified-operators-j5cxc" node="host-10-13-2-160" evaluatedNodes=6 feasibleNodes=3
2025-04-02T02:19:02.581770191Z I0402 02:19:02.581705       1 schedule_one.go:286] "Successfully bound pod to node" pod="openshift-marketplace/redhat-operators-949bz" node="host-10-13-2-89" evaluatedNodes=6 feasibleNodes=3
2025-04-02T02:22:22.640150465Z I0402 02:22:22.639938       1 schedule_one.go:286] "Successfully bound pod to node" pod="openshift-marketplace/community-operators-kqqsw" node="host-10-13-2-160" evaluatedNodes=6 feasibleNodes=3
2025-04-02T02:25:52.549516049Z I0402 02:25:52.549441       1 schedule_one.go:286] "Successfully bound pod to node" pod="openshift-marketplace/redhat-marketplace-xqpkg" node="host-10-13-2-160" evaluatedNodes=6 feasibleNodes=3
2025-04-02T02:30:00.163782701Z I0402 02:30:00.162549       1 schedule_one.go:286] "Successfully bound pod to node" pod="openshift-operator-lifecycle-manager/collect-profiles-29059350-w4nvp" node="host-10-13-2-1" evaluatedNodes=6 feasibleNodes=3
2025-04-02T02:31:07.079287387Z I0402 02:31:07.078587       1 schedule_one.go:286] "Successfully bound pod to node" pod="openshift-marketplace/redhat-operators-9f298" node="host-10-13-2-160" evaluatedNodes=6 feasibleNodes=3
2025-04-02T02:31:07.278755655Z I0402 02:31:07.278606       1 schedule_one.go:286] "Successfully bound pod to node" pod="openshift-marketplace/certified-operators-c8wh7" node="host-10-13-2-89" evaluatedNodes=6 feasibleNodes=3
2025-04-02T02:34:40.411777122Z I0402 02:34:40.411726       1 schedule_one.go:286] "Successfully bound pod to node" pod="openshift-marketplace/community-operators-hzs7z" node="host-10-13-2-160" evaluatedNodes=6 feasibleNodes=3
2025-04-02T02:35:57.005478900Z I0402 02:35:57.005265       1 schedule_one.go:286] "Successfully bound pod to node" pod="openshift-marketplace/redhat-marketplace-ntxjp" node="host-10-13-2-160" evaluatedNodes=6 feasibleNodes=3
2025-04-02T02:41:35.801381669Z I0402 02:41:35.801225       1 schedule_one.go:286] "Successfully bound pod to node" pod="openshift-marketplace/redhat-operators-sbjmx" node="host-10-13-2-160" evaluatedNodes=6 feasibleNodes=3
2025-04-02T02:42:11.300125327Z I0402 02:42:11.299507       1 schedule_one.go:286] "Successfully bound pod to node" pod="openshift-marketplace/certified-operators-l7sv7" node="host-10-13-2-160" evaluatedNodes=6 feasibleNodes=3
2025-04-02T02:45:00.212359196Z I0402 02:45:00.212227       1 schedule_one.go:286] "Successfully bound pod to node" pod="openshift-operator-lifecycle-manager/collect-profiles-29059365-ll5s7" node="host-10-13-2-1" evaluatedNodes=6 feasibleNodes=3
2025-04-02T02:45:52.885943888Z I0402 02:45:52.885049       1 schedule_one.go:286] "Successfully bound pod to node" pod="openshift-marketplace/community-operators-c8j82" node="host-10-13-2-160" evaluatedNodes=6 feasibleNodes=3
2025-04-02T02:46:40.838428245Z I0402 02:46:40.838372       1 schedule_one.go:286] "Successfully bound pod to node" pod="openshift-marketplace/redhat-marketplace-nc2kc" node="host-10-13-2-160" evaluatedNodes=6 feasibleNodes=3
2025-04-02T02:52:26.847926934Z I0402 02:52:26.847653       1 schedule_one.go:286] "Successfully bound pod to node" pod="openshift-marketplace/redhat-operators-fwccn" node="host-10-13-2-160" evaluatedNodes=6 feasibleNodes=3
2025-04-02T02:52:35.727115904Z I0402 02:52:35.726502       1 schedule_one.go:286] "Successfully bound pod to node" pod="openshift-marketplace/certified-operators-4dlkb" node="host-10-13-2-89" evaluatedNodes=6 feasibleNodes=3
2025-04-02T02:56:40.407925097Z I0402 02:56:40.407832       1 schedule_one.go:286] "Successfully bound pod to node" pod="openshift-marketplace/redhat-marketplace-wbj2t" node="host-10-13-2-160" evaluatedNodes=6 feasibleNodes=3
2025-04-02T03:00:00.156729092Z I0402 03:00:00.156622       1 schedule_one.go:286] "Successfully bound pod to node" pod="openshift-operator-lifecycle-manager/collect-profiles-29059380-vbwr7" node="host-10-13-2-1" evaluatedNodes=6 feasibleNodes=3
2025-04-02T03:00:43.233595092Z I0402 03:00:43.233557       1 schedule_one.go:286] "Successfully bound pod to node" pod="openshift-marketplace/community-operators-g5gkd" node="host-10-13-2-160" evaluatedNodes=6 feasibleNodes=3
2025-04-02T03:02:55.583951790Z I0402 03:02:55.582271       1 schedule_one.go:286] "Successfully bound pod to node" pod="openshift-marketplace/redhat-operators-4rttm" node="host-10-13-2-160" evaluatedNodes=6 feasibleNodes=3
2025-04-02T03:04:15.099818557Z I0402 03:04:15.099519       1 schedule_one.go:286] "Successfully bound pod to node" pod="openshift-marketplace/certified-operators-fpxbq" node="host-10-13-2-160" evaluatedNodes=6 feasibleNodes=3
2025-04-02T03:07:22.975505891Z I0402 03:07:22.974676       1 schedule_one.go:286] "Successfully bound pod to node" pod="openshift-marketplace/redhat-marketplace-4bxwp" node="host-10-13-2-160" evaluatedNodes=6 feasibleNodes=3
2025-04-02T03:13:44.648094383Z I0402 03:13:44.646526       1 schedule_one.go:286] "Successfully bound pod to node" pod="openshift-marketplace/community-operators-f5rvx" node="host-10-13-2-160" evaluatedNodes=6 feasibleNodes=3
2025-04-02T03:13:46.015360573Z I0402 03:13:46.014398       1 schedule_one.go:286] "Successfully bound pod to node" pod="openshift-marketplace/redhat-operators-xt8lr" node="host-10-13-2-89" evaluatedNodes=6 feasibleNodes=3
2025-04-02T03:15:00.160974303Z I0402 03:15:00.160832       1 schedule_one.go:286] "Successfully bound pod to node" pod="openshift-operator-lifecycle-manager/collect-profiles-29059395-g9s94" node="host-10-13-2-1" evaluatedNodes=6 feasibleNodes=3
2025-04-02T03:15:20.542104050Z I0402 03:15:20.540077       1 schedule_one.go:286] "Successfully bound pod to node" pod="openshift-marketplace/certified-operators-rqxcl" node="host-10-13-2-160" evaluatedNodes=6 feasibleNodes=3
2025-04-02T03:19:25.519885518Z I0402 03:19:25.518554       1 schedule_one.go:286] "Successfully bound pod to node" pod="openshift-marketplace/redhat-marketplace-2lrgq" node="host-10-13-2-160" evaluatedNodes=6 feasibleNodes=3
2025-04-02T03:24:13.918408589Z I0402 03:24:13.917223       1 schedule_one.go:286] "Successfully bound pod to node" pod="openshift-marketplace/redhat-operators-wb9dr" node="host-10-13-2-160" evaluatedNodes=6 feasibleNodes=3
2025-04-02T03:24:17.098277935Z I0402 03:24:17.098227       1 schedule_one.go:286] "Successfully bound pod to node" pod="openshift-marketplace/community-operators-wv9z6" node="host-10-13-2-89" evaluatedNodes=6 feasibleNodes=3
2025-04-02T03:26:46.038546456Z I0402 03:26:46.038500       1 schedule_one.go:286] "Successfully bound pod to node" pod="openshift-marketplace/certified-operators-hz5bv" node="host-10-13-2-160" evaluatedNodes=6 feasibleNodes=3
2025-04-02T03:30:00.157100954Z I0402 03:30:00.156961       1 schedule_one.go:286] "Successfully bound pod to node" pod="openshift-operator-lifecycle-manager/collect-profiles-29059410-xrw6f" node="host-10-13-2-1" evaluatedNodes=6 feasibleNodes=3
2025-04-02T03:30:36.278081804Z I0402 03:30:36.277438       1 schedule_one.go:286] "Successfully bound pod to node" pod="openshift-marketplace/redhat-marketplace-vbcj5" node="host-10-13-2-160" evaluatedNodes=6 feasibleNodes=3
2025-04-02T03:35:15.183258476Z I0402 03:35:15.183225       1 schedule_one.go:286] "Successfully bound pod to node" pod="openshift-marketplace/community-operators-lnn8n" node="host-10-13-2-160" evaluatedNodes=6 feasibleNodes=3
2025-04-02T03:35:22.624474128Z I0402 03:35:22.624146       1 schedule_one.go:286] "Successfully bound pod to node" pod="openshift-marketplace/redhat-operators-rzdt7" node="host-10-13-2-89" evaluatedNodes=6 feasibleNodes=3
2025-04-02T03:37:17.167792222Z I0402 03:37:17.167114       1 schedule_one.go:286] "Successfully bound pod to node" pod="openshift-marketplace/certified-operators-wtdgl" node="host-10-13-2-160" evaluatedNodes=6 feasibleNodes=3
2025-04-02T03:41:26.997095975Z I0402 03:41:26.997056       1 schedule_one.go:286] "Successfully bound pod to node" pod="openshift-marketplace/redhat-marketplace-lhdfg" node="host-10-13-2-160" evaluatedNodes=6 feasibleNodes=3
2025-04-02T03:45:00.212770813Z I0402 03:45:00.212734       1 schedule_one.go:286] "Successfully bound pod to node" pod="openshift-operator-lifecycle-manager/collect-profiles-29059425-nks2p" node="host-10-13-2-1" evaluatedNodes=6 feasibleNodes=3
2025-04-02T03:46:11.003118303Z I0402 03:46:11.002709       1 schedule_one.go:286] "Successfully bound pod to node" pod="openshift-marketplace/community-operators-vhvcn" node="host-10-13-2-160" evaluatedNodes=6 feasibleNodes=3
2025-04-02T03:46:51.940930147Z I0402 03:46:51.940831       1 schedule_one.go:286] "Successfully bound pod to node" pod="openshift-marketplace/redhat-operators-gxjwf" node="host-10-13-2-160" evaluatedNodes=6 feasibleNodes=3
2025-04-02T03:47:36.629093721Z I0402 03:47:36.628545       1 schedule_one.go:286] "Successfully bound pod to node" pod="openshift-marketplace/certified-operators-qgc5d" node="host-10-13-2-160" evaluatedNodes=6 feasibleNodes=3
2025-04-02T03:52:49.641716718Z I0402 03:52:49.641564       1 schedule_one.go:286] "Successfully bound pod to node" pod="openshift-marketplace/redhat-marketplace-x62df" node="host-10-13-2-160" evaluatedNodes=6 feasibleNodes=3
2025-04-02T03:58:19.746393497Z I0402 03:58:19.745798       1 schedule_one.go:286] "Successfully bound pod to node" pod="openshift-marketplace/redhat-operators-xvnsl" node="host-10-13-2-160" evaluatedNodes=6 feasibleNodes=3
2025-04-02T03:58:29.326286978Z I0402 03:58:29.325346       1 schedule_one.go:286] "Successfully bound pod to node" pod="openshift-marketplace/certified-operators-9ssrx" node="host-10-13-2-89" evaluatedNodes=6 feasibleNodes=3
2025-04-02T04:00:00.165133499Z I0402 04:00:00.165010       1 schedule_one.go:286] "Successfully bound pod to node" pod="openshift-operator-lifecycle-manager/collect-profiles-29059440-rl95t" node="host-10-13-2-1" evaluatedNodes=6 feasibleNodes=3
2025-04-02T04:03:16.138458668Z I0402 04:03:16.138295       1 schedule_one.go:286] "Successfully bound pod to node" pod="openshift-marketplace/redhat-marketplace-sksnq" node="host-10-13-2-89" evaluatedNodes=6 feasibleNodes=3
2025-04-02T04:03:46.382918617Z I0402 04:03:46.382835       1 schedule_one.go:286] "Successfully bound pod to node" pod="openshift-marketplace/community-operators-rjlt6" node="host-10-13-2-89" evaluatedNodes=6 feasibleNodes=3
2025-04-02T04:09:18.097734961Z I0402 04:09:18.096751       1 schedule_one.go:286] "Successfully bound pod to node" pod="openshift-marketplace/certified-operators-ngwsp" node="host-10-13-2-160" evaluatedNodes=6 feasibleNodes=3
2025-04-02T04:10:09.147002339Z I0402 04:10:09.144717       1 schedule_one.go:286] "Successfully bound pod to node" pod="openshift-marketplace/redhat-operators-kctmq" node="host-10-13-2-160" evaluatedNodes=6 feasibleNodes=3
2025-04-02T04:13:35.258978565Z I0402 04:13:35.258330       1 schedule_one.go:286] "Successfully bound pod to node" pod="openshift-marketplace/redhat-marketplace-kftk2" node="host-10-13-2-160" evaluatedNodes=6 feasibleNodes=3
2025-04-02T04:15:00.151573989Z I0402 04:15:00.151539       1 schedule_one.go:286] "Successfully bound pod to node" pod="openshift-operator-lifecycle-manager/collect-profiles-29059455-wrwvb" node="host-10-13-2-1" evaluatedNodes=6 feasibleNodes=3
2025-04-02T04:18:52.248436010Z I0402 04:18:52.247791       1 schedule_one.go:286] "Successfully bound pod to node" pod="openshift-marketplace/community-operators-wt6zl" node="host-10-13-2-160" evaluatedNodes=6 feasibleNodes=3
2025-04-02T04:19:54.176908097Z I0402 04:19:54.174613       1 schedule_one.go:286] "Successfully bound pod to node" pod="openshift-marketplace/certified-operators-k27xl" node="host-10-13-2-160" evaluatedNodes=6 feasibleNodes=3
2025-04-02T04:24:31.070731782Z I0402 04:24:31.070675       1 schedule_one.go:286] "Successfully bound pod to node" pod="openshift-marketplace/redhat-marketplace-xtxf5" node="host-10-13-2-160" evaluatedNodes=6 feasibleNodes=3
2025-04-02T04:24:32.061460583Z I0402 04:24:32.061409       1 schedule_one.go:286] "Successfully bound pod to node" pod="openshift-marketplace/redhat-operators-kmr76" node="host-10-13-2-160" evaluatedNodes=6 feasibleNodes=3
2025-04-02T04:30:00.156324162Z I0402 04:30:00.156244       1 schedule_one.go:286] "Successfully bound pod to node" pod="openshift-operator-lifecycle-manager/collect-profiles-29059470-58p7z" node="host-10-13-2-1" evaluatedNodes=6 feasibleNodes=3
2025-04-02T04:30:08.621687635Z I0402 04:30:08.621615       1 schedule_one.go:286] "Successfully bound pod to node" pod="openshift-marketplace/certified-operators-t8tn5" node="host-10-13-2-160" evaluatedNodes=6 feasibleNodes=3
2025-04-02T04:30:49.749359349Z I0402 04:30:49.747109       1 schedule_one.go:286] "Successfully bound pod to node" pod="openshift-marketplace/community-operators-hcfm5" node="host-10-13-2-160" evaluatedNodes=6 feasibleNodes=3
2025-04-02T04:34:48.103498169Z I0402 04:34:48.103430       1 schedule_one.go:286] "Successfully bound pod to node" pod="openshift-marketplace/redhat-marketplace-8fgj7" node="host-10-13-2-160" evaluatedNodes=6 feasibleNodes=3
2025-04-02T04:34:55.572157170Z I0402 04:34:55.571472       1 schedule_one.go:286] "Successfully bound pod to node" pod="openshift-marketplace/redhat-operators-9fg2z" node="host-10-13-2-89" evaluatedNodes=6 feasibleNodes=3
2025-04-02T04:40:17.440028862Z I0402 04:40:17.439906       1 schedule_one.go:286] "Successfully bound pod to node" pod="openshift-marketplace/certified-operators-sl5xj" node="host-10-13-2-160" evaluatedNodes=6 feasibleNodes=3
2025-04-02T04:41:28.475820090Z I0402 04:41:28.475762       1 schedule_one.go:286] "Successfully bound pod to node" pod="openshift-marketplace/community-operators-4hdhk" node="host-10-13-2-160" evaluatedNodes=6 feasibleNodes=3
2025-04-02T04:44:55.081243737Z I0402 04:44:55.081193       1 schedule_one.go:286] "Successfully bound pod to node" pod="openshift-marketplace/redhat-marketplace-xphzt" node="host-10-13-2-160" evaluatedNodes=6 feasibleNodes=3
2025-04-02T04:45:00.222038557Z I0402 04:45:00.221997       1 schedule_one.go:286] "Successfully bound pod to node" pod="openshift-operator-lifecycle-manager/collect-profiles-29059485-9jkwx" node="host-10-13-2-1" evaluatedNodes=6 feasibleNodes=3
2025-04-02T04:45:18.812664162Z I0402 04:45:18.812416       1 schedule_one.go:286] "Successfully bound pod to node" pod="openshift-marketplace/redhat-operators-rdqt7" node="host-10-13-2-160" evaluatedNodes=6 feasibleNodes=3
2025-04-02T04:50:20.868860307Z I0402 04:50:20.868585       1 schedule_one.go:286] "Successfully bound pod to node" pod="openshift-marketplace/certified-operators-4g9mg" node="host-10-13-2-160" evaluatedNodes=6 feasibleNodes=3
2025-04-02T04:52:43.840054832Z I0402 04:52:43.839368       1 schedule_one.go:286] "Successfully bound pod to node" pod="openshift-marketplace/community-operators-rs5wb" node="host-10-13-2-160" evaluatedNodes=6 feasibleNodes=3
2025-04-02T04:55:50.809713437Z I0402 04:55:50.809332       1 schedule_one.go:286] "Successfully bound pod to node" pod="openshift-marketplace/redhat-operators-2bfqv" node="host-10-13-2-160" evaluatedNodes=6 feasibleNodes=3
2025-04-02T04:55:54.586938035Z I0402 04:55:54.584800       1 schedule_one.go:286] "Successfully bound pod to node" pod="openshift-marketplace/redhat-marketplace-pt9tg" node="host-10-13-2-160" evaluatedNodes=6 feasibleNodes=3
2025-04-02T05:00:00.164454505Z I0402 05:00:00.164155       1 schedule_one.go:286] "Successfully bound pod to node" pod="openshift-operator-lifecycle-manager/collect-profiles-29059500-b2v2v" node="host-10-13-2-1" evaluatedNodes=6 feasibleNodes=3
2025-04-02T05:01:16.010298565Z I0402 05:01:16.006182       1 schedule_one.go:286] "Successfully bound pod to node" pod="openshift-marketplace/certified-operators-sp4zr" node="host-10-13-2-160" evaluatedNodes=6 feasibleNodes=3
2025-04-02T05:03:51.941329196Z I0402 05:03:51.938192       1 schedule_one.go:286] "Successfully bound pod to node" pod="openshift-marketplace/community-operators-tzcx4" node="host-10-13-2-160" evaluatedNodes=6 feasibleNodes=3
2025-04-02T05:06:31.851347430Z I0402 05:06:31.851306       1 schedule_one.go:286] "Successfully bound pod to node" pod="openshift-marketplace/redhat-marketplace-dz5n5" node="host-10-13-2-89" evaluatedNodes=6 feasibleNodes=3
2025-04-02T05:06:32.221603298Z I0402 05:06:32.221415       1 schedule_one.go:286] "Successfully bound pod to node" pod="openshift-marketplace/redhat-operators-7mrbx" node="host-10-13-2-89" evaluatedNodes=6 feasibleNodes=3
2025-04-02T05:12:18.663455322Z I0402 05:12:18.662834       1 schedule_one.go:286] "Successfully bound pod to node" pod="openshift-marketplace/certified-operators-w77b8" node="host-10-13-2-89" evaluatedNodes=6 feasibleNodes=3
2025-04-02T05:15:00.165531080Z I0402 05:15:00.165481       1 schedule_one.go:286] "Successfully bound pod to node" pod="openshift-operator-lifecycle-manager/collect-profiles-29059515-r58br" node="host-10-13-2-1" evaluatedNodes=6 feasibleNodes=3
2025-04-02T05:17:19.543570716Z I0402 05:17:19.543520       1 schedule_one.go:286] "Successfully bound pod to node" pod="openshift-marketplace/redhat-operators-gcpll" node="host-10-13-2-89" evaluatedNodes=6 feasibleNodes=3
2025-04-02T05:20:20.653376307Z I0402 05:20:20.653302       1 schedule_one.go:286] "Successfully bound pod to node" pod="openshift-marketplace/community-operators-9hh27" node="host-10-13-2-160" evaluatedNodes=6 feasibleNodes=3
2025-04-02T05:20:20.655115054Z I0402 05:20:20.655076       1 schedule_one.go:286] "Successfully bound pod to node" pod="openshift-marketplace/redhat-marketplace-qjptd" node="host-10-13-2-89" evaluatedNodes=6 feasibleNodes=3
2025-04-02T05:23:16.726918491Z I0402 05:23:16.726835       1 schedule_one.go:286] "Successfully bound pod to node" pod="openshift-marketplace/certified-operators-q88dl" node="host-10-13-2-89" evaluatedNodes=6 feasibleNodes=3
2025-04-02T05:30:00.165756148Z I0402 05:30:00.165222       1 schedule_one.go:286] "Successfully bound pod to node" pod="openshift-operator-lifecycle-manager/collect-profiles-29059530-gj7l6" node="host-10-13-2-1" evaluatedNodes=6 feasibleNodes=3
2025-04-02T05:31:36.206816181Z I0402 05:31:36.206453       1 schedule_one.go:286] "Successfully bound pod to node" pod="openshift-marketplace/community-operators-7rdcz" node="host-10-13-2-89" evaluatedNodes=6 feasibleNodes=3
2025-04-02T05:32:26.542863021Z I0402 05:32:26.542803       1 schedule_one.go:286] "Successfully bound pod to node" pod="openshift-marketplace/redhat-marketplace-c8l8k" node="host-10-13-2-89" evaluatedNodes=6 feasibleNodes=3
2025-04-02T05:32:26.733824113Z I0402 05:32:26.733514       1 schedule_one.go:286] "Successfully bound pod to node" pod="openshift-marketplace/redhat-operators-55gbl" node="host-10-13-2-89" evaluatedNodes=6 feasibleNodes=3
2025-04-02T05:33:24.352156020Z I0402 05:33:24.351607       1 schedule_one.go:286] "Successfully bound pod to node" pod="openshift-marketplace/certified-operators-bcj4d" node="host-10-13-2-89" evaluatedNodes=6 feasibleNodes=3
2025-04-02T05:42:14.548318712Z I0402 05:42:14.547912       1 schedule_one.go:286] "Successfully bound pod to node" pod="openshift-marketplace/community-operators-c6w4t" node="host-10-13-2-89" evaluatedNodes=6 feasibleNodes=3
2025-04-02T05:42:29.798735346Z I0402 05:42:29.798621       1 schedule_one.go:286] "Successfully bound pod to node" pod="openshift-marketplace/redhat-operators-wtqhl" node="host-10-13-2-89" evaluatedNodes=6 feasibleNodes=3
2025-04-02T05:43:20.494296291Z I0402 05:43:20.494142       1 schedule_one.go:286] "Successfully bound pod to node" pod="openshift-marketplace/redhat-marketplace-qbst9" node="host-10-13-2-89" evaluatedNodes=6 feasibleNodes=3
2025-04-02T05:44:25.066696663Z I0402 05:44:25.065231       1 schedule_one.go:286] "Successfully bound pod to node" pod="openshift-marketplace/certified-operators-z9w47" node="host-10-13-2-89" evaluatedNodes=6 feasibleNodes=3
2025-04-02T05:45:00.224473927Z I0402 05:45:00.224146       1 schedule_one.go:286] "Successfully bound pod to node" pod="openshift-operator-lifecycle-manager/collect-profiles-29059545-dxr6s" node="host-10-13-2-1" evaluatedNodes=6 feasibleNodes=3
2025-04-02T05:52:44.460646150Z I0402 05:52:44.460590       1 schedule_one.go:286] "Successfully bound pod to node" pod="openshift-marketplace/redhat-operators-bhwq5" node="host-10-13-2-89" evaluatedNodes=6 feasibleNodes=3
2025-04-02T05:53:39.203276016Z I0402 05:53:39.203093       1 schedule_one.go:286] "Successfully bound pod to node" pod="openshift-marketplace/redhat-marketplace-d4z6v" node="host-10-13-2-89" evaluatedNodes=6 feasibleNodes=3
2025-04-02T05:54:28.484129673Z I0402 05:54:28.484038       1 schedule_one.go:286] "Successfully bound pod to node" pod="openshift-marketplace/certified-operators-c24qs" node="host-10-13-2-89" evaluatedNodes=6 feasibleNodes=3
2025-04-02T05:54:30.471652908Z I0402 05:54:30.470484       1 schedule_one.go:286] "Successfully bound pod to node" pod="openshift-marketplace/community-operators-dh6j7" node="host-10-13-2-160" evaluatedNodes=6 feasibleNodes=3
2025-04-02T06:00:00.157346521Z I0402 06:00:00.157040       1 schedule_one.go:286] "Successfully bound pod to node" pod="openshift-operator-lifecycle-manager/collect-profiles-29059560-x5xr5" node="host-10-13-2-1" evaluatedNodes=6 feasibleNodes=3
2025-04-02T06:03:03.736847755Z I0402 06:03:03.736780       1 schedule_one.go:286] "Successfully bound pod to node" pod="openshift-marketplace/redhat-operators-nqw8q" node="host-10-13-2-89" evaluatedNodes=6 feasibleNodes=3
2025-04-02T06:03:53.040515499Z I0402 06:03:53.040411       1 schedule_one.go:286] "Successfully bound pod to node" pod="openshift-marketplace/redhat-marketplace-w56xv" node="host-10-13-2-89" evaluatedNodes=6 feasibleNodes=3
2025-04-02T06:05:56.314526427Z I0402 06:05:56.314147       1 schedule_one.go:286] "Successfully bound pod to node" pod="openshift-marketplace/community-operators-8pbv6" node="host-10-13-2-89" evaluatedNodes=6 feasibleNodes=3
2025-04-02T06:08:41.845729104Z I0402 06:08:41.843501       1 schedule_one.go:286] "Successfully bound pod to node" pod="openshift-marketplace/certified-operators-mv4pf" node="host-10-13-2-89" evaluatedNodes=6 feasibleNodes=3
2025-04-02T06:14:00.338808667Z I0402 06:14:00.336467       1 schedule_one.go:286] "Successfully bound pod to node" pod="openshift-marketplace/redhat-operators-mrjp9" node="host-10-13-2-89" evaluatedNodes=6 feasibleNodes=3
2025-04-02T06:15:00.153183867Z I0402 06:15:00.153122       1 schedule_one.go:286] "Successfully bound pod to node" pod="openshift-operator-lifecycle-manager/collect-profiles-29059575-7m8sc" node="host-10-13-2-1" evaluatedNodes=6 feasibleNodes=3
2025-04-02T06:16:04.376311958Z I0402 06:16:04.373528       1 schedule_one.go:286] "Successfully bound pod to node" pod="openshift-marketplace/community-operators-9lb96" node="host-10-13-2-89" evaluatedNodes=6 feasibleNodes=3
2025-04-02T06:16:04.530191323Z I0402 06:16:04.529970       1 schedule_one.go:286] "Successfully bound pod to node" pod="openshift-marketplace/redhat-marketplace-r4msv" node="host-10-13-2-160" evaluatedNodes=6 feasibleNodes=3
2025-04-02T06:18:44.550022337Z I0402 06:18:44.549837       1 schedule_one.go:286] "Successfully bound pod to node" pod="openshift-marketplace/certified-operators-w77tp" node="host-10-13-2-89" evaluatedNodes=6 feasibleNodes=3
2025-04-02T06:24:32.081200639Z I0402 06:24:32.080154       1 schedule_one.go:286] "Successfully bound pod to node" pod="openshift-marketplace/redhat-operators-fqmxz" node="host-10-13-2-89" evaluatedNodes=6 feasibleNodes=3
2025-04-02T06:29:05.756446822Z I0402 06:29:05.755592       1 schedule_one.go:286] "Successfully bound pod to node" pod="openshift-marketplace/community-operators-ldz2n" node="host-10-13-2-89" evaluatedNodes=6 feasibleNodes=3
2025-04-02T06:29:05.774955015Z I0402 06:29:05.773165       1 schedule_one.go:286] "Successfully bound pod to node" pod="openshift-marketplace/certified-operators-74llq" node="host-10-13-2-160" evaluatedNodes=6 feasibleNodes=3
2025-04-02T06:29:06.742858736Z I0402 06:29:06.741711       1 schedule_one.go:286] "Successfully bound pod to node" pod="openshift-marketplace/redhat-marketplace-mw9r7" node="host-10-13-2-89" evaluatedNodes=6 feasibleNodes=3
2025-04-02T06:30:00.162833955Z I0402 06:30:00.162093       1 schedule_one.go:286] "Successfully bound pod to node" pod="openshift-operator-lifecycle-manager/collect-profiles-29059590-tjfz6" node="host-10-13-2-1" evaluatedNodes=6 feasibleNodes=3
2025-04-02T06:35:47.122724900Z I0402 06:35:47.122673       1 schedule_one.go:286] "Successfully bound pod to node" pod="openshift-marketplace/redhat-operators-k4k5p" node="host-10-13-2-89" evaluatedNodes=6 feasibleNodes=3
2025-04-02T06:39:11.379601847Z I0402 06:39:11.379542       1 schedule_one.go:286] "Successfully bound pod to node" pod="openshift-marketplace/redhat-marketplace-cvpkq" node="host-10-13-2-89" evaluatedNodes=6 feasibleNodes=3
2025-04-02T06:39:32.890041418Z I0402 06:39:32.889998       1 schedule_one.go:286] "Successfully bound pod to node" pod="openshift-marketplace/community-operators-bxhj7" node="host-10-13-2-89" evaluatedNodes=6 feasibleNodes=3
2025-04-02T06:40:28.715200285Z I0402 06:40:28.714905       1 schedule_one.go:286] "Successfully bound pod to node" pod="openshift-marketplace/certified-operators-hw79d" node="host-10-13-2-89" evaluatedNodes=6 feasibleNodes=3
2025-04-02T06:45:00.231400438Z I0402 06:45:00.231325       1 schedule_one.go:286] "Successfully bound pod to node" pod="openshift-operator-lifecycle-manager/collect-profiles-29059605-75kw2" node="host-10-13-2-1" evaluatedNodes=6 feasibleNodes=3
2025-04-02T06:46:40.792334322Z I0402 06:46:40.792273       1 schedule_one.go:286] "Successfully bound pod to node" pod="openshift-marketplace/redhat-operators-pcb5t" node="host-10-13-2-89" evaluatedNodes=6 feasibleNodes=3
2025-04-02T06:49:36.716475546Z I0402 06:49:36.716438       1 schedule_one.go:286] "Successfully bound pod to node" pod="openshift-marketplace/redhat-marketplace-cjq4k" node="host-10-13-2-89" evaluatedNodes=6 feasibleNodes=3
2025-04-02T06:53:38.178203979Z I0402 06:53:38.177249       1 schedule_one.go:286] "Successfully bound pod to node" pod="openshift-marketplace/community-operators-ng8rl" node="host-10-13-2-89" evaluatedNodes=6 feasibleNodes=3
2025-04-02T06:53:39.549805428Z I0402 06:53:39.549644       1 schedule_one.go:286] "Successfully bound pod to node" pod="openshift-marketplace/certified-operators-6rq7s" node="host-10-13-2-89" evaluatedNodes=6 feasibleNodes=3
2025-04-02T06:56:56.525807522Z I0402 06:56:56.525761       1 schedule_one.go:286] "Successfully bound pod to node" pod="openshift-marketplace/redhat-operators-tdjwz" node="host-10-13-2-89" evaluatedNodes=6 feasibleNodes=3
2025-04-02T07:00:00.159704465Z I0402 07:00:00.159460       1 schedule_one.go:286] "Successfully bound pod to node" pod="openshift-operator-lifecycle-manager/collect-profiles-29059620-zsxh2" node="host-10-13-2-1" evaluatedNodes=6 feasibleNodes=3
2025-04-02T07:00:03.622331778Z I0402 07:00:03.622287       1 schedule_one.go:286] "Successfully bound pod to node" pod="openshift-marketplace/redhat-marketplace-ffgwq" node="host-10-13-2-89" evaluatedNodes=6 feasibleNodes=3
2025-04-02T07:04:08.559475252Z I0402 07:04:08.559445       1 schedule_one.go:286] "Successfully bound pod to node" pod="openshift-marketplace/community-operators-trrb5" node="host-10-13-2-89" evaluatedNodes=6 feasibleNodes=3
2025-04-02T07:06:58.618019099Z I0402 07:06:58.615210       1 schedule_one.go:286] "Successfully bound pod to node" pod="openshift-marketplace/redhat-operators-72mtk" node="host-10-13-2-89" evaluatedNodes=6 feasibleNodes=3
2025-04-02T07:08:09.997032882Z I0402 07:08:09.996982       1 schedule_one.go:286] "Successfully bound pod to node" pod="openshift-marketplace/certified-operators-5m2d7" node="host-10-13-2-89" evaluatedNodes=6 feasibleNodes=3
2025-04-02T07:11:11.592734741Z I0402 07:11:11.592059       1 schedule_one.go:286] "Successfully bound pod to node" pod="openshift-marketplace/redhat-marketplace-8ztzr" node="host-10-13-2-89" evaluatedNodes=6 feasibleNodes=3
2025-04-02T07:15:00.172749260Z I0402 07:15:00.172650       1 schedule_one.go:286] "Successfully bound pod to node" pod="openshift-operator-lifecycle-manager/collect-profiles-29059635-7vtx2" node="host-10-13-2-1" evaluatedNodes=6 feasibleNodes=3
2025-04-02T07:15:14.314771580Z I0402 07:15:14.314706       1 schedule_one.go:286] "Successfully bound pod to node" pod="openshift-marketplace/community-operators-4mr5z" node="host-10-13-2-89" evaluatedNodes=6 feasibleNodes=3
2025-04-02T07:17:43.123370968Z I0402 07:17:43.122619       1 schedule_one.go:286] "Successfully bound pod to node" pod="openshift-marketplace/redhat-operators-s72zh" node="host-10-13-2-89" evaluatedNodes=6 feasibleNodes=3
2025-04-02T07:21:11.412420035Z I0402 07:21:11.412360       1 schedule_one.go:286] "Successfully bound pod to node" pod="openshift-marketplace/certified-operators-xxlnk" node="host-10-13-2-89" evaluatedNodes=6 feasibleNodes=3
2025-04-02T07:21:11.570935058Z I0402 07:21:11.570759       1 schedule_one.go:286] "Successfully bound pod to node" pod="openshift-marketplace/redhat-marketplace-6m4cp" node="host-10-13-2-89" evaluatedNodes=6 feasibleNodes=3
2025-04-02T07:28:06.387815568Z I0402 07:28:06.387221       1 schedule_one.go:286] "Successfully bound pod to node" pod="openshift-marketplace/redhat-operators-bzfqd" node="host-10-13-2-89" evaluatedNodes=6 feasibleNodes=3
2025-04-02T07:29:20.271907892Z I0402 07:29:20.271576       1 schedule_one.go:286] "Successfully bound pod to node" pod="openshift-marketplace/community-operators-n6rm9" node="host-10-13-2-89" evaluatedNodes=6 feasibleNodes=3
2025-04-02T07:30:00.166599625Z I0402 07:30:00.161646       1 schedule_one.go:286] "Successfully bound pod to node" pod="openshift-operator-lifecycle-manager/collect-profiles-29059650-lmvdh" node="host-10-13-2-1" evaluatedNodes=6 feasibleNodes=3
2025-04-02T07:32:13.990744010Z I0402 07:32:13.990687       1 schedule_one.go:286] "Successfully bound pod to node" pod="openshift-marketplace/redhat-marketplace-8gvdw" node="host-10-13-2-89" evaluatedNodes=6 feasibleNodes=3
2025-04-02T07:33:19.504781669Z I0402 07:33:19.504511       1 schedule_one.go:286] "Successfully bound pod to node" pod="openshift-marketplace/certified-operators-n44fk" node="host-10-13-2-89" evaluatedNodes=6 feasibleNodes=3
2025-04-02T07:34:35.828687868Z I0402 07:34:35.828602       1 schedule_one.go:286] "Successfully bound pod to node" pod="default/nginx" node="host-10-13-2-1" evaluatedNodes=6 feasibleNodes=3
2025-04-02T07:38:27.714476042Z I0402 07:38:27.714251       1 schedule_one.go:286] "Successfully bound pod to node" pod="openshift-marketplace/redhat-operators-qfb2t" node="host-10-13-2-89" evaluatedNodes=6 feasibleNodes=3
2025-04-02T07:40:16.448839479Z I0402 07:40:16.447099       1 schedule_one.go:286] "Successfully bound pod to node" pod="openshift-marketplace/community-operators-5zxgc" node="host-10-13-2-89" evaluatedNodes=6 feasibleNodes=3
2025-04-02T07:45:00.202903446Z I0402 07:45:00.202595       1 schedule_one.go:286] "Successfully bound pod to node" pod="openshift-operator-lifecycle-manager/collect-profiles-29059665-cjpnh" node="host-10-13-2-1" evaluatedNodes=6 feasibleNodes=3
2025-04-02T07:45:24.235854240Z I0402 07:45:24.235813       1 schedule_one.go:286] "Successfully bound pod to node" pod="openshift-marketplace/certified-operators-gccwp" node="host-10-13-2-89" evaluatedNodes=6 feasibleNodes=3
2025-04-02T07:45:24.402158173Z I0402 07:45:24.402122       1 schedule_one.go:286] "Successfully bound pod to node" pod="openshift-marketplace/redhat-marketplace-rlvkj" node="host-10-13-2-89" evaluatedNodes=6 feasibleNodes=3
2025-04-02T07:48:08.702140133Z I0402 07:48:08.702093       1 schedule_one.go:286] "Successfully bound pod to node" pod="openshift-must-gather-btwwf/must-gather-n42zw" node="host-10-13-0-150" evaluatedNodes=6 feasibleNodes=3
