2025-03-31T20:30:06.761726774Z W0331 20:30:06.761497       1 feature_gate.go:227] unrecognized feature gate: DNSNameResolver
2025-03-31T20:30:06.761726774Z W0331 20:30:06.761570       1 feature_gate.go:227] unrecognized feature gate: ExternalCloudProviderGCP
2025-03-31T20:30:06.761726774Z W0331 20:30:06.761574       1 feature_gate.go:227] unrecognized feature gate: MachineAPIOperatorDisableMachineHealthCheckController
2025-03-31T20:30:06.761726774Z W0331 20:30:06.761577       1 feature_gate.go:227] unrecognized feature gate: MachineAPIProviderOpenStack
2025-03-31T20:30:06.761726774Z W0331 20:30:06.761580       1 feature_gate.go:227] unrecognized feature gate: AlibabaPlatform
2025-03-31T20:30:06.761726774Z W0331 20:30:06.761583       1 feature_gate.go:227] unrecognized feature gate: AutomatedEtcdBackup
2025-03-31T20:30:06.761726774Z W0331 20:30:06.761585       1 feature_gate.go:227] unrecognized feature gate: OnClusterBuild
2025-03-31T20:30:06.761726774Z W0331 20:30:06.761588       1 feature_gate.go:227] unrecognized feature gate: VSphereStaticIPs
2025-03-31T20:30:06.761726774Z W0331 20:30:06.761591       1 feature_gate.go:227] unrecognized feature gate: AzureWorkloadIdentity
2025-03-31T20:30:06.761726774Z W0331 20:30:06.761597       1 feature_gate.go:227] unrecognized feature gate: CSIDriverSharedResource
2025-03-31T20:30:06.761726774Z W0331 20:30:06.761600       1 feature_gate.go:227] unrecognized feature gate: ExternalCloudProviderExternal
2025-03-31T20:30:06.761726774Z W0331 20:30:06.761602       1 feature_gate.go:227] unrecognized feature gate: OpenShiftPodSecurityAdmission
2025-03-31T20:30:06.761726774Z W0331 20:30:06.761605       1 feature_gate.go:227] unrecognized feature gate: RouteExternalCertificate
2025-03-31T20:30:06.761726774Z W0331 20:30:06.761608       1 feature_gate.go:227] unrecognized feature gate: PrivateHostedZoneAWS
2025-03-31T20:30:06.761726774Z W0331 20:30:06.761611       1 feature_gate.go:227] unrecognized feature gate: VSphereControlPlaneMachineSet
2025-03-31T20:30:06.761726774Z W0331 20:30:06.761614       1 feature_gate.go:227] unrecognized feature gate: BuildCSIVolumes
2025-03-31T20:30:06.761726774Z W0331 20:30:06.761616       1 feature_gate.go:227] unrecognized feature gate: ClusterAPIInstall
2025-03-31T20:30:06.761726774Z W0331 20:30:06.761619       1 feature_gate.go:227] unrecognized feature gate: InsightsConfigAPI
2025-03-31T20:30:06.761726774Z W0331 20:30:06.761622       1 feature_gate.go:227] unrecognized feature gate: MetricsServer
2025-03-31T20:30:06.761726774Z W0331 20:30:06.761625       1 feature_gate.go:227] unrecognized feature gate: SigstoreImageVerification
2025-03-31T20:30:06.761726774Z W0331 20:30:06.761628       1 feature_gate.go:227] unrecognized feature gate: ExternalCloudProvider
2025-03-31T20:30:06.761726774Z W0331 20:30:06.761631       1 feature_gate.go:227] unrecognized feature gate: GatewayAPI
2025-03-31T20:30:06.761726774Z W0331 20:30:06.761634       1 feature_gate.go:227] unrecognized feature gate: MachineConfigNodes
2025-03-31T20:30:06.761726774Z W0331 20:30:06.761637       1 feature_gate.go:227] unrecognized feature gate: MixedCPUsAllocation
2025-03-31T20:30:06.761726774Z W0331 20:30:06.761640       1 feature_gate.go:227] unrecognized feature gate: GCPLabelsTags
2025-03-31T20:30:06.761726774Z W0331 20:30:06.761642       1 feature_gate.go:227] unrecognized feature gate: NetworkLiveMigration
2025-03-31T20:30:06.761726774Z W0331 20:30:06.761645       1 feature_gate.go:227] unrecognized feature gate: SignatureStores
2025-03-31T20:30:06.761726774Z W0331 20:30:06.761653       1 feature_gate.go:227] unrecognized feature gate: ExternalCloudProviderAzure
2025-03-31T20:30:06.761726774Z W0331 20:30:06.761656       1 feature_gate.go:227] unrecognized feature gate: InstallAlternateInfrastructureAWS
2025-03-31T20:30:06.761726774Z W0331 20:30:06.761659       1 feature_gate.go:227] unrecognized feature gate: ManagedBootImages
2025-03-31T20:30:06.761726774Z W0331 20:30:06.761661       1 feature_gate.go:227] unrecognized feature gate: AdminNetworkPolicy
2025-03-31T20:30:06.761726774Z W0331 20:30:06.761664       1 feature_gate.go:227] unrecognized feature gate: GCPClusterHostedDNS
2025-03-31T20:30:06.761726774Z I0331 20:30:06.761703       1 flags.go:64] FLAG: --allow-metric-labels="[]"
2025-03-31T20:30:06.761726774Z I0331 20:30:06.761711       1 flags.go:64] FLAG: --authentication-kubeconfig="/etc/kubernetes/static-pod-resources/configmaps/scheduler-kubeconfig/kubeconfig"
2025-03-31T20:30:06.761726774Z I0331 20:30:06.761717       1 flags.go:64] FLAG: --authentication-skip-lookup="false"
2025-03-31T20:30:06.761726774Z I0331 20:30:06.761720       1 flags.go:64] FLAG: --authentication-token-webhook-cache-ttl="10s"
2025-03-31T20:30:06.761823092Z I0331 20:30:06.761723       1 flags.go:64] FLAG: --authentication-tolerate-lookup-failure="true"
2025-03-31T20:30:06.761823092Z I0331 20:30:06.761727       1 flags.go:64] FLAG: --authorization-always-allow-paths="[/healthz,/readyz,/livez]"
2025-03-31T20:30:06.761823092Z I0331 20:30:06.761731       1 flags.go:64] FLAG: --authorization-kubeconfig="/etc/kubernetes/static-pod-resources/configmaps/scheduler-kubeconfig/kubeconfig"
2025-03-31T20:30:06.761823092Z I0331 20:30:06.761733       1 flags.go:64] FLAG: --authorization-webhook-cache-authorized-ttl="10s"
2025-03-31T20:30:06.761823092Z I0331 20:30:06.761736       1 flags.go:64] FLAG: --authorization-webhook-cache-unauthorized-ttl="10s"
2025-03-31T20:30:06.761823092Z I0331 20:30:06.761738       1 flags.go:64] FLAG: --bind-address="0.0.0.0"
2025-03-31T20:30:06.761823092Z I0331 20:30:06.761741       1 flags.go:64] FLAG: --cert-dir="/var/run/kubernetes"
2025-03-31T20:30:06.761823092Z I0331 20:30:06.761744       1 flags.go:64] FLAG: --client-ca-file=""
2025-03-31T20:30:06.761823092Z I0331 20:30:06.761746       1 flags.go:64] FLAG: --config="/etc/kubernetes/static-pod-resources/configmaps/config/config.yaml"
2025-03-31T20:30:06.761823092Z I0331 20:30:06.761749       1 flags.go:64] FLAG: --contention-profiling="true"
2025-03-31T20:30:06.761823092Z I0331 20:30:06.761751       1 flags.go:64] FLAG: --disabled-metrics="[]"
2025-03-31T20:30:06.761823092Z I0331 20:30:06.761754       1 flags.go:64] FLAG: --feature-gates="CloudDualStackNodeIPs=true,DisableKubeletCloudCredentialProviders=false,DynamicResourceAllocation=false,EventedPLEG=false,MaxUnavailableStatefulSet=false,NodeSwap=false,ValidatingAdmissionPolicy=false"
2025-03-31T20:30:06.761823092Z I0331 20:30:06.761763       1 flags.go:64] FLAG: --help="false"
2025-03-31T20:30:06.761823092Z I0331 20:30:06.761766       1 flags.go:64] FLAG: --http2-max-streams-per-connection="0"
2025-03-31T20:30:06.761823092Z I0331 20:30:06.761769       1 flags.go:64] FLAG: --kube-api-burst="100"
2025-03-31T20:30:06.761823092Z I0331 20:30:06.761772       1 flags.go:64] FLAG: --kube-api-content-type="application/vnd.kubernetes.protobuf"
2025-03-31T20:30:06.761823092Z I0331 20:30:06.761775       1 flags.go:64] FLAG: --kube-api-qps="50"
2025-03-31T20:30:06.761823092Z I0331 20:30:06.761778       1 flags.go:64] FLAG: --kubeconfig=""
2025-03-31T20:30:06.761823092Z I0331 20:30:06.761780       1 flags.go:64] FLAG: --leader-elect="true"
2025-03-31T20:30:06.761823092Z I0331 20:30:06.761783       1 flags.go:64] FLAG: --leader-elect-lease-duration="15s"
2025-03-31T20:30:06.761823092Z I0331 20:30:06.761785       1 flags.go:64] FLAG: --leader-elect-renew-deadline="10s"
2025-03-31T20:30:06.761823092Z I0331 20:30:06.761787       1 flags.go:64] FLAG: --leader-elect-resource-lock="leases"
2025-03-31T20:30:06.761823092Z I0331 20:30:06.761790       1 flags.go:64] FLAG: --leader-elect-resource-name="kube-scheduler"
2025-03-31T20:30:06.761823092Z I0331 20:30:06.761792       1 flags.go:64] FLAG: --leader-elect-resource-namespace="kube-system"
2025-03-31T20:30:06.761823092Z I0331 20:30:06.761794       1 flags.go:64] FLAG: --leader-elect-retry-period="2s"
2025-03-31T20:30:06.761823092Z I0331 20:30:06.761796       1 flags.go:64] FLAG: --log-flush-frequency="5s"
2025-03-31T20:30:06.761823092Z I0331 20:30:06.761799       1 flags.go:64] FLAG: --log-json-info-buffer-size="0"
2025-03-31T20:30:06.761823092Z I0331 20:30:06.761803       1 flags.go:64] FLAG: --log-json-split-stream="false"
2025-03-31T20:30:06.761823092Z I0331 20:30:06.761805       1 flags.go:64] FLAG: --logging-format="text"
2025-03-31T20:30:06.761823092Z I0331 20:30:06.761807       1 flags.go:64] FLAG: --master=""
2025-03-31T20:30:06.761823092Z I0331 20:30:06.761810       1 flags.go:64] FLAG: --permit-address-sharing="false"
2025-03-31T20:30:06.761823092Z I0331 20:30:06.761812       1 flags.go:64] FLAG: --permit-port-sharing="false"
2025-03-31T20:30:06.761823092Z I0331 20:30:06.761814       1 flags.go:64] FLAG: --pod-max-in-unschedulable-pods-duration="5m0s"
2025-03-31T20:30:06.761823092Z I0331 20:30:06.761817       1 flags.go:64] FLAG: --profiling="true"
2025-03-31T20:30:06.761823092Z I0331 20:30:06.761819       1 flags.go:64] FLAG: --requestheader-allowed-names="[]"
2025-03-31T20:30:06.761839632Z I0331 20:30:06.761822       1 flags.go:64] FLAG: --requestheader-client-ca-file=""
2025-03-31T20:30:06.761839632Z I0331 20:30:06.761824       1 flags.go:64] FLAG: --requestheader-extra-headers-prefix="[x-remote-extra-]"
2025-03-31T20:30:06.761839632Z I0331 20:30:06.761827       1 flags.go:64] FLAG: --requestheader-group-headers="[x-remote-group]"
2025-03-31T20:30:06.761839632Z I0331 20:30:06.761830       1 flags.go:64] FLAG: --requestheader-username-headers="[x-remote-user]"
2025-03-31T20:30:06.761839632Z I0331 20:30:06.761833       1 flags.go:64] FLAG: --secure-port="10259"
2025-03-31T20:30:06.761839632Z I0331 20:30:06.761835       1 flags.go:64] FLAG: --show-hidden-metrics-for-version=""
2025-03-31T20:30:06.761847381Z I0331 20:30:06.761838       1 flags.go:64] FLAG: --tls-cert-file="/etc/kubernetes/static-pod-resources/secrets/serving-cert/tls.crt"
2025-03-31T20:30:06.761847381Z I0331 20:30:06.761841       1 flags.go:64] FLAG: --tls-cipher-suites="[TLS_ECDHE_ECDSA_WITH_AES_128_GCM_SHA256,TLS_ECDHE_RSA_WITH_AES_128_GCM_SHA256,TLS_ECDHE_ECDSA_WITH_AES_256_GCM_SHA384,TLS_ECDHE_RSA_WITH_AES_256_GCM_SHA384,TLS_ECDHE_ECDSA_WITH_CHACHA20_POLY1305_SHA256,TLS_ECDHE_RSA_WITH_CHACHA20_POLY1305_SHA256]"
2025-03-31T20:30:06.761909010Z I0331 20:30:06.761846       1 flags.go:64] FLAG: --tls-min-version="VersionTLS12"
2025-03-31T20:30:06.761909010Z I0331 20:30:06.761849       1 flags.go:64] FLAG: --tls-private-key-file="/etc/kubernetes/static-pod-resources/secrets/serving-cert/tls.key"
2025-03-31T20:30:06.761909010Z I0331 20:30:06.761851       1 flags.go:64] FLAG: --tls-sni-cert-key="[]"
2025-03-31T20:30:06.761909010Z I0331 20:30:06.761855       1 flags.go:64] FLAG: --unsupported-kube-api-over-localhost="false"
2025-03-31T20:30:06.761909010Z I0331 20:30:06.761857       1 flags.go:64] FLAG: --v="2"
2025-03-31T20:30:06.761909010Z I0331 20:30:06.761860       1 flags.go:64] FLAG: --version="false"
2025-03-31T20:30:06.761909010Z I0331 20:30:06.761863       1 flags.go:64] FLAG: --vmodule=""
2025-03-31T20:30:06.761909010Z I0331 20:30:06.761867       1 flags.go:64] FLAG: --write-config-to=""
2025-03-31T20:30:06.764672178Z I0331 20:30:06.764140       1 dynamic_serving_content.go:113] "Loaded a new cert/key pair" name="serving-cert::/etc/kubernetes/static-pod-resources/secrets/serving-cert/tls.crt::/etc/kubernetes/static-pod-resources/secrets/serving-cert/tls.key"
2025-03-31T20:31:07.195030199Z W0331 20:31:07.194950       1 authentication.go:368] Error looking up in-cluster authentication configuration: Get "https://api-int.ovhcpococp.trikorasolutions.net:6443/api/v1/namespaces/kube-system/configmaps/extension-apiserver-authentication": stream error: stream ID 1; INTERNAL_ERROR; received from peer
2025-03-31T20:31:07.195030199Z W0331 20:31:07.194989       1 authentication.go:369] Continuing without authentication configuration. This may treat all requests as anonymous.
2025-03-31T20:31:07.195030199Z W0331 20:31:07.195001       1 authentication.go:370] To require authentication configuration lookup to succeed, set --authentication-tolerate-lookup-failure=false
2025-03-31T20:31:07.223414948Z I0331 20:31:07.223325       1 configfile.go:101] "Using component config" config=<
2025-03-31T20:31:07.223414948Z 	apiVersion: kubescheduler.config.k8s.io/v1
2025-03-31T20:31:07.223414948Z 	clientConnection:
2025-03-31T20:31:07.223414948Z 	  acceptContentTypes: ""
2025-03-31T20:31:07.223414948Z 	  burst: 100
2025-03-31T20:31:07.223414948Z 	  contentType: application/vnd.kubernetes.protobuf
2025-03-31T20:31:07.223414948Z 	  kubeconfig: /etc/kubernetes/static-pod-resources/configmaps/scheduler-kubeconfig/kubeconfig
2025-03-31T20:31:07.223414948Z 	  qps: 50
2025-03-31T20:31:07.223414948Z 	enableContentionProfiling: false
2025-03-31T20:31:07.223414948Z 	enableProfiling: false
2025-03-31T20:31:07.223414948Z 	kind: KubeSchedulerConfiguration
2025-03-31T20:31:07.223414948Z 	leaderElection:
2025-03-31T20:31:07.223414948Z 	  leaderElect: true
2025-03-31T20:31:07.223414948Z 	  leaseDuration: 2m17s
2025-03-31T20:31:07.223414948Z 	  renewDeadline: 1m47s
2025-03-31T20:31:07.223414948Z 	  resourceLock: leases
2025-03-31T20:31:07.223414948Z 	  resourceName: kube-scheduler
2025-03-31T20:31:07.223414948Z 	  resourceNamespace: openshift-kube-scheduler
2025-03-31T20:31:07.223414948Z 	  retryPeriod: 26s
2025-03-31T20:31:07.223414948Z 	parallelism: 16
2025-03-31T20:31:07.223414948Z 	percentageOfNodesToScore: 0
2025-03-31T20:31:07.223414948Z 	podInitialBackoffSeconds: 1
2025-03-31T20:31:07.223414948Z 	podMaxBackoffSeconds: 10
2025-03-31T20:31:07.223414948Z 	profiles:
2025-03-31T20:31:07.223414948Z 	- pluginConfig:
2025-03-31T20:31:07.223414948Z 	  - args:
2025-03-31T20:31:07.223414948Z 	      apiVersion: kubescheduler.config.k8s.io/v1
2025-03-31T20:31:07.223414948Z 	      kind: DefaultPreemptionArgs
2025-03-31T20:31:07.223414948Z 	      minCandidateNodesAbsolute: 100
2025-03-31T20:31:07.223414948Z 	      minCandidateNodesPercentage: 10
2025-03-31T20:31:07.223414948Z 	    name: DefaultPreemption
2025-03-31T20:31:07.223414948Z 	  - args:
2025-03-31T20:31:07.223414948Z 	      apiVersion: kubescheduler.config.k8s.io/v1
2025-03-31T20:31:07.223414948Z 	      hardPodAffinityWeight: 1
2025-03-31T20:31:07.223414948Z 	      ignorePreferredTermsOfExistingPods: false
2025-03-31T20:31:07.223414948Z 	      kind: InterPodAffinityArgs
2025-03-31T20:31:07.223414948Z 	    name: InterPodAffinity
2025-03-31T20:31:07.223414948Z 	  - args:
2025-03-31T20:31:07.223414948Z 	      apiVersion: kubescheduler.config.k8s.io/v1
2025-03-31T20:31:07.223414948Z 	      kind: NodeAffinityArgs
2025-03-31T20:31:07.223414948Z 	    name: NodeAffinity
2025-03-31T20:31:07.223414948Z 	  - args:
2025-03-31T20:31:07.223414948Z 	      apiVersion: kubescheduler.config.k8s.io/v1
2025-03-31T20:31:07.223414948Z 	      kind: NodeResourcesBalancedAllocationArgs
2025-03-31T20:31:07.223414948Z 	      resources:
2025-03-31T20:31:07.223414948Z 	      - name: cpu
2025-03-31T20:31:07.223414948Z 	        weight: 1
2025-03-31T20:31:07.223414948Z 	      - name: memory
2025-03-31T20:31:07.223414948Z 	        weight: 1
2025-03-31T20:31:07.223414948Z 	    name: NodeResourcesBalancedAllocation
2025-03-31T20:31:07.223414948Z 	  - args:
2025-03-31T20:31:07.223414948Z 	      apiVersion: kubescheduler.config.k8s.io/v1
2025-03-31T20:31:07.223414948Z 	      kind: NodeResourcesFitArgs
2025-03-31T20:31:07.223414948Z 	      scoringStrategy:
2025-03-31T20:31:07.223414948Z 	        resources:
2025-03-31T20:31:07.223414948Z 	        - name: cpu
2025-03-31T20:31:07.223414948Z 	          weight: 1
2025-03-31T20:31:07.223414948Z 	        - name: memory
2025-03-31T20:31:07.223414948Z 	          weight: 1
2025-03-31T20:31:07.223414948Z 	        type: LeastAllocated
2025-03-31T20:31:07.223414948Z 	    name: NodeResourcesFit
2025-03-31T20:31:07.223414948Z 	  - args:
2025-03-31T20:31:07.223414948Z 	      apiVersion: kubescheduler.config.k8s.io/v1
2025-03-31T20:31:07.223414948Z 	      defaultingType: System
2025-03-31T20:31:07.223414948Z 	      kind: PodTopologySpreadArgs
2025-03-31T20:31:07.223414948Z 	    name: PodTopologySpread
2025-03-31T20:31:07.223414948Z 	  - args:
2025-03-31T20:31:07.223414948Z 	      apiVersion: kubescheduler.config.k8s.io/v1
2025-03-31T20:31:07.223414948Z 	      bindTimeoutSeconds: 600
2025-03-31T20:31:07.223414948Z 	      kind: VolumeBindingArgs
2025-03-31T20:31:07.223414948Z 	    name: VolumeBinding
2025-03-31T20:31:07.223414948Z 	  plugins:
2025-03-31T20:31:07.223414948Z 	    bind: {}
2025-03-31T20:31:07.223414948Z 	    filter: {}
2025-03-31T20:31:07.223414948Z 	    multiPoint:
2025-03-31T20:31:07.223414948Z 	      enabled:
2025-03-31T20:31:07.223414948Z 	      - name: PrioritySort
2025-03-31T20:31:07.223414948Z 	        weight: 0
2025-03-31T20:31:07.223414948Z 	      - name: NodeUnschedulable
2025-03-31T20:31:07.223414948Z 	        weight: 0
2025-03-31T20:31:07.223414948Z 	      - name: NodeName
2025-03-31T20:31:07.223414948Z 	        weight: 0
2025-03-31T20:31:07.223414948Z 	      - name: TaintToleration
2025-03-31T20:31:07.223414948Z 	        weight: 3
2025-03-31T20:31:07.223414948Z 	      - name: NodeAffinity
2025-03-31T20:31:07.223414948Z 	        weight: 2
2025-03-31T20:31:07.223414948Z 	      - name: NodePorts
2025-03-31T20:31:07.223414948Z 	        weight: 0
2025-03-31T20:31:07.223414948Z 	      - name: NodeResourcesFit
2025-03-31T20:31:07.223414948Z 	        weight: 1
2025-03-31T20:31:07.223414948Z 	      - name: VolumeRestrictions
2025-03-31T20:31:07.223414948Z 	        weight: 0
2025-03-31T20:31:07.223414948Z 	      - name: EBSLimits
2025-03-31T20:31:07.223414948Z 	        weight: 0
2025-03-31T20:31:07.223414948Z 	      - name: GCEPDLimits
2025-03-31T20:31:07.223414948Z 	        weight: 0
2025-03-31T20:31:07.223414948Z 	      - name: NodeVolumeLimits
2025-03-31T20:31:07.223414948Z 	        weight: 0
2025-03-31T20:31:07.223414948Z 	      - name: AzureDiskLimits
2025-03-31T20:31:07.223414948Z 	        weight: 0
2025-03-31T20:31:07.223414948Z 	      - name: VolumeBinding
2025-03-31T20:31:07.223414948Z 	        weight: 0
2025-03-31T20:31:07.223414948Z 	      - name: VolumeZone
2025-03-31T20:31:07.223414948Z 	        weight: 0
2025-03-31T20:31:07.223414948Z 	      - name: PodTopologySpread
2025-03-31T20:31:07.223414948Z 	        weight: 2
2025-03-31T20:31:07.223414948Z 	      - name: InterPodAffinity
2025-03-31T20:31:07.223414948Z 	        weight: 2
2025-03-31T20:31:07.223414948Z 	      - name: DefaultPreemption
2025-03-31T20:31:07.223414948Z 	        weight: 0
2025-03-31T20:31:07.223414948Z 	      - name: NodeResourcesBalancedAllocation
2025-03-31T20:31:07.223414948Z 	        weight: 1
2025-03-31T20:31:07.223414948Z 	      - name: ImageLocality
2025-03-31T20:31:07.223414948Z 	        weight: 1
2025-03-31T20:31:07.223414948Z 	      - name: DefaultBinder
2025-03-31T20:31:07.223414948Z 	        weight: 0
2025-03-31T20:31:07.223414948Z 	      - name: SchedulingGates
2025-03-31T20:31:07.223414948Z 	        weight: 0
2025-03-31T20:31:07.223414948Z 	    permit: {}
2025-03-31T20:31:07.223414948Z 	    postBind: {}
2025-03-31T20:31:07.223414948Z 	    postFilter: {}
2025-03-31T20:31:07.223414948Z 	    preBind: {}
2025-03-31T20:31:07.223414948Z 	    preEnqueue: {}
2025-03-31T20:31:07.223414948Z 	    preFilter: {}
2025-03-31T20:31:07.223414948Z 	    preScore: {}
2025-03-31T20:31:07.223414948Z 	    queueSort: {}
2025-03-31T20:31:07.223414948Z 	    reserve: {}
2025-03-31T20:31:07.223414948Z 	    score: {}
2025-03-31T20:31:07.223414948Z 	  schedulerName: default-scheduler
2025-03-31T20:31:07.223414948Z  >
2025-03-31T20:31:07.223694213Z I0331 20:31:07.223659       1 server.go:159] "Starting Kubernetes Scheduler" version="v1.28.15+ff493be"
2025-03-31T20:31:07.223694213Z I0331 20:31:07.223677       1 server.go:161] "Golang settings" GOGC="" GOMAXPROCS="" GOTRACEBACK=""
2025-03-31T20:31:07.225038948Z I0331 20:31:07.224931       1 configmap_cafile_content.go:202] "Starting controller" name="client-ca::kube-system::extension-apiserver-authentication::client-ca-file"
2025-03-31T20:31:07.225149885Z I0331 20:31:07.225080       1 shared_informer.go:311] Waiting for caches to sync for client-ca::kube-system::extension-apiserver-authentication::client-ca-file
2025-03-31T20:31:07.225713485Z I0331 20:31:07.225677       1 dynamic_serving_content.go:132] "Starting controller" name="serving-cert::/etc/kubernetes/static-pod-resources/secrets/serving-cert/tls.crt::/etc/kubernetes/static-pod-resources/secrets/serving-cert/tls.key"
2025-03-31T20:31:07.226285474Z I0331 20:31:07.226251       1 tlsconfig.go:200] "Loaded serving cert" certName="serving-cert::/etc/kubernetes/static-pod-resources/secrets/serving-cert/tls.crt::/etc/kubernetes/static-pod-resources/secrets/serving-cert/tls.key" certDetail="\"scheduler.openshift-kube-scheduler.svc\" [serving] validServingFor=[scheduler.openshift-kube-scheduler.svc,scheduler.openshift-kube-scheduler.svc.cluster.local] issuer=\"openshift-service-serving-signer@1743452529\" (2025-03-31 20:22:27 +0000 UTC to 2027-03-31 20:22:28 +0000 UTC (now=2025-03-31 20:31:07.226201125 +0000 UTC))"
2025-03-31T20:31:07.226853353Z I0331 20:31:07.226820       1 named_certificates.go:53] "Loaded SNI cert" index=0 certName="self-signed loopback" certDetail="\"apiserver-loopback-client@1743453007\" [serving] validServingFor=[apiserver-loopback-client] issuer=\"apiserver-loopback-client-ca@1743453006\" (2025-03-31 19:30:06 +0000 UTC to 2026-03-31 19:30:06 +0000 UTC (now=2025-03-31 20:31:07.226790124 +0000 UTC))"
2025-03-31T20:31:07.226900542Z I0331 20:31:07.226851       1 secure_serving.go:213] Serving securely on [::]:10259
2025-03-31T20:31:07.226921712Z I0331 20:31:07.226907       1 tlsconfig.go:240] "Starting DynamicServingCertificateController"
2025-03-31T20:31:07.285829949Z I0331 20:31:07.285729       1 node_tree.go:65] "Added node in listed group to NodeTree" node="host-10-13-0-150" zone=""
2025-03-31T20:31:07.286063785Z I0331 20:31:07.286033       1 node_tree.go:65] "Added node in listed group to NodeTree" node="host-10-13-2-160" zone=""
2025-03-31T20:31:07.287401219Z I0331 20:31:07.287245       1 node_tree.go:65] "Added node in listed group to NodeTree" node="host-10-13-2-89" zone=""
2025-03-31T20:31:07.325675981Z I0331 20:31:07.325635       1 shared_informer.go:318] Caches are synced for client-ca::kube-system::extension-apiserver-authentication::client-ca-file
2025-03-31T20:31:07.326162662Z I0331 20:31:07.326135       1 tlsconfig.go:178] "Loaded client CA" index=0 certName="client-ca::kube-system::extension-apiserver-authentication::client-ca-file" certDetail="\"admin-kubeconfig-signer\" [] issuer=\"<self>\" (2025-03-31 12:55:13 +0000 UTC to 2035-03-29 12:55:13 +0000 UTC (now=2025-03-31 20:31:07.326106122 +0000 UTC))"
2025-03-31T20:31:07.326225710Z I0331 20:31:07.326210       1 tlsconfig.go:178] "Loaded client CA" index=1 certName="client-ca::kube-system::extension-apiserver-authentication::client-ca-file" certDetail="\"kubelet-signer\" [] issuer=\"<self>\" (2025-03-31 12:55:15 +0000 UTC to 2025-04-01 12:55:15 +0000 UTC (now=2025-03-31 20:31:07.326195011 +0000 UTC))"
2025-03-31T20:31:07.326273739Z I0331 20:31:07.326260       1 tlsconfig.go:178] "Loaded client CA" index=2 certName="client-ca::kube-system::extension-apiserver-authentication::client-ca-file" certDetail="\"kube-control-plane-signer\" [] issuer=\"<self>\" (2025-03-31 12:55:15 +0000 UTC to 2026-03-31 12:55:15 +0000 UTC (now=2025-03-31 20:31:07.32624735 +0000 UTC))"
2025-03-31T20:31:07.326320328Z I0331 20:31:07.326306       1 tlsconfig.go:178] "Loaded client CA" index=3 certName="client-ca::kube-system::extension-apiserver-authentication::client-ca-file" certDetail="\"kube-apiserver-to-kubelet-signer\" [] issuer=\"<self>\" (2025-03-31 12:55:15 +0000 UTC to 2026-03-31 12:55:15 +0000 UTC (now=2025-03-31 20:31:07.326294979 +0000 UTC))"
2025-03-31T20:31:07.326366627Z I0331 20:31:07.326353       1 tlsconfig.go:178] "Loaded client CA" index=4 certName="client-ca::kube-system::extension-apiserver-authentication::client-ca-file" certDetail="\"kubelet-bootstrap-kubeconfig-signer\" [] issuer=\"<self>\" (2025-03-31 12:55:13 +0000 UTC to 2035-03-29 12:55:13 +0000 UTC (now=2025-03-31 20:31:07.326341318 +0000 UTC))"
2025-03-31T20:31:07.326412026Z I0331 20:31:07.326399       1 tlsconfig.go:178] "Loaded client CA" index=5 certName="client-ca::kube-system::extension-apiserver-authentication::client-ca-file" certDetail="\"kube-csr-signer_@1743452525\" [] issuer=\"kubelet-signer\" (2025-03-31 20:22:04 +0000 UTC to 2025-04-01 12:55:15 +0000 UTC (now=2025-03-31 20:31:07.326387507 +0000 UTC))"
2025-03-31T20:31:07.326477086Z I0331 20:31:07.326450       1 tlsconfig.go:178] "Loaded client CA" index=6 certName="client-ca::kube-system::extension-apiserver-authentication::client-ca-file" certDetail="\"openshift-kube-apiserver-operator_node-system-admin-signer@1743452539\" [] issuer=\"<self>\" (2025-03-31 20:22:18 +0000 UTC to 2026-03-31 20:22:19 +0000 UTC (now=2025-03-31 20:31:07.326433847 +0000 UTC))"
2025-03-31T20:31:07.327047915Z I0331 20:31:07.327024       1 tlsconfig.go:200] "Loaded serving cert" certName="serving-cert::/etc/kubernetes/static-pod-resources/secrets/serving-cert/tls.crt::/etc/kubernetes/static-pod-resources/secrets/serving-cert/tls.key" certDetail="\"scheduler.openshift-kube-scheduler.svc\" [serving] validServingFor=[scheduler.openshift-kube-scheduler.svc,scheduler.openshift-kube-scheduler.svc.cluster.local] issuer=\"openshift-service-serving-signer@1743452529\" (2025-03-31 20:22:27 +0000 UTC to 2027-03-31 20:22:28 +0000 UTC (now=2025-03-31 20:31:07.327002795 +0000 UTC))"
2025-03-31T20:31:07.328683423Z I0331 20:31:07.328653       1 named_certificates.go:53] "Loaded SNI cert" index=0 certName="self-signed loopback" certDetail="\"apiserver-loopback-client@1743453007\" [serving] validServingFor=[apiserver-loopback-client] issuer=\"apiserver-loopback-client-ca@1743453006\" (2025-03-31 19:30:06 +0000 UTC to 2026-03-31 19:30:06 +0000 UTC (now=2025-03-31 20:31:07.328627885 +0000 UTC))"
2025-03-31T20:31:07.428591261Z I0331 20:31:07.428522       1 leaderelection.go:250] attempting to acquire leader lease openshift-kube-scheduler/kube-scheduler...
2025-03-31T20:32:00.930148285Z E0331 20:32:00.929840       1 leaderelection.go:332] error retrieving resource lock openshift-kube-scheduler/kube-scheduler: Get "https://api-int.ovhcpococp.trikorasolutions.net:6443/apis/coordination.k8s.io/v1/namespaces/openshift-kube-scheduler/leases/kube-scheduler?timeout=53.5s": net/http: request canceled (Client.Timeout exceeded while awaiting headers)
2025-03-31T20:32:14.904507972Z E0331 20:32:14.904435       1 webhook.go:223] Failed to make webhook authorizer request: client rate limiter Wait returned an error: context canceled
2025-03-31T20:32:14.904559201Z E0331 20:32:14.904507       1 errors.go:77] client rate limiter Wait returned an error: context canceled
2025-03-31T20:32:28.681494538Z E0331 20:32:28.681448       1 webhook.go:223] Failed to make webhook authorizer request: client rate limiter Wait returned an error: context canceled
2025-03-31T20:32:28.681516008Z E0331 20:32:28.681491       1 errors.go:77] client rate limiter Wait returned an error: context canceled
2025-03-31T20:32:56.170892470Z I0331 20:32:56.170841       1 leaderelection.go:260] successfully acquired lease openshift-kube-scheduler/kube-scheduler
2025-03-31T20:32:56.172275714Z I0331 20:32:56.172251       1 schedule_one.go:988] "Unable to schedule pod; no fit; waiting" pod="openshift-authentication/oauth-openshift-8ffff85df-4wpjs" err="0/3 nodes are available: 3 node(s) didn't match pod anti-affinity rules. preemption: 0/3 nodes are available: 3 node(s) didn't match pod anti-affinity rules.."
2025-03-31T20:32:56.172551308Z I0331 20:32:56.172536       1 schedule_one.go:988] "Unable to schedule pod; no fit; waiting" pod="openshift-console/console-7bb5586f9f-jszjw" err="0/3 nodes are available: 3 node(s) didn't match pod anti-affinity rules. preemption: 0/3 nodes are available: 3 node(s) didn't match pod anti-affinity rules.."
2025-03-31T20:32:56.180028084Z I0331 20:32:56.180009       1 schedule_one.go:286] "Successfully bound pod to node" pod="openshift-apiserver/apiserver-c685f8bb4-2l67r" node="host-10-13-2-89" evaluatedNodes=3 feasibleNodes=1
2025-03-31T20:32:56.184047677Z I0331 20:32:56.182794       1 schedule_one.go:286] "Successfully bound pod to node" pod="openshift-oauth-apiserver/apiserver-cfdd6ccdb-vs8hh" node="host-10-13-0-150" evaluatedNodes=3 feasibleNodes=1
2025-03-31T20:32:56.184047677Z I0331 20:32:56.183010       1 schedule_one.go:286] "Successfully bound pod to node" pod="openshift-operator-lifecycle-manager/collect-profiles-29057550-gv2bq" node="host-10-13-2-89" evaluatedNodes=3 feasibleNodes=3
2025-03-31T20:32:56.184047677Z I0331 20:32:56.183034       1 schedule_one.go:286] "Successfully bound pod to node" pod="openshift-authentication/oauth-openshift-78b64d5655-4m857" node="host-10-13-2-89" evaluatedNodes=3 feasibleNodes=1
2025-03-31T20:32:57.775863940Z I0331 20:32:57.775830       1 schedule_one.go:286] "Successfully bound pod to node" pod="openshift-multus/multus-admission-controller-7bdf9cfb97-mmgf2" node="host-10-13-0-150" evaluatedNodes=3 feasibleNodes=3
2025-03-31T20:32:57.789521188Z I0331 20:32:57.778143       1 schedule_one.go:286] "Successfully bound pod to node" pod="openshift-multus/cni-sysctl-allowlist-ds-8z6pm" node="host-10-13-2-89" evaluatedNodes=1 feasibleNodes=1
2025-03-31T20:32:57.789784013Z I0331 20:32:57.789759       1 schedule_one.go:286] "Successfully bound pod to node" pod="openshift-multus/cni-sysctl-allowlist-ds-k54t4" node="host-10-13-0-150" evaluatedNodes=1 feasibleNodes=1
2025-03-31T20:32:57.790042809Z I0331 20:32:57.790027       1 schedule_one.go:286] "Successfully bound pod to node" pod="openshift-multus/cni-sysctl-allowlist-ds-tqnm5" node="host-10-13-2-160" evaluatedNodes=1 feasibleNodes=1
2025-03-31T20:32:57.790162956Z I0331 20:32:57.790137       1 schedule_one.go:286] "Successfully bound pod to node" pod="openshift-console/console-7bb5586f9f-jszjw" node="host-10-13-2-89" evaluatedNodes=3 feasibleNodes=1
2025-03-31T20:32:57.790543449Z I0331 20:32:57.790530       1 schedule_one.go:286] "Successfully bound pod to node" pod="openshift-authentication/oauth-openshift-8ffff85df-4wpjs" node="host-10-13-2-160" evaluatedNodes=3 feasibleNodes=1
2025-03-31T20:33:00.438769136Z I0331 20:33:00.438726       1 schedule_one.go:286] "Successfully bound pod to node" pod="openshift-multus/multus-admission-controller-7bdf9cfb97-mxrgk" node="host-10-13-2-89" evaluatedNodes=3 feasibleNodes=3
2025-03-31T20:33:01.135926894Z I0331 20:33:01.127207       1 schedule_one.go:988] "Unable to schedule pod; no fit; waiting" pod="openshift-authentication/oauth-openshift-8ffff85df-ksdgg" err="0/3 nodes are available: 3 node(s) didn't match pod anti-affinity rules. preemption: 0/3 nodes are available: 3 node(s) didn't match pod anti-affinity rules.."
2025-03-31T20:33:02.177143184Z I0331 20:33:02.176341       1 schedule_one.go:988] "Unable to schedule pod; no fit; waiting" pod="openshift-authentication/oauth-openshift-8ffff85df-ksdgg" err="0/3 nodes are available: 3 node(s) didn't match pod anti-affinity rules. preemption: 0/3 nodes are available: 3 node(s) didn't match pod anti-affinity rules.."
2025-03-31T20:33:03.583737907Z I0331 20:33:03.583703       1 schedule_one.go:988] "Unable to schedule pod; no fit; waiting" pod="openshift-oauth-apiserver/apiserver-cfdd6ccdb-dlgkr" err="0/3 nodes are available: 3 node(s) didn't match pod anti-affinity rules. preemption: 0/3 nodes are available: 3 node(s) didn't match pod anti-affinity rules.."
2025-03-31T20:33:04.517798343Z I0331 20:33:04.517460       1 schedule_one.go:988] "Unable to schedule pod; no fit; waiting" pod="openshift-apiserver/apiserver-c685f8bb4-jz8r5" err="0/3 nodes are available: 3 node(s) didn't match pod anti-affinity rules. preemption: 0/3 nodes are available: 3 node(s) didn't match pod anti-affinity rules.."
2025-03-31T20:33:10.897693409Z I0331 20:33:10.897667       1 schedule_one.go:988] "Unable to schedule pod; no fit; waiting" pod="openshift-oauth-apiserver/apiserver-cfdd6ccdb-dlgkr" err="0/3 nodes are available: 3 node(s) didn't match pod anti-affinity rules. preemption: 0/3 nodes are available: 3 node(s) didn't match pod anti-affinity rules.."
2025-03-31T20:33:10.898395185Z I0331 20:33:10.898378       1 schedule_one.go:988] "Unable to schedule pod; no fit; waiting" pod="openshift-apiserver/apiserver-c685f8bb4-jz8r5" err="0/3 nodes are available: 3 node(s) didn't match pod anti-affinity rules. preemption: 0/3 nodes are available: 3 node(s) didn't match pod anti-affinity rules.."
2025-03-31T20:33:10.898693339Z I0331 20:33:10.898678       1 schedule_one.go:988] "Unable to schedule pod; no fit; waiting" pod="openshift-authentication/oauth-openshift-8ffff85df-ksdgg" err="0/3 nodes are available: 3 node(s) didn't match pod anti-affinity rules. preemption: 0/3 nodes are available: 3 node(s) didn't match pod anti-affinity rules.."
2025-03-31T20:33:11.173825206Z I0331 20:33:11.173794       1 schedule_one.go:286] "Successfully bound pod to node" pod="openshift-monitoring/alertmanager-main-1" node="host-10-13-2-160" evaluatedNodes=3 feasibleNodes=2
2025-03-31T20:33:13.182811938Z I0331 20:33:13.182778       1 schedule_one.go:988] "Unable to schedule pod; no fit; waiting" pod="openshift-oauth-apiserver/apiserver-cfdd6ccdb-dlgkr" err="0/3 nodes are available: 3 node(s) didn't match pod anti-affinity rules. preemption: 0/3 nodes are available: 3 node(s) didn't match pod anti-affinity rules.."
2025-03-31T20:33:13.183299428Z I0331 20:33:13.183261       1 schedule_one.go:988] "Unable to schedule pod; no fit; waiting" pod="openshift-apiserver/apiserver-c685f8bb4-jz8r5" err="0/3 nodes are available: 3 node(s) didn't match pod anti-affinity rules. preemption: 0/3 nodes are available: 3 node(s) didn't match pod anti-affinity rules.."
2025-03-31T20:33:15.183764703Z I0331 20:33:15.183706       1 schedule_one.go:988] "Unable to schedule pod; no fit; waiting" pod="openshift-authentication/oauth-openshift-8ffff85df-ksdgg" err="0/3 nodes are available: 3 node(s) didn't match pod anti-affinity rules. preemption: 0/3 nodes are available: 3 node(s) didn't match pod anti-affinity rules.."
2025-03-31T20:33:16.180706078Z I0331 20:33:16.180634       1 schedule_one.go:286] "Successfully bound pod to node" pod="openshift-monitoring/prometheus-k8s-1" node="host-10-13-2-160" evaluatedNodes=3 feasibleNodes=2
2025-03-31T20:33:17.185820436Z I0331 20:33:17.185756       1 schedule_one.go:988] "Unable to schedule pod; no fit; waiting" pod="openshift-oauth-apiserver/apiserver-cfdd6ccdb-dlgkr" err="0/3 nodes are available: 3 node(s) didn't match pod anti-affinity rules. preemption: 0/3 nodes are available: 3 node(s) didn't match pod anti-affinity rules.."
2025-03-31T20:33:17.186504754Z I0331 20:33:17.186475       1 schedule_one.go:988] "Unable to schedule pod; no fit; waiting" pod="openshift-apiserver/apiserver-c685f8bb4-jz8r5" err="0/3 nodes are available: 3 node(s) didn't match pod anti-affinity rules. preemption: 0/3 nodes are available: 3 node(s) didn't match pod anti-affinity rules.."
2025-03-31T20:33:23.189491946Z I0331 20:33:23.189429       1 schedule_one.go:988] "Unable to schedule pod; no fit; waiting" pod="openshift-authentication/oauth-openshift-8ffff85df-ksdgg" err="0/3 nodes are available: 3 node(s) didn't match pod anti-affinity rules. preemption: 0/3 nodes are available: 3 node(s) didn't match pod anti-affinity rules.."
2025-03-31T20:33:26.491554588Z I0331 20:33:26.491518       1 schedule_one.go:988] "Unable to schedule pod; no fit; waiting" pod="openshift-oauth-apiserver/apiserver-cfdd6ccdb-dlgkr" err="0/3 nodes are available: 3 node(s) didn't match pod anti-affinity rules. preemption: 0/3 nodes are available: 3 node(s) didn't match pod anti-affinity rules.."
2025-03-31T20:33:26.491950340Z I0331 20:33:26.491910       1 schedule_one.go:988] "Unable to schedule pod; no fit; waiting" pod="openshift-apiserver/apiserver-c685f8bb4-jz8r5" err="0/3 nodes are available: 3 node(s) didn't match pod anti-affinity rules. preemption: 0/3 nodes are available: 3 node(s) didn't match pod anti-affinity rules.."
2025-03-31T20:33:33.202846754Z I0331 20:33:33.202543       1 schedule_one.go:286] "Successfully bound pod to node" pod="openshift-authentication/oauth-openshift-8ffff85df-ksdgg" node="host-10-13-0-150" evaluatedNodes=3 feasibleNodes=1
2025-03-31T20:33:34.303494970Z I0331 20:33:34.303447       1 schedule_one.go:286] "Successfully bound pod to node" pod="openshift-marketplace/certified-operators-27gfr" node="host-10-13-2-89" evaluatedNodes=3 feasibleNodes=3
2025-03-31T20:33:34.362461223Z I0331 20:33:34.362410       1 schedule_one.go:286] "Successfully bound pod to node" pod="openshift-monitoring/prometheus-k8s-0" node="host-10-13-2-89" evaluatedNodes=3 feasibleNodes=2
2025-03-31T20:33:35.670781053Z I0331 20:33:35.670744       1 schedule_one.go:988] "Unable to schedule pod; no fit; waiting" pod="openshift-authentication/oauth-openshift-8ffff85df-rdllr" err="0/3 nodes are available: 3 node(s) didn't match pod anti-affinity rules. preemption: 0/3 nodes are available: 3 node(s) didn't match pod anti-affinity rules.."
2025-03-31T20:33:37.198296018Z I0331 20:33:37.198123       1 schedule_one.go:988] "Unable to schedule pod; no fit; waiting" pod="openshift-oauth-apiserver/apiserver-cfdd6ccdb-dlgkr" err="0/3 nodes are available: 3 node(s) didn't match pod anti-affinity rules. preemption: 0/3 nodes are available: 3 node(s) didn't match pod anti-affinity rules.."
2025-03-31T20:33:37.199191101Z I0331 20:33:37.199158       1 schedule_one.go:988] "Unable to schedule pod; no fit; waiting" pod="openshift-apiserver/apiserver-c685f8bb4-jz8r5" err="0/3 nodes are available: 3 node(s) didn't match pod anti-affinity rules. preemption: 0/3 nodes are available: 3 node(s) didn't match pod anti-affinity rules.."
2025-03-31T20:33:39.032256550Z I0331 20:33:39.032184       1 schedule_one.go:286] "Successfully bound pod to node" pod="openshift-marketplace/community-operators-hmnvj" node="host-10-13-2-89" evaluatedNodes=3 feasibleNodes=3
2025-03-31T20:33:42.982100804Z I0331 20:33:42.981438       1 schedule_one.go:988] "Unable to schedule pod; no fit; waiting" pod="openshift-authentication/oauth-openshift-8ffff85df-rdllr" err="0/3 nodes are available: 3 node(s) didn't match pod anti-affinity rules. preemption: 0/3 nodes are available: 3 node(s) didn't match pod anti-affinity rules.."
2025-03-31T20:33:43.411305749Z I0331 20:33:43.411063       1 schedule_one.go:286] "Successfully bound pod to node" pod="openshift-monitoring/alertmanager-main-0" node="host-10-13-2-89" evaluatedNodes=3 feasibleNodes=2
2025-03-31T20:33:45.100538335Z I0331 20:33:45.100342       1 schedule_one.go:286] "Successfully bound pod to node" pod="openshift-marketplace/redhat-operators-qgb7j" node="host-10-13-2-89" evaluatedNodes=3 feasibleNodes=3
2025-03-31T20:33:47.203983312Z I0331 20:33:47.203923       1 schedule_one.go:988] "Unable to schedule pod; no fit; waiting" pod="openshift-oauth-apiserver/apiserver-cfdd6ccdb-dlgkr" err="0/3 nodes are available: 3 node(s) didn't match pod anti-affinity rules. preemption: 0/3 nodes are available: 3 node(s) didn't match pod anti-affinity rules.."
2025-03-31T20:33:47.204587221Z I0331 20:33:47.204556       1 schedule_one.go:988] "Unable to schedule pod; no fit; waiting" pod="openshift-apiserver/apiserver-c685f8bb4-jz8r5" err="0/3 nodes are available: 3 node(s) didn't match pod anti-affinity rules. preemption: 0/3 nodes are available: 3 node(s) didn't match pod anti-affinity rules.."
2025-03-31T20:33:47.680822989Z I0331 20:33:47.680744       1 schedule_one.go:988] "Unable to schedule pod; no fit; waiting" pod="openshift-authentication/oauth-openshift-8ffff85df-rdllr" err="0/3 nodes are available: 3 node(s) didn't match pod anti-affinity rules. preemption: 0/3 nodes are available: 3 node(s) didn't match pod anti-affinity rules.."
2025-03-31T20:33:48.901397853Z I0331 20:33:48.897660       1 schedule_one.go:988] "Unable to schedule pod; no fit; waiting" pod="openshift-controller-manager/controller-manager-6494df548f-dtgv6" err="0/3 nodes are available: 3 node(s) didn't match pod anti-affinity rules. preemption: 0/3 nodes are available: 3 node(s) didn't match pod anti-affinity rules.."
2025-03-31T20:33:48.912625029Z I0331 20:33:48.912592       1 schedule_one.go:988] "Unable to schedule pod; no fit; waiting" pod="openshift-route-controller-manager/route-controller-manager-768ccd577d-2d4n5" err="0/3 nodes are available: 3 node(s) didn't match pod anti-affinity rules. preemption: 0/3 nodes are available: 3 node(s) didn't match pod anti-affinity rules.."
2025-03-31T20:33:50.213158907Z I0331 20:33:50.212203       1 schedule_one.go:286] "Successfully bound pod to node" pod="openshift-controller-manager/controller-manager-6494df548f-dtgv6" node="host-10-13-2-160" evaluatedNodes=3 feasibleNodes=1
2025-03-31T20:33:50.217018594Z I0331 20:33:50.216913       1 schedule_one.go:286] "Successfully bound pod to node" pod="openshift-route-controller-manager/route-controller-manager-768ccd577d-2d4n5" node="host-10-13-2-160" evaluatedNodes=3 feasibleNodes=1
2025-03-31T20:33:50.393907206Z I0331 20:33:50.393771       1 schedule_one.go:286] "Successfully bound pod to node" pod="openshift-marketplace/redhat-marketplace-vgqw6" node="host-10-13-2-89" evaluatedNodes=3 feasibleNodes=3
2025-03-31T20:33:51.484660760Z I0331 20:33:51.484619       1 schedule_one.go:988] "Unable to schedule pod; no fit; waiting" pod="openshift-controller-manager/controller-manager-6494df548f-phnl9" err="0/3 nodes are available: 3 node(s) didn't match pod anti-affinity rules. preemption: 0/3 nodes are available: 3 node(s) didn't match pod anti-affinity rules.."
2025-03-31T20:33:51.867287665Z I0331 20:33:51.866409       1 schedule_one.go:988] "Unable to schedule pod; no fit; waiting" pod="openshift-route-controller-manager/route-controller-manager-768ccd577d-rlbhr" err="0/3 nodes are available: 3 node(s) didn't match pod anti-affinity rules. preemption: 0/3 nodes are available: 3 node(s) didn't match pod anti-affinity rules.."
2025-03-31T20:33:52.206214614Z I0331 20:33:52.206174       1 schedule_one.go:988] "Unable to schedule pod; no fit; waiting" pod="openshift-authentication/oauth-openshift-8ffff85df-rdllr" err="0/3 nodes are available: 3 node(s) didn't match pod anti-affinity rules. preemption: 0/3 nodes are available: 3 node(s) didn't match pod anti-affinity rules.."
2025-03-31T20:33:53.213275575Z I0331 20:33:53.213241       1 schedule_one.go:286] "Successfully bound pod to node" pod="openshift-route-controller-manager/route-controller-manager-768ccd577d-rlbhr" node="host-10-13-0-150" evaluatedNodes=3 feasibleNodes=1
2025-03-31T20:33:53.213412853Z I0331 20:33:53.213399       1 schedule_one.go:286] "Successfully bound pod to node" pod="openshift-controller-manager/controller-manager-6494df548f-phnl9" node="host-10-13-2-89" evaluatedNodes=3 feasibleNodes=1
2025-03-31T20:33:54.519821988Z I0331 20:33:54.519785       1 schedule_one.go:988] "Unable to schedule pod; no fit; waiting" pod="openshift-controller-manager/controller-manager-6494df548f-nbbbs" err="0/3 nodes are available: 3 node(s) didn't match pod anti-affinity rules. preemption: 0/3 nodes are available: 3 node(s) didn't match pod anti-affinity rules.."
2025-03-31T20:33:54.750066622Z I0331 20:33:54.750004       1 schedule_one.go:988] "Unable to schedule pod; no fit; waiting" pod="openshift-route-controller-manager/route-controller-manager-768ccd577d-b8prk" err="0/3 nodes are available: 3 node(s) didn't match pod anti-affinity rules. preemption: 0/3 nodes are available: 3 node(s) didn't match pod anti-affinity rules.."
2025-03-31T20:33:56.218632372Z I0331 20:33:56.217056       1 schedule_one.go:286] "Successfully bound pod to node" pod="openshift-controller-manager/controller-manager-6494df548f-nbbbs" node="host-10-13-0-150" evaluatedNodes=3 feasibleNodes=1
2025-03-31T20:33:56.220566935Z I0331 20:33:56.220263       1 schedule_one.go:286] "Successfully bound pod to node" pod="openshift-route-controller-manager/route-controller-manager-768ccd577d-b8prk" node="host-10-13-2-89" evaluatedNodes=3 feasibleNodes=1
2025-03-31T20:33:57.209775197Z I0331 20:33:57.209733       1 schedule_one.go:988] "Unable to schedule pod; no fit; waiting" pod="openshift-oauth-apiserver/apiserver-cfdd6ccdb-dlgkr" err="0/3 nodes are available: 3 node(s) didn't match pod anti-affinity rules. preemption: 0/3 nodes are available: 3 node(s) didn't match pod anti-affinity rules.."
2025-03-31T20:33:57.210411115Z I0331 20:33:57.210382       1 schedule_one.go:988] "Unable to schedule pod; no fit; waiting" pod="openshift-apiserver/apiserver-c685f8bb4-jz8r5" err="0/3 nodes are available: 3 node(s) didn't match pod anti-affinity rules. preemption: 0/3 nodes are available: 3 node(s) didn't match pod anti-affinity rules.."
2025-03-31T20:34:00.212098163Z I0331 20:34:00.212042       1 schedule_one.go:988] "Unable to schedule pod; no fit; waiting" pod="openshift-authentication/oauth-openshift-8ffff85df-rdllr" err="0/3 nodes are available: 3 node(s) didn't match pod anti-affinity rules. preemption: 0/3 nodes are available: 3 node(s) didn't match pod anti-affinity rules.."
2025-03-31T20:34:07.218241970Z I0331 20:34:07.218173       1 schedule_one.go:988] "Unable to schedule pod; no fit; waiting" pod="openshift-apiserver/apiserver-c685f8bb4-jz8r5" err="0/3 nodes are available: 3 node(s) didn't match pod anti-affinity rules. preemption: 0/3 nodes are available: 3 node(s) didn't match pod anti-affinity rules.."
2025-03-31T20:34:07.228774019Z I0331 20:34:07.227174       1 schedule_one.go:286] "Successfully bound pod to node" pod="openshift-oauth-apiserver/apiserver-cfdd6ccdb-dlgkr" node="host-10-13-2-160" evaluatedNodes=3 feasibleNodes=1
2025-03-31T20:34:10.227312147Z I0331 20:34:10.227275       1 schedule_one.go:286] "Successfully bound pod to node" pod="openshift-authentication/oauth-openshift-8ffff85df-rdllr" node="host-10-13-2-89" evaluatedNodes=3 feasibleNodes=1
2025-03-31T20:34:13.498356220Z I0331 20:34:13.498211       1 schedule_one.go:988] "Unable to schedule pod; no fit; waiting" pod="openshift-oauth-apiserver/apiserver-cfdd6ccdb-7fqn9" err="0/3 nodes are available: 3 node(s) didn't match pod anti-affinity rules. preemption: 0/3 nodes are available: 3 node(s) didn't match pod anti-affinity rules.."
2025-03-31T20:34:15.070831276Z I0331 20:34:15.070800       1 schedule_one.go:988] "Unable to schedule pod; no fit; waiting" pod="openshift-oauth-apiserver/apiserver-cfdd6ccdb-7fqn9" err="0/3 nodes are available: 3 node(s) didn't match pod anti-affinity rules. preemption: 0/3 nodes are available: 3 node(s) didn't match pod anti-affinity rules.."
2025-03-31T20:34:17.224905418Z I0331 20:34:17.224726       1 schedule_one.go:988] "Unable to schedule pod; no fit; waiting" pod="openshift-apiserver/apiserver-c685f8bb4-jz8r5" err="0/3 nodes are available: 3 node(s) didn't match pod anti-affinity rules. preemption: 0/3 nodes are available: 3 node(s) didn't match pod anti-affinity rules.."
2025-03-31T20:34:19.467937080Z I0331 20:34:19.467866       1 schedule_one.go:988] "Unable to schedule pod; no fit; waiting" pod="openshift-oauth-apiserver/apiserver-cfdd6ccdb-7fqn9" err="0/3 nodes are available: 3 node(s) didn't match pod anti-affinity rules. preemption: 0/3 nodes are available: 3 node(s) didn't match pod anti-affinity rules.."
2025-03-31T20:34:24.228308598Z I0331 20:34:24.228095       1 schedule_one.go:988] "Unable to schedule pod; no fit; waiting" pod="openshift-oauth-apiserver/apiserver-cfdd6ccdb-7fqn9" err="0/3 nodes are available: 3 node(s) didn't match pod anti-affinity rules. preemption: 0/3 nodes are available: 3 node(s) didn't match pod anti-affinity rules.."
2025-03-31T20:34:27.239110091Z I0331 20:34:27.239067       1 schedule_one.go:286] "Successfully bound pod to node" pod="openshift-apiserver/apiserver-c685f8bb4-jz8r5" node="host-10-13-2-160" evaluatedNodes=3 feasibleNodes=1
2025-03-31T20:34:27.870099223Z I0331 20:34:27.870065       1 schedule_one.go:988] "Unable to schedule pod; no fit; waiting" pod="openshift-console/console-776c8ff8fd-xvq9g" err="0/3 nodes are available: 3 node(s) didn't match pod anti-affinity rules. preemption: 0/3 nodes are available: 3 node(s) didn't match pod anti-affinity rules.."
2025-03-31T20:34:27.882978647Z I0331 20:34:27.882849       1 schedule_one.go:988] "Unable to schedule pod; no fit; waiting" pod="openshift-console/console-776c8ff8fd-j4rm9" err="0/3 nodes are available: 3 node(s) didn't match pod anti-affinity rules. preemption: 0/3 nodes are available: 3 node(s) didn't match pod anti-affinity rules.."
2025-03-31T20:34:32.233791755Z I0331 20:34:32.233727       1 schedule_one.go:988] "Unable to schedule pod; no fit; waiting" pod="openshift-oauth-apiserver/apiserver-cfdd6ccdb-7fqn9" err="0/3 nodes are available: 3 node(s) didn't match pod anti-affinity rules. preemption: 0/3 nodes are available: 3 node(s) didn't match pod anti-affinity rules.."
2025-03-31T20:34:33.683686751Z I0331 20:34:33.683641       1 schedule_one.go:988] "Unable to schedule pod; no fit; waiting" pod="openshift-apiserver/apiserver-c685f8bb4-7cvzp" err="0/3 nodes are available: 3 node(s) didn't match pod anti-affinity rules. preemption: 0/3 nodes are available: 3 node(s) didn't match pod anti-affinity rules.."
2025-03-31T20:34:53.290745884Z I0331 20:34:53.290619       1 schedule_one.go:988] "Unable to schedule pod; no fit; waiting" pod="openshift-oauth-apiserver/apiserver-cfdd6ccdb-7fqn9" err="0/3 nodes are available: 3 node(s) didn't match pod anti-affinity rules. preemption: 0/3 nodes are available: 3 node(s) didn't match pod anti-affinity rules.."
2025-03-31T20:34:53.291114957Z I0331 20:34:53.291098       1 schedule_one.go:988] "Unable to schedule pod; no fit; waiting" pod="openshift-apiserver/apiserver-c685f8bb4-7cvzp" err="0/3 nodes are available: 3 node(s) didn't match pod anti-affinity rules. preemption: 0/3 nodes are available: 3 node(s) didn't match pod anti-affinity rules.."
2025-03-31T20:34:53.292344433Z I0331 20:34:53.291463       1 schedule_one.go:988] "Unable to schedule pod; no fit; waiting" pod="openshift-console/console-776c8ff8fd-j4rm9" err="0/3 nodes are available: 3 node(s) didn't match pod anti-affinity rules. preemption: 0/3 nodes are available: 3 node(s) didn't match pod anti-affinity rules.."
2025-03-31T20:34:53.300728173Z I0331 20:34:53.299387       1 schedule_one.go:286] "Successfully bound pod to node" pod="openshift-console/console-776c8ff8fd-xvq9g" node="host-10-13-2-160" evaluatedNodes=3 feasibleNodes=1
2025-03-31T20:34:56.249142008Z I0331 20:34:56.249063       1 schedule_one.go:988] "Unable to schedule pod; no fit; waiting" pod="openshift-apiserver/apiserver-c685f8bb4-7cvzp" err="0/3 nodes are available: 3 node(s) didn't match pod anti-affinity rules. preemption: 0/3 nodes are available: 3 node(s) didn't match pod anti-affinity rules.."
2025-03-31T20:34:56.259205936Z I0331 20:34:56.259001       1 schedule_one.go:286] "Successfully bound pod to node" pod="openshift-console/console-776c8ff8fd-j4rm9" node="host-10-13-0-150" evaluatedNodes=3 feasibleNodes=1
2025-03-31T20:35:01.794027927Z I0331 20:35:01.793983       1 schedule_one.go:988] "Unable to schedule pod; no fit; waiting" pod="openshift-apiserver/apiserver-c685f8bb4-7cvzp" err="0/3 nodes are available: 3 node(s) didn't match pod anti-affinity rules. preemption: 0/3 nodes are available: 3 node(s) didn't match pod anti-affinity rules.."
2025-03-31T20:35:04.252705241Z I0331 20:35:04.252642       1 schedule_one.go:988] "Unable to schedule pod; no fit; waiting" pod="openshift-oauth-apiserver/apiserver-cfdd6ccdb-7fqn9" err="0/3 nodes are available: 3 node(s) didn't match pod anti-affinity rules. preemption: 0/3 nodes are available: 3 node(s) didn't match pod anti-affinity rules.."
2025-03-31T20:35:13.843419809Z I0331 20:35:13.843377       1 schedule_one.go:988] "Unable to schedule pod; no fit; waiting" pod="openshift-apiserver/apiserver-c685f8bb4-7cvzp" err="0/3 nodes are available: 3 node(s) didn't match pod anti-affinity rules. preemption: 0/3 nodes are available: 3 node(s) didn't match pod anti-affinity rules.."
2025-03-31T20:35:14.267421892Z I0331 20:35:14.267266       1 schedule_one.go:286] "Successfully bound pod to node" pod="openshift-oauth-apiserver/apiserver-cfdd6ccdb-7fqn9" node="host-10-13-2-89" evaluatedNodes=3 feasibleNodes=1
2025-03-31T20:35:24.264629272Z I0331 20:35:24.264595       1 schedule_one.go:988] "Unable to schedule pod; no fit; waiting" pod="openshift-apiserver/apiserver-c685f8bb4-7cvzp" err="0/3 nodes are available: 3 node(s) didn't match pod anti-affinity rules. preemption: 0/3 nodes are available: 3 node(s) didn't match pod anti-affinity rules.."
2025-03-31T20:35:34.277202596Z I0331 20:35:34.277123       1 schedule_one.go:988] "Unable to schedule pod; no fit; waiting" pod="openshift-apiserver/apiserver-c685f8bb4-7cvzp" err="0/3 nodes are available: 3 node(s) didn't match pod anti-affinity rules. preemption: 0/3 nodes are available: 3 node(s) didn't match pod anti-affinity rules.."
2025-03-31T20:35:44.283275560Z I0331 20:35:44.283155       1 schedule_one.go:988] "Unable to schedule pod; no fit; waiting" pod="openshift-apiserver/apiserver-c685f8bb4-7cvzp" err="0/3 nodes are available: 3 node(s) didn't match pod anti-affinity rules. preemption: 0/3 nodes are available: 3 node(s) didn't match pod anti-affinity rules.."
2025-03-31T20:35:54.295983991Z I0331 20:35:54.295325       1 schedule_one.go:286] "Successfully bound pod to node" pod="openshift-apiserver/apiserver-c685f8bb4-7cvzp" node="host-10-13-0-150" evaluatedNodes=3 feasibleNodes=1
2025-03-31T20:39:01.854208825Z E0331 20:39:01.854143       1 leaderelection.go:332] error retrieving resource lock openshift-kube-scheduler/kube-scheduler: Get "https://api-int.ovhcpococp.trikorasolutions.net:6443/apis/coordination.k8s.io/v1/namespaces/openshift-kube-scheduler/leases/kube-scheduler?timeout=53.5s": context deadline exceeded
2025-03-31T20:39:55.354518743Z E0331 20:39:55.354468       1 leaderelection.go:332] error retrieving resource lock openshift-kube-scheduler/kube-scheduler: Get "https://api-int.ovhcpococp.trikorasolutions.net:6443/apis/coordination.k8s.io/v1/namespaces/openshift-kube-scheduler/leases/kube-scheduler?timeout=53.5s": context deadline exceeded
2025-03-31T20:39:55.354630970Z I0331 20:39:55.354601       1 leaderelection.go:285] failed to renew lease openshift-kube-scheduler/kube-scheduler: timed out waiting for the condition
2025-03-31T20:40:00.383353282Z E0331 20:40:00.383277       1 server.go:252] "Leaderelection lost"
